2019-02-01 11:44:56,982 INFO org.apache.hadoop.yarn.server.resourcemanager.ResourceManager: STARTUP_MSG: 
/************************************************************
STARTUP_MSG: Starting ResourceManager
STARTUP_MSG:   host = ubuntu-HP-Pavilion-dv6-NoteBook-PC/127.0.1.1
STARTUP_MSG:   args = []
STARTUP_MSG:   version = 2.7.3
STARTUP_MSG:   build = https://git-wip-us.apache.org/repos/asf/hadoop.git -r baa91f7c6bc9cb92be5982de4719c1c8af91ccff; compiled by 'root' on 2016-08-18T01:41Z
STARTUP_MSG:   java = 1.8.0_171
************************************************************/
2019-02-01 11:44:57,021 INFO org.apache.hadoop.yarn.server.resourcemanager.ResourceManager: registered UNIX signal handlers for [TERM, HUP, INT]
2019-02-01 11:44:59,166 INFO org.apache.hadoop.conf.Configuration: found resource core-site.xml at file:/opt/hadoop/hadoop-2.7.3/etc/hadoop/core-site.xml
2019-02-01 11:44:59,549 WARN org.apache.hadoop.util.NativeCodeLoader: Unable to load native-hadoop library for your platform... using builtin-java classes where applicable
2019-02-01 11:44:59,768 INFO org.apache.hadoop.security.Groups: clearing userToGroupsMap cache
2019-02-01 11:45:00,605 INFO org.apache.hadoop.conf.Configuration: found resource yarn-site.xml at file:/opt/hadoop/hadoop-2.7.3/etc/hadoop/yarn-site.xml
2019-02-01 11:45:01,820 INFO org.apache.hadoop.yarn.event.AsyncDispatcher: Registering class org.apache.hadoop.yarn.server.resourcemanager.RMFatalEventType for class org.apache.hadoop.yarn.server.resourcemanager.ResourceManager$RMFatalEventDispatcher
2019-02-01 11:45:02,269 INFO org.apache.hadoop.yarn.server.resourcemanager.security.NMTokenSecretManagerInRM: NMTokenKeyRollingInterval: 86400000ms and NMTokenKeyActivationDelay: 900000ms
2019-02-01 11:45:02,308 INFO org.apache.hadoop.yarn.server.resourcemanager.security.RMContainerTokenSecretManager: ContainerTokenKeyRollingInterval: 86400000ms and ContainerTokenKeyActivationDelay: 900000ms
2019-02-01 11:45:02,346 INFO org.apache.hadoop.yarn.server.resourcemanager.security.AMRMTokenSecretManager: AMRMTokenKeyRollingInterval: 86400000ms and AMRMTokenKeyActivationDelay: 900000 ms
2019-02-01 11:45:02,888 INFO org.apache.hadoop.yarn.event.AsyncDispatcher: Registering class org.apache.hadoop.yarn.server.resourcemanager.recovery.RMStateStoreEventType for class org.apache.hadoop.yarn.server.resourcemanager.recovery.RMStateStore$ForwardingEventHandler
2019-02-01 11:45:02,919 INFO org.apache.hadoop.yarn.event.AsyncDispatcher: Registering class org.apache.hadoop.yarn.server.resourcemanager.NodesListManagerEventType for class org.apache.hadoop.yarn.server.resourcemanager.NodesListManager
2019-02-01 11:45:02,920 INFO org.apache.hadoop.yarn.server.resourcemanager.ResourceManager: Using Scheduler: org.apache.hadoop.yarn.server.resourcemanager.scheduler.capacity.CapacityScheduler
2019-02-01 11:45:03,389 INFO org.apache.hadoop.yarn.event.AsyncDispatcher: Registering class org.apache.hadoop.yarn.server.resourcemanager.scheduler.event.SchedulerEventType for class org.apache.hadoop.yarn.server.resourcemanager.ResourceManager$SchedulerEventDispatcher
2019-02-01 11:45:03,391 INFO org.apache.hadoop.yarn.event.AsyncDispatcher: Registering class org.apache.hadoop.yarn.server.resourcemanager.rmapp.RMAppEventType for class org.apache.hadoop.yarn.server.resourcemanager.ResourceManager$ApplicationEventDispatcher
2019-02-01 11:45:03,398 INFO org.apache.hadoop.yarn.event.AsyncDispatcher: Registering class org.apache.hadoop.yarn.server.resourcemanager.rmapp.attempt.RMAppAttemptEventType for class org.apache.hadoop.yarn.server.resourcemanager.ResourceManager$ApplicationAttemptEventDispatcher
2019-02-01 11:45:03,416 INFO org.apache.hadoop.yarn.event.AsyncDispatcher: Registering class org.apache.hadoop.yarn.server.resourcemanager.rmnode.RMNodeEventType for class org.apache.hadoop.yarn.server.resourcemanager.ResourceManager$NodeEventDispatcher
2019-02-01 11:45:05,510 INFO org.apache.hadoop.metrics2.impl.MetricsConfig: loaded properties from hadoop-metrics2.properties
2019-02-01 11:45:06,688 INFO org.apache.hadoop.metrics2.impl.MetricsSystemImpl: Scheduled snapshot period at 10 second(s).
2019-02-01 11:45:06,689 INFO org.apache.hadoop.metrics2.impl.MetricsSystemImpl: ResourceManager metrics system started
2019-02-01 11:45:06,875 INFO org.apache.hadoop.yarn.event.AsyncDispatcher: Registering class org.apache.hadoop.yarn.server.resourcemanager.RMAppManagerEventType for class org.apache.hadoop.yarn.server.resourcemanager.RMAppManager
2019-02-01 11:45:06,935 INFO org.apache.hadoop.yarn.event.AsyncDispatcher: Registering class org.apache.hadoop.yarn.server.resourcemanager.amlauncher.AMLauncherEventType for class org.apache.hadoop.yarn.server.resourcemanager.amlauncher.ApplicationMasterLauncher
2019-02-01 11:45:06,946 INFO org.apache.hadoop.yarn.server.resourcemanager.RMNMInfo: Registered RMNMInfo MBean
2019-02-01 11:45:06,957 INFO org.apache.hadoop.yarn.security.YarnAuthorizationProvider: org.apache.hadoop.yarn.security.ConfiguredYarnAuthorizer is instiantiated.
2019-02-01 11:45:06,961 INFO org.apache.hadoop.util.HostsFileReader: Refreshing hosts (include/exclude) list
2019-02-01 11:45:06,969 INFO org.apache.hadoop.conf.Configuration: found resource capacity-scheduler.xml at file:/opt/hadoop/hadoop-2.7.3/etc/hadoop/capacity-scheduler.xml
2019-02-01 11:45:07,676 INFO org.apache.hadoop.yarn.server.resourcemanager.scheduler.capacity.CapacitySchedulerConfiguration: max alloc mb per queue for root is undefined
2019-02-01 11:45:07,676 INFO org.apache.hadoop.yarn.server.resourcemanager.scheduler.capacity.CapacitySchedulerConfiguration: max alloc vcore per queue for root is undefined
2019-02-01 11:45:07,695 INFO org.apache.hadoop.yarn.server.resourcemanager.scheduler.capacity.ParentQueue: root, capacity=1.0, asboluteCapacity=1.0, maxCapacity=1.0, asboluteMaxCapacity=1.0, state=RUNNING, acls=ADMINISTER_QUEUE:*SUBMIT_APP:*, labels=*,
, reservationsContinueLooking=true
2019-02-01 11:45:07,695 INFO org.apache.hadoop.yarn.server.resourcemanager.scheduler.capacity.ParentQueue: Initialized parent-queue root name=root, fullname=root
2019-02-01 11:45:07,743 INFO org.apache.hadoop.yarn.server.resourcemanager.scheduler.capacity.CapacitySchedulerConfiguration: max alloc mb per queue for root.default is undefined
2019-02-01 11:45:07,744 INFO org.apache.hadoop.yarn.server.resourcemanager.scheduler.capacity.CapacitySchedulerConfiguration: max alloc vcore per queue for root.default is undefined
2019-02-01 11:45:07,825 INFO org.apache.hadoop.yarn.server.resourcemanager.scheduler.capacity.LeafQueue: Initializing default
capacity = 1.0 [= (float) configuredCapacity / 100 ]
asboluteCapacity = 1.0 [= parentAbsoluteCapacity * capacity ]
maxCapacity = 1.0 [= configuredMaxCapacity ]
absoluteMaxCapacity = 1.0 [= 1.0 maximumCapacity undefined, (parentAbsoluteMaxCapacity * maximumCapacity) / 100 otherwise ]
userLimit = 100 [= configuredUserLimit ]
userLimitFactor = 1.0 [= configuredUserLimitFactor ]
maxApplications = 10000 [= configuredMaximumSystemApplicationsPerQueue or (int)(configuredMaximumSystemApplications * absoluteCapacity)]
maxApplicationsPerUser = 10000 [= (int)(maxApplications * (userLimit / 100.0f) * userLimitFactor) ]
usedCapacity = 0.0 [= usedResourcesMemory / (clusterResourceMemory * absoluteCapacity)]
absoluteUsedCapacity = 0.0 [= usedResourcesMemory / clusterResourceMemory]
maxAMResourcePerQueuePercent = 0.1 [= configuredMaximumAMResourcePercent ]
minimumAllocationFactor = 0.875 [= (float)(maximumAllocationMemory - minimumAllocationMemory) / maximumAllocationMemory ]
maximumAllocation = <memory:8192, vCores:32> [= configuredMaxAllocation ]
numContainers = 0 [= currentNumContainers ]
state = RUNNING [= configuredState ]
acls = ADMINISTER_QUEUE:*SUBMIT_APP:* [= configuredAcls ]
nodeLocalityDelay = 40
labels=*,
nodeLocalityDelay = 40
reservationsContinueLooking = true
preemptionDisabled = true

2019-02-01 11:45:07,826 INFO org.apache.hadoop.yarn.server.resourcemanager.scheduler.capacity.CapacityScheduler: Initialized queue: default: capacity=1.0, absoluteCapacity=1.0, usedResources=<memory:0, vCores:0>, usedCapacity=0.0, absoluteUsedCapacity=0.0, numApps=0, numContainers=0
2019-02-01 11:45:07,828 INFO org.apache.hadoop.yarn.server.resourcemanager.scheduler.capacity.CapacityScheduler: Initialized queue: root: numChildQueue= 1, capacity=1.0, absoluteCapacity=1.0, usedResources=<memory:0, vCores:0>usedCapacity=0.0, numApps=0, numContainers=0
2019-02-01 11:45:07,832 INFO org.apache.hadoop.yarn.server.resourcemanager.scheduler.capacity.CapacityScheduler: Initialized root queue root: numChildQueue= 1, capacity=1.0, absoluteCapacity=1.0, usedResources=<memory:0, vCores:0>usedCapacity=0.0, numApps=0, numContainers=0
2019-02-01 11:45:07,832 INFO org.apache.hadoop.yarn.server.resourcemanager.scheduler.capacity.CapacityScheduler: Initialized queue mappings, override: false
2019-02-01 11:45:07,834 INFO org.apache.hadoop.yarn.server.resourcemanager.scheduler.capacity.CapacityScheduler: Initialized CapacityScheduler with calculator=class org.apache.hadoop.yarn.util.resource.DefaultResourceCalculator, minimumAllocation=<<memory:1024, vCores:1>>, maximumAllocation=<<memory:8192, vCores:32>>, asynchronousScheduling=false, asyncScheduleInterval=5ms
2019-02-01 11:45:07,971 INFO org.apache.hadoop.yarn.server.resourcemanager.metrics.SystemMetricsPublisher: YARN system metrics publishing service is not enabled
2019-02-01 11:45:07,972 INFO org.apache.hadoop.yarn.server.resourcemanager.ResourceManager: Transitioning to active state
2019-02-01 11:45:08,173 INFO org.apache.hadoop.yarn.server.resourcemanager.recovery.RMStateStore: Updating AMRMToken
2019-02-01 11:45:08,174 INFO org.apache.hadoop.yarn.server.resourcemanager.security.RMContainerTokenSecretManager: Rolling master-key for container-tokens
2019-02-01 11:45:08,175 INFO org.apache.hadoop.yarn.server.resourcemanager.security.NMTokenSecretManagerInRM: Rolling master-key for nm-tokens
2019-02-01 11:45:08,179 INFO org.apache.hadoop.security.token.delegation.AbstractDelegationTokenSecretManager: Updating the current master key for generating delegation tokens
2019-02-01 11:45:08,183 INFO org.apache.hadoop.yarn.server.resourcemanager.security.RMDelegationTokenSecretManager: storing master key with keyID 1
2019-02-01 11:45:08,184 INFO org.apache.hadoop.yarn.server.resourcemanager.recovery.RMStateStore: Storing RMDTMasterKey.
2019-02-01 11:45:08,194 INFO org.apache.hadoop.security.token.delegation.AbstractDelegationTokenSecretManager: Starting expired delegation token remover thread, tokenRemoverScanInterval=60 min(s)
2019-02-01 11:45:08,229 INFO org.apache.hadoop.yarn.event.AsyncDispatcher: Registering class org.apache.hadoop.yarn.nodelabels.event.NodeLabelsStoreEventType for class org.apache.hadoop.yarn.nodelabels.CommonNodeLabelsManager$ForwardingEventHandler
2019-02-01 11:45:08,232 INFO org.apache.hadoop.security.token.delegation.AbstractDelegationTokenSecretManager: Updating the current master key for generating delegation tokens
2019-02-01 11:45:08,266 INFO org.apache.hadoop.yarn.server.resourcemanager.security.RMDelegationTokenSecretManager: storing master key with keyID 2
2019-02-01 11:45:08,267 INFO org.apache.hadoop.yarn.server.resourcemanager.recovery.RMStateStore: Storing RMDTMasterKey.
2019-02-01 11:45:08,607 INFO org.apache.hadoop.ipc.CallQueueManager: Using callQueue class java.util.concurrent.LinkedBlockingQueue
2019-02-01 11:45:08,785 INFO org.apache.hadoop.ipc.Server: Starting Socket Reader #1 for port 8031
2019-02-01 11:45:09,042 INFO org.apache.hadoop.yarn.factories.impl.pb.RpcServerFactoryPBImpl: Adding protocol org.apache.hadoop.yarn.server.api.ResourceTrackerPB to the server
2019-02-01 11:45:09,044 INFO org.apache.hadoop.ipc.Server: IPC Server Responder: starting
2019-02-01 11:45:09,125 INFO org.apache.hadoop.ipc.Server: IPC Server listener on 8031: starting
2019-02-01 11:45:09,501 INFO org.apache.hadoop.ipc.CallQueueManager: Using callQueue class java.util.concurrent.LinkedBlockingQueue
2019-02-01 11:45:09,557 INFO org.apache.hadoop.ipc.Server: Starting Socket Reader #1 for port 8030
2019-02-01 11:45:09,620 INFO org.apache.hadoop.yarn.factories.impl.pb.RpcServerFactoryPBImpl: Adding protocol org.apache.hadoop.yarn.api.ApplicationMasterProtocolPB to the server
2019-02-01 11:45:09,642 INFO org.apache.hadoop.ipc.Server: IPC Server Responder: starting
2019-02-01 11:45:09,653 INFO org.apache.hadoop.ipc.Server: IPC Server listener on 8030: starting
2019-02-01 11:45:11,045 INFO org.apache.hadoop.ipc.CallQueueManager: Using callQueue class java.util.concurrent.LinkedBlockingQueue
2019-02-01 11:45:11,086 INFO org.apache.hadoop.ipc.Server: Starting Socket Reader #1 for port 8032
2019-02-01 11:45:11,223 INFO org.apache.hadoop.yarn.factories.impl.pb.RpcServerFactoryPBImpl: Adding protocol org.apache.hadoop.yarn.api.ApplicationClientProtocolPB to the server
2019-02-01 11:45:11,224 INFO org.apache.hadoop.ipc.Server: IPC Server Responder: starting
2019-02-01 11:45:11,264 INFO org.apache.hadoop.ipc.Server: IPC Server listener on 8032: starting
2019-02-01 11:45:11,475 INFO org.apache.hadoop.yarn.server.resourcemanager.ResourceManager: Transitioned to active state
2019-02-01 11:45:12,957 INFO org.mortbay.log: Logging to org.slf4j.impl.Log4jLoggerAdapter(org.mortbay.log) via org.mortbay.log.Slf4jLog
2019-02-01 11:45:13,012 INFO org.apache.hadoop.security.authentication.server.AuthenticationFilter: Unable to initialize FileSignerSecretProvider, falling back to use random secrets.
2019-02-01 11:45:13,055 INFO org.apache.hadoop.http.HttpRequestLog: Http request log for http.requests.resourcemanager is not defined
2019-02-01 11:45:13,264 INFO org.apache.hadoop.http.HttpServer2: Added global filter 'safety' (class=org.apache.hadoop.http.HttpServer2$QuotingInputFilter)
2019-02-01 11:45:13,340 INFO org.apache.hadoop.http.HttpServer2: Added filter RMAuthenticationFilter (class=org.apache.hadoop.yarn.server.security.http.RMAuthenticationFilter) to context cluster
2019-02-01 11:45:13,349 INFO org.apache.hadoop.http.HttpServer2: Added filter RMAuthenticationFilter (class=org.apache.hadoop.yarn.server.security.http.RMAuthenticationFilter) to context static
2019-02-01 11:45:13,350 INFO org.apache.hadoop.http.HttpServer2: Added filter RMAuthenticationFilter (class=org.apache.hadoop.yarn.server.security.http.RMAuthenticationFilter) to context logs
2019-02-01 11:45:13,416 INFO org.apache.hadoop.http.HttpServer2: Added filter static_user_filter (class=org.apache.hadoop.http.lib.StaticUserWebFilter$StaticUserFilter) to context cluster
2019-02-01 11:45:13,427 INFO org.apache.hadoop.http.HttpServer2: Added filter static_user_filter (class=org.apache.hadoop.http.lib.StaticUserWebFilter$StaticUserFilter) to context static
2019-02-01 11:45:13,427 INFO org.apache.hadoop.http.HttpServer2: Added filter static_user_filter (class=org.apache.hadoop.http.lib.StaticUserWebFilter$StaticUserFilter) to context logs
2019-02-01 11:45:13,495 INFO org.apache.hadoop.http.HttpServer2: adding path spec: /cluster/*
2019-02-01 11:45:13,496 INFO org.apache.hadoop.http.HttpServer2: adding path spec: /ws/*
2019-02-01 11:45:17,420 INFO org.apache.hadoop.yarn.webapp.WebApps: Registered webapp guice modules
2019-02-01 11:45:17,429 INFO org.apache.hadoop.http.HttpServer2: Jetty bound to port 8088
2019-02-01 11:45:17,430 INFO org.mortbay.log: jetty-6.1.26
2019-02-01 11:45:18,300 INFO org.mortbay.log: Extract jar:file:/opt/hadoop/hadoop-2.7.3/share/hadoop/yarn/hadoop-yarn-common-2.7.3.jar!/webapps/cluster to /tmp/Jetty_0_0_0_0_8088_cluster____u0rgz3/webapp
2019-02-01 11:45:19,852 INFO org.apache.hadoop.security.token.delegation.AbstractDelegationTokenSecretManager: Updating the current master key for generating delegation tokens
2019-02-01 11:45:19,862 INFO org.apache.hadoop.security.token.delegation.AbstractDelegationTokenSecretManager: Starting expired delegation token remover thread, tokenRemoverScanInterval=60 min(s)
2019-02-01 11:45:19,869 INFO org.apache.hadoop.security.token.delegation.AbstractDelegationTokenSecretManager: Updating the current master key for generating delegation tokens
2019-02-01 11:45:40,962 INFO org.apache.hadoop.yarn.util.RackResolver: Resolved ubuntu-HP-Pavilion-dv6-NoteBook-PC to /default-rack
2019-02-01 11:45:40,986 INFO org.apache.hadoop.yarn.server.resourcemanager.ResourceTrackerService: NodeManager from node ubuntu-HP-Pavilion-dv6-NoteBook-PC(cmPort: 35625 httpPort: 8042) registered with capability: <memory:8192, vCores:8>, assigned nodeId ubuntu-HP-Pavilion-dv6-NoteBook-PC:35625
2019-02-01 11:45:41,183 INFO org.mortbay.log: Started HttpServer2$SelectChannelConnectorWithSafeStartup@0.0.0.0:8088
2019-02-01 11:45:41,183 INFO org.apache.hadoop.yarn.webapp.WebApps: Web app cluster started at 8088
2019-02-01 11:45:41,464 INFO org.apache.hadoop.yarn.server.resourcemanager.rmnode.RMNodeImpl: ubuntu-HP-Pavilion-dv6-NoteBook-PC:35625 Node Transitioned from NEW to RUNNING
2019-02-01 11:45:41,530 INFO org.apache.hadoop.ipc.CallQueueManager: Using callQueue class java.util.concurrent.LinkedBlockingQueue
2019-02-01 11:45:41,553 INFO org.apache.hadoop.ipc.Server: Starting Socket Reader #1 for port 8033
2019-02-01 11:45:41,534 INFO org.apache.hadoop.yarn.server.resourcemanager.scheduler.capacity.CapacityScheduler: Added node ubuntu-HP-Pavilion-dv6-NoteBook-PC:35625 clusterResource: <memory:8192, vCores:8>
2019-02-01 11:45:41,579 INFO org.apache.hadoop.yarn.factories.impl.pb.RpcServerFactoryPBImpl: Adding protocol org.apache.hadoop.yarn.server.api.ResourceManagerAdministrationProtocolPB to the server
2019-02-01 11:45:41,584 INFO org.apache.hadoop.ipc.Server: IPC Server Responder: starting
2019-02-01 11:45:41,590 INFO org.apache.hadoop.ipc.Server: IPC Server listener on 8033: starting
2019-02-01 11:55:06,969 INFO org.apache.hadoop.yarn.server.resourcemanager.scheduler.AbstractYarnScheduler: Release request cache is cleaned up
2019-02-01 12:23:17,529 INFO org.apache.hadoop.ipc.Server: Socket Reader #1 for port 8030: readAndProcess from client 127.0.0.1 threw exception [org.apache.hadoop.security.AccessControlException: SIMPLE authentication is not enabled.  Available:[TOKEN]]
org.apache.hadoop.security.AccessControlException: SIMPLE authentication is not enabled.  Available:[TOKEN]
	at org.apache.hadoop.ipc.Server$Connection.initializeAuthContext(Server.java:1564)
	at org.apache.hadoop.ipc.Server$Connection.readAndProcess(Server.java:1520)
	at org.apache.hadoop.ipc.Server$Listener.doRead(Server.java:771)
	at org.apache.hadoop.ipc.Server$Listener$Reader.doRunLoop(Server.java:637)
	at org.apache.hadoop.ipc.Server$Listener$Reader.run(Server.java:608)
2019-02-01 12:23:17,606 INFO org.apache.hadoop.ipc.Server: Socket Reader #1 for port 8030: readAndProcess from client 127.0.0.1 threw exception [org.apache.hadoop.security.AccessControlException: SIMPLE authentication is not enabled.  Available:[TOKEN]]
org.apache.hadoop.security.AccessControlException: SIMPLE authentication is not enabled.  Available:[TOKEN]
	at org.apache.hadoop.ipc.Server$Connection.initializeAuthContext(Server.java:1564)
	at org.apache.hadoop.ipc.Server$Connection.readAndProcess(Server.java:1520)
	at org.apache.hadoop.ipc.Server$Listener.doRead(Server.java:771)
	at org.apache.hadoop.ipc.Server$Listener$Reader.doRunLoop(Server.java:637)
	at org.apache.hadoop.ipc.Server$Listener$Reader.run(Server.java:608)
2019-02-01 12:38:42,521 ERROR org.apache.hadoop.yarn.server.resourcemanager.ResourceManager: RECEIVED SIGNAL 15: SIGTERM
2019-02-01 12:38:42,531 ERROR org.apache.hadoop.security.token.delegation.AbstractDelegationTokenSecretManager: ExpiredTokenRemover received java.lang.InterruptedException: sleep interrupted
2019-02-01 12:38:42,535 INFO org.mortbay.log: Stopped HttpServer2$SelectChannelConnectorWithSafeStartup@0.0.0.0:8088
2019-02-01 12:38:42,539 INFO org.apache.hadoop.ipc.Server: Stopping server on 8032
2019-02-01 12:38:42,545 INFO org.apache.hadoop.ipc.Server: Stopping IPC Server listener on 8032
2019-02-01 12:38:42,545 INFO org.apache.hadoop.ipc.Server: Stopping IPC Server Responder
2019-02-01 12:38:42,548 INFO org.apache.hadoop.ipc.Server: Stopping server on 8033
2019-02-01 12:38:42,549 INFO org.apache.hadoop.ipc.Server: Stopping IPC Server listener on 8033
2019-02-01 12:38:42,549 INFO org.apache.hadoop.ipc.Server: Stopping IPC Server Responder
2019-02-01 12:38:42,552 INFO org.apache.hadoop.yarn.server.resourcemanager.ResourceManager: Transitioning to standby state
2019-02-01 12:38:42,553 WARN org.apache.hadoop.yarn.server.resourcemanager.amlauncher.ApplicationMasterLauncher: org.apache.hadoop.yarn.server.resourcemanager.amlauncher.ApplicationMasterLauncher$LauncherThread interrupted. Returning.
2019-02-01 12:38:42,553 INFO org.apache.hadoop.ipc.Server: Stopping server on 8030
2019-02-01 12:38:42,558 INFO org.apache.hadoop.ipc.Server: Stopping IPC Server listener on 8030
2019-02-01 12:38:42,559 INFO org.apache.hadoop.ipc.Server: Stopping IPC Server Responder
2019-02-01 12:38:42,559 INFO org.apache.hadoop.ipc.Server: Stopping server on 8031
2019-02-01 12:38:42,564 INFO org.apache.hadoop.ipc.Server: Stopping IPC Server listener on 8031
2019-02-01 12:38:42,564 INFO org.apache.hadoop.ipc.Server: Stopping IPC Server Responder
2019-02-01 12:38:42,564 INFO org.apache.hadoop.yarn.util.AbstractLivelinessMonitor: NMLivelinessMonitor thread interrupted
2019-02-01 12:38:42,565 ERROR org.apache.hadoop.yarn.server.resourcemanager.ResourceManager: Returning, interrupted : java.lang.InterruptedException
2019-02-01 12:38:42,565 INFO org.apache.hadoop.yarn.event.AsyncDispatcher: AsyncDispatcher is draining to stop, igonring any new events.
2019-02-01 12:38:42,566 INFO org.apache.hadoop.yarn.util.AbstractLivelinessMonitor: AMLivelinessMonitor thread interrupted
2019-02-01 12:38:42,566 INFO org.apache.hadoop.yarn.util.AbstractLivelinessMonitor: AMLivelinessMonitor thread interrupted
2019-02-01 12:38:42,566 INFO org.apache.hadoop.yarn.util.AbstractLivelinessMonitor: org.apache.hadoop.yarn.server.resourcemanager.rmcontainer.ContainerAllocationExpirer thread interrupted
2019-02-01 12:38:42,567 ERROR org.apache.hadoop.security.token.delegation.AbstractDelegationTokenSecretManager: ExpiredTokenRemover received java.lang.InterruptedException: sleep interrupted
2019-02-01 12:38:42,567 INFO org.apache.hadoop.metrics2.impl.MetricsSystemImpl: Stopping ResourceManager metrics system...
2019-02-01 12:38:42,569 INFO org.apache.hadoop.metrics2.impl.MetricsSystemImpl: ResourceManager metrics system stopped.
2019-02-01 12:38:42,569 INFO org.apache.hadoop.metrics2.impl.MetricsSystemImpl: ResourceManager metrics system shutdown complete.
2019-02-01 12:38:42,569 INFO org.apache.hadoop.yarn.event.AsyncDispatcher: AsyncDispatcher is draining to stop, igonring any new events.
2019-02-01 12:38:42,570 INFO org.apache.hadoop.yarn.server.resourcemanager.ResourceManager: Transitioned to standby state
2019-02-01 12:38:42,570 INFO org.apache.hadoop.yarn.server.resourcemanager.ResourceManager: SHUTDOWN_MSG: 
/************************************************************
SHUTDOWN_MSG: Shutting down ResourceManager at ubuntu-HP-Pavilion-dv6-NoteBook-PC/127.0.1.1
************************************************************/
2019-02-03 09:50:06,290 INFO org.apache.hadoop.yarn.server.resourcemanager.ResourceManager: STARTUP_MSG: 
/************************************************************
STARTUP_MSG: Starting ResourceManager
STARTUP_MSG:   host = ubuntu-HP-Pavilion-dv6-NoteBook-PC/127.0.1.1
STARTUP_MSG:   args = []
STARTUP_MSG:   version = 2.7.3
STARTUP_MSG:   build = https://git-wip-us.apache.org/repos/asf/hadoop.git -r baa91f7c6bc9cb92be5982de4719c1c8af91ccff; compiled by 'root' on 2016-08-18T01:41Z
STARTUP_MSG:   java = 1.8.0_171
************************************************************/
2019-02-03 09:50:06,318 INFO org.apache.hadoop.yarn.server.resourcemanager.ResourceManager: registered UNIX signal handlers for [TERM, HUP, INT]
2019-02-03 09:50:06,653 INFO org.apache.hadoop.conf.Configuration: found resource core-site.xml at file:/opt/hadoop/hadoop-2.7.3/etc/hadoop/core-site.xml
2019-02-03 09:50:06,720 WARN org.apache.hadoop.util.NativeCodeLoader: Unable to load native-hadoop library for your platform... using builtin-java classes where applicable
2019-02-03 09:50:06,767 INFO org.apache.hadoop.security.Groups: clearing userToGroupsMap cache
2019-02-03 09:50:06,946 INFO org.apache.hadoop.conf.Configuration: found resource yarn-site.xml at file:/opt/hadoop/hadoop-2.7.3/etc/hadoop/yarn-site.xml
2019-02-03 09:50:07,175 INFO org.apache.hadoop.yarn.event.AsyncDispatcher: Registering class org.apache.hadoop.yarn.server.resourcemanager.RMFatalEventType for class org.apache.hadoop.yarn.server.resourcemanager.ResourceManager$RMFatalEventDispatcher
2019-02-03 09:50:07,281 INFO org.apache.hadoop.yarn.server.resourcemanager.security.NMTokenSecretManagerInRM: NMTokenKeyRollingInterval: 86400000ms and NMTokenKeyActivationDelay: 900000ms
2019-02-03 09:50:07,288 INFO org.apache.hadoop.yarn.server.resourcemanager.security.RMContainerTokenSecretManager: ContainerTokenKeyRollingInterval: 86400000ms and ContainerTokenKeyActivationDelay: 900000ms
2019-02-03 09:50:07,296 INFO org.apache.hadoop.yarn.server.resourcemanager.security.AMRMTokenSecretManager: AMRMTokenKeyRollingInterval: 86400000ms and AMRMTokenKeyActivationDelay: 900000 ms
2019-02-03 09:50:07,359 INFO org.apache.hadoop.yarn.event.AsyncDispatcher: Registering class org.apache.hadoop.yarn.server.resourcemanager.recovery.RMStateStoreEventType for class org.apache.hadoop.yarn.server.resourcemanager.recovery.RMStateStore$ForwardingEventHandler
2019-02-03 09:50:07,361 INFO org.apache.hadoop.yarn.event.AsyncDispatcher: Registering class org.apache.hadoop.yarn.server.resourcemanager.NodesListManagerEventType for class org.apache.hadoop.yarn.server.resourcemanager.NodesListManager
2019-02-03 09:50:07,361 INFO org.apache.hadoop.yarn.server.resourcemanager.ResourceManager: Using Scheduler: org.apache.hadoop.yarn.server.resourcemanager.scheduler.capacity.CapacityScheduler
2019-02-03 09:50:07,390 INFO org.apache.hadoop.yarn.event.AsyncDispatcher: Registering class org.apache.hadoop.yarn.server.resourcemanager.scheduler.event.SchedulerEventType for class org.apache.hadoop.yarn.server.resourcemanager.ResourceManager$SchedulerEventDispatcher
2019-02-03 09:50:07,391 INFO org.apache.hadoop.yarn.event.AsyncDispatcher: Registering class org.apache.hadoop.yarn.server.resourcemanager.rmapp.RMAppEventType for class org.apache.hadoop.yarn.server.resourcemanager.ResourceManager$ApplicationEventDispatcher
2019-02-03 09:50:07,392 INFO org.apache.hadoop.yarn.event.AsyncDispatcher: Registering class org.apache.hadoop.yarn.server.resourcemanager.rmapp.attempt.RMAppAttemptEventType for class org.apache.hadoop.yarn.server.resourcemanager.ResourceManager$ApplicationAttemptEventDispatcher
2019-02-03 09:50:07,393 INFO org.apache.hadoop.yarn.event.AsyncDispatcher: Registering class org.apache.hadoop.yarn.server.resourcemanager.rmnode.RMNodeEventType for class org.apache.hadoop.yarn.server.resourcemanager.ResourceManager$NodeEventDispatcher
2019-02-03 09:50:07,505 INFO org.apache.hadoop.metrics2.impl.MetricsConfig: loaded properties from hadoop-metrics2.properties
2019-02-03 09:50:07,607 INFO org.apache.hadoop.metrics2.impl.MetricsSystemImpl: Scheduled snapshot period at 10 second(s).
2019-02-03 09:50:07,607 INFO org.apache.hadoop.metrics2.impl.MetricsSystemImpl: ResourceManager metrics system started
2019-02-03 09:50:07,641 INFO org.apache.hadoop.yarn.event.AsyncDispatcher: Registering class org.apache.hadoop.yarn.server.resourcemanager.RMAppManagerEventType for class org.apache.hadoop.yarn.server.resourcemanager.RMAppManager
2019-02-03 09:50:07,668 INFO org.apache.hadoop.yarn.event.AsyncDispatcher: Registering class org.apache.hadoop.yarn.server.resourcemanager.amlauncher.AMLauncherEventType for class org.apache.hadoop.yarn.server.resourcemanager.amlauncher.ApplicationMasterLauncher
2019-02-03 09:50:07,672 INFO org.apache.hadoop.yarn.server.resourcemanager.RMNMInfo: Registered RMNMInfo MBean
2019-02-03 09:50:07,675 INFO org.apache.hadoop.yarn.security.YarnAuthorizationProvider: org.apache.hadoop.yarn.security.ConfiguredYarnAuthorizer is instiantiated.
2019-02-03 09:50:07,676 INFO org.apache.hadoop.util.HostsFileReader: Refreshing hosts (include/exclude) list
2019-02-03 09:50:07,691 INFO org.apache.hadoop.conf.Configuration: found resource capacity-scheduler.xml at file:/opt/hadoop/hadoop-2.7.3/etc/hadoop/capacity-scheduler.xml
2019-02-03 09:50:07,845 INFO org.apache.hadoop.yarn.server.resourcemanager.scheduler.capacity.CapacitySchedulerConfiguration: max alloc mb per queue for root is undefined
2019-02-03 09:50:07,845 INFO org.apache.hadoop.yarn.server.resourcemanager.scheduler.capacity.CapacitySchedulerConfiguration: max alloc vcore per queue for root is undefined
2019-02-03 09:50:07,851 INFO org.apache.hadoop.yarn.server.resourcemanager.scheduler.capacity.ParentQueue: root, capacity=1.0, asboluteCapacity=1.0, maxCapacity=1.0, asboluteMaxCapacity=1.0, state=RUNNING, acls=ADMINISTER_QUEUE:*SUBMIT_APP:*, labels=*,
, reservationsContinueLooking=true
2019-02-03 09:50:07,851 INFO org.apache.hadoop.yarn.server.resourcemanager.scheduler.capacity.ParentQueue: Initialized parent-queue root name=root, fullname=root
2019-02-03 09:50:07,865 INFO org.apache.hadoop.yarn.server.resourcemanager.scheduler.capacity.CapacitySchedulerConfiguration: max alloc mb per queue for root.default is undefined
2019-02-03 09:50:07,865 INFO org.apache.hadoop.yarn.server.resourcemanager.scheduler.capacity.CapacitySchedulerConfiguration: max alloc vcore per queue for root.default is undefined
2019-02-03 09:50:07,866 INFO org.apache.hadoop.yarn.server.resourcemanager.scheduler.capacity.LeafQueue: Initializing default
capacity = 1.0 [= (float) configuredCapacity / 100 ]
asboluteCapacity = 1.0 [= parentAbsoluteCapacity * capacity ]
maxCapacity = 1.0 [= configuredMaxCapacity ]
absoluteMaxCapacity = 1.0 [= 1.0 maximumCapacity undefined, (parentAbsoluteMaxCapacity * maximumCapacity) / 100 otherwise ]
userLimit = 100 [= configuredUserLimit ]
userLimitFactor = 1.0 [= configuredUserLimitFactor ]
maxApplications = 10000 [= configuredMaximumSystemApplicationsPerQueue or (int)(configuredMaximumSystemApplications * absoluteCapacity)]
maxApplicationsPerUser = 10000 [= (int)(maxApplications * (userLimit / 100.0f) * userLimitFactor) ]
usedCapacity = 0.0 [= usedResourcesMemory / (clusterResourceMemory * absoluteCapacity)]
absoluteUsedCapacity = 0.0 [= usedResourcesMemory / clusterResourceMemory]
maxAMResourcePerQueuePercent = 0.1 [= configuredMaximumAMResourcePercent ]
minimumAllocationFactor = 0.875 [= (float)(maximumAllocationMemory - minimumAllocationMemory) / maximumAllocationMemory ]
maximumAllocation = <memory:8192, vCores:32> [= configuredMaxAllocation ]
numContainers = 0 [= currentNumContainers ]
state = RUNNING [= configuredState ]
acls = ADMINISTER_QUEUE:*SUBMIT_APP:* [= configuredAcls ]
nodeLocalityDelay = 40
labels=*,
nodeLocalityDelay = 40
reservationsContinueLooking = true
preemptionDisabled = true

2019-02-03 09:50:07,866 INFO org.apache.hadoop.yarn.server.resourcemanager.scheduler.capacity.CapacityScheduler: Initialized queue: default: capacity=1.0, absoluteCapacity=1.0, usedResources=<memory:0, vCores:0>, usedCapacity=0.0, absoluteUsedCapacity=0.0, numApps=0, numContainers=0
2019-02-03 09:50:07,866 INFO org.apache.hadoop.yarn.server.resourcemanager.scheduler.capacity.CapacityScheduler: Initialized queue: root: numChildQueue= 1, capacity=1.0, absoluteCapacity=1.0, usedResources=<memory:0, vCores:0>usedCapacity=0.0, numApps=0, numContainers=0
2019-02-03 09:50:07,867 INFO org.apache.hadoop.yarn.server.resourcemanager.scheduler.capacity.CapacityScheduler: Initialized root queue root: numChildQueue= 1, capacity=1.0, absoluteCapacity=1.0, usedResources=<memory:0, vCores:0>usedCapacity=0.0, numApps=0, numContainers=0
2019-02-03 09:50:07,867 INFO org.apache.hadoop.yarn.server.resourcemanager.scheduler.capacity.CapacityScheduler: Initialized queue mappings, override: false
2019-02-03 09:50:07,868 INFO org.apache.hadoop.yarn.server.resourcemanager.scheduler.capacity.CapacityScheduler: Initialized CapacityScheduler with calculator=class org.apache.hadoop.yarn.util.resource.DefaultResourceCalculator, minimumAllocation=<<memory:1024, vCores:1>>, maximumAllocation=<<memory:8192, vCores:32>>, asynchronousScheduling=false, asyncScheduleInterval=5ms
2019-02-03 09:50:07,894 INFO org.apache.hadoop.yarn.server.resourcemanager.metrics.SystemMetricsPublisher: YARN system metrics publishing service is not enabled
2019-02-03 09:50:07,894 INFO org.apache.hadoop.yarn.server.resourcemanager.ResourceManager: Transitioning to active state
2019-02-03 09:50:07,926 INFO org.apache.hadoop.yarn.server.resourcemanager.recovery.RMStateStore: Updating AMRMToken
2019-02-03 09:50:07,926 INFO org.apache.hadoop.yarn.server.resourcemanager.security.RMContainerTokenSecretManager: Rolling master-key for container-tokens
2019-02-03 09:50:07,927 INFO org.apache.hadoop.yarn.server.resourcemanager.security.NMTokenSecretManagerInRM: Rolling master-key for nm-tokens
2019-02-03 09:50:07,927 INFO org.apache.hadoop.security.token.delegation.AbstractDelegationTokenSecretManager: Updating the current master key for generating delegation tokens
2019-02-03 09:50:07,928 INFO org.apache.hadoop.yarn.server.resourcemanager.security.RMDelegationTokenSecretManager: storing master key with keyID 1
2019-02-03 09:50:07,928 INFO org.apache.hadoop.yarn.server.resourcemanager.recovery.RMStateStore: Storing RMDTMasterKey.
2019-02-03 09:50:07,930 INFO org.apache.hadoop.security.token.delegation.AbstractDelegationTokenSecretManager: Starting expired delegation token remover thread, tokenRemoverScanInterval=60 min(s)
2019-02-03 09:50:07,930 INFO org.apache.hadoop.security.token.delegation.AbstractDelegationTokenSecretManager: Updating the current master key for generating delegation tokens
2019-02-03 09:50:07,930 INFO org.apache.hadoop.yarn.server.resourcemanager.security.RMDelegationTokenSecretManager: storing master key with keyID 2
2019-02-03 09:50:07,930 INFO org.apache.hadoop.yarn.server.resourcemanager.recovery.RMStateStore: Storing RMDTMasterKey.
2019-02-03 09:50:07,945 INFO org.apache.hadoop.yarn.event.AsyncDispatcher: Registering class org.apache.hadoop.yarn.nodelabels.event.NodeLabelsStoreEventType for class org.apache.hadoop.yarn.nodelabels.CommonNodeLabelsManager$ForwardingEventHandler
2019-02-03 09:50:08,000 INFO org.apache.hadoop.ipc.CallQueueManager: Using callQueue class java.util.concurrent.LinkedBlockingQueue
2019-02-03 09:50:08,014 INFO org.apache.hadoop.ipc.Server: Starting Socket Reader #1 for port 8031
2019-02-03 09:50:08,031 INFO org.apache.hadoop.yarn.factories.impl.pb.RpcServerFactoryPBImpl: Adding protocol org.apache.hadoop.yarn.server.api.ResourceTrackerPB to the server
2019-02-03 09:50:08,032 INFO org.apache.hadoop.ipc.Server: IPC Server Responder: starting
2019-02-03 09:50:08,032 INFO org.apache.hadoop.ipc.Server: IPC Server listener on 8031: starting
2019-02-03 09:50:08,101 INFO org.apache.hadoop.ipc.CallQueueManager: Using callQueue class java.util.concurrent.LinkedBlockingQueue
2019-02-03 09:50:08,109 INFO org.apache.hadoop.ipc.Server: Starting Socket Reader #1 for port 8030
2019-02-03 09:50:08,120 INFO org.apache.hadoop.yarn.factories.impl.pb.RpcServerFactoryPBImpl: Adding protocol org.apache.hadoop.yarn.api.ApplicationMasterProtocolPB to the server
2019-02-03 09:50:08,120 INFO org.apache.hadoop.ipc.Server: IPC Server Responder: starting
2019-02-03 09:50:08,120 INFO org.apache.hadoop.ipc.Server: IPC Server listener on 8030: starting
2019-02-03 09:50:08,219 INFO org.apache.hadoop.ipc.CallQueueManager: Using callQueue class java.util.concurrent.LinkedBlockingQueue
2019-02-03 09:50:08,220 INFO org.apache.hadoop.ipc.Server: Starting Socket Reader #1 for port 8032
2019-02-03 09:50:08,223 INFO org.apache.hadoop.yarn.factories.impl.pb.RpcServerFactoryPBImpl: Adding protocol org.apache.hadoop.yarn.api.ApplicationClientProtocolPB to the server
2019-02-03 09:50:08,225 INFO org.apache.hadoop.ipc.Server: IPC Server Responder: starting
2019-02-03 09:50:08,225 INFO org.apache.hadoop.ipc.Server: IPC Server listener on 8032: starting
2019-02-03 09:50:08,249 INFO org.apache.hadoop.yarn.server.resourcemanager.ResourceManager: Transitioned to active state
2019-02-03 09:50:08,363 INFO org.mortbay.log: Logging to org.slf4j.impl.Log4jLoggerAdapter(org.mortbay.log) via org.mortbay.log.Slf4jLog
2019-02-03 09:50:08,376 INFO org.apache.hadoop.security.authentication.server.AuthenticationFilter: Unable to initialize FileSignerSecretProvider, falling back to use random secrets.
2019-02-03 09:50:08,425 INFO org.apache.hadoop.http.HttpRequestLog: Http request log for http.requests.resourcemanager is not defined
2019-02-03 09:50:08,439 INFO org.apache.hadoop.http.HttpServer2: Added global filter 'safety' (class=org.apache.hadoop.http.HttpServer2$QuotingInputFilter)
2019-02-03 09:50:08,457 INFO org.apache.hadoop.http.HttpServer2: Added filter RMAuthenticationFilter (class=org.apache.hadoop.yarn.server.security.http.RMAuthenticationFilter) to context cluster
2019-02-03 09:50:08,458 INFO org.apache.hadoop.http.HttpServer2: Added filter RMAuthenticationFilter (class=org.apache.hadoop.yarn.server.security.http.RMAuthenticationFilter) to context static
2019-02-03 09:50:08,458 INFO org.apache.hadoop.http.HttpServer2: Added filter RMAuthenticationFilter (class=org.apache.hadoop.yarn.server.security.http.RMAuthenticationFilter) to context logs
2019-02-03 09:50:08,459 INFO org.apache.hadoop.http.HttpServer2: Added filter static_user_filter (class=org.apache.hadoop.http.lib.StaticUserWebFilter$StaticUserFilter) to context cluster
2019-02-03 09:50:08,460 INFO org.apache.hadoop.http.HttpServer2: Added filter static_user_filter (class=org.apache.hadoop.http.lib.StaticUserWebFilter$StaticUserFilter) to context static
2019-02-03 09:50:08,460 INFO org.apache.hadoop.http.HttpServer2: Added filter static_user_filter (class=org.apache.hadoop.http.lib.StaticUserWebFilter$StaticUserFilter) to context logs
2019-02-03 09:50:08,469 INFO org.apache.hadoop.http.HttpServer2: adding path spec: /cluster/*
2019-02-03 09:50:08,469 INFO org.apache.hadoop.http.HttpServer2: adding path spec: /ws/*
2019-02-03 09:50:09,292 INFO org.apache.hadoop.yarn.webapp.WebApps: Registered webapp guice modules
2019-02-03 09:50:09,296 INFO org.apache.hadoop.http.HttpServer2: Jetty bound to port 8088
2019-02-03 09:50:09,297 INFO org.mortbay.log: jetty-6.1.26
2019-02-03 09:50:09,474 INFO org.mortbay.log: Extract jar:file:/opt/hadoop/hadoop-2.7.3/share/hadoop/yarn/hadoop-yarn-common-2.7.3.jar!/webapps/cluster to /tmp/Jetty_0_0_0_0_8088_cluster____u0rgz3/webapp
2019-02-03 09:50:09,807 INFO org.apache.hadoop.security.token.delegation.AbstractDelegationTokenSecretManager: Updating the current master key for generating delegation tokens
2019-02-03 09:50:09,807 INFO org.apache.hadoop.security.token.delegation.AbstractDelegationTokenSecretManager: Starting expired delegation token remover thread, tokenRemoverScanInterval=60 min(s)
2019-02-03 09:50:09,808 INFO org.apache.hadoop.security.token.delegation.AbstractDelegationTokenSecretManager: Updating the current master key for generating delegation tokens
2019-02-03 09:50:12,722 INFO org.mortbay.log: Started HttpServer2$SelectChannelConnectorWithSafeStartup@0.0.0.0:8088
2019-02-03 09:50:12,723 INFO org.apache.hadoop.yarn.webapp.WebApps: Web app cluster started at 8088
2019-02-03 09:50:12,762 INFO org.apache.hadoop.ipc.CallQueueManager: Using callQueue class java.util.concurrent.LinkedBlockingQueue
2019-02-03 09:50:12,763 INFO org.apache.hadoop.ipc.Server: Starting Socket Reader #1 for port 8033
2019-02-03 09:50:12,769 INFO org.apache.hadoop.yarn.factories.impl.pb.RpcServerFactoryPBImpl: Adding protocol org.apache.hadoop.yarn.server.api.ResourceManagerAdministrationProtocolPB to the server
2019-02-03 09:50:12,773 INFO org.apache.hadoop.ipc.Server: IPC Server Responder: starting
2019-02-03 09:50:12,776 INFO org.apache.hadoop.ipc.Server: IPC Server listener on 8033: starting
2019-02-03 09:50:13,682 INFO org.apache.hadoop.yarn.util.RackResolver: Resolved ubuntu-HP-Pavilion-dv6-NoteBook-PC to /default-rack
2019-02-03 09:50:13,692 INFO org.apache.hadoop.yarn.server.resourcemanager.rmnode.RMNodeImpl: ubuntu-HP-Pavilion-dv6-NoteBook-PC:36263 Node Transitioned from NEW to RUNNING
2019-02-03 09:50:13,697 INFO org.apache.hadoop.yarn.server.resourcemanager.scheduler.capacity.CapacityScheduler: Added node ubuntu-HP-Pavilion-dv6-NoteBook-PC:36263 clusterResource: <memory:8192, vCores:8>
2019-02-03 09:50:13,699 INFO org.apache.hadoop.yarn.server.resourcemanager.ResourceTrackerService: NodeManager from node ubuntu-HP-Pavilion-dv6-NoteBook-PC(cmPort: 36263 httpPort: 8042) registered with capability: <memory:8192, vCores:8>, assigned nodeId ubuntu-HP-Pavilion-dv6-NoteBook-PC:36263
2019-02-03 10:00:07,692 INFO org.apache.hadoop.yarn.server.resourcemanager.scheduler.AbstractYarnScheduler: Release request cache is cleaned up
2019-02-03 12:11:41,205 INFO org.apache.hadoop.yarn.server.resourcemanager.ClientRMService: Allocated new applicationId: 1
2019-02-03 12:11:42,240 INFO org.apache.hadoop.yarn.server.resourcemanager.ClientRMService: Application with id 1 submitted by user root
2019-02-03 12:11:42,241 INFO org.apache.hadoop.yarn.server.resourcemanager.rmapp.RMAppImpl: Storing application with id application_1549167607896_0001
2019-02-03 12:11:42,243 INFO org.apache.hadoop.yarn.server.resourcemanager.RMAuditLogger: USER=root	IP=127.0.0.1	OPERATION=Submit Application Request	TARGET=ClientRMService	RESULT=SUCCESS	APPID=application_1549167607896_0001
2019-02-03 12:11:42,251 INFO org.apache.hadoop.yarn.server.resourcemanager.rmapp.RMAppImpl: application_1549167607896_0001 State change from NEW to NEW_SAVING
2019-02-03 12:11:42,252 INFO org.apache.hadoop.yarn.server.resourcemanager.recovery.RMStateStore: Storing info for app: application_1549167607896_0001
2019-02-03 12:11:42,253 INFO org.apache.hadoop.yarn.server.resourcemanager.rmapp.RMAppImpl: application_1549167607896_0001 State change from NEW_SAVING to SUBMITTED
2019-02-03 12:11:42,256 INFO org.apache.hadoop.yarn.server.resourcemanager.scheduler.capacity.ParentQueue: Application added - appId: application_1549167607896_0001 user: root leaf-queue of parent: root #applications: 1
2019-02-03 12:11:42,257 INFO org.apache.hadoop.yarn.server.resourcemanager.scheduler.capacity.CapacityScheduler: Accepted application application_1549167607896_0001 from user: root, in queue: default
2019-02-03 12:11:42,266 INFO org.apache.hadoop.yarn.server.resourcemanager.rmapp.RMAppImpl: application_1549167607896_0001 State change from SUBMITTED to ACCEPTED
2019-02-03 12:11:42,300 INFO org.apache.hadoop.yarn.server.resourcemanager.ApplicationMasterService: Registering app attempt : appattempt_1549167607896_0001_000001
2019-02-03 12:11:42,301 INFO org.apache.hadoop.yarn.server.resourcemanager.rmapp.attempt.RMAppAttemptImpl: appattempt_1549167607896_0001_000001 State change from NEW to SUBMITTED
2019-02-03 12:11:42,317 WARN org.apache.hadoop.yarn.server.resourcemanager.scheduler.capacity.LeafQueue: maximum-am-resource-percent is insufficient to start a single application in queue, it is likely set too low. skipping enforcement to allow at least one application to start
2019-02-03 12:11:42,317 WARN org.apache.hadoop.yarn.server.resourcemanager.scheduler.capacity.LeafQueue: maximum-am-resource-percent is insufficient to start a single application in queue for user, it is likely set too low. skipping enforcement to allow at least one application to start
2019-02-03 12:11:42,317 INFO org.apache.hadoop.yarn.server.resourcemanager.scheduler.capacity.LeafQueue: Application application_1549167607896_0001 from user: root activated in queue: default
2019-02-03 12:11:42,318 INFO org.apache.hadoop.yarn.server.resourcemanager.scheduler.capacity.LeafQueue: Application added - appId: application_1549167607896_0001 user: org.apache.hadoop.yarn.server.resourcemanager.scheduler.capacity.LeafQueue$User@75aaa04a, leaf-queue: default #user-pending-applications: 0 #user-active-applications: 1 #queue-pending-applications: 0 #queue-active-applications: 1
2019-02-03 12:11:42,318 INFO org.apache.hadoop.yarn.server.resourcemanager.scheduler.capacity.CapacityScheduler: Added Application Attempt appattempt_1549167607896_0001_000001 to scheduler from user root in queue default
2019-02-03 12:11:42,320 INFO org.apache.hadoop.yarn.server.resourcemanager.rmapp.attempt.RMAppAttemptImpl: appattempt_1549167607896_0001_000001 State change from SUBMITTED to SCHEDULED
2019-02-03 12:11:43,136 INFO org.apache.hadoop.yarn.server.resourcemanager.rmcontainer.RMContainerImpl: container_1549167607896_0001_01_000001 Container Transitioned from NEW to ALLOCATED
2019-02-03 12:11:43,137 INFO org.apache.hadoop.yarn.server.resourcemanager.RMAuditLogger: USER=root	OPERATION=AM Allocated Container	TARGET=SchedulerApp	RESULT=SUCCESS	APPID=application_1549167607896_0001	CONTAINERID=container_1549167607896_0001_01_000001
2019-02-03 12:11:43,138 INFO org.apache.hadoop.yarn.server.resourcemanager.scheduler.SchedulerNode: Assigned container container_1549167607896_0001_01_000001 of capacity <memory:2048, vCores:1> on host ubuntu-HP-Pavilion-dv6-NoteBook-PC:36263, which has 1 containers, <memory:2048, vCores:1> used and <memory:6144, vCores:7> available after allocation
2019-02-03 12:11:43,138 INFO org.apache.hadoop.yarn.server.resourcemanager.scheduler.capacity.LeafQueue: assignedContainer application attempt=appattempt_1549167607896_0001_000001 container=Container: [ContainerId: container_1549167607896_0001_01_000001, NodeId: ubuntu-HP-Pavilion-dv6-NoteBook-PC:36263, NodeHttpAddress: ubuntu-HP-Pavilion-dv6-NoteBook-PC:8042, Resource: <memory:2048, vCores:1>, Priority: 0, Token: null, ] queue=default: capacity=1.0, absoluteCapacity=1.0, usedResources=<memory:0, vCores:0>, usedCapacity=0.0, absoluteUsedCapacity=0.0, numApps=1, numContainers=0 clusterResource=<memory:8192, vCores:8> type=OFF_SWITCH
2019-02-03 12:11:43,146 INFO org.apache.hadoop.yarn.server.resourcemanager.scheduler.capacity.ParentQueue: Re-sorting assigned queue: root.default stats: default: capacity=1.0, absoluteCapacity=1.0, usedResources=<memory:2048, vCores:1>, usedCapacity=0.25, absoluteUsedCapacity=0.25, numApps=1, numContainers=1
2019-02-03 12:11:43,146 INFO org.apache.hadoop.yarn.server.resourcemanager.scheduler.capacity.ParentQueue: assignedContainer queue=root usedCapacity=0.25 absoluteUsedCapacity=0.25 used=<memory:2048, vCores:1> cluster=<memory:8192, vCores:8>
2019-02-03 12:11:43,180 INFO org.apache.hadoop.yarn.server.resourcemanager.security.NMTokenSecretManagerInRM: Sending NMToken for nodeId : ubuntu-HP-Pavilion-dv6-NoteBook-PC:36263 for container : container_1549167607896_0001_01_000001
2019-02-03 12:11:43,193 INFO org.apache.hadoop.yarn.server.resourcemanager.rmcontainer.RMContainerImpl: container_1549167607896_0001_01_000001 Container Transitioned from ALLOCATED to ACQUIRED
2019-02-03 12:11:43,193 INFO org.apache.hadoop.yarn.server.resourcemanager.security.NMTokenSecretManagerInRM: Clear node set for appattempt_1549167607896_0001_000001
2019-02-03 12:11:43,196 INFO org.apache.hadoop.yarn.server.resourcemanager.rmapp.attempt.RMAppAttemptImpl: Storing attempt: AppId: application_1549167607896_0001 AttemptId: appattempt_1549167607896_0001_000001 MasterContainer: Container: [ContainerId: container_1549167607896_0001_01_000001, NodeId: ubuntu-HP-Pavilion-dv6-NoteBook-PC:36263, NodeHttpAddress: ubuntu-HP-Pavilion-dv6-NoteBook-PC:8042, Resource: <memory:2048, vCores:1>, Priority: 0, Token: Token { kind: ContainerToken, service: 127.0.1.1:36263 }, ]
2019-02-03 12:11:43,212 INFO org.apache.hadoop.yarn.server.resourcemanager.rmapp.attempt.RMAppAttemptImpl: appattempt_1549167607896_0001_000001 State change from SCHEDULED to ALLOCATED_SAVING
2019-02-03 12:11:43,214 INFO org.apache.hadoop.yarn.server.resourcemanager.rmapp.attempt.RMAppAttemptImpl: appattempt_1549167607896_0001_000001 State change from ALLOCATED_SAVING to ALLOCATED
2019-02-03 12:11:43,218 INFO org.apache.hadoop.yarn.server.resourcemanager.amlauncher.AMLauncher: Launching masterappattempt_1549167607896_0001_000001
2019-02-03 12:11:43,258 INFO org.apache.hadoop.yarn.server.resourcemanager.amlauncher.AMLauncher: Setting up container Container: [ContainerId: container_1549167607896_0001_01_000001, NodeId: ubuntu-HP-Pavilion-dv6-NoteBook-PC:36263, NodeHttpAddress: ubuntu-HP-Pavilion-dv6-NoteBook-PC:8042, Resource: <memory:2048, vCores:1>, Priority: 0, Token: Token { kind: ContainerToken, service: 127.0.1.1:36263 }, ] for AM appattempt_1549167607896_0001_000001
2019-02-03 12:11:43,258 INFO org.apache.hadoop.yarn.server.resourcemanager.amlauncher.AMLauncher: Command to launch container container_1549167607896_0001_01_000001 : $JAVA_HOME/bin/java -Djava.io.tmpdir=$PWD/tmp -Dlog4j.configuration=container-log4j.properties -Dyarn.app.container.log.dir=<LOG_DIR> -Dyarn.app.container.log.filesize=0 -Dhadoop.root.logger=INFO,CLA -Dhadoop.root.logfile=syslog  -Xmx1024m org.apache.hadoop.mapreduce.v2.app.MRAppMaster 1><LOG_DIR>/stdout 2><LOG_DIR>/stderr 
2019-02-03 12:11:43,261 INFO org.apache.hadoop.yarn.server.resourcemanager.security.AMRMTokenSecretManager: Create AMRMToken for ApplicationAttempt: appattempt_1549167607896_0001_000001
2019-02-03 12:11:43,264 INFO org.apache.hadoop.yarn.server.resourcemanager.security.AMRMTokenSecretManager: Creating password for appattempt_1549167607896_0001_000001
2019-02-03 12:11:43,710 INFO org.apache.hadoop.yarn.server.resourcemanager.amlauncher.AMLauncher: Done launching container Container: [ContainerId: container_1549167607896_0001_01_000001, NodeId: ubuntu-HP-Pavilion-dv6-NoteBook-PC:36263, NodeHttpAddress: ubuntu-HP-Pavilion-dv6-NoteBook-PC:8042, Resource: <memory:2048, vCores:1>, Priority: 0, Token: Token { kind: ContainerToken, service: 127.0.1.1:36263 }, ] for AM appattempt_1549167607896_0001_000001
2019-02-03 12:11:43,711 INFO org.apache.hadoop.yarn.server.resourcemanager.rmapp.attempt.RMAppAttemptImpl: appattempt_1549167607896_0001_000001 State change from ALLOCATED to LAUNCHED
2019-02-03 12:11:44,027 INFO org.apache.hadoop.yarn.server.resourcemanager.rmcontainer.RMContainerImpl: container_1549167607896_0001_01_000001 Container Transitioned from ACQUIRED to RUNNING
2019-02-03 12:11:49,421 INFO org.apache.hadoop.yarn.server.resourcemanager.rmcontainer.RMContainerImpl: container_1549167607896_0001_01_000001 Container Transitioned from RUNNING to COMPLETED
2019-02-03 12:11:49,421 INFO org.apache.hadoop.yarn.server.resourcemanager.scheduler.common.fica.FiCaSchedulerApp: Completed container: container_1549167607896_0001_01_000001 in state: COMPLETED event:FINISHED
2019-02-03 12:11:49,421 INFO org.apache.hadoop.yarn.server.resourcemanager.RMAuditLogger: USER=root	OPERATION=AM Released Container	TARGET=SchedulerApp	RESULT=SUCCESS	APPID=application_1549167607896_0001	CONTAINERID=container_1549167607896_0001_01_000001
2019-02-03 12:11:49,422 INFO org.apache.hadoop.yarn.server.resourcemanager.scheduler.SchedulerNode: Released container container_1549167607896_0001_01_000001 of capacity <memory:2048, vCores:1> on host ubuntu-HP-Pavilion-dv6-NoteBook-PC:36263, which currently has 0 containers, <memory:0, vCores:0> used and <memory:8192, vCores:8> available, release resources=true
2019-02-03 12:11:49,423 INFO org.apache.hadoop.yarn.server.resourcemanager.scheduler.capacity.LeafQueue: default used=<memory:0, vCores:0> numContainers=0 user=root user-resources=<memory:0, vCores:0>
2019-02-03 12:11:49,423 INFO org.apache.hadoop.yarn.server.resourcemanager.scheduler.capacity.LeafQueue: completedContainer container=Container: [ContainerId: container_1549167607896_0001_01_000001, NodeId: ubuntu-HP-Pavilion-dv6-NoteBook-PC:36263, NodeHttpAddress: ubuntu-HP-Pavilion-dv6-NoteBook-PC:8042, Resource: <memory:2048, vCores:1>, Priority: 0, Token: Token { kind: ContainerToken, service: 127.0.1.1:36263 }, ] queue=default: capacity=1.0, absoluteCapacity=1.0, usedResources=<memory:0, vCores:0>, usedCapacity=0.0, absoluteUsedCapacity=0.0, numApps=1, numContainers=0 cluster=<memory:8192, vCores:8>
2019-02-03 12:11:49,423 INFO org.apache.hadoop.yarn.server.resourcemanager.scheduler.capacity.ParentQueue: completedContainer queue=root usedCapacity=0.0 absoluteUsedCapacity=0.0 used=<memory:0, vCores:0> cluster=<memory:8192, vCores:8>
2019-02-03 12:11:49,423 INFO org.apache.hadoop.yarn.server.resourcemanager.scheduler.capacity.ParentQueue: Re-sorting completed queue: root.default stats: default: capacity=1.0, absoluteCapacity=1.0, usedResources=<memory:0, vCores:0>, usedCapacity=0.0, absoluteUsedCapacity=0.0, numApps=1, numContainers=0
2019-02-03 12:11:49,423 INFO org.apache.hadoop.yarn.server.resourcemanager.scheduler.capacity.CapacityScheduler: Application attempt appattempt_1549167607896_0001_000001 released container container_1549167607896_0001_01_000001 on node: host: ubuntu-HP-Pavilion-dv6-NoteBook-PC:36263 #containers=0 available=<memory:8192, vCores:8> used=<memory:0, vCores:0> with event: FINISHED
2019-02-03 12:11:49,424 INFO org.apache.hadoop.yarn.server.resourcemanager.rmapp.attempt.RMAppAttemptImpl: Updating application attempt appattempt_1549167607896_0001_000001 with final state: FAILED, and exit status: -103
2019-02-03 12:11:49,426 INFO org.apache.hadoop.yarn.server.resourcemanager.rmapp.attempt.RMAppAttemptImpl: appattempt_1549167607896_0001_000001 State change from LAUNCHED to FINAL_SAVING
2019-02-03 12:11:49,427 INFO org.apache.hadoop.yarn.server.resourcemanager.ApplicationMasterService: Unregistering app attempt : appattempt_1549167607896_0001_000001
2019-02-03 12:11:49,428 INFO org.apache.hadoop.yarn.server.resourcemanager.security.AMRMTokenSecretManager: Application finished, removing password for appattempt_1549167607896_0001_000001
2019-02-03 12:11:49,428 INFO org.apache.hadoop.yarn.server.resourcemanager.rmapp.attempt.RMAppAttemptImpl: appattempt_1549167607896_0001_000001 State change from FINAL_SAVING to FAILED
2019-02-03 12:11:49,428 INFO org.apache.hadoop.yarn.server.resourcemanager.rmapp.RMAppImpl: The number of failed attempts is 1. The max attempts is 2
2019-02-03 12:11:49,429 INFO org.apache.hadoop.yarn.server.resourcemanager.scheduler.capacity.CapacityScheduler: Application Attempt appattempt_1549167607896_0001_000001 is done. finalState=FAILED
2019-02-03 12:11:49,429 INFO org.apache.hadoop.yarn.server.resourcemanager.scheduler.AppSchedulingInfo: Application application_1549167607896_0001 requests cleared
2019-02-03 12:11:49,429 INFO org.apache.hadoop.yarn.server.resourcemanager.scheduler.capacity.LeafQueue: Application removed - appId: application_1549167607896_0001 user: root queue: default #user-pending-applications: 0 #user-active-applications: 0 #queue-pending-applications: 0 #queue-active-applications: 0
2019-02-03 12:11:49,429 INFO org.apache.hadoop.yarn.server.resourcemanager.ApplicationMasterService: Registering app attempt : appattempt_1549167607896_0001_000002
2019-02-03 12:11:49,429 INFO org.apache.hadoop.yarn.server.resourcemanager.rmapp.attempt.RMAppAttemptImpl: appattempt_1549167607896_0001_000002 State change from NEW to SUBMITTED
2019-02-03 12:11:49,429 WARN org.apache.hadoop.yarn.server.resourcemanager.scheduler.capacity.LeafQueue: maximum-am-resource-percent is insufficient to start a single application in queue, it is likely set too low. skipping enforcement to allow at least one application to start
2019-02-03 12:11:49,429 WARN org.apache.hadoop.yarn.server.resourcemanager.scheduler.capacity.LeafQueue: maximum-am-resource-percent is insufficient to start a single application in queue for user, it is likely set too low. skipping enforcement to allow at least one application to start
2019-02-03 12:11:49,429 INFO org.apache.hadoop.yarn.server.resourcemanager.scheduler.capacity.LeafQueue: Application application_1549167607896_0001 from user: root activated in queue: default
2019-02-03 12:11:49,429 INFO org.apache.hadoop.yarn.server.resourcemanager.scheduler.capacity.LeafQueue: Application added - appId: application_1549167607896_0001 user: org.apache.hadoop.yarn.server.resourcemanager.scheduler.capacity.LeafQueue$User@697b1086, leaf-queue: default #user-pending-applications: 0 #user-active-applications: 1 #queue-pending-applications: 0 #queue-active-applications: 1
2019-02-03 12:11:49,429 INFO org.apache.hadoop.yarn.server.resourcemanager.scheduler.capacity.CapacityScheduler: Added Application Attempt appattempt_1549167607896_0001_000002 to scheduler from user root in queue default
2019-02-03 12:11:49,430 INFO org.apache.hadoop.yarn.server.resourcemanager.rmapp.attempt.RMAppAttemptImpl: appattempt_1549167607896_0001_000002 State change from SUBMITTED to SCHEDULED
2019-02-03 12:11:50,429 INFO org.apache.hadoop.yarn.server.resourcemanager.rmcontainer.RMContainerImpl: container_1549167607896_0001_02_000001 Container Transitioned from NEW to ALLOCATED
2019-02-03 12:11:50,429 INFO org.apache.hadoop.yarn.server.resourcemanager.RMAuditLogger: USER=root	OPERATION=AM Allocated Container	TARGET=SchedulerApp	RESULT=SUCCESS	APPID=application_1549167607896_0001	CONTAINERID=container_1549167607896_0001_02_000001
2019-02-03 12:11:50,429 INFO org.apache.hadoop.yarn.server.resourcemanager.scheduler.SchedulerNode: Assigned container container_1549167607896_0001_02_000001 of capacity <memory:2048, vCores:1> on host ubuntu-HP-Pavilion-dv6-NoteBook-PC:36263, which has 1 containers, <memory:2048, vCores:1> used and <memory:6144, vCores:7> available after allocation
2019-02-03 12:11:50,430 INFO org.apache.hadoop.yarn.server.resourcemanager.scheduler.capacity.LeafQueue: assignedContainer application attempt=appattempt_1549167607896_0001_000002 container=Container: [ContainerId: container_1549167607896_0001_02_000001, NodeId: ubuntu-HP-Pavilion-dv6-NoteBook-PC:36263, NodeHttpAddress: ubuntu-HP-Pavilion-dv6-NoteBook-PC:8042, Resource: <memory:2048, vCores:1>, Priority: 0, Token: null, ] queue=default: capacity=1.0, absoluteCapacity=1.0, usedResources=<memory:0, vCores:0>, usedCapacity=0.0, absoluteUsedCapacity=0.0, numApps=1, numContainers=0 clusterResource=<memory:8192, vCores:8> type=OFF_SWITCH
2019-02-03 12:11:50,431 INFO org.apache.hadoop.yarn.server.resourcemanager.scheduler.capacity.ParentQueue: Re-sorting assigned queue: root.default stats: default: capacity=1.0, absoluteCapacity=1.0, usedResources=<memory:2048, vCores:1>, usedCapacity=0.25, absoluteUsedCapacity=0.25, numApps=1, numContainers=1
2019-02-03 12:11:50,431 INFO org.apache.hadoop.yarn.server.resourcemanager.scheduler.capacity.ParentQueue: assignedContainer queue=root usedCapacity=0.25 absoluteUsedCapacity=0.25 used=<memory:2048, vCores:1> cluster=<memory:8192, vCores:8>
2019-02-03 12:11:50,434 INFO org.apache.hadoop.yarn.server.resourcemanager.security.NMTokenSecretManagerInRM: Sending NMToken for nodeId : ubuntu-HP-Pavilion-dv6-NoteBook-PC:36263 for container : container_1549167607896_0001_02_000001
2019-02-03 12:11:50,436 INFO org.apache.hadoop.yarn.server.resourcemanager.rmcontainer.RMContainerImpl: container_1549167607896_0001_02_000001 Container Transitioned from ALLOCATED to ACQUIRED
2019-02-03 12:11:50,436 INFO org.apache.hadoop.yarn.server.resourcemanager.security.NMTokenSecretManagerInRM: Clear node set for appattempt_1549167607896_0001_000002
2019-02-03 12:11:50,436 INFO org.apache.hadoop.yarn.server.resourcemanager.rmapp.attempt.RMAppAttemptImpl: Storing attempt: AppId: application_1549167607896_0001 AttemptId: appattempt_1549167607896_0001_000002 MasterContainer: Container: [ContainerId: container_1549167607896_0001_02_000001, NodeId: ubuntu-HP-Pavilion-dv6-NoteBook-PC:36263, NodeHttpAddress: ubuntu-HP-Pavilion-dv6-NoteBook-PC:8042, Resource: <memory:2048, vCores:1>, Priority: 0, Token: Token { kind: ContainerToken, service: 127.0.1.1:36263 }, ]
2019-02-03 12:11:50,437 INFO org.apache.hadoop.yarn.server.resourcemanager.rmapp.attempt.RMAppAttemptImpl: appattempt_1549167607896_0001_000002 State change from SCHEDULED to ALLOCATED_SAVING
2019-02-03 12:11:50,437 INFO org.apache.hadoop.yarn.server.resourcemanager.rmapp.attempt.RMAppAttemptImpl: appattempt_1549167607896_0001_000002 State change from ALLOCATED_SAVING to ALLOCATED
2019-02-03 12:11:50,438 INFO org.apache.hadoop.yarn.server.resourcemanager.amlauncher.AMLauncher: Launching masterappattempt_1549167607896_0001_000002
2019-02-03 12:11:50,444 INFO org.apache.hadoop.yarn.server.resourcemanager.amlauncher.AMLauncher: Setting up container Container: [ContainerId: container_1549167607896_0001_02_000001, NodeId: ubuntu-HP-Pavilion-dv6-NoteBook-PC:36263, NodeHttpAddress: ubuntu-HP-Pavilion-dv6-NoteBook-PC:8042, Resource: <memory:2048, vCores:1>, Priority: 0, Token: Token { kind: ContainerToken, service: 127.0.1.1:36263 }, ] for AM appattempt_1549167607896_0001_000002
2019-02-03 12:11:50,445 INFO org.apache.hadoop.yarn.server.resourcemanager.amlauncher.AMLauncher: Command to launch container container_1549167607896_0001_02_000001 : $JAVA_HOME/bin/java -Djava.io.tmpdir=$PWD/tmp -Dlog4j.configuration=container-log4j.properties -Dyarn.app.container.log.dir=<LOG_DIR> -Dyarn.app.container.log.filesize=0 -Dhadoop.root.logger=INFO,CLA -Dhadoop.root.logfile=syslog  -Xmx1024m org.apache.hadoop.mapreduce.v2.app.MRAppMaster 1><LOG_DIR>/stdout 2><LOG_DIR>/stderr 
2019-02-03 12:11:50,445 INFO org.apache.hadoop.yarn.server.resourcemanager.security.AMRMTokenSecretManager: Create AMRMToken for ApplicationAttempt: appattempt_1549167607896_0001_000002
2019-02-03 12:11:50,445 INFO org.apache.hadoop.yarn.server.resourcemanager.security.AMRMTokenSecretManager: Creating password for appattempt_1549167607896_0001_000002
2019-02-03 12:11:50,466 INFO org.apache.hadoop.yarn.server.resourcemanager.amlauncher.AMLauncher: Done launching container Container: [ContainerId: container_1549167607896_0001_02_000001, NodeId: ubuntu-HP-Pavilion-dv6-NoteBook-PC:36263, NodeHttpAddress: ubuntu-HP-Pavilion-dv6-NoteBook-PC:8042, Resource: <memory:2048, vCores:1>, Priority: 0, Token: Token { kind: ContainerToken, service: 127.0.1.1:36263 }, ] for AM appattempt_1549167607896_0001_000002
2019-02-03 12:11:50,468 INFO org.apache.hadoop.yarn.server.resourcemanager.rmapp.attempt.RMAppAttemptImpl: appattempt_1549167607896_0001_000002 State change from ALLOCATED to LAUNCHED
2019-02-03 12:11:51,437 INFO org.apache.hadoop.yarn.server.resourcemanager.rmcontainer.RMContainerImpl: container_1549167607896_0001_02_000001 Container Transitioned from ACQUIRED to RUNNING
2019-02-03 12:11:55,461 INFO org.apache.hadoop.yarn.server.resourcemanager.rmcontainer.RMContainerImpl: container_1549167607896_0001_02_000001 Container Transitioned from RUNNING to COMPLETED
2019-02-03 12:11:55,461 INFO org.apache.hadoop.yarn.server.resourcemanager.scheduler.common.fica.FiCaSchedulerApp: Completed container: container_1549167607896_0001_02_000001 in state: COMPLETED event:FINISHED
2019-02-03 12:11:55,461 INFO org.apache.hadoop.yarn.server.resourcemanager.RMAuditLogger: USER=root	OPERATION=AM Released Container	TARGET=SchedulerApp	RESULT=SUCCESS	APPID=application_1549167607896_0001	CONTAINERID=container_1549167607896_0001_02_000001
2019-02-03 12:11:55,461 INFO org.apache.hadoop.yarn.server.resourcemanager.scheduler.SchedulerNode: Released container container_1549167607896_0001_02_000001 of capacity <memory:2048, vCores:1> on host ubuntu-HP-Pavilion-dv6-NoteBook-PC:36263, which currently has 0 containers, <memory:0, vCores:0> used and <memory:8192, vCores:8> available, release resources=true
2019-02-03 12:11:55,461 INFO org.apache.hadoop.yarn.server.resourcemanager.rmapp.attempt.RMAppAttemptImpl: Updating application attempt appattempt_1549167607896_0001_000002 with final state: FAILED, and exit status: -103
2019-02-03 12:11:55,461 INFO org.apache.hadoop.yarn.server.resourcemanager.scheduler.capacity.LeafQueue: default used=<memory:0, vCores:0> numContainers=0 user=root user-resources=<memory:0, vCores:0>
2019-02-03 12:11:55,461 INFO org.apache.hadoop.yarn.server.resourcemanager.rmapp.attempt.RMAppAttemptImpl: appattempt_1549167607896_0001_000002 State change from LAUNCHED to FINAL_SAVING
2019-02-03 12:11:55,461 INFO org.apache.hadoop.yarn.server.resourcemanager.scheduler.capacity.LeafQueue: completedContainer container=Container: [ContainerId: container_1549167607896_0001_02_000001, NodeId: ubuntu-HP-Pavilion-dv6-NoteBook-PC:36263, NodeHttpAddress: ubuntu-HP-Pavilion-dv6-NoteBook-PC:8042, Resource: <memory:2048, vCores:1>, Priority: 0, Token: Token { kind: ContainerToken, service: 127.0.1.1:36263 }, ] queue=default: capacity=1.0, absoluteCapacity=1.0, usedResources=<memory:0, vCores:0>, usedCapacity=0.0, absoluteUsedCapacity=0.0, numApps=1, numContainers=0 cluster=<memory:8192, vCores:8>
2019-02-03 12:11:55,461 INFO org.apache.hadoop.yarn.server.resourcemanager.scheduler.capacity.ParentQueue: completedContainer queue=root usedCapacity=0.0 absoluteUsedCapacity=0.0 used=<memory:0, vCores:0> cluster=<memory:8192, vCores:8>
2019-02-03 12:11:55,462 INFO org.apache.hadoop.yarn.server.resourcemanager.scheduler.capacity.ParentQueue: Re-sorting completed queue: root.default stats: default: capacity=1.0, absoluteCapacity=1.0, usedResources=<memory:0, vCores:0>, usedCapacity=0.0, absoluteUsedCapacity=0.0, numApps=1, numContainers=0
2019-02-03 12:11:55,462 INFO org.apache.hadoop.yarn.server.resourcemanager.scheduler.capacity.CapacityScheduler: Application attempt appattempt_1549167607896_0001_000002 released container container_1549167607896_0001_02_000001 on node: host: ubuntu-HP-Pavilion-dv6-NoteBook-PC:36263 #containers=0 available=<memory:8192, vCores:8> used=<memory:0, vCores:0> with event: FINISHED
2019-02-03 12:11:55,462 INFO org.apache.hadoop.yarn.server.resourcemanager.ApplicationMasterService: Unregistering app attempt : appattempt_1549167607896_0001_000002
2019-02-03 12:11:55,462 INFO org.apache.hadoop.yarn.server.resourcemanager.security.AMRMTokenSecretManager: Application finished, removing password for appattempt_1549167607896_0001_000002
2019-02-03 12:11:55,463 INFO org.apache.hadoop.yarn.server.resourcemanager.rmapp.attempt.RMAppAttemptImpl: appattempt_1549167607896_0001_000002 State change from FINAL_SAVING to FAILED
2019-02-03 12:11:55,463 INFO org.apache.hadoop.yarn.server.resourcemanager.rmapp.RMAppImpl: The number of failed attempts is 2. The max attempts is 2
2019-02-03 12:11:55,463 INFO org.apache.hadoop.yarn.server.resourcemanager.rmapp.RMAppImpl: Updating application application_1549167607896_0001 with final state: FAILED
2019-02-03 12:11:55,464 INFO org.apache.hadoop.yarn.server.resourcemanager.rmapp.RMAppImpl: application_1549167607896_0001 State change from ACCEPTED to FINAL_SAVING
2019-02-03 12:11:55,464 INFO org.apache.hadoop.yarn.server.resourcemanager.recovery.RMStateStore: Updating info for app: application_1549167607896_0001
2019-02-03 12:11:55,464 INFO org.apache.hadoop.yarn.server.resourcemanager.scheduler.capacity.CapacityScheduler: Application Attempt appattempt_1549167607896_0001_000002 is done. finalState=FAILED
2019-02-03 12:11:55,464 INFO org.apache.hadoop.yarn.server.resourcemanager.scheduler.AppSchedulingInfo: Application application_1549167607896_0001 requests cleared
2019-02-03 12:11:55,464 INFO org.apache.hadoop.yarn.server.resourcemanager.rmapp.RMAppImpl: Application application_1549167607896_0001 failed 2 times due to AM Container for appattempt_1549167607896_0001_000002 exited with  exitCode: -103
For more detailed output, check application tracking page:http://ubuntu-HP-Pavilion-dv6-NoteBook-PC:8088/cluster/app/application_1549167607896_0001Then, click on links to logs of each attempt.
Diagnostics: Container [pid=13598,containerID=container_1549167607896_0001_02_000001] is running beyond virtual memory limits. Current usage: 288.7 MB of 2 GB physical memory used; 4.4 GB of 4.2 GB virtual memory used. Killing container.
Dump of the process-tree for container_1549167607896_0001_02_000001 :
	|- PID PPID PGRPID SESSID CMD_NAME USER_MODE_TIME(MILLIS) SYSTEM_TIME(MILLIS) VMEM_USAGE(BYTES) RSSMEM_USAGE(PAGES) FULL_CMD_LINE
	|- 13608 13598 13598 13598 (java) 1083 34 4741472256 73242 /usr/lib/jvm/java-8-openjdk-amd64/bin/java -Djava.io.tmpdir=/home/ubuntu/hdata/nm-local-dir/usercache/root/appcache/application_1549167607896_0001/container_1549167607896_0001_02_000001/tmp -Dlog4j.configuration=container-log4j.properties -Dyarn.app.container.log.dir=/opt/hadoop/hadoop-2.7.3/logs/userlogs/application_1549167607896_0001/container_1549167607896_0001_02_000001 -Dyarn.app.container.log.filesize=0 -Dhadoop.root.logger=INFO,CLA -Dhadoop.root.logfile=syslog -Xmx1024m org.apache.hadoop.mapreduce.v2.app.MRAppMaster 
	|- 13598 13596 13598 13598 (bash) 0 0 14725120 673 /bin/bash -c /usr/lib/jvm/java-8-openjdk-amd64/bin/java -Djava.io.tmpdir=/home/ubuntu/hdata/nm-local-dir/usercache/root/appcache/application_1549167607896_0001/container_1549167607896_0001_02_000001/tmp -Dlog4j.configuration=container-log4j.properties -Dyarn.app.container.log.dir=/opt/hadoop/hadoop-2.7.3/logs/userlogs/application_1549167607896_0001/container_1549167607896_0001_02_000001 -Dyarn.app.container.log.filesize=0 -Dhadoop.root.logger=INFO,CLA -Dhadoop.root.logfile=syslog  -Xmx1024m org.apache.hadoop.mapreduce.v2.app.MRAppMaster 1>/opt/hadoop/hadoop-2.7.3/logs/userlogs/application_1549167607896_0001/container_1549167607896_0001_02_000001/stdout 2>/opt/hadoop/hadoop-2.7.3/logs/userlogs/application_1549167607896_0001/container_1549167607896_0001_02_000001/stderr  

Container killed on request. Exit code is 143
Container exited with a non-zero exit code 143
Failing this attempt. Failing the application.
2019-02-03 12:11:55,464 INFO org.apache.hadoop.yarn.server.resourcemanager.scheduler.capacity.LeafQueue: Application removed - appId: application_1549167607896_0001 user: root queue: default #user-pending-applications: 0 #user-active-applications: 0 #queue-pending-applications: 0 #queue-active-applications: 0
2019-02-03 12:11:55,466 INFO org.apache.hadoop.yarn.server.resourcemanager.rmapp.RMAppImpl: application_1549167607896_0001 State change from FINAL_SAVING to FAILED
2019-02-03 12:11:55,467 INFO org.apache.hadoop.yarn.server.resourcemanager.scheduler.capacity.ParentQueue: Application removed - appId: application_1549167607896_0001 user: root leaf-queue of parent: root #applications: 0
2019-02-03 12:11:55,468 WARN org.apache.hadoop.yarn.server.resourcemanager.RMAuditLogger: USER=root	OPERATION=Application Finished - Failed	TARGET=RMAppManager	RESULT=FAILURE	DESCRIPTION=App failed with state: FAILED	PERMISSIONS=Application application_1549167607896_0001 failed 2 times due to AM Container for appattempt_1549167607896_0001_000002 exited with  exitCode: -103
For more detailed output, check application tracking page:http://ubuntu-HP-Pavilion-dv6-NoteBook-PC:8088/cluster/app/application_1549167607896_0001Then, click on links to logs of each attempt.
Diagnostics: Container [pid=13598,containerID=container_1549167607896_0001_02_000001] is running beyond virtual memory limits. Current usage: 288.7 MB of 2 GB physical memory used; 4.4 GB of 4.2 GB virtual memory used. Killing container.
Dump of the process-tree for container_1549167607896_0001_02_000001 :
	|- PID PPID PGRPID SESSID CMD_NAME USER_MODE_TIME(MILLIS) SYSTEM_TIME(MILLIS) VMEM_USAGE(BYTES) RSSMEM_USAGE(PAGES) FULL_CMD_LINE
	|- 13608 13598 13598 13598 (java) 1083 34 4741472256 73242 /usr/lib/jvm/java-8-openjdk-amd64/bin/java -Djava.io.tmpdir=/home/ubuntu/hdata/nm-local-dir/usercache/root/appcache/application_1549167607896_0001/container_1549167607896_0001_02_000001/tmp -Dlog4j.configuration=container-log4j.properties -Dyarn.app.container.log.dir=/opt/hadoop/hadoop-2.7.3/logs/userlogs/application_1549167607896_0001/container_1549167607896_0001_02_000001 -Dyarn.app.container.log.filesize=0 -Dhadoop.root.logger=INFO,CLA -Dhadoop.root.logfile=syslog -Xmx1024m org.apache.hadoop.mapreduce.v2.app.MRAppMaster 
	|- 13598 13596 13598 13598 (bash) 0 0 14725120 673 /bin/bash -c /usr/lib/jvm/java-8-openjdk-amd64/bin/java -Djava.io.tmpdir=/home/ubuntu/hdata/nm-local-dir/usercache/root/appcache/application_1549167607896_0001/container_1549167607896_0001_02_000001/tmp -Dlog4j.configuration=container-log4j.properties -Dyarn.app.container.log.dir=/opt/hadoop/hadoop-2.7.3/logs/userlogs/application_1549167607896_0001/container_1549167607896_0001_02_000001 -Dyarn.app.container.log.filesize=0 -Dhadoop.root.logger=INFO,CLA -Dhadoop.root.logfile=syslog  -Xmx1024m org.apache.hadoop.mapreduce.v2.app.MRAppMaster 1>/opt/hadoop/hadoop-2.7.3/logs/userlogs/application_1549167607896_0001/container_1549167607896_0001_02_000001/stdout 2>/opt/hadoop/hadoop-2.7.3/logs/userlogs/application_1549167607896_0001/container_1549167607896_0001_02_000001/stderr  

Container killed on request. Exit code is 143
Container exited with a non-zero exit code 143
Failing this attempt. Failing the application.	APPID=application_1549167607896_0001
2019-02-03 12:11:55,471 INFO org.apache.hadoop.yarn.server.resourcemanager.RMAppManager$ApplicationSummary: appId=application_1549167607896_0001,name=SELECT count(*) FROM stocks WHERE...'NASDAQ'(Stage-1),user=root,queue=default,state=FAILED,trackingUrl=http://ubuntu-HP-Pavilion-dv6-NoteBook-PC:8088/cluster/app/application_1549167607896_0001,appMasterHost=N/A,startTime=1549176102240,finishTime=1549176115463,finalStatus=FAILED,memorySeconds=23190,vcoreSeconds=11,preemptedAMContainers=0,preemptedNonAMContainers=0,preemptedResources=<memory:0\, vCores:0>,applicationType=MAPREDUCE
2019-02-03 12:11:55,780 INFO org.apache.hadoop.yarn.server.resourcemanager.RMAuditLogger: USER=root	IP=127.0.0.1	OPERATION=Kill Application Request	TARGET=ClientRMService	RESULT=SUCCESS	APPID=application_1549167607896_0001
2019-02-03 12:13:11,792 INFO org.apache.hadoop.yarn.server.webproxy.WebAppProxyServlet: dr.who is accessing unchecked http://ubuntu-HP-Pavilion-dv6-NoteBook-PC:8088/cluster/app/application_1549167607896_0001 which is the app master GUI of application_1549167607896_0001 owned by root
2019-02-03 12:13:26,784 INFO org.apache.hadoop.yarn.server.webproxy.WebAppProxyServlet: dr.who is accessing unchecked http://ubuntu-HP-Pavilion-dv6-NoteBook-PC:8088/cluster/app/application_1549167607896_0001 which is the app master GUI of application_1549167607896_0001 owned by root
2019-02-03 12:17:05,258 INFO org.apache.hadoop.yarn.server.resourcemanager.ClientRMService: Allocated new applicationId: 2
2019-02-03 12:17:05,714 INFO org.apache.hadoop.yarn.server.resourcemanager.ClientRMService: Application with id 2 submitted by user root
2019-02-03 12:17:05,714 INFO org.apache.hadoop.yarn.server.resourcemanager.rmapp.RMAppImpl: Storing application with id application_1549167607896_0002
2019-02-03 12:17:05,714 INFO org.apache.hadoop.yarn.server.resourcemanager.RMAuditLogger: USER=root	IP=127.0.0.1	OPERATION=Submit Application Request	TARGET=ClientRMService	RESULT=SUCCESS	APPID=application_1549167607896_0002
2019-02-03 12:17:05,714 INFO org.apache.hadoop.yarn.server.resourcemanager.rmapp.RMAppImpl: application_1549167607896_0002 State change from NEW to NEW_SAVING
2019-02-03 12:17:05,715 INFO org.apache.hadoop.yarn.server.resourcemanager.recovery.RMStateStore: Storing info for app: application_1549167607896_0002
2019-02-03 12:17:05,715 INFO org.apache.hadoop.yarn.server.resourcemanager.rmapp.RMAppImpl: application_1549167607896_0002 State change from NEW_SAVING to SUBMITTED
2019-02-03 12:17:05,716 INFO org.apache.hadoop.yarn.server.resourcemanager.scheduler.capacity.ParentQueue: Application added - appId: application_1549167607896_0002 user: root leaf-queue of parent: root #applications: 1
2019-02-03 12:17:05,716 INFO org.apache.hadoop.yarn.server.resourcemanager.scheduler.capacity.CapacityScheduler: Accepted application application_1549167607896_0002 from user: root, in queue: default
2019-02-03 12:17:05,716 INFO org.apache.hadoop.yarn.server.resourcemanager.rmapp.RMAppImpl: application_1549167607896_0002 State change from SUBMITTED to ACCEPTED
2019-02-03 12:17:05,717 INFO org.apache.hadoop.yarn.server.resourcemanager.ApplicationMasterService: Registering app attempt : appattempt_1549167607896_0002_000001
2019-02-03 12:17:05,717 INFO org.apache.hadoop.yarn.server.resourcemanager.rmapp.attempt.RMAppAttemptImpl: appattempt_1549167607896_0002_000001 State change from NEW to SUBMITTED
2019-02-03 12:17:05,717 WARN org.apache.hadoop.yarn.server.resourcemanager.scheduler.capacity.LeafQueue: maximum-am-resource-percent is insufficient to start a single application in queue, it is likely set too low. skipping enforcement to allow at least one application to start
2019-02-03 12:17:05,717 WARN org.apache.hadoop.yarn.server.resourcemanager.scheduler.capacity.LeafQueue: maximum-am-resource-percent is insufficient to start a single application in queue for user, it is likely set too low. skipping enforcement to allow at least one application to start
2019-02-03 12:17:05,717 INFO org.apache.hadoop.yarn.server.resourcemanager.scheduler.capacity.LeafQueue: Application application_1549167607896_0002 from user: root activated in queue: default
2019-02-03 12:17:05,717 INFO org.apache.hadoop.yarn.server.resourcemanager.scheduler.capacity.LeafQueue: Application added - appId: application_1549167607896_0002 user: org.apache.hadoop.yarn.server.resourcemanager.scheduler.capacity.LeafQueue$User@21ec3400, leaf-queue: default #user-pending-applications: 0 #user-active-applications: 1 #queue-pending-applications: 0 #queue-active-applications: 1
2019-02-03 12:17:05,717 INFO org.apache.hadoop.yarn.server.resourcemanager.scheduler.capacity.CapacityScheduler: Added Application Attempt appattempt_1549167607896_0002_000001 to scheduler from user root in queue default
2019-02-03 12:17:05,718 INFO org.apache.hadoop.yarn.server.resourcemanager.rmapp.attempt.RMAppAttemptImpl: appattempt_1549167607896_0002_000001 State change from SUBMITTED to SCHEDULED
2019-02-03 12:17:06,016 INFO org.apache.hadoop.yarn.server.resourcemanager.rmcontainer.RMContainerImpl: container_1549167607896_0002_01_000001 Container Transitioned from NEW to ALLOCATED
2019-02-03 12:17:06,017 INFO org.apache.hadoop.yarn.server.resourcemanager.RMAuditLogger: USER=root	OPERATION=AM Allocated Container	TARGET=SchedulerApp	RESULT=SUCCESS	APPID=application_1549167607896_0002	CONTAINERID=container_1549167607896_0002_01_000001
2019-02-03 12:17:06,017 INFO org.apache.hadoop.yarn.server.resourcemanager.scheduler.SchedulerNode: Assigned container container_1549167607896_0002_01_000001 of capacity <memory:2048, vCores:1> on host ubuntu-HP-Pavilion-dv6-NoteBook-PC:36263, which has 1 containers, <memory:2048, vCores:1> used and <memory:6144, vCores:7> available after allocation
2019-02-03 12:17:06,017 INFO org.apache.hadoop.yarn.server.resourcemanager.scheduler.capacity.LeafQueue: assignedContainer application attempt=appattempt_1549167607896_0002_000001 container=Container: [ContainerId: container_1549167607896_0002_01_000001, NodeId: ubuntu-HP-Pavilion-dv6-NoteBook-PC:36263, NodeHttpAddress: ubuntu-HP-Pavilion-dv6-NoteBook-PC:8042, Resource: <memory:2048, vCores:1>, Priority: 0, Token: null, ] queue=default: capacity=1.0, absoluteCapacity=1.0, usedResources=<memory:0, vCores:0>, usedCapacity=0.0, absoluteUsedCapacity=0.0, numApps=1, numContainers=0 clusterResource=<memory:8192, vCores:8> type=OFF_SWITCH
2019-02-03 12:17:06,018 INFO org.apache.hadoop.yarn.server.resourcemanager.scheduler.capacity.ParentQueue: Re-sorting assigned queue: root.default stats: default: capacity=1.0, absoluteCapacity=1.0, usedResources=<memory:2048, vCores:1>, usedCapacity=0.25, absoluteUsedCapacity=0.25, numApps=1, numContainers=1
2019-02-03 12:17:06,019 INFO org.apache.hadoop.yarn.server.resourcemanager.scheduler.capacity.ParentQueue: assignedContainer queue=root usedCapacity=0.25 absoluteUsedCapacity=0.25 used=<memory:2048, vCores:1> cluster=<memory:8192, vCores:8>
2019-02-03 12:17:06,021 INFO org.apache.hadoop.yarn.server.resourcemanager.security.NMTokenSecretManagerInRM: Sending NMToken for nodeId : ubuntu-HP-Pavilion-dv6-NoteBook-PC:36263 for container : container_1549167607896_0002_01_000001
2019-02-03 12:17:06,029 INFO org.apache.hadoop.yarn.server.resourcemanager.rmcontainer.RMContainerImpl: container_1549167607896_0002_01_000001 Container Transitioned from ALLOCATED to ACQUIRED
2019-02-03 12:17:06,029 INFO org.apache.hadoop.yarn.server.resourcemanager.security.NMTokenSecretManagerInRM: Clear node set for appattempt_1549167607896_0002_000001
2019-02-03 12:17:06,029 INFO org.apache.hadoop.yarn.server.resourcemanager.rmapp.attempt.RMAppAttemptImpl: Storing attempt: AppId: application_1549167607896_0002 AttemptId: appattempt_1549167607896_0002_000001 MasterContainer: Container: [ContainerId: container_1549167607896_0002_01_000001, NodeId: ubuntu-HP-Pavilion-dv6-NoteBook-PC:36263, NodeHttpAddress: ubuntu-HP-Pavilion-dv6-NoteBook-PC:8042, Resource: <memory:2048, vCores:1>, Priority: 0, Token: Token { kind: ContainerToken, service: 127.0.1.1:36263 }, ]
2019-02-03 12:17:06,029 INFO org.apache.hadoop.yarn.server.resourcemanager.rmapp.attempt.RMAppAttemptImpl: appattempt_1549167607896_0002_000001 State change from SCHEDULED to ALLOCATED_SAVING
2019-02-03 12:17:06,030 INFO org.apache.hadoop.yarn.server.resourcemanager.rmapp.attempt.RMAppAttemptImpl: appattempt_1549167607896_0002_000001 State change from ALLOCATED_SAVING to ALLOCATED
2019-02-03 12:17:06,030 INFO org.apache.hadoop.yarn.server.resourcemanager.amlauncher.AMLauncher: Launching masterappattempt_1549167607896_0002_000001
2019-02-03 12:17:06,034 INFO org.apache.hadoop.yarn.server.resourcemanager.amlauncher.AMLauncher: Setting up container Container: [ContainerId: container_1549167607896_0002_01_000001, NodeId: ubuntu-HP-Pavilion-dv6-NoteBook-PC:36263, NodeHttpAddress: ubuntu-HP-Pavilion-dv6-NoteBook-PC:8042, Resource: <memory:2048, vCores:1>, Priority: 0, Token: Token { kind: ContainerToken, service: 127.0.1.1:36263 }, ] for AM appattempt_1549167607896_0002_000001
2019-02-03 12:17:06,034 INFO org.apache.hadoop.yarn.server.resourcemanager.amlauncher.AMLauncher: Command to launch container container_1549167607896_0002_01_000001 : $JAVA_HOME/bin/java -Djava.io.tmpdir=$PWD/tmp -Dlog4j.configuration=container-log4j.properties -Dyarn.app.container.log.dir=<LOG_DIR> -Dyarn.app.container.log.filesize=0 -Dhadoop.root.logger=INFO,CLA -Dhadoop.root.logfile=syslog  -Xmx1024m org.apache.hadoop.mapreduce.v2.app.MRAppMaster 1><LOG_DIR>/stdout 2><LOG_DIR>/stderr 
2019-02-03 12:17:06,034 INFO org.apache.hadoop.yarn.server.resourcemanager.security.AMRMTokenSecretManager: Create AMRMToken for ApplicationAttempt: appattempt_1549167607896_0002_000001
2019-02-03 12:17:06,034 INFO org.apache.hadoop.yarn.server.resourcemanager.security.AMRMTokenSecretManager: Creating password for appattempt_1549167607896_0002_000001
2019-02-03 12:17:06,050 INFO org.apache.hadoop.yarn.server.resourcemanager.amlauncher.AMLauncher: Done launching container Container: [ContainerId: container_1549167607896_0002_01_000001, NodeId: ubuntu-HP-Pavilion-dv6-NoteBook-PC:36263, NodeHttpAddress: ubuntu-HP-Pavilion-dv6-NoteBook-PC:8042, Resource: <memory:2048, vCores:1>, Priority: 0, Token: Token { kind: ContainerToken, service: 127.0.1.1:36263 }, ] for AM appattempt_1549167607896_0002_000001
2019-02-03 12:17:06,050 INFO org.apache.hadoop.yarn.server.resourcemanager.rmapp.attempt.RMAppAttemptImpl: appattempt_1549167607896_0002_000001 State change from ALLOCATED to LAUNCHED
2019-02-03 12:17:07,017 INFO org.apache.hadoop.yarn.server.resourcemanager.rmcontainer.RMContainerImpl: container_1549167607896_0002_01_000001 Container Transitioned from ACQUIRED to RUNNING
2019-02-03 12:17:10,564 INFO org.apache.hadoop.yarn.server.resourcemanager.rmcontainer.RMContainerImpl: container_1549167607896_0002_01_000001 Container Transitioned from RUNNING to COMPLETED
2019-02-03 12:17:10,565 INFO org.apache.hadoop.yarn.server.resourcemanager.scheduler.common.fica.FiCaSchedulerApp: Completed container: container_1549167607896_0002_01_000001 in state: COMPLETED event:FINISHED
2019-02-03 12:17:10,565 INFO org.apache.hadoop.yarn.server.resourcemanager.RMAuditLogger: USER=root	OPERATION=AM Released Container	TARGET=SchedulerApp	RESULT=SUCCESS	APPID=application_1549167607896_0002	CONTAINERID=container_1549167607896_0002_01_000001
2019-02-03 12:17:10,565 INFO org.apache.hadoop.yarn.server.resourcemanager.scheduler.SchedulerNode: Released container container_1549167607896_0002_01_000001 of capacity <memory:2048, vCores:1> on host ubuntu-HP-Pavilion-dv6-NoteBook-PC:36263, which currently has 0 containers, <memory:0, vCores:0> used and <memory:8192, vCores:8> available, release resources=true
2019-02-03 12:17:10,565 INFO org.apache.hadoop.yarn.server.resourcemanager.scheduler.capacity.LeafQueue: default used=<memory:0, vCores:0> numContainers=0 user=root user-resources=<memory:0, vCores:0>
2019-02-03 12:17:10,565 INFO org.apache.hadoop.yarn.server.resourcemanager.scheduler.capacity.LeafQueue: completedContainer container=Container: [ContainerId: container_1549167607896_0002_01_000001, NodeId: ubuntu-HP-Pavilion-dv6-NoteBook-PC:36263, NodeHttpAddress: ubuntu-HP-Pavilion-dv6-NoteBook-PC:8042, Resource: <memory:2048, vCores:1>, Priority: 0, Token: Token { kind: ContainerToken, service: 127.0.1.1:36263 }, ] queue=default: capacity=1.0, absoluteCapacity=1.0, usedResources=<memory:0, vCores:0>, usedCapacity=0.0, absoluteUsedCapacity=0.0, numApps=1, numContainers=0 cluster=<memory:8192, vCores:8>
2019-02-03 12:17:10,565 INFO org.apache.hadoop.yarn.server.resourcemanager.scheduler.capacity.ParentQueue: completedContainer queue=root usedCapacity=0.0 absoluteUsedCapacity=0.0 used=<memory:0, vCores:0> cluster=<memory:8192, vCores:8>
2019-02-03 12:17:10,565 INFO org.apache.hadoop.yarn.server.resourcemanager.scheduler.capacity.ParentQueue: Re-sorting completed queue: root.default stats: default: capacity=1.0, absoluteCapacity=1.0, usedResources=<memory:0, vCores:0>, usedCapacity=0.0, absoluteUsedCapacity=0.0, numApps=1, numContainers=0
2019-02-03 12:17:10,565 INFO org.apache.hadoop.yarn.server.resourcemanager.scheduler.capacity.CapacityScheduler: Application attempt appattempt_1549167607896_0002_000001 released container container_1549167607896_0002_01_000001 on node: host: ubuntu-HP-Pavilion-dv6-NoteBook-PC:36263 #containers=0 available=<memory:8192, vCores:8> used=<memory:0, vCores:0> with event: FINISHED
2019-02-03 12:17:10,566 INFO org.apache.hadoop.yarn.server.resourcemanager.rmapp.attempt.RMAppAttemptImpl: Updating application attempt appattempt_1549167607896_0002_000001 with final state: FAILED, and exit status: -103
2019-02-03 12:17:10,566 INFO org.apache.hadoop.yarn.server.resourcemanager.rmapp.attempt.RMAppAttemptImpl: appattempt_1549167607896_0002_000001 State change from LAUNCHED to FINAL_SAVING
2019-02-03 12:17:10,567 INFO org.apache.hadoop.yarn.server.resourcemanager.ApplicationMasterService: Unregistering app attempt : appattempt_1549167607896_0002_000001
2019-02-03 12:17:10,567 INFO org.apache.hadoop.yarn.server.resourcemanager.security.AMRMTokenSecretManager: Application finished, removing password for appattempt_1549167607896_0002_000001
2019-02-03 12:17:10,567 INFO org.apache.hadoop.yarn.server.resourcemanager.rmapp.attempt.RMAppAttemptImpl: appattempt_1549167607896_0002_000001 State change from FINAL_SAVING to FAILED
2019-02-03 12:17:10,567 INFO org.apache.hadoop.yarn.server.resourcemanager.rmapp.RMAppImpl: The number of failed attempts is 1. The max attempts is 2
2019-02-03 12:17:10,567 INFO org.apache.hadoop.yarn.server.resourcemanager.ApplicationMasterService: Registering app attempt : appattempt_1549167607896_0002_000002
2019-02-03 12:17:10,567 INFO org.apache.hadoop.yarn.server.resourcemanager.rmapp.attempt.RMAppAttemptImpl: appattempt_1549167607896_0002_000002 State change from NEW to SUBMITTED
2019-02-03 12:17:10,567 INFO org.apache.hadoop.yarn.server.resourcemanager.scheduler.capacity.CapacityScheduler: Application Attempt appattempt_1549167607896_0002_000001 is done. finalState=FAILED
2019-02-03 12:17:10,567 INFO org.apache.hadoop.yarn.server.resourcemanager.scheduler.AppSchedulingInfo: Application application_1549167607896_0002 requests cleared
2019-02-03 12:17:10,567 INFO org.apache.hadoop.yarn.server.resourcemanager.scheduler.capacity.LeafQueue: Application removed - appId: application_1549167607896_0002 user: root queue: default #user-pending-applications: 0 #user-active-applications: 0 #queue-pending-applications: 0 #queue-active-applications: 0
2019-02-03 12:17:10,568 WARN org.apache.hadoop.yarn.server.resourcemanager.scheduler.capacity.LeafQueue: maximum-am-resource-percent is insufficient to start a single application in queue, it is likely set too low. skipping enforcement to allow at least one application to start
2019-02-03 12:17:10,568 WARN org.apache.hadoop.yarn.server.resourcemanager.scheduler.capacity.LeafQueue: maximum-am-resource-percent is insufficient to start a single application in queue for user, it is likely set too low. skipping enforcement to allow at least one application to start
2019-02-03 12:17:10,568 INFO org.apache.hadoop.yarn.server.resourcemanager.scheduler.capacity.LeafQueue: Application application_1549167607896_0002 from user: root activated in queue: default
2019-02-03 12:17:10,568 INFO org.apache.hadoop.yarn.server.resourcemanager.scheduler.capacity.LeafQueue: Application added - appId: application_1549167607896_0002 user: org.apache.hadoop.yarn.server.resourcemanager.scheduler.capacity.LeafQueue$User@10a2ef9b, leaf-queue: default #user-pending-applications: 0 #user-active-applications: 1 #queue-pending-applications: 0 #queue-active-applications: 1
2019-02-03 12:17:10,568 INFO org.apache.hadoop.yarn.server.resourcemanager.scheduler.capacity.CapacityScheduler: Added Application Attempt appattempt_1549167607896_0002_000002 to scheduler from user root in queue default
2019-02-03 12:17:10,569 INFO org.apache.hadoop.yarn.server.resourcemanager.rmapp.attempt.RMAppAttemptImpl: appattempt_1549167607896_0002_000002 State change from SUBMITTED to SCHEDULED
2019-02-03 12:17:11,580 INFO org.apache.hadoop.yarn.server.resourcemanager.rmcontainer.RMContainerImpl: container_1549167607896_0002_02_000001 Container Transitioned from NEW to ALLOCATED
2019-02-03 12:17:11,580 INFO org.apache.hadoop.yarn.server.resourcemanager.RMAuditLogger: USER=root	OPERATION=AM Allocated Container	TARGET=SchedulerApp	RESULT=SUCCESS	APPID=application_1549167607896_0002	CONTAINERID=container_1549167607896_0002_02_000001
2019-02-03 12:17:11,580 INFO org.apache.hadoop.yarn.server.resourcemanager.scheduler.SchedulerNode: Assigned container container_1549167607896_0002_02_000001 of capacity <memory:2048, vCores:1> on host ubuntu-HP-Pavilion-dv6-NoteBook-PC:36263, which has 1 containers, <memory:2048, vCores:1> used and <memory:6144, vCores:7> available after allocation
2019-02-03 12:17:11,581 INFO org.apache.hadoop.yarn.server.resourcemanager.scheduler.capacity.LeafQueue: assignedContainer application attempt=appattempt_1549167607896_0002_000002 container=Container: [ContainerId: container_1549167607896_0002_02_000001, NodeId: ubuntu-HP-Pavilion-dv6-NoteBook-PC:36263, NodeHttpAddress: ubuntu-HP-Pavilion-dv6-NoteBook-PC:8042, Resource: <memory:2048, vCores:1>, Priority: 0, Token: null, ] queue=default: capacity=1.0, absoluteCapacity=1.0, usedResources=<memory:0, vCores:0>, usedCapacity=0.0, absoluteUsedCapacity=0.0, numApps=1, numContainers=0 clusterResource=<memory:8192, vCores:8> type=OFF_SWITCH
2019-02-03 12:17:11,581 INFO org.apache.hadoop.yarn.server.resourcemanager.scheduler.capacity.ParentQueue: Re-sorting assigned queue: root.default stats: default: capacity=1.0, absoluteCapacity=1.0, usedResources=<memory:2048, vCores:1>, usedCapacity=0.25, absoluteUsedCapacity=0.25, numApps=1, numContainers=1
2019-02-03 12:17:11,582 INFO org.apache.hadoop.yarn.server.resourcemanager.scheduler.capacity.ParentQueue: assignedContainer queue=root usedCapacity=0.25 absoluteUsedCapacity=0.25 used=<memory:2048, vCores:1> cluster=<memory:8192, vCores:8>
2019-02-03 12:17:11,585 INFO org.apache.hadoop.yarn.server.resourcemanager.security.NMTokenSecretManagerInRM: Sending NMToken for nodeId : ubuntu-HP-Pavilion-dv6-NoteBook-PC:36263 for container : container_1549167607896_0002_02_000001
2019-02-03 12:17:11,589 INFO org.apache.hadoop.yarn.server.resourcemanager.rmcontainer.RMContainerImpl: container_1549167607896_0002_02_000001 Container Transitioned from ALLOCATED to ACQUIRED
2019-02-03 12:17:11,589 INFO org.apache.hadoop.yarn.server.resourcemanager.security.NMTokenSecretManagerInRM: Clear node set for appattempt_1549167607896_0002_000002
2019-02-03 12:17:11,589 INFO org.apache.hadoop.yarn.server.resourcemanager.rmapp.attempt.RMAppAttemptImpl: Storing attempt: AppId: application_1549167607896_0002 AttemptId: appattempt_1549167607896_0002_000002 MasterContainer: Container: [ContainerId: container_1549167607896_0002_02_000001, NodeId: ubuntu-HP-Pavilion-dv6-NoteBook-PC:36263, NodeHttpAddress: ubuntu-HP-Pavilion-dv6-NoteBook-PC:8042, Resource: <memory:2048, vCores:1>, Priority: 0, Token: Token { kind: ContainerToken, service: 127.0.1.1:36263 }, ]
2019-02-03 12:17:11,589 INFO org.apache.hadoop.yarn.server.resourcemanager.rmapp.attempt.RMAppAttemptImpl: appattempt_1549167607896_0002_000002 State change from SCHEDULED to ALLOCATED_SAVING
2019-02-03 12:17:11,589 INFO org.apache.hadoop.yarn.server.resourcemanager.rmapp.attempt.RMAppAttemptImpl: appattempt_1549167607896_0002_000002 State change from ALLOCATED_SAVING to ALLOCATED
2019-02-03 12:17:11,590 INFO org.apache.hadoop.yarn.server.resourcemanager.amlauncher.AMLauncher: Launching masterappattempt_1549167607896_0002_000002
2019-02-03 12:17:11,599 INFO org.apache.hadoop.yarn.server.resourcemanager.amlauncher.AMLauncher: Setting up container Container: [ContainerId: container_1549167607896_0002_02_000001, NodeId: ubuntu-HP-Pavilion-dv6-NoteBook-PC:36263, NodeHttpAddress: ubuntu-HP-Pavilion-dv6-NoteBook-PC:8042, Resource: <memory:2048, vCores:1>, Priority: 0, Token: Token { kind: ContainerToken, service: 127.0.1.1:36263 }, ] for AM appattempt_1549167607896_0002_000002
2019-02-03 12:17:11,599 INFO org.apache.hadoop.yarn.server.resourcemanager.amlauncher.AMLauncher: Command to launch container container_1549167607896_0002_02_000001 : $JAVA_HOME/bin/java -Djava.io.tmpdir=$PWD/tmp -Dlog4j.configuration=container-log4j.properties -Dyarn.app.container.log.dir=<LOG_DIR> -Dyarn.app.container.log.filesize=0 -Dhadoop.root.logger=INFO,CLA -Dhadoop.root.logfile=syslog  -Xmx1024m org.apache.hadoop.mapreduce.v2.app.MRAppMaster 1><LOG_DIR>/stdout 2><LOG_DIR>/stderr 
2019-02-03 12:17:11,599 INFO org.apache.hadoop.yarn.server.resourcemanager.security.AMRMTokenSecretManager: Create AMRMToken for ApplicationAttempt: appattempt_1549167607896_0002_000002
2019-02-03 12:17:11,600 INFO org.apache.hadoop.yarn.server.resourcemanager.security.AMRMTokenSecretManager: Creating password for appattempt_1549167607896_0002_000002
2019-02-03 12:17:11,615 INFO org.apache.hadoop.yarn.server.resourcemanager.amlauncher.AMLauncher: Done launching container Container: [ContainerId: container_1549167607896_0002_02_000001, NodeId: ubuntu-HP-Pavilion-dv6-NoteBook-PC:36263, NodeHttpAddress: ubuntu-HP-Pavilion-dv6-NoteBook-PC:8042, Resource: <memory:2048, vCores:1>, Priority: 0, Token: Token { kind: ContainerToken, service: 127.0.1.1:36263 }, ] for AM appattempt_1549167607896_0002_000002
2019-02-03 12:17:11,615 INFO org.apache.hadoop.yarn.server.resourcemanager.rmapp.attempt.RMAppAttemptImpl: appattempt_1549167607896_0002_000002 State change from ALLOCATED to LAUNCHED
2019-02-03 12:17:12,582 INFO org.apache.hadoop.yarn.server.resourcemanager.rmcontainer.RMContainerImpl: container_1549167607896_0002_02_000001 Container Transitioned from ACQUIRED to RUNNING
2019-02-03 12:17:16,452 INFO SecurityLogger.org.apache.hadoop.ipc.Server: Auth successful for appattempt_1549167607896_0002_000002 (auth:SIMPLE)
2019-02-03 12:17:16,461 INFO org.apache.hadoop.yarn.server.resourcemanager.ApplicationMasterService: AM registration appattempt_1549167607896_0002_000002
2019-02-03 12:17:16,462 INFO org.apache.hadoop.yarn.server.resourcemanager.RMAuditLogger: USER=root	IP=127.0.0.1	OPERATION=Register App Master	TARGET=ApplicationMasterService	RESULT=SUCCESS	APPID=application_1549167607896_0002	APPATTEMPTID=appattempt_1549167607896_0002_000002
2019-02-03 12:17:16,462 INFO org.apache.hadoop.yarn.server.resourcemanager.rmapp.attempt.RMAppAttemptImpl: appattempt_1549167607896_0002_000002 State change from LAUNCHED to RUNNING
2019-02-03 12:17:16,462 INFO org.apache.hadoop.yarn.server.resourcemanager.rmapp.RMAppImpl: application_1549167607896_0002 State change from ACCEPTED to RUNNING
2019-02-03 12:17:16,583 INFO org.apache.hadoop.yarn.server.resourcemanager.rmcontainer.RMContainerImpl: container_1549167607896_0002_02_000001 Container Transitioned from RUNNING to COMPLETED
2019-02-03 12:17:16,583 INFO org.apache.hadoop.yarn.server.resourcemanager.scheduler.common.fica.FiCaSchedulerApp: Completed container: container_1549167607896_0002_02_000001 in state: COMPLETED event:FINISHED
2019-02-03 12:17:16,583 INFO org.apache.hadoop.yarn.server.resourcemanager.RMAuditLogger: USER=root	OPERATION=AM Released Container	TARGET=SchedulerApp	RESULT=SUCCESS	APPID=application_1549167607896_0002	CONTAINERID=container_1549167607896_0002_02_000001
2019-02-03 12:17:16,583 INFO org.apache.hadoop.yarn.server.resourcemanager.scheduler.SchedulerNode: Released container container_1549167607896_0002_02_000001 of capacity <memory:2048, vCores:1> on host ubuntu-HP-Pavilion-dv6-NoteBook-PC:36263, which currently has 0 containers, <memory:0, vCores:0> used and <memory:8192, vCores:8> available, release resources=true
2019-02-03 12:17:16,583 INFO org.apache.hadoop.yarn.server.resourcemanager.rmapp.attempt.RMAppAttemptImpl: Updating application attempt appattempt_1549167607896_0002_000002 with final state: FAILED, and exit status: -103
2019-02-03 12:17:16,583 INFO org.apache.hadoop.yarn.server.resourcemanager.rmapp.attempt.RMAppAttemptImpl: appattempt_1549167607896_0002_000002 State change from RUNNING to FINAL_SAVING
2019-02-03 12:17:16,584 INFO org.apache.hadoop.yarn.server.resourcemanager.scheduler.capacity.LeafQueue: default used=<memory:0, vCores:0> numContainers=0 user=root user-resources=<memory:0, vCores:0>
2019-02-03 12:17:16,584 INFO org.apache.hadoop.yarn.server.resourcemanager.scheduler.capacity.LeafQueue: completedContainer container=Container: [ContainerId: container_1549167607896_0002_02_000001, NodeId: ubuntu-HP-Pavilion-dv6-NoteBook-PC:36263, NodeHttpAddress: ubuntu-HP-Pavilion-dv6-NoteBook-PC:8042, Resource: <memory:2048, vCores:1>, Priority: 0, Token: Token { kind: ContainerToken, service: 127.0.1.1:36263 }, ] queue=default: capacity=1.0, absoluteCapacity=1.0, usedResources=<memory:0, vCores:0>, usedCapacity=0.0, absoluteUsedCapacity=0.0, numApps=1, numContainers=0 cluster=<memory:8192, vCores:8>
2019-02-03 12:17:16,584 INFO org.apache.hadoop.yarn.server.resourcemanager.ApplicationMasterService: Unregistering app attempt : appattempt_1549167607896_0002_000002
2019-02-03 12:17:16,584 INFO org.apache.hadoop.yarn.server.resourcemanager.scheduler.capacity.ParentQueue: completedContainer queue=root usedCapacity=0.0 absoluteUsedCapacity=0.0 used=<memory:0, vCores:0> cluster=<memory:8192, vCores:8>
2019-02-03 12:17:16,584 INFO org.apache.hadoop.yarn.server.resourcemanager.security.AMRMTokenSecretManager: Application finished, removing password for appattempt_1549167607896_0002_000002
2019-02-03 12:17:16,584 INFO org.apache.hadoop.yarn.server.resourcemanager.scheduler.capacity.ParentQueue: Re-sorting completed queue: root.default stats: default: capacity=1.0, absoluteCapacity=1.0, usedResources=<memory:0, vCores:0>, usedCapacity=0.0, absoluteUsedCapacity=0.0, numApps=1, numContainers=0
2019-02-03 12:17:16,584 INFO org.apache.hadoop.yarn.server.resourcemanager.scheduler.capacity.CapacityScheduler: Application attempt appattempt_1549167607896_0002_000002 released container container_1549167607896_0002_02_000001 on node: host: ubuntu-HP-Pavilion-dv6-NoteBook-PC:36263 #containers=0 available=<memory:8192, vCores:8> used=<memory:0, vCores:0> with event: FINISHED
2019-02-03 12:17:16,584 INFO org.apache.hadoop.yarn.server.resourcemanager.rmapp.attempt.RMAppAttemptImpl: appattempt_1549167607896_0002_000002 State change from FINAL_SAVING to FAILED
2019-02-03 12:17:16,584 INFO org.apache.hadoop.yarn.server.resourcemanager.rmapp.RMAppImpl: The number of failed attempts is 2. The max attempts is 2
2019-02-03 12:17:16,584 INFO org.apache.hadoop.yarn.server.resourcemanager.rmapp.RMAppImpl: Updating application application_1549167607896_0002 with final state: FAILED
2019-02-03 12:17:16,585 INFO org.apache.hadoop.yarn.server.resourcemanager.rmapp.RMAppImpl: application_1549167607896_0002 State change from RUNNING to FINAL_SAVING
2019-02-03 12:17:16,585 INFO org.apache.hadoop.yarn.server.resourcemanager.recovery.RMStateStore: Updating info for app: application_1549167607896_0002
2019-02-03 12:17:16,585 INFO org.apache.hadoop.yarn.server.resourcemanager.scheduler.capacity.CapacityScheduler: Application Attempt appattempt_1549167607896_0002_000002 is done. finalState=FAILED
2019-02-03 12:17:16,585 INFO org.apache.hadoop.yarn.server.resourcemanager.rmapp.RMAppImpl: Application application_1549167607896_0002 failed 2 times due to AM Container for appattempt_1549167607896_0002_000002 exited with  exitCode: -103
For more detailed output, check application tracking page:http://ubuntu-HP-Pavilion-dv6-NoteBook-PC:8088/cluster/app/application_1549167607896_0002Then, click on links to logs of each attempt.
Diagnostics: Container [pid=13935,containerID=container_1549167607896_0002_02_000001] is running beyond virtual memory limits. Current usage: 294.4 MB of 2 GB physical memory used; 4.5 GB of 4.2 GB virtual memory used. Killing container.
Dump of the process-tree for container_1549167607896_0002_02_000001 :
	|- PID PPID PGRPID SESSID CMD_NAME USER_MODE_TIME(MILLIS) SYSTEM_TIME(MILLIS) VMEM_USAGE(BYTES) RSSMEM_USAGE(PAGES) FULL_CMD_LINE
	|- 13945 13935 13935 13935 (java) 1179 34 4787789824 74662 /usr/lib/jvm/java-8-openjdk-amd64/bin/java -Djava.io.tmpdir=/home/ubuntu/hdata/nm-local-dir/usercache/root/appcache/application_1549167607896_0002/container_1549167607896_0002_02_000001/tmp -Dlog4j.configuration=container-log4j.properties -Dyarn.app.container.log.dir=/opt/hadoop/hadoop-2.7.3/logs/userlogs/application_1549167607896_0002/container_1549167607896_0002_02_000001 -Dyarn.app.container.log.filesize=0 -Dhadoop.root.logger=INFO,CLA -Dhadoop.root.logfile=syslog -Xmx1024m org.apache.hadoop.mapreduce.v2.app.MRAppMaster 
	|- 13935 13933 13935 13935 (bash) 0 0 14725120 696 /bin/bash -c /usr/lib/jvm/java-8-openjdk-amd64/bin/java -Djava.io.tmpdir=/home/ubuntu/hdata/nm-local-dir/usercache/root/appcache/application_1549167607896_0002/container_1549167607896_0002_02_000001/tmp -Dlog4j.configuration=container-log4j.properties -Dyarn.app.container.log.dir=/opt/hadoop/hadoop-2.7.3/logs/userlogs/application_1549167607896_0002/container_1549167607896_0002_02_000001 -Dyarn.app.container.log.filesize=0 -Dhadoop.root.logger=INFO,CLA -Dhadoop.root.logfile=syslog  -Xmx1024m org.apache.hadoop.mapreduce.v2.app.MRAppMaster 1>/opt/hadoop/hadoop-2.7.3/logs/userlogs/application_1549167607896_0002/container_1549167607896_0002_02_000001/stdout 2>/opt/hadoop/hadoop-2.7.3/logs/userlogs/application_1549167607896_0002/container_1549167607896_0002_02_000001/stderr  

Container killed on request. Exit code is 143
Container exited with a non-zero exit code 143
Failing this attempt. Failing the application.
2019-02-03 12:17:16,585 INFO org.apache.hadoop.yarn.server.resourcemanager.scheduler.AppSchedulingInfo: Application application_1549167607896_0002 requests cleared
2019-02-03 12:17:16,585 INFO org.apache.hadoop.yarn.server.resourcemanager.rmapp.RMAppImpl: application_1549167607896_0002 State change from FINAL_SAVING to FAILED
2019-02-03 12:17:16,585 INFO org.apache.hadoop.yarn.server.resourcemanager.scheduler.capacity.LeafQueue: Application removed - appId: application_1549167607896_0002 user: root queue: default #user-pending-applications: 0 #user-active-applications: 0 #queue-pending-applications: 0 #queue-active-applications: 0
2019-02-03 12:17:16,585 INFO org.apache.hadoop.yarn.server.resourcemanager.scheduler.capacity.ParentQueue: Application removed - appId: application_1549167607896_0002 user: root leaf-queue of parent: root #applications: 0
2019-02-03 12:17:16,585 WARN org.apache.hadoop.yarn.server.resourcemanager.RMAuditLogger: USER=root	OPERATION=Application Finished - Failed	TARGET=RMAppManager	RESULT=FAILURE	DESCRIPTION=App failed with state: FAILED	PERMISSIONS=Application application_1549167607896_0002 failed 2 times due to AM Container for appattempt_1549167607896_0002_000002 exited with  exitCode: -103
For more detailed output, check application tracking page:http://ubuntu-HP-Pavilion-dv6-NoteBook-PC:8088/cluster/app/application_1549167607896_0002Then, click on links to logs of each attempt.
Diagnostics: Container [pid=13935,containerID=container_1549167607896_0002_02_000001] is running beyond virtual memory limits. Current usage: 294.4 MB of 2 GB physical memory used; 4.5 GB of 4.2 GB virtual memory used. Killing container.
Dump of the process-tree for container_1549167607896_0002_02_000001 :
	|- PID PPID PGRPID SESSID CMD_NAME USER_MODE_TIME(MILLIS) SYSTEM_TIME(MILLIS) VMEM_USAGE(BYTES) RSSMEM_USAGE(PAGES) FULL_CMD_LINE
	|- 13945 13935 13935 13935 (java) 1179 34 4787789824 74662 /usr/lib/jvm/java-8-openjdk-amd64/bin/java -Djava.io.tmpdir=/home/ubuntu/hdata/nm-local-dir/usercache/root/appcache/application_1549167607896_0002/container_1549167607896_0002_02_000001/tmp -Dlog4j.configuration=container-log4j.properties -Dyarn.app.container.log.dir=/opt/hadoop/hadoop-2.7.3/logs/userlogs/application_1549167607896_0002/container_1549167607896_0002_02_000001 -Dyarn.app.container.log.filesize=0 -Dhadoop.root.logger=INFO,CLA -Dhadoop.root.logfile=syslog -Xmx1024m org.apache.hadoop.mapreduce.v2.app.MRAppMaster 
	|- 13935 13933 13935 13935 (bash) 0 0 14725120 696 /bin/bash -c /usr/lib/jvm/java-8-openjdk-amd64/bin/java -Djava.io.tmpdir=/home/ubuntu/hdata/nm-local-dir/usercache/root/appcache/application_1549167607896_0002/container_1549167607896_0002_02_000001/tmp -Dlog4j.configuration=container-log4j.properties -Dyarn.app.container.log.dir=/opt/hadoop/hadoop-2.7.3/logs/userlogs/application_1549167607896_0002/container_1549167607896_0002_02_000001 -Dyarn.app.container.log.filesize=0 -Dhadoop.root.logger=INFO,CLA -Dhadoop.root.logfile=syslog  -Xmx1024m org.apache.hadoop.mapreduce.v2.app.MRAppMaster 1>/opt/hadoop/hadoop-2.7.3/logs/userlogs/application_1549167607896_0002/container_1549167607896_0002_02_000001/stdout 2>/opt/hadoop/hadoop-2.7.3/logs/userlogs/application_1549167607896_0002/container_1549167607896_0002_02_000001/stderr  

Container killed on request. Exit code is 143
Container exited with a non-zero exit code 143
Failing this attempt. Failing the application.	APPID=application_1549167607896_0002
2019-02-03 12:17:16,586 INFO org.apache.hadoop.yarn.server.resourcemanager.amlauncher.AMLauncher: Cleaning master appattempt_1549167607896_0002_000002
2019-02-03 12:17:16,586 INFO org.apache.hadoop.yarn.server.resourcemanager.RMAppManager$ApplicationSummary: appId=application_1549167607896_0002,name=SELECT count(*) FROM stocks WHERE...'NASDAQ'(Stage-1),user=root,queue=default,state=FAILED,trackingUrl=http://ubuntu-HP-Pavilion-dv6-NoteBook-PC:8088/cluster/app/application_1549167607896_0002,appMasterHost=N/A,startTime=1549176425714,finishTime=1549176436584,finalStatus=FAILED,memorySeconds=19562,vcoreSeconds=9,preemptedAMContainers=0,preemptedNonAMContainers=0,preemptedResources=<memory:0\, vCores:0>,applicationType=MAPREDUCE
2019-02-03 12:17:17,313 INFO org.apache.hadoop.yarn.server.resourcemanager.RMAuditLogger: USER=root	IP=127.0.0.1	OPERATION=Kill Application Request	TARGET=ClientRMService	RESULT=SUCCESS	APPID=application_1549167607896_0002
2019-02-03 12:18:18,586 INFO org.apache.hadoop.yarn.server.resourcemanager.ClientRMService: Allocated new applicationId: 3
2019-02-03 12:18:18,978 INFO org.apache.hadoop.yarn.server.resourcemanager.ClientRMService: Application with id 3 submitted by user root
2019-02-03 12:18:18,978 INFO org.apache.hadoop.yarn.server.resourcemanager.rmapp.RMAppImpl: Storing application with id application_1549167607896_0003
2019-02-03 12:18:18,978 INFO org.apache.hadoop.yarn.server.resourcemanager.RMAuditLogger: USER=root	IP=127.0.0.1	OPERATION=Submit Application Request	TARGET=ClientRMService	RESULT=SUCCESS	APPID=application_1549167607896_0003
2019-02-03 12:18:18,978 INFO org.apache.hadoop.yarn.server.resourcemanager.rmapp.RMAppImpl: application_1549167607896_0003 State change from NEW to NEW_SAVING
2019-02-03 12:18:18,979 INFO org.apache.hadoop.yarn.server.resourcemanager.recovery.RMStateStore: Storing info for app: application_1549167607896_0003
2019-02-03 12:18:18,979 INFO org.apache.hadoop.yarn.server.resourcemanager.rmapp.RMAppImpl: application_1549167607896_0003 State change from NEW_SAVING to SUBMITTED
2019-02-03 12:18:18,979 INFO org.apache.hadoop.yarn.server.resourcemanager.scheduler.capacity.ParentQueue: Application added - appId: application_1549167607896_0003 user: root leaf-queue of parent: root #applications: 1
2019-02-03 12:18:18,979 INFO org.apache.hadoop.yarn.server.resourcemanager.scheduler.capacity.CapacityScheduler: Accepted application application_1549167607896_0003 from user: root, in queue: default
2019-02-03 12:18:18,980 INFO org.apache.hadoop.yarn.server.resourcemanager.rmapp.RMAppImpl: application_1549167607896_0003 State change from SUBMITTED to ACCEPTED
2019-02-03 12:18:18,980 INFO org.apache.hadoop.yarn.server.resourcemanager.ApplicationMasterService: Registering app attempt : appattempt_1549167607896_0003_000001
2019-02-03 12:18:18,980 INFO org.apache.hadoop.yarn.server.resourcemanager.rmapp.attempt.RMAppAttemptImpl: appattempt_1549167607896_0003_000001 State change from NEW to SUBMITTED
2019-02-03 12:18:18,981 WARN org.apache.hadoop.yarn.server.resourcemanager.scheduler.capacity.LeafQueue: maximum-am-resource-percent is insufficient to start a single application in queue, it is likely set too low. skipping enforcement to allow at least one application to start
2019-02-03 12:18:18,981 WARN org.apache.hadoop.yarn.server.resourcemanager.scheduler.capacity.LeafQueue: maximum-am-resource-percent is insufficient to start a single application in queue for user, it is likely set too low. skipping enforcement to allow at least one application to start
2019-02-03 12:18:18,981 INFO org.apache.hadoop.yarn.server.resourcemanager.scheduler.capacity.LeafQueue: Application application_1549167607896_0003 from user: root activated in queue: default
2019-02-03 12:18:18,981 INFO org.apache.hadoop.yarn.server.resourcemanager.scheduler.capacity.LeafQueue: Application added - appId: application_1549167607896_0003 user: org.apache.hadoop.yarn.server.resourcemanager.scheduler.capacity.LeafQueue$User@250c0d4b, leaf-queue: default #user-pending-applications: 0 #user-active-applications: 1 #queue-pending-applications: 0 #queue-active-applications: 1
2019-02-03 12:18:18,981 INFO org.apache.hadoop.yarn.server.resourcemanager.scheduler.capacity.CapacityScheduler: Added Application Attempt appattempt_1549167607896_0003_000001 to scheduler from user root in queue default
2019-02-03 12:18:18,982 INFO org.apache.hadoop.yarn.server.resourcemanager.rmapp.attempt.RMAppAttemptImpl: appattempt_1549167607896_0003_000001 State change from SUBMITTED to SCHEDULED
2019-02-03 12:18:19,681 INFO org.apache.hadoop.yarn.server.resourcemanager.rmcontainer.RMContainerImpl: container_1549167607896_0003_01_000001 Container Transitioned from NEW to ALLOCATED
2019-02-03 12:18:19,681 INFO org.apache.hadoop.yarn.server.resourcemanager.RMAuditLogger: USER=root	OPERATION=AM Allocated Container	TARGET=SchedulerApp	RESULT=SUCCESS	APPID=application_1549167607896_0003	CONTAINERID=container_1549167607896_0003_01_000001
2019-02-03 12:18:19,681 INFO org.apache.hadoop.yarn.server.resourcemanager.scheduler.SchedulerNode: Assigned container container_1549167607896_0003_01_000001 of capacity <memory:2048, vCores:1> on host ubuntu-HP-Pavilion-dv6-NoteBook-PC:36263, which has 1 containers, <memory:2048, vCores:1> used and <memory:6144, vCores:7> available after allocation
2019-02-03 12:18:19,682 INFO org.apache.hadoop.yarn.server.resourcemanager.scheduler.capacity.LeafQueue: assignedContainer application attempt=appattempt_1549167607896_0003_000001 container=Container: [ContainerId: container_1549167607896_0003_01_000001, NodeId: ubuntu-HP-Pavilion-dv6-NoteBook-PC:36263, NodeHttpAddress: ubuntu-HP-Pavilion-dv6-NoteBook-PC:8042, Resource: <memory:2048, vCores:1>, Priority: 0, Token: null, ] queue=default: capacity=1.0, absoluteCapacity=1.0, usedResources=<memory:0, vCores:0>, usedCapacity=0.0, absoluteUsedCapacity=0.0, numApps=1, numContainers=0 clusterResource=<memory:8192, vCores:8> type=OFF_SWITCH
2019-02-03 12:18:19,682 INFO org.apache.hadoop.yarn.server.resourcemanager.scheduler.capacity.ParentQueue: Re-sorting assigned queue: root.default stats: default: capacity=1.0, absoluteCapacity=1.0, usedResources=<memory:2048, vCores:1>, usedCapacity=0.25, absoluteUsedCapacity=0.25, numApps=1, numContainers=1
2019-02-03 12:18:19,683 INFO org.apache.hadoop.yarn.server.resourcemanager.scheduler.capacity.ParentQueue: assignedContainer queue=root usedCapacity=0.25 absoluteUsedCapacity=0.25 used=<memory:2048, vCores:1> cluster=<memory:8192, vCores:8>
2019-02-03 12:18:19,686 INFO org.apache.hadoop.yarn.server.resourcemanager.security.NMTokenSecretManagerInRM: Sending NMToken for nodeId : ubuntu-HP-Pavilion-dv6-NoteBook-PC:36263 for container : container_1549167607896_0003_01_000001
2019-02-03 12:18:19,690 INFO org.apache.hadoop.yarn.server.resourcemanager.rmcontainer.RMContainerImpl: container_1549167607896_0003_01_000001 Container Transitioned from ALLOCATED to ACQUIRED
2019-02-03 12:18:19,691 INFO org.apache.hadoop.yarn.server.resourcemanager.security.NMTokenSecretManagerInRM: Clear node set for appattempt_1549167607896_0003_000001
2019-02-03 12:18:19,691 INFO org.apache.hadoop.yarn.server.resourcemanager.rmapp.attempt.RMAppAttemptImpl: Storing attempt: AppId: application_1549167607896_0003 AttemptId: appattempt_1549167607896_0003_000001 MasterContainer: Container: [ContainerId: container_1549167607896_0003_01_000001, NodeId: ubuntu-HP-Pavilion-dv6-NoteBook-PC:36263, NodeHttpAddress: ubuntu-HP-Pavilion-dv6-NoteBook-PC:8042, Resource: <memory:2048, vCores:1>, Priority: 0, Token: Token { kind: ContainerToken, service: 127.0.1.1:36263 }, ]
2019-02-03 12:18:19,691 INFO org.apache.hadoop.yarn.server.resourcemanager.rmapp.attempt.RMAppAttemptImpl: appattempt_1549167607896_0003_000001 State change from SCHEDULED to ALLOCATED_SAVING
2019-02-03 12:18:19,691 INFO org.apache.hadoop.yarn.server.resourcemanager.rmapp.attempt.RMAppAttemptImpl: appattempt_1549167607896_0003_000001 State change from ALLOCATED_SAVING to ALLOCATED
2019-02-03 12:18:19,692 INFO org.apache.hadoop.yarn.server.resourcemanager.amlauncher.AMLauncher: Launching masterappattempt_1549167607896_0003_000001
2019-02-03 12:18:19,695 INFO org.apache.hadoop.yarn.server.resourcemanager.amlauncher.AMLauncher: Setting up container Container: [ContainerId: container_1549167607896_0003_01_000001, NodeId: ubuntu-HP-Pavilion-dv6-NoteBook-PC:36263, NodeHttpAddress: ubuntu-HP-Pavilion-dv6-NoteBook-PC:8042, Resource: <memory:2048, vCores:1>, Priority: 0, Token: Token { kind: ContainerToken, service: 127.0.1.1:36263 }, ] for AM appattempt_1549167607896_0003_000001
2019-02-03 12:18:19,695 INFO org.apache.hadoop.yarn.server.resourcemanager.amlauncher.AMLauncher: Command to launch container container_1549167607896_0003_01_000001 : $JAVA_HOME/bin/java -Djava.io.tmpdir=$PWD/tmp -Dlog4j.configuration=container-log4j.properties -Dyarn.app.container.log.dir=<LOG_DIR> -Dyarn.app.container.log.filesize=0 -Dhadoop.root.logger=INFO,CLA -Dhadoop.root.logfile=syslog  -Xmx1024m org.apache.hadoop.mapreduce.v2.app.MRAppMaster 1><LOG_DIR>/stdout 2><LOG_DIR>/stderr 
2019-02-03 12:18:19,695 INFO org.apache.hadoop.yarn.server.resourcemanager.security.AMRMTokenSecretManager: Create AMRMToken for ApplicationAttempt: appattempt_1549167607896_0003_000001
2019-02-03 12:18:19,695 INFO org.apache.hadoop.yarn.server.resourcemanager.security.AMRMTokenSecretManager: Creating password for appattempt_1549167607896_0003_000001
2019-02-03 12:18:19,708 INFO org.apache.hadoop.yarn.server.resourcemanager.amlauncher.AMLauncher: Done launching container Container: [ContainerId: container_1549167607896_0003_01_000001, NodeId: ubuntu-HP-Pavilion-dv6-NoteBook-PC:36263, NodeHttpAddress: ubuntu-HP-Pavilion-dv6-NoteBook-PC:8042, Resource: <memory:2048, vCores:1>, Priority: 0, Token: Token { kind: ContainerToken, service: 127.0.1.1:36263 }, ] for AM appattempt_1549167607896_0003_000001
2019-02-03 12:18:19,708 INFO org.apache.hadoop.yarn.server.resourcemanager.rmapp.attempt.RMAppAttemptImpl: appattempt_1549167607896_0003_000001 State change from ALLOCATED to LAUNCHED
2019-02-03 12:18:20,681 INFO org.apache.hadoop.yarn.server.resourcemanager.rmcontainer.RMContainerImpl: container_1549167607896_0003_01_000001 Container Transitioned from ACQUIRED to RUNNING
2019-02-03 12:18:24,985 INFO SecurityLogger.org.apache.hadoop.ipc.Server: Auth successful for appattempt_1549167607896_0003_000001 (auth:SIMPLE)
2019-02-03 12:18:24,998 INFO org.apache.hadoop.yarn.server.resourcemanager.ApplicationMasterService: AM registration appattempt_1549167607896_0003_000001
2019-02-03 12:18:24,998 INFO org.apache.hadoop.yarn.server.resourcemanager.rmapp.attempt.RMAppAttemptImpl: appattempt_1549167607896_0003_000001 State change from LAUNCHED to RUNNING
2019-02-03 12:18:24,998 INFO org.apache.hadoop.yarn.server.resourcemanager.rmapp.RMAppImpl: application_1549167607896_0003 State change from ACCEPTED to RUNNING
2019-02-03 12:18:25,002 INFO org.apache.hadoop.yarn.server.resourcemanager.RMAuditLogger: USER=root	IP=127.0.0.1	OPERATION=Register App Master	TARGET=ApplicationMasterService	RESULT=SUCCESS	APPID=application_1549167607896_0003	APPATTEMPTID=appattempt_1549167607896_0003_000001
2019-02-03 12:18:25,754 INFO org.apache.hadoop.yarn.server.resourcemanager.rmcontainer.RMContainerImpl: container_1549167607896_0003_01_000001 Container Transitioned from RUNNING to COMPLETED
2019-02-03 12:18:25,754 INFO org.apache.hadoop.yarn.server.resourcemanager.scheduler.common.fica.FiCaSchedulerApp: Completed container: container_1549167607896_0003_01_000001 in state: COMPLETED event:FINISHED
2019-02-03 12:18:25,754 INFO org.apache.hadoop.yarn.server.resourcemanager.RMAuditLogger: USER=root	OPERATION=AM Released Container	TARGET=SchedulerApp	RESULT=SUCCESS	APPID=application_1549167607896_0003	CONTAINERID=container_1549167607896_0003_01_000001
2019-02-03 12:18:25,754 INFO org.apache.hadoop.yarn.server.resourcemanager.scheduler.SchedulerNode: Released container container_1549167607896_0003_01_000001 of capacity <memory:2048, vCores:1> on host ubuntu-HP-Pavilion-dv6-NoteBook-PC:36263, which currently has 0 containers, <memory:0, vCores:0> used and <memory:8192, vCores:8> available, release resources=true
2019-02-03 12:18:25,754 INFO org.apache.hadoop.yarn.server.resourcemanager.scheduler.capacity.LeafQueue: default used=<memory:0, vCores:0> numContainers=0 user=root user-resources=<memory:0, vCores:0>
2019-02-03 12:18:25,754 INFO org.apache.hadoop.yarn.server.resourcemanager.scheduler.capacity.LeafQueue: completedContainer container=Container: [ContainerId: container_1549167607896_0003_01_000001, NodeId: ubuntu-HP-Pavilion-dv6-NoteBook-PC:36263, NodeHttpAddress: ubuntu-HP-Pavilion-dv6-NoteBook-PC:8042, Resource: <memory:2048, vCores:1>, Priority: 0, Token: Token { kind: ContainerToken, service: 127.0.1.1:36263 }, ] queue=default: capacity=1.0, absoluteCapacity=1.0, usedResources=<memory:0, vCores:0>, usedCapacity=0.0, absoluteUsedCapacity=0.0, numApps=1, numContainers=0 cluster=<memory:8192, vCores:8>
2019-02-03 12:18:25,755 INFO org.apache.hadoop.yarn.server.resourcemanager.scheduler.capacity.ParentQueue: completedContainer queue=root usedCapacity=0.0 absoluteUsedCapacity=0.0 used=<memory:0, vCores:0> cluster=<memory:8192, vCores:8>
2019-02-03 12:18:25,755 INFO org.apache.hadoop.yarn.server.resourcemanager.scheduler.capacity.ParentQueue: Re-sorting completed queue: root.default stats: default: capacity=1.0, absoluteCapacity=1.0, usedResources=<memory:0, vCores:0>, usedCapacity=0.0, absoluteUsedCapacity=0.0, numApps=1, numContainers=0
2019-02-03 12:18:25,755 INFO org.apache.hadoop.yarn.server.resourcemanager.scheduler.capacity.CapacityScheduler: Application attempt appattempt_1549167607896_0003_000001 released container container_1549167607896_0003_01_000001 on node: host: ubuntu-HP-Pavilion-dv6-NoteBook-PC:36263 #containers=0 available=<memory:8192, vCores:8> used=<memory:0, vCores:0> with event: FINISHED
2019-02-03 12:18:25,755 INFO org.apache.hadoop.yarn.server.resourcemanager.rmapp.attempt.RMAppAttemptImpl: Updating application attempt appattempt_1549167607896_0003_000001 with final state: FAILED, and exit status: -103
2019-02-03 12:18:25,755 INFO org.apache.hadoop.yarn.server.resourcemanager.rmapp.attempt.RMAppAttemptImpl: appattempt_1549167607896_0003_000001 State change from RUNNING to FINAL_SAVING
2019-02-03 12:18:25,756 INFO org.apache.hadoop.yarn.server.resourcemanager.ApplicationMasterService: Unregistering app attempt : appattempt_1549167607896_0003_000001
2019-02-03 12:18:25,756 INFO org.apache.hadoop.yarn.server.resourcemanager.security.AMRMTokenSecretManager: Application finished, removing password for appattempt_1549167607896_0003_000001
2019-02-03 12:18:25,756 INFO org.apache.hadoop.yarn.server.resourcemanager.rmapp.attempt.RMAppAttemptImpl: appattempt_1549167607896_0003_000001 State change from FINAL_SAVING to FAILED
2019-02-03 12:18:25,756 INFO org.apache.hadoop.yarn.server.resourcemanager.rmapp.RMAppImpl: The number of failed attempts is 1. The max attempts is 2
2019-02-03 12:18:25,756 INFO org.apache.hadoop.yarn.server.resourcemanager.rmapp.RMAppImpl: application_1549167607896_0003 State change from RUNNING to ACCEPTED
2019-02-03 12:18:25,756 INFO org.apache.hadoop.yarn.server.resourcemanager.ApplicationMasterService: Registering app attempt : appattempt_1549167607896_0003_000002
2019-02-03 12:18:25,756 INFO org.apache.hadoop.yarn.server.resourcemanager.rmapp.attempt.RMAppAttemptImpl: appattempt_1549167607896_0003_000002 State change from NEW to SUBMITTED
2019-02-03 12:18:25,757 INFO org.apache.hadoop.yarn.server.resourcemanager.scheduler.capacity.CapacityScheduler: Application Attempt appattempt_1549167607896_0003_000001 is done. finalState=FAILED
2019-02-03 12:18:25,757 INFO org.apache.hadoop.yarn.server.resourcemanager.scheduler.AppSchedulingInfo: Application application_1549167607896_0003 requests cleared
2019-02-03 12:18:25,757 INFO org.apache.hadoop.yarn.server.resourcemanager.amlauncher.AMLauncher: Cleaning master appattempt_1549167607896_0003_000001
2019-02-03 12:18:25,758 INFO org.apache.hadoop.yarn.server.resourcemanager.scheduler.capacity.LeafQueue: Application removed - appId: application_1549167607896_0003 user: root queue: default #user-pending-applications: 0 #user-active-applications: 0 #queue-pending-applications: 0 #queue-active-applications: 0
2019-02-03 12:18:25,758 WARN org.apache.hadoop.yarn.server.resourcemanager.scheduler.capacity.LeafQueue: maximum-am-resource-percent is insufficient to start a single application in queue, it is likely set too low. skipping enforcement to allow at least one application to start
2019-02-03 12:18:25,758 WARN org.apache.hadoop.yarn.server.resourcemanager.scheduler.capacity.LeafQueue: maximum-am-resource-percent is insufficient to start a single application in queue for user, it is likely set too low. skipping enforcement to allow at least one application to start
2019-02-03 12:18:25,758 INFO org.apache.hadoop.yarn.server.resourcemanager.scheduler.capacity.LeafQueue: Application application_1549167607896_0003 from user: root activated in queue: default
2019-02-03 12:18:25,758 INFO org.apache.hadoop.yarn.server.resourcemanager.scheduler.capacity.LeafQueue: Application added - appId: application_1549167607896_0003 user: org.apache.hadoop.yarn.server.resourcemanager.scheduler.capacity.LeafQueue$User@634f0db, leaf-queue: default #user-pending-applications: 0 #user-active-applications: 1 #queue-pending-applications: 0 #queue-active-applications: 1
2019-02-03 12:18:25,758 INFO org.apache.hadoop.yarn.server.resourcemanager.scheduler.capacity.CapacityScheduler: Added Application Attempt appattempt_1549167607896_0003_000002 to scheduler from user root in queue default
2019-02-03 12:18:25,759 INFO org.apache.hadoop.yarn.server.resourcemanager.rmapp.attempt.RMAppAttemptImpl: appattempt_1549167607896_0003_000002 State change from SUBMITTED to SCHEDULED
2019-02-03 12:18:26,769 INFO org.apache.hadoop.yarn.server.resourcemanager.rmcontainer.RMContainerImpl: container_1549167607896_0003_02_000001 Container Transitioned from NEW to ALLOCATED
2019-02-03 12:18:26,770 INFO org.apache.hadoop.yarn.server.resourcemanager.RMAuditLogger: USER=root	OPERATION=AM Allocated Container	TARGET=SchedulerApp	RESULT=SUCCESS	APPID=application_1549167607896_0003	CONTAINERID=container_1549167607896_0003_02_000001
2019-02-03 12:18:26,770 INFO org.apache.hadoop.yarn.server.resourcemanager.scheduler.SchedulerNode: Assigned container container_1549167607896_0003_02_000001 of capacity <memory:2048, vCores:1> on host ubuntu-HP-Pavilion-dv6-NoteBook-PC:36263, which has 1 containers, <memory:2048, vCores:1> used and <memory:6144, vCores:7> available after allocation
2019-02-03 12:18:26,770 INFO org.apache.hadoop.yarn.server.resourcemanager.scheduler.capacity.LeafQueue: assignedContainer application attempt=appattempt_1549167607896_0003_000002 container=Container: [ContainerId: container_1549167607896_0003_02_000001, NodeId: ubuntu-HP-Pavilion-dv6-NoteBook-PC:36263, NodeHttpAddress: ubuntu-HP-Pavilion-dv6-NoteBook-PC:8042, Resource: <memory:2048, vCores:1>, Priority: 0, Token: null, ] queue=default: capacity=1.0, absoluteCapacity=1.0, usedResources=<memory:0, vCores:0>, usedCapacity=0.0, absoluteUsedCapacity=0.0, numApps=1, numContainers=0 clusterResource=<memory:8192, vCores:8> type=OFF_SWITCH
2019-02-03 12:18:26,771 INFO org.apache.hadoop.yarn.server.resourcemanager.scheduler.capacity.ParentQueue: Re-sorting assigned queue: root.default stats: default: capacity=1.0, absoluteCapacity=1.0, usedResources=<memory:2048, vCores:1>, usedCapacity=0.25, absoluteUsedCapacity=0.25, numApps=1, numContainers=1
2019-02-03 12:18:26,771 INFO org.apache.hadoop.yarn.server.resourcemanager.scheduler.capacity.ParentQueue: assignedContainer queue=root usedCapacity=0.25 absoluteUsedCapacity=0.25 used=<memory:2048, vCores:1> cluster=<memory:8192, vCores:8>
2019-02-03 12:18:26,773 INFO org.apache.hadoop.yarn.server.resourcemanager.security.NMTokenSecretManagerInRM: Sending NMToken for nodeId : ubuntu-HP-Pavilion-dv6-NoteBook-PC:36263 for container : container_1549167607896_0003_02_000001
2019-02-03 12:18:26,777 INFO org.apache.hadoop.yarn.server.resourcemanager.rmcontainer.RMContainerImpl: container_1549167607896_0003_02_000001 Container Transitioned from ALLOCATED to ACQUIRED
2019-02-03 12:18:26,777 INFO org.apache.hadoop.yarn.server.resourcemanager.security.NMTokenSecretManagerInRM: Clear node set for appattempt_1549167607896_0003_000002
2019-02-03 12:18:26,777 INFO org.apache.hadoop.yarn.server.resourcemanager.rmapp.attempt.RMAppAttemptImpl: Storing attempt: AppId: application_1549167607896_0003 AttemptId: appattempt_1549167607896_0003_000002 MasterContainer: Container: [ContainerId: container_1549167607896_0003_02_000001, NodeId: ubuntu-HP-Pavilion-dv6-NoteBook-PC:36263, NodeHttpAddress: ubuntu-HP-Pavilion-dv6-NoteBook-PC:8042, Resource: <memory:2048, vCores:1>, Priority: 0, Token: Token { kind: ContainerToken, service: 127.0.1.1:36263 }, ]
2019-02-03 12:18:26,778 INFO org.apache.hadoop.yarn.server.resourcemanager.rmapp.attempt.RMAppAttemptImpl: appattempt_1549167607896_0003_000002 State change from SCHEDULED to ALLOCATED_SAVING
2019-02-03 12:18:26,778 INFO org.apache.hadoop.yarn.server.resourcemanager.rmapp.attempt.RMAppAttemptImpl: appattempt_1549167607896_0003_000002 State change from ALLOCATED_SAVING to ALLOCATED
2019-02-03 12:18:26,779 INFO org.apache.hadoop.yarn.server.resourcemanager.amlauncher.AMLauncher: Launching masterappattempt_1549167607896_0003_000002
2019-02-03 12:18:26,783 INFO org.apache.hadoop.yarn.server.resourcemanager.amlauncher.AMLauncher: Setting up container Container: [ContainerId: container_1549167607896_0003_02_000001, NodeId: ubuntu-HP-Pavilion-dv6-NoteBook-PC:36263, NodeHttpAddress: ubuntu-HP-Pavilion-dv6-NoteBook-PC:8042, Resource: <memory:2048, vCores:1>, Priority: 0, Token: Token { kind: ContainerToken, service: 127.0.1.1:36263 }, ] for AM appattempt_1549167607896_0003_000002
2019-02-03 12:18:26,783 INFO org.apache.hadoop.yarn.server.resourcemanager.amlauncher.AMLauncher: Command to launch container container_1549167607896_0003_02_000001 : $JAVA_HOME/bin/java -Djava.io.tmpdir=$PWD/tmp -Dlog4j.configuration=container-log4j.properties -Dyarn.app.container.log.dir=<LOG_DIR> -Dyarn.app.container.log.filesize=0 -Dhadoop.root.logger=INFO,CLA -Dhadoop.root.logfile=syslog  -Xmx1024m org.apache.hadoop.mapreduce.v2.app.MRAppMaster 1><LOG_DIR>/stdout 2><LOG_DIR>/stderr 
2019-02-03 12:18:26,783 INFO org.apache.hadoop.yarn.server.resourcemanager.security.AMRMTokenSecretManager: Create AMRMToken for ApplicationAttempt: appattempt_1549167607896_0003_000002
2019-02-03 12:18:26,783 INFO org.apache.hadoop.yarn.server.resourcemanager.security.AMRMTokenSecretManager: Creating password for appattempt_1549167607896_0003_000002
2019-02-03 12:18:26,806 INFO org.apache.hadoop.yarn.server.resourcemanager.amlauncher.AMLauncher: Done launching container Container: [ContainerId: container_1549167607896_0003_02_000001, NodeId: ubuntu-HP-Pavilion-dv6-NoteBook-PC:36263, NodeHttpAddress: ubuntu-HP-Pavilion-dv6-NoteBook-PC:8042, Resource: <memory:2048, vCores:1>, Priority: 0, Token: Token { kind: ContainerToken, service: 127.0.1.1:36263 }, ] for AM appattempt_1549167607896_0003_000002
2019-02-03 12:18:26,806 INFO org.apache.hadoop.yarn.server.resourcemanager.rmapp.attempt.RMAppAttemptImpl: appattempt_1549167607896_0003_000002 State change from ALLOCATED to LAUNCHED
2019-02-03 12:18:27,771 INFO org.apache.hadoop.yarn.server.resourcemanager.rmcontainer.RMContainerImpl: container_1549167607896_0003_02_000001 Container Transitioned from ACQUIRED to RUNNING
2019-02-03 12:18:31,769 INFO org.apache.hadoop.yarn.server.resourcemanager.rmcontainer.RMContainerImpl: container_1549167607896_0003_02_000001 Container Transitioned from RUNNING to COMPLETED
2019-02-03 12:18:31,769 INFO org.apache.hadoop.yarn.server.resourcemanager.scheduler.common.fica.FiCaSchedulerApp: Completed container: container_1549167607896_0003_02_000001 in state: COMPLETED event:FINISHED
2019-02-03 12:18:31,769 INFO org.apache.hadoop.yarn.server.resourcemanager.RMAuditLogger: USER=root	OPERATION=AM Released Container	TARGET=SchedulerApp	RESULT=SUCCESS	APPID=application_1549167607896_0003	CONTAINERID=container_1549167607896_0003_02_000001
2019-02-03 12:18:31,769 INFO org.apache.hadoop.yarn.server.resourcemanager.scheduler.SchedulerNode: Released container container_1549167607896_0003_02_000001 of capacity <memory:2048, vCores:1> on host ubuntu-HP-Pavilion-dv6-NoteBook-PC:36263, which currently has 0 containers, <memory:0, vCores:0> used and <memory:8192, vCores:8> available, release resources=true
2019-02-03 12:18:31,769 INFO org.apache.hadoop.yarn.server.resourcemanager.scheduler.capacity.LeafQueue: default used=<memory:0, vCores:0> numContainers=0 user=root user-resources=<memory:0, vCores:0>
2019-02-03 12:18:31,769 INFO org.apache.hadoop.yarn.server.resourcemanager.rmapp.attempt.RMAppAttemptImpl: Updating application attempt appattempt_1549167607896_0003_000002 with final state: FAILED, and exit status: -103
2019-02-03 12:18:31,769 INFO org.apache.hadoop.yarn.server.resourcemanager.scheduler.capacity.LeafQueue: completedContainer container=Container: [ContainerId: container_1549167607896_0003_02_000001, NodeId: ubuntu-HP-Pavilion-dv6-NoteBook-PC:36263, NodeHttpAddress: ubuntu-HP-Pavilion-dv6-NoteBook-PC:8042, Resource: <memory:2048, vCores:1>, Priority: 0, Token: Token { kind: ContainerToken, service: 127.0.1.1:36263 }, ] queue=default: capacity=1.0, absoluteCapacity=1.0, usedResources=<memory:0, vCores:0>, usedCapacity=0.0, absoluteUsedCapacity=0.0, numApps=1, numContainers=0 cluster=<memory:8192, vCores:8>
2019-02-03 12:18:31,769 INFO org.apache.hadoop.yarn.server.resourcemanager.rmapp.attempt.RMAppAttemptImpl: appattempt_1549167607896_0003_000002 State change from LAUNCHED to FINAL_SAVING
2019-02-03 12:18:31,769 INFO org.apache.hadoop.yarn.server.resourcemanager.scheduler.capacity.ParentQueue: completedContainer queue=root usedCapacity=0.0 absoluteUsedCapacity=0.0 used=<memory:0, vCores:0> cluster=<memory:8192, vCores:8>
2019-02-03 12:18:31,770 INFO org.apache.hadoop.yarn.server.resourcemanager.scheduler.capacity.ParentQueue: Re-sorting completed queue: root.default stats: default: capacity=1.0, absoluteCapacity=1.0, usedResources=<memory:0, vCores:0>, usedCapacity=0.0, absoluteUsedCapacity=0.0, numApps=1, numContainers=0
2019-02-03 12:18:31,770 INFO org.apache.hadoop.yarn.server.resourcemanager.scheduler.capacity.CapacityScheduler: Application attempt appattempt_1549167607896_0003_000002 released container container_1549167607896_0003_02_000001 on node: host: ubuntu-HP-Pavilion-dv6-NoteBook-PC:36263 #containers=0 available=<memory:8192, vCores:8> used=<memory:0, vCores:0> with event: FINISHED
2019-02-03 12:18:31,770 INFO org.apache.hadoop.yarn.server.resourcemanager.ApplicationMasterService: Unregistering app attempt : appattempt_1549167607896_0003_000002
2019-02-03 12:18:31,770 INFO org.apache.hadoop.yarn.server.resourcemanager.security.AMRMTokenSecretManager: Application finished, removing password for appattempt_1549167607896_0003_000002
2019-02-03 12:18:31,770 INFO org.apache.hadoop.yarn.server.resourcemanager.rmapp.attempt.RMAppAttemptImpl: appattempt_1549167607896_0003_000002 State change from FINAL_SAVING to FAILED
2019-02-03 12:18:31,770 INFO org.apache.hadoop.yarn.server.resourcemanager.rmapp.RMAppImpl: The number of failed attempts is 2. The max attempts is 2
2019-02-03 12:18:31,770 INFO org.apache.hadoop.yarn.server.resourcemanager.rmapp.RMAppImpl: Updating application application_1549167607896_0003 with final state: FAILED
2019-02-03 12:18:31,770 INFO org.apache.hadoop.yarn.server.resourcemanager.rmapp.RMAppImpl: application_1549167607896_0003 State change from ACCEPTED to FINAL_SAVING
2019-02-03 12:18:31,771 INFO org.apache.hadoop.yarn.server.resourcemanager.scheduler.capacity.CapacityScheduler: Application Attempt appattempt_1549167607896_0003_000002 is done. finalState=FAILED
2019-02-03 12:18:31,771 INFO org.apache.hadoop.yarn.server.resourcemanager.recovery.RMStateStore: Updating info for app: application_1549167607896_0003
2019-02-03 12:18:31,771 INFO org.apache.hadoop.yarn.server.resourcemanager.scheduler.AppSchedulingInfo: Application application_1549167607896_0003 requests cleared
2019-02-03 12:18:31,771 INFO org.apache.hadoop.yarn.server.resourcemanager.rmapp.RMAppImpl: Application application_1549167607896_0003 failed 2 times due to AM Container for appattempt_1549167607896_0003_000002 exited with  exitCode: -103
For more detailed output, check application tracking page:http://ubuntu-HP-Pavilion-dv6-NoteBook-PC:8088/cluster/app/application_1549167607896_0003Then, click on links to logs of each attempt.
Diagnostics: Container [pid=14326,containerID=container_1549167607896_0003_02_000001] is running beyond virtual memory limits. Current usage: 285.1 MB of 2 GB physical memory used; 4.4 GB of 4.2 GB virtual memory used. Killing container.
Dump of the process-tree for container_1549167607896_0003_02_000001 :
	|- PID PPID PGRPID SESSID CMD_NAME USER_MODE_TIME(MILLIS) SYSTEM_TIME(MILLIS) VMEM_USAGE(BYTES) RSSMEM_USAGE(PAGES) FULL_CMD_LINE
	|- 14336 14326 14326 14326 (java) 1147 40 4741472256 72287 /usr/lib/jvm/java-8-openjdk-amd64/bin/java -Djava.io.tmpdir=/home/ubuntu/hdata/nm-local-dir/usercache/root/appcache/application_1549167607896_0003/container_1549167607896_0003_02_000001/tmp -Dlog4j.configuration=container-log4j.properties -Dyarn.app.container.log.dir=/opt/hadoop/hadoop-2.7.3/logs/userlogs/application_1549167607896_0003/container_1549167607896_0003_02_000001 -Dyarn.app.container.log.filesize=0 -Dhadoop.root.logger=INFO,CLA -Dhadoop.root.logfile=syslog -Xmx1024m org.apache.hadoop.mapreduce.v2.app.MRAppMaster 
	|- 14326 14324 14326 14326 (bash) 1 0 14725120 686 /bin/bash -c /usr/lib/jvm/java-8-openjdk-amd64/bin/java -Djava.io.tmpdir=/home/ubuntu/hdata/nm-local-dir/usercache/root/appcache/application_1549167607896_0003/container_1549167607896_0003_02_000001/tmp -Dlog4j.configuration=container-log4j.properties -Dyarn.app.container.log.dir=/opt/hadoop/hadoop-2.7.3/logs/userlogs/application_1549167607896_0003/container_1549167607896_0003_02_000001 -Dyarn.app.container.log.filesize=0 -Dhadoop.root.logger=INFO,CLA -Dhadoop.root.logfile=syslog  -Xmx1024m org.apache.hadoop.mapreduce.v2.app.MRAppMaster 1>/opt/hadoop/hadoop-2.7.3/logs/userlogs/application_1549167607896_0003/container_1549167607896_0003_02_000001/stdout 2>/opt/hadoop/hadoop-2.7.3/logs/userlogs/application_1549167607896_0003/container_1549167607896_0003_02_000001/stderr  

Container killed on request. Exit code is 143
Container exited with a non-zero exit code 143
Failing this attempt. Failing the application.
2019-02-03 12:18:31,771 INFO org.apache.hadoop.yarn.server.resourcemanager.scheduler.capacity.LeafQueue: Application removed - appId: application_1549167607896_0003 user: root queue: default #user-pending-applications: 0 #user-active-applications: 0 #queue-pending-applications: 0 #queue-active-applications: 0
2019-02-03 12:18:31,771 INFO org.apache.hadoop.yarn.server.resourcemanager.rmapp.RMAppImpl: application_1549167607896_0003 State change from FINAL_SAVING to FAILED
2019-02-03 12:18:31,772 INFO org.apache.hadoop.yarn.server.resourcemanager.scheduler.capacity.ParentQueue: Application removed - appId: application_1549167607896_0003 user: root leaf-queue of parent: root #applications: 0
2019-02-03 12:18:31,772 WARN org.apache.hadoop.yarn.server.resourcemanager.RMAuditLogger: USER=root	OPERATION=Application Finished - Failed	TARGET=RMAppManager	RESULT=FAILURE	DESCRIPTION=App failed with state: FAILED	PERMISSIONS=Application application_1549167607896_0003 failed 2 times due to AM Container for appattempt_1549167607896_0003_000002 exited with  exitCode: -103
For more detailed output, check application tracking page:http://ubuntu-HP-Pavilion-dv6-NoteBook-PC:8088/cluster/app/application_1549167607896_0003Then, click on links to logs of each attempt.
Diagnostics: Container [pid=14326,containerID=container_1549167607896_0003_02_000001] is running beyond virtual memory limits. Current usage: 285.1 MB of 2 GB physical memory used; 4.4 GB of 4.2 GB virtual memory used. Killing container.
Dump of the process-tree for container_1549167607896_0003_02_000001 :
	|- PID PPID PGRPID SESSID CMD_NAME USER_MODE_TIME(MILLIS) SYSTEM_TIME(MILLIS) VMEM_USAGE(BYTES) RSSMEM_USAGE(PAGES) FULL_CMD_LINE
	|- 14336 14326 14326 14326 (java) 1147 40 4741472256 72287 /usr/lib/jvm/java-8-openjdk-amd64/bin/java -Djava.io.tmpdir=/home/ubuntu/hdata/nm-local-dir/usercache/root/appcache/application_1549167607896_0003/container_1549167607896_0003_02_000001/tmp -Dlog4j.configuration=container-log4j.properties -Dyarn.app.container.log.dir=/opt/hadoop/hadoop-2.7.3/logs/userlogs/application_1549167607896_0003/container_1549167607896_0003_02_000001 -Dyarn.app.container.log.filesize=0 -Dhadoop.root.logger=INFO,CLA -Dhadoop.root.logfile=syslog -Xmx1024m org.apache.hadoop.mapreduce.v2.app.MRAppMaster 
	|- 14326 14324 14326 14326 (bash) 1 0 14725120 686 /bin/bash -c /usr/lib/jvm/java-8-openjdk-amd64/bin/java -Djava.io.tmpdir=/home/ubuntu/hdata/nm-local-dir/usercache/root/appcache/application_1549167607896_0003/container_1549167607896_0003_02_000001/tmp -Dlog4j.configuration=container-log4j.properties -Dyarn.app.container.log.dir=/opt/hadoop/hadoop-2.7.3/logs/userlogs/application_1549167607896_0003/container_1549167607896_0003_02_000001 -Dyarn.app.container.log.filesize=0 -Dhadoop.root.logger=INFO,CLA -Dhadoop.root.logfile=syslog  -Xmx1024m org.apache.hadoop.mapreduce.v2.app.MRAppMaster 1>/opt/hadoop/hadoop-2.7.3/logs/userlogs/application_1549167607896_0003/container_1549167607896_0003_02_000001/stdout 2>/opt/hadoop/hadoop-2.7.3/logs/userlogs/application_1549167607896_0003/container_1549167607896_0003_02_000001/stderr  

Container killed on request. Exit code is 143
Container exited with a non-zero exit code 143
Failing this attempt. Failing the application.	APPID=application_1549167607896_0003
2019-02-03 12:18:31,772 INFO org.apache.hadoop.yarn.server.resourcemanager.RMAppManager$ApplicationSummary: appId=application_1549167607896_0003,name=SELECT DISTINCT symbol FROM stocks(Stage-1),user=root,queue=default,state=FAILED,trackingUrl=http://ubuntu-HP-Pavilion-dv6-NoteBook-PC:8088/cluster/app/application_1549167607896_0003,appMasterHost=N/A,startTime=1549176498977,finishTime=1549176511770,finalStatus=FAILED,memorySeconds=22679,vcoreSeconds=11,preemptedAMContainers=0,preemptedNonAMContainers=0,preemptedResources=<memory:0\, vCores:0>,applicationType=MAPREDUCE
2019-02-03 12:18:32,063 INFO org.apache.hadoop.yarn.server.resourcemanager.RMAuditLogger: USER=root	IP=127.0.0.1	OPERATION=Kill Application Request	TARGET=ClientRMService	RESULT=SUCCESS	APPID=application_1549167607896_0003
2019-02-03 12:19:06,815 INFO org.apache.hadoop.yarn.server.webproxy.WebAppProxyServlet: dr.who is accessing unchecked http://ubuntu-HP-Pavilion-dv6-NoteBook-PC:8088/cluster/app/application_1549167607896_0003 which is the app master GUI of application_1549167607896_0003 owned by root
2019-02-03 12:23:10,331 ERROR org.apache.hadoop.yarn.server.resourcemanager.ResourceManager: RECEIVED SIGNAL 15: SIGTERM
2019-02-03 12:23:10,337 ERROR org.apache.hadoop.security.token.delegation.AbstractDelegationTokenSecretManager: ExpiredTokenRemover received java.lang.InterruptedException: sleep interrupted
2019-02-03 12:23:10,339 INFO org.mortbay.log: Stopped HttpServer2$SelectChannelConnectorWithSafeStartup@0.0.0.0:8088
2019-02-03 12:23:10,442 INFO org.apache.hadoop.ipc.Server: Stopping server on 8032
2019-02-03 12:23:10,451 INFO org.apache.hadoop.ipc.Server: Stopping IPC Server listener on 8032
2019-02-03 12:23:10,451 INFO org.apache.hadoop.ipc.Server: Stopping IPC Server Responder
2019-02-03 12:23:10,451 INFO org.apache.hadoop.ipc.Server: Stopping server on 8033
2019-02-03 12:23:10,453 INFO org.apache.hadoop.ipc.Server: Stopping IPC Server listener on 8033
2019-02-03 12:23:10,454 INFO org.apache.hadoop.ipc.Server: Stopping IPC Server Responder
2019-02-03 12:23:10,454 INFO org.apache.hadoop.yarn.server.resourcemanager.ResourceManager: Transitioning to standby state
2019-02-03 12:23:10,455 WARN org.apache.hadoop.yarn.server.resourcemanager.amlauncher.ApplicationMasterLauncher: org.apache.hadoop.yarn.server.resourcemanager.amlauncher.ApplicationMasterLauncher$LauncherThread interrupted. Returning.
2019-02-03 12:23:10,455 INFO org.apache.hadoop.ipc.Server: Stopping server on 8030
2019-02-03 12:23:10,460 INFO org.apache.hadoop.ipc.Server: Stopping IPC Server listener on 8030
2019-02-03 12:23:10,460 INFO org.apache.hadoop.ipc.Server: Stopping server on 8031
2019-02-03 12:23:10,460 INFO org.apache.hadoop.ipc.Server: Stopping IPC Server Responder
2019-02-03 12:23:10,463 INFO org.apache.hadoop.ipc.Server: Stopping IPC Server listener on 8031
2019-02-03 12:23:10,464 INFO org.apache.hadoop.ipc.Server: Stopping IPC Server Responder
2019-02-03 12:23:10,464 INFO org.apache.hadoop.yarn.util.AbstractLivelinessMonitor: NMLivelinessMonitor thread interrupted
2019-02-03 12:23:10,464 ERROR org.apache.hadoop.yarn.server.resourcemanager.ResourceManager: Returning, interrupted : java.lang.InterruptedException
2019-02-03 12:23:10,464 INFO org.apache.hadoop.yarn.event.AsyncDispatcher: AsyncDispatcher is draining to stop, igonring any new events.
2019-02-03 12:23:10,464 INFO org.apache.hadoop.yarn.util.AbstractLivelinessMonitor: AMLivelinessMonitor thread interrupted
2019-02-03 12:23:10,464 INFO org.apache.hadoop.yarn.util.AbstractLivelinessMonitor: org.apache.hadoop.yarn.server.resourcemanager.rmcontainer.ContainerAllocationExpirer thread interrupted
2019-02-03 12:23:10,464 INFO org.apache.hadoop.yarn.util.AbstractLivelinessMonitor: AMLivelinessMonitor thread interrupted
2019-02-03 12:23:10,464 ERROR org.apache.hadoop.security.token.delegation.AbstractDelegationTokenSecretManager: ExpiredTokenRemover received java.lang.InterruptedException: sleep interrupted
2019-02-03 12:23:10,465 INFO org.apache.hadoop.metrics2.impl.MetricsSystemImpl: Stopping ResourceManager metrics system...
2019-02-03 12:23:10,466 INFO org.apache.hadoop.metrics2.impl.MetricsSystemImpl: ResourceManager metrics system stopped.
2019-02-03 12:23:10,466 INFO org.apache.hadoop.metrics2.impl.MetricsSystemImpl: ResourceManager metrics system shutdown complete.
2019-02-03 12:23:10,466 INFO org.apache.hadoop.yarn.event.AsyncDispatcher: AsyncDispatcher is draining to stop, igonring any new events.
2019-02-03 12:23:10,466 INFO org.apache.hadoop.yarn.server.resourcemanager.ResourceManager: Transitioned to standby state
2019-02-03 12:23:10,466 INFO org.apache.hadoop.yarn.server.resourcemanager.ResourceManager: SHUTDOWN_MSG: 
/************************************************************
SHUTDOWN_MSG: Shutting down ResourceManager at ubuntu-HP-Pavilion-dv6-NoteBook-PC/127.0.1.1
************************************************************/
2019-02-03 12:23:44,787 INFO org.apache.hadoop.yarn.server.resourcemanager.ResourceManager: STARTUP_MSG: 
/************************************************************
STARTUP_MSG: Starting ResourceManager
STARTUP_MSG:   host = ubuntu-HP-Pavilion-dv6-NoteBook-PC/127.0.1.1
STARTUP_MSG:   args = []
STARTUP_MSG:   version = 2.7.3
STARTUP_MSG:   build = https://git-wip-us.apache.org/repos/asf/hadoop.git -r baa91f7c6bc9cb92be5982de4719c1c8af91ccff; compiled by 'root' on 2016-08-18T01:41Z
STARTUP_MSG:   java = 1.8.0_171
************************************************************/
2019-02-03 12:23:44,798 INFO org.apache.hadoop.yarn.server.resourcemanager.ResourceManager: registered UNIX signal handlers for [TERM, HUP, INT]
2019-02-03 12:23:45,111 INFO org.apache.hadoop.conf.Configuration: found resource core-site.xml at file:/opt/hadoop/hadoop-2.7.3/etc/hadoop/core-site.xml
2019-02-03 12:23:45,171 WARN org.apache.hadoop.util.NativeCodeLoader: Unable to load native-hadoop library for your platform... using builtin-java classes where applicable
2019-02-03 12:23:45,206 INFO org.apache.hadoop.security.Groups: clearing userToGroupsMap cache
2019-02-03 12:23:45,268 INFO org.apache.hadoop.conf.Configuration: found resource yarn-site.xml at file:/opt/hadoop/hadoop-2.7.3/etc/hadoop/yarn-site.xml
2019-02-03 12:23:45,613 INFO org.apache.hadoop.yarn.event.AsyncDispatcher: Registering class org.apache.hadoop.yarn.server.resourcemanager.RMFatalEventType for class org.apache.hadoop.yarn.server.resourcemanager.ResourceManager$RMFatalEventDispatcher
2019-02-03 12:23:45,711 INFO org.apache.hadoop.yarn.server.resourcemanager.security.NMTokenSecretManagerInRM: NMTokenKeyRollingInterval: 86400000ms and NMTokenKeyActivationDelay: 900000ms
2019-02-03 12:23:45,718 INFO org.apache.hadoop.yarn.server.resourcemanager.security.RMContainerTokenSecretManager: ContainerTokenKeyRollingInterval: 86400000ms and ContainerTokenKeyActivationDelay: 900000ms
2019-02-03 12:23:45,772 INFO org.apache.hadoop.yarn.server.resourcemanager.security.AMRMTokenSecretManager: AMRMTokenKeyRollingInterval: 86400000ms and AMRMTokenKeyActivationDelay: 900000 ms
2019-02-03 12:23:45,815 INFO org.apache.hadoop.yarn.event.AsyncDispatcher: Registering class org.apache.hadoop.yarn.server.resourcemanager.recovery.RMStateStoreEventType for class org.apache.hadoop.yarn.server.resourcemanager.recovery.RMStateStore$ForwardingEventHandler
2019-02-03 12:23:45,817 INFO org.apache.hadoop.yarn.event.AsyncDispatcher: Registering class org.apache.hadoop.yarn.server.resourcemanager.NodesListManagerEventType for class org.apache.hadoop.yarn.server.resourcemanager.NodesListManager
2019-02-03 12:23:45,817 INFO org.apache.hadoop.yarn.server.resourcemanager.ResourceManager: Using Scheduler: org.apache.hadoop.yarn.server.resourcemanager.scheduler.capacity.CapacityScheduler
2019-02-03 12:23:45,839 INFO org.apache.hadoop.yarn.event.AsyncDispatcher: Registering class org.apache.hadoop.yarn.server.resourcemanager.scheduler.event.SchedulerEventType for class org.apache.hadoop.yarn.server.resourcemanager.ResourceManager$SchedulerEventDispatcher
2019-02-03 12:23:45,840 INFO org.apache.hadoop.yarn.event.AsyncDispatcher: Registering class org.apache.hadoop.yarn.server.resourcemanager.rmapp.RMAppEventType for class org.apache.hadoop.yarn.server.resourcemanager.ResourceManager$ApplicationEventDispatcher
2019-02-03 12:23:45,841 INFO org.apache.hadoop.yarn.event.AsyncDispatcher: Registering class org.apache.hadoop.yarn.server.resourcemanager.rmapp.attempt.RMAppAttemptEventType for class org.apache.hadoop.yarn.server.resourcemanager.ResourceManager$ApplicationAttemptEventDispatcher
2019-02-03 12:23:45,842 INFO org.apache.hadoop.yarn.event.AsyncDispatcher: Registering class org.apache.hadoop.yarn.server.resourcemanager.rmnode.RMNodeEventType for class org.apache.hadoop.yarn.server.resourcemanager.ResourceManager$NodeEventDispatcher
2019-02-03 12:23:45,924 INFO org.apache.hadoop.metrics2.impl.MetricsConfig: loaded properties from hadoop-metrics2.properties
2019-02-03 12:23:46,024 INFO org.apache.hadoop.metrics2.impl.MetricsSystemImpl: Scheduled snapshot period at 10 second(s).
2019-02-03 12:23:46,024 INFO org.apache.hadoop.metrics2.impl.MetricsSystemImpl: ResourceManager metrics system started
2019-02-03 12:23:46,044 INFO org.apache.hadoop.yarn.event.AsyncDispatcher: Registering class org.apache.hadoop.yarn.server.resourcemanager.RMAppManagerEventType for class org.apache.hadoop.yarn.server.resourcemanager.RMAppManager
2019-02-03 12:23:46,056 INFO org.apache.hadoop.yarn.event.AsyncDispatcher: Registering class org.apache.hadoop.yarn.server.resourcemanager.amlauncher.AMLauncherEventType for class org.apache.hadoop.yarn.server.resourcemanager.amlauncher.ApplicationMasterLauncher
2019-02-03 12:23:46,060 INFO org.apache.hadoop.yarn.server.resourcemanager.RMNMInfo: Registered RMNMInfo MBean
2019-02-03 12:23:46,064 INFO org.apache.hadoop.yarn.security.YarnAuthorizationProvider: org.apache.hadoop.yarn.security.ConfiguredYarnAuthorizer is instiantiated.
2019-02-03 12:23:46,065 INFO org.apache.hadoop.util.HostsFileReader: Refreshing hosts (include/exclude) list
2019-02-03 12:23:46,071 INFO org.apache.hadoop.conf.Configuration: found resource capacity-scheduler.xml at file:/opt/hadoop/hadoop-2.7.3/etc/hadoop/capacity-scheduler.xml
2019-02-03 12:23:46,172 INFO org.apache.hadoop.yarn.server.resourcemanager.scheduler.capacity.CapacitySchedulerConfiguration: max alloc mb per queue for root is undefined
2019-02-03 12:23:46,172 INFO org.apache.hadoop.yarn.server.resourcemanager.scheduler.capacity.CapacitySchedulerConfiguration: max alloc vcore per queue for root is undefined
2019-02-03 12:23:46,177 INFO org.apache.hadoop.yarn.server.resourcemanager.scheduler.capacity.ParentQueue: root, capacity=1.0, asboluteCapacity=1.0, maxCapacity=1.0, asboluteMaxCapacity=1.0, state=RUNNING, acls=ADMINISTER_QUEUE:*SUBMIT_APP:*, labels=*,
, reservationsContinueLooking=true
2019-02-03 12:23:46,177 INFO org.apache.hadoop.yarn.server.resourcemanager.scheduler.capacity.ParentQueue: Initialized parent-queue root name=root, fullname=root
2019-02-03 12:23:46,190 INFO org.apache.hadoop.yarn.server.resourcemanager.scheduler.capacity.CapacitySchedulerConfiguration: max alloc mb per queue for root.default is undefined
2019-02-03 12:23:46,190 INFO org.apache.hadoop.yarn.server.resourcemanager.scheduler.capacity.CapacitySchedulerConfiguration: max alloc vcore per queue for root.default is undefined
2019-02-03 12:23:46,191 INFO org.apache.hadoop.yarn.server.resourcemanager.scheduler.capacity.LeafQueue: Initializing default
capacity = 1.0 [= (float) configuredCapacity / 100 ]
asboluteCapacity = 1.0 [= parentAbsoluteCapacity * capacity ]
maxCapacity = 1.0 [= configuredMaxCapacity ]
absoluteMaxCapacity = 1.0 [= 1.0 maximumCapacity undefined, (parentAbsoluteMaxCapacity * maximumCapacity) / 100 otherwise ]
userLimit = 100 [= configuredUserLimit ]
userLimitFactor = 1.0 [= configuredUserLimitFactor ]
maxApplications = 10000 [= configuredMaximumSystemApplicationsPerQueue or (int)(configuredMaximumSystemApplications * absoluteCapacity)]
maxApplicationsPerUser = 10000 [= (int)(maxApplications * (userLimit / 100.0f) * userLimitFactor) ]
usedCapacity = 0.0 [= usedResourcesMemory / (clusterResourceMemory * absoluteCapacity)]
absoluteUsedCapacity = 0.0 [= usedResourcesMemory / clusterResourceMemory]
maxAMResourcePerQueuePercent = 0.1 [= configuredMaximumAMResourcePercent ]
minimumAllocationFactor = 0.875 [= (float)(maximumAllocationMemory - minimumAllocationMemory) / maximumAllocationMemory ]
maximumAllocation = <memory:8192, vCores:32> [= configuredMaxAllocation ]
numContainers = 0 [= currentNumContainers ]
state = RUNNING [= configuredState ]
acls = ADMINISTER_QUEUE:*SUBMIT_APP:* [= configuredAcls ]
nodeLocalityDelay = 40
labels=*,
nodeLocalityDelay = 40
reservationsContinueLooking = true
preemptionDisabled = true

2019-02-03 12:23:46,191 INFO org.apache.hadoop.yarn.server.resourcemanager.scheduler.capacity.CapacityScheduler: Initialized queue: default: capacity=1.0, absoluteCapacity=1.0, usedResources=<memory:0, vCores:0>, usedCapacity=0.0, absoluteUsedCapacity=0.0, numApps=0, numContainers=0
2019-02-03 12:23:46,192 INFO org.apache.hadoop.yarn.server.resourcemanager.scheduler.capacity.CapacityScheduler: Initialized queue: root: numChildQueue= 1, capacity=1.0, absoluteCapacity=1.0, usedResources=<memory:0, vCores:0>usedCapacity=0.0, numApps=0, numContainers=0
2019-02-03 12:23:46,192 INFO org.apache.hadoop.yarn.server.resourcemanager.scheduler.capacity.CapacityScheduler: Initialized root queue root: numChildQueue= 1, capacity=1.0, absoluteCapacity=1.0, usedResources=<memory:0, vCores:0>usedCapacity=0.0, numApps=0, numContainers=0
2019-02-03 12:23:46,193 INFO org.apache.hadoop.yarn.server.resourcemanager.scheduler.capacity.CapacityScheduler: Initialized queue mappings, override: false
2019-02-03 12:23:46,193 INFO org.apache.hadoop.yarn.server.resourcemanager.scheduler.capacity.CapacityScheduler: Initialized CapacityScheduler with calculator=class org.apache.hadoop.yarn.util.resource.DefaultResourceCalculator, minimumAllocation=<<memory:1024, vCores:1>>, maximumAllocation=<<memory:8192, vCores:32>>, asynchronousScheduling=false, asyncScheduleInterval=5ms
2019-02-03 12:23:46,205 INFO org.apache.hadoop.yarn.server.resourcemanager.metrics.SystemMetricsPublisher: YARN system metrics publishing service is not enabled
2019-02-03 12:23:46,205 INFO org.apache.hadoop.yarn.server.resourcemanager.ResourceManager: Transitioning to active state
2019-02-03 12:23:46,221 INFO org.apache.hadoop.yarn.server.resourcemanager.recovery.RMStateStore: Updating AMRMToken
2019-02-03 12:23:46,221 INFO org.apache.hadoop.yarn.server.resourcemanager.security.RMContainerTokenSecretManager: Rolling master-key for container-tokens
2019-02-03 12:23:46,221 INFO org.apache.hadoop.yarn.server.resourcemanager.security.NMTokenSecretManagerInRM: Rolling master-key for nm-tokens
2019-02-03 12:23:46,222 INFO org.apache.hadoop.security.token.delegation.AbstractDelegationTokenSecretManager: Updating the current master key for generating delegation tokens
2019-02-03 12:23:46,223 INFO org.apache.hadoop.yarn.server.resourcemanager.security.RMDelegationTokenSecretManager: storing master key with keyID 1
2019-02-03 12:23:46,223 INFO org.apache.hadoop.yarn.server.resourcemanager.recovery.RMStateStore: Storing RMDTMasterKey.
2019-02-03 12:23:46,226 INFO org.apache.hadoop.security.token.delegation.AbstractDelegationTokenSecretManager: Starting expired delegation token remover thread, tokenRemoverScanInterval=60 min(s)
2019-02-03 12:23:46,226 INFO org.apache.hadoop.security.token.delegation.AbstractDelegationTokenSecretManager: Updating the current master key for generating delegation tokens
2019-02-03 12:23:46,226 INFO org.apache.hadoop.yarn.server.resourcemanager.security.RMDelegationTokenSecretManager: storing master key with keyID 2
2019-02-03 12:23:46,226 INFO org.apache.hadoop.yarn.server.resourcemanager.recovery.RMStateStore: Storing RMDTMasterKey.
2019-02-03 12:23:46,228 INFO org.apache.hadoop.yarn.event.AsyncDispatcher: Registering class org.apache.hadoop.yarn.nodelabels.event.NodeLabelsStoreEventType for class org.apache.hadoop.yarn.nodelabels.CommonNodeLabelsManager$ForwardingEventHandler
2019-02-03 12:23:46,282 INFO org.apache.hadoop.ipc.CallQueueManager: Using callQueue class java.util.concurrent.LinkedBlockingQueue
2019-02-03 12:23:46,307 INFO org.apache.hadoop.ipc.Server: Starting Socket Reader #1 for port 8031
2019-02-03 12:23:46,337 INFO org.apache.hadoop.yarn.factories.impl.pb.RpcServerFactoryPBImpl: Adding protocol org.apache.hadoop.yarn.server.api.ResourceTrackerPB to the server
2019-02-03 12:23:46,338 INFO org.apache.hadoop.ipc.Server: IPC Server Responder: starting
2019-02-03 12:23:46,339 INFO org.apache.hadoop.ipc.Server: IPC Server listener on 8031: starting
2019-02-03 12:23:46,405 INFO org.apache.hadoop.ipc.CallQueueManager: Using callQueue class java.util.concurrent.LinkedBlockingQueue
2019-02-03 12:23:46,419 INFO org.apache.hadoop.ipc.Server: Starting Socket Reader #1 for port 8030
2019-02-03 12:23:46,445 INFO org.apache.hadoop.yarn.factories.impl.pb.RpcServerFactoryPBImpl: Adding protocol org.apache.hadoop.yarn.api.ApplicationMasterProtocolPB to the server
2019-02-03 12:23:46,446 INFO org.apache.hadoop.ipc.Server: IPC Server Responder: starting
2019-02-03 12:23:46,449 INFO org.apache.hadoop.ipc.Server: IPC Server listener on 8030: starting
2019-02-03 12:23:46,571 INFO org.apache.hadoop.ipc.CallQueueManager: Using callQueue class java.util.concurrent.LinkedBlockingQueue
2019-02-03 12:23:46,572 INFO org.apache.hadoop.ipc.Server: Starting Socket Reader #1 for port 8032
2019-02-03 12:23:46,576 INFO org.apache.hadoop.yarn.factories.impl.pb.RpcServerFactoryPBImpl: Adding protocol org.apache.hadoop.yarn.api.ApplicationClientProtocolPB to the server
2019-02-03 12:23:46,582 INFO org.apache.hadoop.ipc.Server: IPC Server Responder: starting
2019-02-03 12:23:46,584 INFO org.apache.hadoop.ipc.Server: IPC Server listener on 8032: starting
2019-02-03 12:23:46,602 INFO org.apache.hadoop.yarn.server.resourcemanager.ResourceManager: Transitioned to active state
2019-02-03 12:23:46,719 INFO org.mortbay.log: Logging to org.slf4j.impl.Log4jLoggerAdapter(org.mortbay.log) via org.mortbay.log.Slf4jLog
2019-02-03 12:23:46,729 INFO org.apache.hadoop.security.authentication.server.AuthenticationFilter: Unable to initialize FileSignerSecretProvider, falling back to use random secrets.
2019-02-03 12:23:46,738 INFO org.apache.hadoop.http.HttpRequestLog: Http request log for http.requests.resourcemanager is not defined
2019-02-03 12:23:46,750 INFO org.apache.hadoop.http.HttpServer2: Added global filter 'safety' (class=org.apache.hadoop.http.HttpServer2$QuotingInputFilter)
2019-02-03 12:23:46,757 INFO org.apache.hadoop.http.HttpServer2: Added filter RMAuthenticationFilter (class=org.apache.hadoop.yarn.server.security.http.RMAuthenticationFilter) to context cluster
2019-02-03 12:23:46,757 INFO org.apache.hadoop.http.HttpServer2: Added filter RMAuthenticationFilter (class=org.apache.hadoop.yarn.server.security.http.RMAuthenticationFilter) to context static
2019-02-03 12:23:46,757 INFO org.apache.hadoop.http.HttpServer2: Added filter RMAuthenticationFilter (class=org.apache.hadoop.yarn.server.security.http.RMAuthenticationFilter) to context logs
2019-02-03 12:23:46,758 INFO org.apache.hadoop.http.HttpServer2: Added filter static_user_filter (class=org.apache.hadoop.http.lib.StaticUserWebFilter$StaticUserFilter) to context cluster
2019-02-03 12:23:46,758 INFO org.apache.hadoop.http.HttpServer2: Added filter static_user_filter (class=org.apache.hadoop.http.lib.StaticUserWebFilter$StaticUserFilter) to context static
2019-02-03 12:23:46,759 INFO org.apache.hadoop.http.HttpServer2: Added filter static_user_filter (class=org.apache.hadoop.http.lib.StaticUserWebFilter$StaticUserFilter) to context logs
2019-02-03 12:23:46,764 INFO org.apache.hadoop.http.HttpServer2: adding path spec: /cluster/*
2019-02-03 12:23:46,764 INFO org.apache.hadoop.http.HttpServer2: adding path spec: /ws/*
2019-02-03 12:23:47,583 INFO org.apache.hadoop.yarn.webapp.WebApps: Registered webapp guice modules
2019-02-03 12:23:47,587 INFO org.apache.hadoop.http.HttpServer2: Jetty bound to port 8088
2019-02-03 12:23:47,588 INFO org.mortbay.log: jetty-6.1.26
2019-02-03 12:23:47,732 INFO org.mortbay.log: Extract jar:file:/opt/hadoop/hadoop-2.7.3/share/hadoop/yarn/hadoop-yarn-common-2.7.3.jar!/webapps/cluster to /tmp/Jetty_0_0_0_0_8088_cluster____u0rgz3/webapp
2019-02-03 12:23:48,103 INFO org.apache.hadoop.security.token.delegation.AbstractDelegationTokenSecretManager: Updating the current master key for generating delegation tokens
2019-02-03 12:23:48,106 INFO org.apache.hadoop.security.token.delegation.AbstractDelegationTokenSecretManager: Starting expired delegation token remover thread, tokenRemoverScanInterval=60 min(s)
2019-02-03 12:23:48,107 INFO org.apache.hadoop.security.token.delegation.AbstractDelegationTokenSecretManager: Updating the current master key for generating delegation tokens
2019-02-03 12:23:50,274 INFO org.mortbay.log: Started HttpServer2$SelectChannelConnectorWithSafeStartup@0.0.0.0:8088
2019-02-03 12:23:50,275 INFO org.apache.hadoop.yarn.webapp.WebApps: Web app cluster started at 8088
2019-02-03 12:23:50,328 INFO org.apache.hadoop.ipc.CallQueueManager: Using callQueue class java.util.concurrent.LinkedBlockingQueue
2019-02-03 12:23:50,329 INFO org.apache.hadoop.ipc.Server: Starting Socket Reader #1 for port 8033
2019-02-03 12:23:50,336 INFO org.apache.hadoop.yarn.factories.impl.pb.RpcServerFactoryPBImpl: Adding protocol org.apache.hadoop.yarn.server.api.ResourceManagerAdministrationProtocolPB to the server
2019-02-03 12:23:50,340 INFO org.apache.hadoop.ipc.Server: IPC Server Responder: starting
2019-02-03 12:23:50,340 INFO org.apache.hadoop.ipc.Server: IPC Server listener on 8033: starting
2019-02-03 12:23:51,953 INFO org.apache.hadoop.yarn.util.RackResolver: Resolved ubuntu-HP-Pavilion-dv6-NoteBook-PC to /default-rack
2019-02-03 12:23:51,968 INFO org.apache.hadoop.yarn.server.resourcemanager.rmnode.RMNodeImpl: ubuntu-HP-Pavilion-dv6-NoteBook-PC:35593 Node Transitioned from NEW to RUNNING
2019-02-03 12:23:51,983 INFO org.apache.hadoop.yarn.server.resourcemanager.ResourceTrackerService: NodeManager from node ubuntu-HP-Pavilion-dv6-NoteBook-PC(cmPort: 35593 httpPort: 8042) registered with capability: <memory:8192, vCores:8>, assigned nodeId ubuntu-HP-Pavilion-dv6-NoteBook-PC:35593
2019-02-03 12:23:51,983 INFO org.apache.hadoop.yarn.server.resourcemanager.scheduler.capacity.CapacityScheduler: Added node ubuntu-HP-Pavilion-dv6-NoteBook-PC:35593 clusterResource: <memory:8192, vCores:8>
2019-02-03 12:27:10,557 INFO org.apache.hadoop.yarn.server.resourcemanager.ClientRMService: Allocated new applicationId: 1
2019-02-03 12:27:11,657 INFO org.apache.hadoop.yarn.server.resourcemanager.ClientRMService: Application with id 1 submitted by user root
2019-02-03 12:27:11,658 INFO org.apache.hadoop.yarn.server.resourcemanager.rmapp.RMAppImpl: Storing application with id application_1549176826207_0001
2019-02-03 12:27:11,659 INFO org.apache.hadoop.yarn.server.resourcemanager.RMAuditLogger: USER=root	IP=127.0.0.1	OPERATION=Submit Application Request	TARGET=ClientRMService	RESULT=SUCCESS	APPID=application_1549176826207_0001
2019-02-03 12:27:11,669 INFO org.apache.hadoop.yarn.server.resourcemanager.rmapp.RMAppImpl: application_1549176826207_0001 State change from NEW to NEW_SAVING
2019-02-03 12:27:11,669 INFO org.apache.hadoop.yarn.server.resourcemanager.recovery.RMStateStore: Storing info for app: application_1549176826207_0001
2019-02-03 12:27:11,670 INFO org.apache.hadoop.yarn.server.resourcemanager.rmapp.RMAppImpl: application_1549176826207_0001 State change from NEW_SAVING to SUBMITTED
2019-02-03 12:27:11,672 INFO org.apache.hadoop.yarn.server.resourcemanager.scheduler.capacity.ParentQueue: Application added - appId: application_1549176826207_0001 user: root leaf-queue of parent: root #applications: 1
2019-02-03 12:27:11,673 INFO org.apache.hadoop.yarn.server.resourcemanager.scheduler.capacity.CapacityScheduler: Accepted application application_1549176826207_0001 from user: root, in queue: default
2019-02-03 12:27:11,687 INFO org.apache.hadoop.yarn.server.resourcemanager.rmapp.RMAppImpl: application_1549176826207_0001 State change from SUBMITTED to ACCEPTED
2019-02-03 12:27:11,733 INFO org.apache.hadoop.yarn.server.resourcemanager.ApplicationMasterService: Registering app attempt : appattempt_1549176826207_0001_000001
2019-02-03 12:27:11,735 INFO org.apache.hadoop.yarn.server.resourcemanager.rmapp.attempt.RMAppAttemptImpl: appattempt_1549176826207_0001_000001 State change from NEW to SUBMITTED
2019-02-03 12:27:11,758 WARN org.apache.hadoop.yarn.server.resourcemanager.scheduler.capacity.LeafQueue: maximum-am-resource-percent is insufficient to start a single application in queue, it is likely set too low. skipping enforcement to allow at least one application to start
2019-02-03 12:27:11,759 WARN org.apache.hadoop.yarn.server.resourcemanager.scheduler.capacity.LeafQueue: maximum-am-resource-percent is insufficient to start a single application in queue for user, it is likely set too low. skipping enforcement to allow at least one application to start
2019-02-03 12:27:11,759 INFO org.apache.hadoop.yarn.server.resourcemanager.scheduler.capacity.LeafQueue: Application application_1549176826207_0001 from user: root activated in queue: default
2019-02-03 12:27:11,759 INFO org.apache.hadoop.yarn.server.resourcemanager.scheduler.capacity.LeafQueue: Application added - appId: application_1549176826207_0001 user: org.apache.hadoop.yarn.server.resourcemanager.scheduler.capacity.LeafQueue$User@58641a99, leaf-queue: default #user-pending-applications: 0 #user-active-applications: 1 #queue-pending-applications: 0 #queue-active-applications: 1
2019-02-03 12:27:11,760 INFO org.apache.hadoop.yarn.server.resourcemanager.scheduler.capacity.CapacityScheduler: Added Application Attempt appattempt_1549176826207_0001_000001 to scheduler from user root in queue default
2019-02-03 12:27:11,764 INFO org.apache.hadoop.yarn.server.resourcemanager.rmapp.attempt.RMAppAttemptImpl: appattempt_1549176826207_0001_000001 State change from SUBMITTED to SCHEDULED
2019-02-03 12:27:11,820 INFO org.apache.hadoop.yarn.server.resourcemanager.rmcontainer.RMContainerImpl: container_1549176826207_0001_01_000001 Container Transitioned from NEW to ALLOCATED
2019-02-03 12:27:11,821 INFO org.apache.hadoop.yarn.server.resourcemanager.RMAuditLogger: USER=root	OPERATION=AM Allocated Container	TARGET=SchedulerApp	RESULT=SUCCESS	APPID=application_1549176826207_0001	CONTAINERID=container_1549176826207_0001_01_000001
2019-02-03 12:27:11,822 INFO org.apache.hadoop.yarn.server.resourcemanager.scheduler.SchedulerNode: Assigned container container_1549176826207_0001_01_000001 of capacity <memory:2048, vCores:1> on host ubuntu-HP-Pavilion-dv6-NoteBook-PC:35593, which has 1 containers, <memory:2048, vCores:1> used and <memory:6144, vCores:7> available after allocation
2019-02-03 12:27:11,822 INFO org.apache.hadoop.yarn.server.resourcemanager.scheduler.capacity.LeafQueue: assignedContainer application attempt=appattempt_1549176826207_0001_000001 container=Container: [ContainerId: container_1549176826207_0001_01_000001, NodeId: ubuntu-HP-Pavilion-dv6-NoteBook-PC:35593, NodeHttpAddress: ubuntu-HP-Pavilion-dv6-NoteBook-PC:8042, Resource: <memory:2048, vCores:1>, Priority: 0, Token: null, ] queue=default: capacity=1.0, absoluteCapacity=1.0, usedResources=<memory:0, vCores:0>, usedCapacity=0.0, absoluteUsedCapacity=0.0, numApps=1, numContainers=0 clusterResource=<memory:8192, vCores:8> type=OFF_SWITCH
2019-02-03 12:27:11,822 INFO org.apache.hadoop.yarn.server.resourcemanager.scheduler.capacity.ParentQueue: Re-sorting assigned queue: root.default stats: default: capacity=1.0, absoluteCapacity=1.0, usedResources=<memory:2048, vCores:1>, usedCapacity=0.25, absoluteUsedCapacity=0.25, numApps=1, numContainers=1
2019-02-03 12:27:11,822 INFO org.apache.hadoop.yarn.server.resourcemanager.scheduler.capacity.ParentQueue: assignedContainer queue=root usedCapacity=0.25 absoluteUsedCapacity=0.25 used=<memory:2048, vCores:1> cluster=<memory:8192, vCores:8>
2019-02-03 12:27:11,847 INFO org.apache.hadoop.yarn.server.resourcemanager.security.NMTokenSecretManagerInRM: Sending NMToken for nodeId : ubuntu-HP-Pavilion-dv6-NoteBook-PC:35593 for container : container_1549176826207_0001_01_000001
2019-02-03 12:27:11,862 INFO org.apache.hadoop.yarn.server.resourcemanager.rmcontainer.RMContainerImpl: container_1549176826207_0001_01_000001 Container Transitioned from ALLOCATED to ACQUIRED
2019-02-03 12:27:11,863 INFO org.apache.hadoop.yarn.server.resourcemanager.security.NMTokenSecretManagerInRM: Clear node set for appattempt_1549176826207_0001_000001
2019-02-03 12:27:11,868 INFO org.apache.hadoop.yarn.server.resourcemanager.rmapp.attempt.RMAppAttemptImpl: Storing attempt: AppId: application_1549176826207_0001 AttemptId: appattempt_1549176826207_0001_000001 MasterContainer: Container: [ContainerId: container_1549176826207_0001_01_000001, NodeId: ubuntu-HP-Pavilion-dv6-NoteBook-PC:35593, NodeHttpAddress: ubuntu-HP-Pavilion-dv6-NoteBook-PC:8042, Resource: <memory:2048, vCores:1>, Priority: 0, Token: Token { kind: ContainerToken, service: 127.0.1.1:35593 }, ]
2019-02-03 12:27:11,881 INFO org.apache.hadoop.yarn.server.resourcemanager.rmapp.attempt.RMAppAttemptImpl: appattempt_1549176826207_0001_000001 State change from SCHEDULED to ALLOCATED_SAVING
2019-02-03 12:27:11,884 INFO org.apache.hadoop.yarn.server.resourcemanager.rmapp.attempt.RMAppAttemptImpl: appattempt_1549176826207_0001_000001 State change from ALLOCATED_SAVING to ALLOCATED
2019-02-03 12:27:11,887 INFO org.apache.hadoop.yarn.server.resourcemanager.amlauncher.AMLauncher: Launching masterappattempt_1549176826207_0001_000001
2019-02-03 12:27:11,930 INFO org.apache.hadoop.yarn.server.resourcemanager.amlauncher.AMLauncher: Setting up container Container: [ContainerId: container_1549176826207_0001_01_000001, NodeId: ubuntu-HP-Pavilion-dv6-NoteBook-PC:35593, NodeHttpAddress: ubuntu-HP-Pavilion-dv6-NoteBook-PC:8042, Resource: <memory:2048, vCores:1>, Priority: 0, Token: Token { kind: ContainerToken, service: 127.0.1.1:35593 }, ] for AM appattempt_1549176826207_0001_000001
2019-02-03 12:27:11,930 INFO org.apache.hadoop.yarn.server.resourcemanager.amlauncher.AMLauncher: Command to launch container container_1549176826207_0001_01_000001 : $JAVA_HOME/bin/java -Djava.io.tmpdir=$PWD/tmp -Dlog4j.configuration=container-log4j.properties -Dyarn.app.container.log.dir=<LOG_DIR> -Dyarn.app.container.log.filesize=0 -Dhadoop.root.logger=INFO,CLA -Dhadoop.root.logfile=syslog  -Xmx1024m org.apache.hadoop.mapreduce.v2.app.MRAppMaster 1><LOG_DIR>/stdout 2><LOG_DIR>/stderr 
2019-02-03 12:27:11,932 INFO org.apache.hadoop.yarn.server.resourcemanager.security.AMRMTokenSecretManager: Create AMRMToken for ApplicationAttempt: appattempt_1549176826207_0001_000001
2019-02-03 12:27:11,936 INFO org.apache.hadoop.yarn.server.resourcemanager.security.AMRMTokenSecretManager: Creating password for appattempt_1549176826207_0001_000001
2019-02-03 12:27:12,367 INFO org.apache.hadoop.yarn.server.resourcemanager.amlauncher.AMLauncher: Done launching container Container: [ContainerId: container_1549176826207_0001_01_000001, NodeId: ubuntu-HP-Pavilion-dv6-NoteBook-PC:35593, NodeHttpAddress: ubuntu-HP-Pavilion-dv6-NoteBook-PC:8042, Resource: <memory:2048, vCores:1>, Priority: 0, Token: Token { kind: ContainerToken, service: 127.0.1.1:35593 }, ] for AM appattempt_1549176826207_0001_000001
2019-02-03 12:27:12,368 INFO org.apache.hadoop.yarn.server.resourcemanager.rmapp.attempt.RMAppAttemptImpl: appattempt_1549176826207_0001_000001 State change from ALLOCATED to LAUNCHED
2019-02-03 12:27:12,808 INFO org.apache.hadoop.yarn.server.resourcemanager.rmcontainer.RMContainerImpl: container_1549176826207_0001_01_000001 Container Transitioned from ACQUIRED to RUNNING
2019-02-03 12:27:18,998 INFO SecurityLogger.org.apache.hadoop.ipc.Server: Auth successful for appattempt_1549176826207_0001_000001 (auth:SIMPLE)
2019-02-03 12:27:19,008 INFO org.apache.hadoop.yarn.server.resourcemanager.ApplicationMasterService: AM registration appattempt_1549176826207_0001_000001
2019-02-03 12:27:19,010 INFO org.apache.hadoop.yarn.server.resourcemanager.RMAuditLogger: USER=root	IP=127.0.0.1	OPERATION=Register App Master	TARGET=ApplicationMasterService	RESULT=SUCCESS	APPID=application_1549176826207_0001	APPATTEMPTID=appattempt_1549176826207_0001_000001
2019-02-03 12:27:19,010 INFO org.apache.hadoop.yarn.server.resourcemanager.rmapp.attempt.RMAppAttemptImpl: appattempt_1549176826207_0001_000001 State change from LAUNCHED to RUNNING
2019-02-03 12:27:19,010 INFO org.apache.hadoop.yarn.server.resourcemanager.rmapp.RMAppImpl: application_1549176826207_0001 State change from ACCEPTED to RUNNING
2019-02-03 12:27:20,870 INFO org.apache.hadoop.yarn.server.resourcemanager.rmcontainer.RMContainerImpl: container_1549176826207_0001_01_000002 Container Transitioned from NEW to ALLOCATED
2019-02-03 12:27:20,871 INFO org.apache.hadoop.yarn.server.resourcemanager.RMAuditLogger: USER=root	OPERATION=AM Allocated Container	TARGET=SchedulerApp	RESULT=SUCCESS	APPID=application_1549176826207_0001	CONTAINERID=container_1549176826207_0001_01_000002
2019-02-03 12:27:20,871 INFO org.apache.hadoop.yarn.server.resourcemanager.scheduler.SchedulerNode: Assigned container container_1549176826207_0001_01_000002 of capacity <memory:1024, vCores:1> on host ubuntu-HP-Pavilion-dv6-NoteBook-PC:35593, which has 2 containers, <memory:3072, vCores:2> used and <memory:5120, vCores:6> available after allocation
2019-02-03 12:27:20,871 INFO org.apache.hadoop.yarn.server.resourcemanager.scheduler.capacity.LeafQueue: assignedContainer application attempt=appattempt_1549176826207_0001_000001 container=Container: [ContainerId: container_1549176826207_0001_01_000002, NodeId: ubuntu-HP-Pavilion-dv6-NoteBook-PC:35593, NodeHttpAddress: ubuntu-HP-Pavilion-dv6-NoteBook-PC:8042, Resource: <memory:1024, vCores:1>, Priority: 20, Token: null, ] queue=default: capacity=1.0, absoluteCapacity=1.0, usedResources=<memory:2048, vCores:1>, usedCapacity=0.25, absoluteUsedCapacity=0.25, numApps=1, numContainers=1 clusterResource=<memory:8192, vCores:8> type=NODE_LOCAL
2019-02-03 12:27:20,872 INFO org.apache.hadoop.yarn.server.resourcemanager.scheduler.capacity.ParentQueue: Re-sorting assigned queue: root.default stats: default: capacity=1.0, absoluteCapacity=1.0, usedResources=<memory:3072, vCores:2>, usedCapacity=0.375, absoluteUsedCapacity=0.375, numApps=1, numContainers=2
2019-02-03 12:27:20,872 INFO org.apache.hadoop.yarn.server.resourcemanager.scheduler.capacity.ParentQueue: assignedContainer queue=root usedCapacity=0.375 absoluteUsedCapacity=0.375 used=<memory:3072, vCores:2> cluster=<memory:8192, vCores:8>
2019-02-03 12:27:21,201 INFO org.apache.hadoop.yarn.server.resourcemanager.security.NMTokenSecretManagerInRM: Sending NMToken for nodeId : ubuntu-HP-Pavilion-dv6-NoteBook-PC:35593 for container : container_1549176826207_0001_01_000002
2019-02-03 12:27:21,206 INFO org.apache.hadoop.yarn.server.resourcemanager.rmcontainer.RMContainerImpl: container_1549176826207_0001_01_000002 Container Transitioned from ALLOCATED to ACQUIRED
2019-02-03 12:27:21,871 INFO org.apache.hadoop.yarn.server.resourcemanager.rmcontainer.RMContainerImpl: container_1549176826207_0001_01_000002 Container Transitioned from ACQUIRED to RUNNING
2019-02-03 12:27:22,225 INFO org.apache.hadoop.yarn.server.resourcemanager.scheduler.AppSchedulingInfo: checking for deactivate of application :application_1549176826207_0001
2019-02-03 12:27:25,755 INFO org.apache.hadoop.yarn.server.resourcemanager.rmcontainer.RMContainerImpl: container_1549176826207_0001_01_000002 Container Transitioned from RUNNING to COMPLETED
2019-02-03 12:27:25,755 INFO org.apache.hadoop.yarn.server.resourcemanager.scheduler.common.fica.FiCaSchedulerApp: Completed container: container_1549176826207_0001_01_000002 in state: COMPLETED event:FINISHED
2019-02-03 12:27:25,755 INFO org.apache.hadoop.yarn.server.resourcemanager.RMAuditLogger: USER=root	OPERATION=AM Released Container	TARGET=SchedulerApp	RESULT=SUCCESS	APPID=application_1549176826207_0001	CONTAINERID=container_1549176826207_0001_01_000002
2019-02-03 12:27:25,755 INFO org.apache.hadoop.yarn.server.resourcemanager.scheduler.SchedulerNode: Released container container_1549176826207_0001_01_000002 of capacity <memory:1024, vCores:1> on host ubuntu-HP-Pavilion-dv6-NoteBook-PC:35593, which currently has 1 containers, <memory:2048, vCores:1> used and <memory:6144, vCores:7> available, release resources=true
2019-02-03 12:27:25,756 INFO org.apache.hadoop.yarn.server.resourcemanager.scheduler.capacity.LeafQueue: default used=<memory:2048, vCores:1> numContainers=1 user=root user-resources=<memory:2048, vCores:1>
2019-02-03 12:27:25,757 INFO org.apache.hadoop.yarn.server.resourcemanager.scheduler.capacity.LeafQueue: completedContainer container=Container: [ContainerId: container_1549176826207_0001_01_000002, NodeId: ubuntu-HP-Pavilion-dv6-NoteBook-PC:35593, NodeHttpAddress: ubuntu-HP-Pavilion-dv6-NoteBook-PC:8042, Resource: <memory:1024, vCores:1>, Priority: 20, Token: Token { kind: ContainerToken, service: 127.0.1.1:35593 }, ] queue=default: capacity=1.0, absoluteCapacity=1.0, usedResources=<memory:2048, vCores:1>, usedCapacity=0.25, absoluteUsedCapacity=0.25, numApps=1, numContainers=1 cluster=<memory:8192, vCores:8>
2019-02-03 12:27:25,757 INFO org.apache.hadoop.yarn.server.resourcemanager.scheduler.capacity.ParentQueue: completedContainer queue=root usedCapacity=0.25 absoluteUsedCapacity=0.25 used=<memory:2048, vCores:1> cluster=<memory:8192, vCores:8>
2019-02-03 12:27:25,757 INFO org.apache.hadoop.yarn.server.resourcemanager.scheduler.capacity.ParentQueue: Re-sorting completed queue: root.default stats: default: capacity=1.0, absoluteCapacity=1.0, usedResources=<memory:2048, vCores:1>, usedCapacity=0.25, absoluteUsedCapacity=0.25, numApps=1, numContainers=1
2019-02-03 12:27:25,757 INFO org.apache.hadoop.yarn.server.resourcemanager.scheduler.capacity.CapacityScheduler: Application attempt appattempt_1549176826207_0001_000001 released container container_1549176826207_0001_01_000002 on node: host: ubuntu-HP-Pavilion-dv6-NoteBook-PC:35593 #containers=1 available=<memory:6144, vCores:7> used=<memory:2048, vCores:1> with event: FINISHED
2019-02-03 12:27:27,769 INFO org.apache.hadoop.yarn.server.resourcemanager.rmcontainer.RMContainerImpl: container_1549176826207_0001_01_000003 Container Transitioned from NEW to ALLOCATED
2019-02-03 12:27:27,769 INFO org.apache.hadoop.yarn.server.resourcemanager.RMAuditLogger: USER=root	OPERATION=AM Allocated Container	TARGET=SchedulerApp	RESULT=SUCCESS	APPID=application_1549176826207_0001	CONTAINERID=container_1549176826207_0001_01_000003
2019-02-03 12:27:27,769 INFO org.apache.hadoop.yarn.server.resourcemanager.scheduler.SchedulerNode: Assigned container container_1549176826207_0001_01_000003 of capacity <memory:1024, vCores:1> on host ubuntu-HP-Pavilion-dv6-NoteBook-PC:35593, which has 2 containers, <memory:3072, vCores:2> used and <memory:5120, vCores:6> available after allocation
2019-02-03 12:27:27,769 INFO org.apache.hadoop.yarn.server.resourcemanager.scheduler.capacity.LeafQueue: assignedContainer application attempt=appattempt_1549176826207_0001_000001 container=Container: [ContainerId: container_1549176826207_0001_01_000003, NodeId: ubuntu-HP-Pavilion-dv6-NoteBook-PC:35593, NodeHttpAddress: ubuntu-HP-Pavilion-dv6-NoteBook-PC:8042, Resource: <memory:1024, vCores:1>, Priority: 10, Token: null, ] queue=default: capacity=1.0, absoluteCapacity=1.0, usedResources=<memory:2048, vCores:1>, usedCapacity=0.25, absoluteUsedCapacity=0.25, numApps=1, numContainers=1 clusterResource=<memory:8192, vCores:8> type=OFF_SWITCH
2019-02-03 12:27:27,769 INFO org.apache.hadoop.yarn.server.resourcemanager.scheduler.capacity.ParentQueue: Re-sorting assigned queue: root.default stats: default: capacity=1.0, absoluteCapacity=1.0, usedResources=<memory:3072, vCores:2>, usedCapacity=0.375, absoluteUsedCapacity=0.375, numApps=1, numContainers=2
2019-02-03 12:27:27,770 INFO org.apache.hadoop.yarn.server.resourcemanager.scheduler.capacity.ParentQueue: assignedContainer queue=root usedCapacity=0.375 absoluteUsedCapacity=0.375 used=<memory:3072, vCores:2> cluster=<memory:8192, vCores:8>
2019-02-03 12:27:28,271 INFO org.apache.hadoop.yarn.server.resourcemanager.rmcontainer.RMContainerImpl: container_1549176826207_0001_01_000003 Container Transitioned from ALLOCATED to ACQUIRED
2019-02-03 12:27:28,770 INFO org.apache.hadoop.yarn.server.resourcemanager.rmcontainer.RMContainerImpl: container_1549176826207_0001_01_000003 Container Transitioned from ACQUIRED to RUNNING
2019-02-03 12:27:29,280 INFO org.apache.hadoop.yarn.server.resourcemanager.scheduler.AppSchedulingInfo: checking for deactivate of application :application_1549176826207_0001
2019-02-03 12:27:32,648 INFO org.apache.hadoop.yarn.server.resourcemanager.rmcontainer.RMContainerImpl: container_1549176826207_0001_01_000003 Container Transitioned from RUNNING to COMPLETED
2019-02-03 12:27:32,648 INFO org.apache.hadoop.yarn.server.resourcemanager.scheduler.common.fica.FiCaSchedulerApp: Completed container: container_1549176826207_0001_01_000003 in state: COMPLETED event:FINISHED
2019-02-03 12:27:32,648 INFO org.apache.hadoop.yarn.server.resourcemanager.RMAuditLogger: USER=root	OPERATION=AM Released Container	TARGET=SchedulerApp	RESULT=SUCCESS	APPID=application_1549176826207_0001	CONTAINERID=container_1549176826207_0001_01_000003
2019-02-03 12:27:32,649 INFO org.apache.hadoop.yarn.server.resourcemanager.scheduler.SchedulerNode: Released container container_1549176826207_0001_01_000003 of capacity <memory:1024, vCores:1> on host ubuntu-HP-Pavilion-dv6-NoteBook-PC:35593, which currently has 1 containers, <memory:2048, vCores:1> used and <memory:6144, vCores:7> available, release resources=true
2019-02-03 12:27:32,649 INFO org.apache.hadoop.yarn.server.resourcemanager.scheduler.capacity.LeafQueue: default used=<memory:2048, vCores:1> numContainers=1 user=root user-resources=<memory:2048, vCores:1>
2019-02-03 12:27:32,649 INFO org.apache.hadoop.yarn.server.resourcemanager.scheduler.capacity.LeafQueue: completedContainer container=Container: [ContainerId: container_1549176826207_0001_01_000003, NodeId: ubuntu-HP-Pavilion-dv6-NoteBook-PC:35593, NodeHttpAddress: ubuntu-HP-Pavilion-dv6-NoteBook-PC:8042, Resource: <memory:1024, vCores:1>, Priority: 10, Token: Token { kind: ContainerToken, service: 127.0.1.1:35593 }, ] queue=default: capacity=1.0, absoluteCapacity=1.0, usedResources=<memory:2048, vCores:1>, usedCapacity=0.25, absoluteUsedCapacity=0.25, numApps=1, numContainers=1 cluster=<memory:8192, vCores:8>
2019-02-03 12:27:32,650 INFO org.apache.hadoop.yarn.server.resourcemanager.scheduler.capacity.ParentQueue: completedContainer queue=root usedCapacity=0.25 absoluteUsedCapacity=0.25 used=<memory:2048, vCores:1> cluster=<memory:8192, vCores:8>
2019-02-03 12:27:32,650 INFO org.apache.hadoop.yarn.server.resourcemanager.scheduler.capacity.ParentQueue: Re-sorting completed queue: root.default stats: default: capacity=1.0, absoluteCapacity=1.0, usedResources=<memory:2048, vCores:1>, usedCapacity=0.25, absoluteUsedCapacity=0.25, numApps=1, numContainers=1
2019-02-03 12:27:32,650 INFO org.apache.hadoop.yarn.server.resourcemanager.scheduler.capacity.CapacityScheduler: Application attempt appattempt_1549176826207_0001_000001 released container container_1549176826207_0001_01_000003 on node: host: ubuntu-HP-Pavilion-dv6-NoteBook-PC:35593 #containers=1 available=<memory:6144, vCores:7> used=<memory:2048, vCores:1> with event: FINISHED
2019-02-03 12:27:33,358 INFO org.apache.hadoop.yarn.server.resourcemanager.rmapp.attempt.RMAppAttemptImpl: Updating application attempt appattempt_1549176826207_0001_000001 with final state: FINISHING, and exit status: -1000
2019-02-03 12:27:33,359 INFO org.apache.hadoop.yarn.server.resourcemanager.rmapp.attempt.RMAppAttemptImpl: appattempt_1549176826207_0001_000001 State change from RUNNING to FINAL_SAVING
2019-02-03 12:27:33,359 INFO org.apache.hadoop.yarn.server.resourcemanager.rmapp.RMAppImpl: Updating application application_1549176826207_0001 with final state: FINISHING
2019-02-03 12:27:33,360 INFO org.apache.hadoop.yarn.server.resourcemanager.rmapp.RMAppImpl: application_1549176826207_0001 State change from RUNNING to FINAL_SAVING
2019-02-03 12:27:33,360 INFO org.apache.hadoop.yarn.server.resourcemanager.recovery.RMStateStore: Updating info for app: application_1549176826207_0001
2019-02-03 12:27:33,360 INFO org.apache.hadoop.yarn.server.resourcemanager.rmapp.attempt.RMAppAttemptImpl: appattempt_1549176826207_0001_000001 State change from FINAL_SAVING to FINISHING
2019-02-03 12:27:33,360 INFO org.apache.hadoop.yarn.server.resourcemanager.rmapp.RMAppImpl: application_1549176826207_0001 State change from FINAL_SAVING to FINISHING
2019-02-03 12:27:34,364 INFO org.apache.hadoop.yarn.server.resourcemanager.ApplicationMasterService: application_1549176826207_0001 unregistered successfully. 
2019-02-03 12:27:39,908 INFO org.apache.hadoop.yarn.server.resourcemanager.rmcontainer.RMContainerImpl: container_1549176826207_0001_01_000001 Container Transitioned from RUNNING to COMPLETED
2019-02-03 12:27:39,908 INFO org.apache.hadoop.yarn.server.resourcemanager.scheduler.common.fica.FiCaSchedulerApp: Completed container: container_1549176826207_0001_01_000001 in state: COMPLETED event:FINISHED
2019-02-03 12:27:39,909 INFO org.apache.hadoop.yarn.server.resourcemanager.ApplicationMasterService: Unregistering app attempt : appattempt_1549176826207_0001_000001
2019-02-03 12:27:39,909 INFO org.apache.hadoop.yarn.server.resourcemanager.RMAuditLogger: USER=root	OPERATION=AM Released Container	TARGET=SchedulerApp	RESULT=SUCCESS	APPID=application_1549176826207_0001	CONTAINERID=container_1549176826207_0001_01_000001
2019-02-03 12:27:39,909 INFO org.apache.hadoop.yarn.server.resourcemanager.scheduler.SchedulerNode: Released container container_1549176826207_0001_01_000001 of capacity <memory:2048, vCores:1> on host ubuntu-HP-Pavilion-dv6-NoteBook-PC:35593, which currently has 0 containers, <memory:0, vCores:0> used and <memory:8192, vCores:8> available, release resources=true
2019-02-03 12:27:39,909 INFO org.apache.hadoop.yarn.server.resourcemanager.scheduler.capacity.LeafQueue: default used=<memory:0, vCores:0> numContainers=0 user=root user-resources=<memory:0, vCores:0>
2019-02-03 12:27:39,909 INFO org.apache.hadoop.yarn.server.resourcemanager.scheduler.capacity.LeafQueue: completedContainer container=Container: [ContainerId: container_1549176826207_0001_01_000001, NodeId: ubuntu-HP-Pavilion-dv6-NoteBook-PC:35593, NodeHttpAddress: ubuntu-HP-Pavilion-dv6-NoteBook-PC:8042, Resource: <memory:2048, vCores:1>, Priority: 0, Token: Token { kind: ContainerToken, service: 127.0.1.1:35593 }, ] queue=default: capacity=1.0, absoluteCapacity=1.0, usedResources=<memory:0, vCores:0>, usedCapacity=0.0, absoluteUsedCapacity=0.0, numApps=1, numContainers=0 cluster=<memory:8192, vCores:8>
2019-02-03 12:27:39,909 INFO org.apache.hadoop.yarn.server.resourcemanager.scheduler.capacity.ParentQueue: completedContainer queue=root usedCapacity=0.0 absoluteUsedCapacity=0.0 used=<memory:0, vCores:0> cluster=<memory:8192, vCores:8>
2019-02-03 12:27:39,909 INFO org.apache.hadoop.yarn.server.resourcemanager.scheduler.capacity.ParentQueue: Re-sorting completed queue: root.default stats: default: capacity=1.0, absoluteCapacity=1.0, usedResources=<memory:0, vCores:0>, usedCapacity=0.0, absoluteUsedCapacity=0.0, numApps=1, numContainers=0
2019-02-03 12:27:39,909 INFO org.apache.hadoop.yarn.server.resourcemanager.scheduler.capacity.CapacityScheduler: Application attempt appattempt_1549176826207_0001_000001 released container container_1549176826207_0001_01_000001 on node: host: ubuntu-HP-Pavilion-dv6-NoteBook-PC:35593 #containers=0 available=<memory:8192, vCores:8> used=<memory:0, vCores:0> with event: FINISHED
2019-02-03 12:27:39,909 INFO org.apache.hadoop.yarn.server.resourcemanager.security.AMRMTokenSecretManager: Application finished, removing password for appattempt_1549176826207_0001_000001
2019-02-03 12:27:39,910 INFO org.apache.hadoop.yarn.server.resourcemanager.rmapp.attempt.RMAppAttemptImpl: appattempt_1549176826207_0001_000001 State change from FINISHING to FINISHED
2019-02-03 12:27:39,913 INFO org.apache.hadoop.yarn.server.resourcemanager.rmapp.RMAppImpl: application_1549176826207_0001 State change from FINISHING to FINISHED
2019-02-03 12:27:39,913 INFO org.apache.hadoop.yarn.server.resourcemanager.scheduler.capacity.CapacityScheduler: Application Attempt appattempt_1549176826207_0001_000001 is done. finalState=FINISHED
2019-02-03 12:27:39,914 INFO org.apache.hadoop.yarn.server.resourcemanager.scheduler.AppSchedulingInfo: Application application_1549176826207_0001 requests cleared
2019-02-03 12:27:39,914 INFO org.apache.hadoop.yarn.server.resourcemanager.scheduler.capacity.LeafQueue: Application removed - appId: application_1549176826207_0001 user: root queue: default #user-pending-applications: 0 #user-active-applications: 0 #queue-pending-applications: 0 #queue-active-applications: 0
2019-02-03 12:27:39,915 INFO org.apache.hadoop.yarn.server.resourcemanager.RMAuditLogger: USER=root	OPERATION=Application Finished - Succeeded	TARGET=RMAppManager	RESULT=SUCCESS	APPID=application_1549176826207_0001
2019-02-03 12:27:39,915 INFO org.apache.hadoop.yarn.server.resourcemanager.scheduler.capacity.ParentQueue: Application removed - appId: application_1549176826207_0001 user: root leaf-queue of parent: root #applications: 0
2019-02-03 12:27:39,915 INFO org.apache.hadoop.yarn.server.resourcemanager.amlauncher.AMLauncher: Cleaning master appattempt_1549176826207_0001_000001
2019-02-03 12:27:39,928 INFO org.apache.hadoop.yarn.server.resourcemanager.RMAppManager$ApplicationSummary: appId=application_1549176826207_0001,name=SELECT DISTINCT symbol FROM stocks(Stage-1),user=root,queue=default,state=FINISHED,trackingUrl=http://ubuntu-HP-Pavilion-dv6-NoteBook-PC:8088/proxy/application_1549176826207_0001/,appMasterHost=ubuntu-HP-Pavilion-dv6-NoteBook-PC,startTime=1549177031656,finishTime=1549177053359,finalStatus=SUCCEEDED,memorySeconds=67526,vcoreSeconds=36,preemptedAMContainers=0,preemptedNonAMContainers=0,preemptedResources=<memory:0\, vCores:0>,applicationType=MAPREDUCE
2019-02-03 12:27:59,300 INFO org.apache.hadoop.yarn.server.resourcemanager.ClientRMService: Allocated new applicationId: 2
2019-02-03 12:28:00,138 INFO org.apache.hadoop.yarn.server.resourcemanager.ClientRMService: Application with id 2 submitted by user root
2019-02-03 12:28:00,138 INFO org.apache.hadoop.yarn.server.resourcemanager.rmapp.RMAppImpl: Storing application with id application_1549176826207_0002
2019-02-03 12:28:00,139 INFO org.apache.hadoop.yarn.server.resourcemanager.rmapp.RMAppImpl: application_1549176826207_0002 State change from NEW to NEW_SAVING
2019-02-03 12:28:00,139 INFO org.apache.hadoop.yarn.server.resourcemanager.recovery.RMStateStore: Storing info for app: application_1549176826207_0002
2019-02-03 12:28:00,139 INFO org.apache.hadoop.yarn.server.resourcemanager.RMAuditLogger: USER=root	IP=127.0.0.1	OPERATION=Submit Application Request	TARGET=ClientRMService	RESULT=SUCCESS	APPID=application_1549176826207_0002
2019-02-03 12:28:00,139 INFO org.apache.hadoop.yarn.server.resourcemanager.rmapp.RMAppImpl: application_1549176826207_0002 State change from NEW_SAVING to SUBMITTED
2019-02-03 12:28:00,139 INFO org.apache.hadoop.yarn.server.resourcemanager.scheduler.capacity.ParentQueue: Application added - appId: application_1549176826207_0002 user: root leaf-queue of parent: root #applications: 1
2019-02-03 12:28:00,139 INFO org.apache.hadoop.yarn.server.resourcemanager.scheduler.capacity.CapacityScheduler: Accepted application application_1549176826207_0002 from user: root, in queue: default
2019-02-03 12:28:00,140 INFO org.apache.hadoop.yarn.server.resourcemanager.rmapp.RMAppImpl: application_1549176826207_0002 State change from SUBMITTED to ACCEPTED
2019-02-03 12:28:00,141 INFO org.apache.hadoop.yarn.server.resourcemanager.ApplicationMasterService: Registering app attempt : appattempt_1549176826207_0002_000001
2019-02-03 12:28:00,141 INFO org.apache.hadoop.yarn.server.resourcemanager.rmapp.attempt.RMAppAttemptImpl: appattempt_1549176826207_0002_000001 State change from NEW to SUBMITTED
2019-02-03 12:28:00,141 WARN org.apache.hadoop.yarn.server.resourcemanager.scheduler.capacity.LeafQueue: maximum-am-resource-percent is insufficient to start a single application in queue, it is likely set too low. skipping enforcement to allow at least one application to start
2019-02-03 12:28:00,141 WARN org.apache.hadoop.yarn.server.resourcemanager.scheduler.capacity.LeafQueue: maximum-am-resource-percent is insufficient to start a single application in queue for user, it is likely set too low. skipping enforcement to allow at least one application to start
2019-02-03 12:28:00,141 INFO org.apache.hadoop.yarn.server.resourcemanager.scheduler.capacity.LeafQueue: Application application_1549176826207_0002 from user: root activated in queue: default
2019-02-03 12:28:00,141 INFO org.apache.hadoop.yarn.server.resourcemanager.scheduler.capacity.LeafQueue: Application added - appId: application_1549176826207_0002 user: org.apache.hadoop.yarn.server.resourcemanager.scheduler.capacity.LeafQueue$User@622bc94b, leaf-queue: default #user-pending-applications: 0 #user-active-applications: 1 #queue-pending-applications: 0 #queue-active-applications: 1
2019-02-03 12:28:00,141 INFO org.apache.hadoop.yarn.server.resourcemanager.scheduler.capacity.CapacityScheduler: Added Application Attempt appattempt_1549176826207_0002_000001 to scheduler from user root in queue default
2019-02-03 12:28:00,142 INFO org.apache.hadoop.yarn.server.resourcemanager.rmapp.attempt.RMAppAttemptImpl: appattempt_1549176826207_0002_000001 State change from SUBMITTED to SCHEDULED
2019-02-03 12:28:00,976 INFO org.apache.hadoop.yarn.server.resourcemanager.rmcontainer.RMContainerImpl: container_1549176826207_0002_01_000001 Container Transitioned from NEW to ALLOCATED
2019-02-03 12:28:00,976 INFO org.apache.hadoop.yarn.server.resourcemanager.RMAuditLogger: USER=root	OPERATION=AM Allocated Container	TARGET=SchedulerApp	RESULT=SUCCESS	APPID=application_1549176826207_0002	CONTAINERID=container_1549176826207_0002_01_000001
2019-02-03 12:28:00,977 INFO org.apache.hadoop.yarn.server.resourcemanager.scheduler.SchedulerNode: Assigned container container_1549176826207_0002_01_000001 of capacity <memory:2048, vCores:1> on host ubuntu-HP-Pavilion-dv6-NoteBook-PC:35593, which has 1 containers, <memory:2048, vCores:1> used and <memory:6144, vCores:7> available after allocation
2019-02-03 12:28:00,977 INFO org.apache.hadoop.yarn.server.resourcemanager.scheduler.capacity.LeafQueue: assignedContainer application attempt=appattempt_1549176826207_0002_000001 container=Container: [ContainerId: container_1549176826207_0002_01_000001, NodeId: ubuntu-HP-Pavilion-dv6-NoteBook-PC:35593, NodeHttpAddress: ubuntu-HP-Pavilion-dv6-NoteBook-PC:8042, Resource: <memory:2048, vCores:1>, Priority: 0, Token: null, ] queue=default: capacity=1.0, absoluteCapacity=1.0, usedResources=<memory:0, vCores:0>, usedCapacity=0.0, absoluteUsedCapacity=0.0, numApps=1, numContainers=0 clusterResource=<memory:8192, vCores:8> type=OFF_SWITCH
2019-02-03 12:28:00,978 INFO org.apache.hadoop.yarn.server.resourcemanager.scheduler.capacity.ParentQueue: Re-sorting assigned queue: root.default stats: default: capacity=1.0, absoluteCapacity=1.0, usedResources=<memory:2048, vCores:1>, usedCapacity=0.25, absoluteUsedCapacity=0.25, numApps=1, numContainers=1
2019-02-03 12:28:00,978 INFO org.apache.hadoop.yarn.server.resourcemanager.scheduler.capacity.ParentQueue: assignedContainer queue=root usedCapacity=0.25 absoluteUsedCapacity=0.25 used=<memory:2048, vCores:1> cluster=<memory:8192, vCores:8>
2019-02-03 12:28:00,982 INFO org.apache.hadoop.yarn.server.resourcemanager.security.NMTokenSecretManagerInRM: Sending NMToken for nodeId : ubuntu-HP-Pavilion-dv6-NoteBook-PC:35593 for container : container_1549176826207_0002_01_000001
2019-02-03 12:28:00,986 INFO org.apache.hadoop.yarn.server.resourcemanager.rmcontainer.RMContainerImpl: container_1549176826207_0002_01_000001 Container Transitioned from ALLOCATED to ACQUIRED
2019-02-03 12:28:00,986 INFO org.apache.hadoop.yarn.server.resourcemanager.security.NMTokenSecretManagerInRM: Clear node set for appattempt_1549176826207_0002_000001
2019-02-03 12:28:00,987 INFO org.apache.hadoop.yarn.server.resourcemanager.rmapp.attempt.RMAppAttemptImpl: Storing attempt: AppId: application_1549176826207_0002 AttemptId: appattempt_1549176826207_0002_000001 MasterContainer: Container: [ContainerId: container_1549176826207_0002_01_000001, NodeId: ubuntu-HP-Pavilion-dv6-NoteBook-PC:35593, NodeHttpAddress: ubuntu-HP-Pavilion-dv6-NoteBook-PC:8042, Resource: <memory:2048, vCores:1>, Priority: 0, Token: Token { kind: ContainerToken, service: 127.0.1.1:35593 }, ]
2019-02-03 12:28:00,987 INFO org.apache.hadoop.yarn.server.resourcemanager.rmapp.attempt.RMAppAttemptImpl: appattempt_1549176826207_0002_000001 State change from SCHEDULED to ALLOCATED_SAVING
2019-02-03 12:28:00,987 INFO org.apache.hadoop.yarn.server.resourcemanager.rmapp.attempt.RMAppAttemptImpl: appattempt_1549176826207_0002_000001 State change from ALLOCATED_SAVING to ALLOCATED
2019-02-03 12:28:00,988 INFO org.apache.hadoop.yarn.server.resourcemanager.amlauncher.AMLauncher: Launching masterappattempt_1549176826207_0002_000001
2019-02-03 12:28:00,993 INFO org.apache.hadoop.yarn.server.resourcemanager.amlauncher.AMLauncher: Setting up container Container: [ContainerId: container_1549176826207_0002_01_000001, NodeId: ubuntu-HP-Pavilion-dv6-NoteBook-PC:35593, NodeHttpAddress: ubuntu-HP-Pavilion-dv6-NoteBook-PC:8042, Resource: <memory:2048, vCores:1>, Priority: 0, Token: Token { kind: ContainerToken, service: 127.0.1.1:35593 }, ] for AM appattempt_1549176826207_0002_000001
2019-02-03 12:28:00,993 INFO org.apache.hadoop.yarn.server.resourcemanager.amlauncher.AMLauncher: Command to launch container container_1549176826207_0002_01_000001 : $JAVA_HOME/bin/java -Djava.io.tmpdir=$PWD/tmp -Dlog4j.configuration=container-log4j.properties -Dyarn.app.container.log.dir=<LOG_DIR> -Dyarn.app.container.log.filesize=0 -Dhadoop.root.logger=INFO,CLA -Dhadoop.root.logfile=syslog  -Xmx1024m org.apache.hadoop.mapreduce.v2.app.MRAppMaster 1><LOG_DIR>/stdout 2><LOG_DIR>/stderr 
2019-02-03 12:28:00,993 INFO org.apache.hadoop.yarn.server.resourcemanager.security.AMRMTokenSecretManager: Create AMRMToken for ApplicationAttempt: appattempt_1549176826207_0002_000001
2019-02-03 12:28:00,993 INFO org.apache.hadoop.yarn.server.resourcemanager.security.AMRMTokenSecretManager: Creating password for appattempt_1549176826207_0002_000001
2019-02-03 12:28:01,007 INFO org.apache.hadoop.yarn.server.resourcemanager.amlauncher.AMLauncher: Done launching container Container: [ContainerId: container_1549176826207_0002_01_000001, NodeId: ubuntu-HP-Pavilion-dv6-NoteBook-PC:35593, NodeHttpAddress: ubuntu-HP-Pavilion-dv6-NoteBook-PC:8042, Resource: <memory:2048, vCores:1>, Priority: 0, Token: Token { kind: ContainerToken, service: 127.0.1.1:35593 }, ] for AM appattempt_1549176826207_0002_000001
2019-02-03 12:28:01,008 INFO org.apache.hadoop.yarn.server.resourcemanager.rmapp.attempt.RMAppAttemptImpl: appattempt_1549176826207_0002_000001 State change from ALLOCATED to LAUNCHED
2019-02-03 12:28:01,977 INFO org.apache.hadoop.yarn.server.resourcemanager.rmcontainer.RMContainerImpl: container_1549176826207_0002_01_000001 Container Transitioned from ACQUIRED to RUNNING
2019-02-03 12:28:06,383 INFO SecurityLogger.org.apache.hadoop.ipc.Server: Auth successful for appattempt_1549176826207_0002_000001 (auth:SIMPLE)
2019-02-03 12:28:06,389 INFO org.apache.hadoop.yarn.server.resourcemanager.ApplicationMasterService: AM registration appattempt_1549176826207_0002_000001
2019-02-03 12:28:06,390 INFO org.apache.hadoop.yarn.server.resourcemanager.RMAuditLogger: USER=root	IP=127.0.0.1	OPERATION=Register App Master	TARGET=ApplicationMasterService	RESULT=SUCCESS	APPID=application_1549176826207_0002	APPATTEMPTID=appattempt_1549176826207_0002_000001
2019-02-03 12:28:06,390 INFO org.apache.hadoop.yarn.server.resourcemanager.rmapp.attempt.RMAppAttemptImpl: appattempt_1549176826207_0002_000001 State change from LAUNCHED to RUNNING
2019-02-03 12:28:06,390 INFO org.apache.hadoop.yarn.server.resourcemanager.rmapp.RMAppImpl: application_1549176826207_0002 State change from ACCEPTED to RUNNING
2019-02-03 12:28:08,005 INFO org.apache.hadoop.yarn.server.resourcemanager.rmcontainer.RMContainerImpl: container_1549176826207_0002_01_000002 Container Transitioned from NEW to ALLOCATED
2019-02-03 12:28:08,005 INFO org.apache.hadoop.yarn.server.resourcemanager.RMAuditLogger: USER=root	OPERATION=AM Allocated Container	TARGET=SchedulerApp	RESULT=SUCCESS	APPID=application_1549176826207_0002	CONTAINERID=container_1549176826207_0002_01_000002
2019-02-03 12:28:08,006 INFO org.apache.hadoop.yarn.server.resourcemanager.scheduler.SchedulerNode: Assigned container container_1549176826207_0002_01_000002 of capacity <memory:1024, vCores:1> on host ubuntu-HP-Pavilion-dv6-NoteBook-PC:35593, which has 2 containers, <memory:3072, vCores:2> used and <memory:5120, vCores:6> available after allocation
2019-02-03 12:28:08,006 INFO org.apache.hadoop.yarn.server.resourcemanager.scheduler.capacity.LeafQueue: assignedContainer application attempt=appattempt_1549176826207_0002_000001 container=Container: [ContainerId: container_1549176826207_0002_01_000002, NodeId: ubuntu-HP-Pavilion-dv6-NoteBook-PC:35593, NodeHttpAddress: ubuntu-HP-Pavilion-dv6-NoteBook-PC:8042, Resource: <memory:1024, vCores:1>, Priority: 20, Token: null, ] queue=default: capacity=1.0, absoluteCapacity=1.0, usedResources=<memory:2048, vCores:1>, usedCapacity=0.25, absoluteUsedCapacity=0.25, numApps=1, numContainers=1 clusterResource=<memory:8192, vCores:8> type=NODE_LOCAL
2019-02-03 12:28:08,007 INFO org.apache.hadoop.yarn.server.resourcemanager.scheduler.capacity.ParentQueue: Re-sorting assigned queue: root.default stats: default: capacity=1.0, absoluteCapacity=1.0, usedResources=<memory:3072, vCores:2>, usedCapacity=0.375, absoluteUsedCapacity=0.375, numApps=1, numContainers=2
2019-02-03 12:28:08,007 INFO org.apache.hadoop.yarn.server.resourcemanager.scheduler.capacity.ParentQueue: assignedContainer queue=root usedCapacity=0.375 absoluteUsedCapacity=0.375 used=<memory:3072, vCores:2> cluster=<memory:8192, vCores:8>
2019-02-03 12:28:08,476 INFO org.apache.hadoop.yarn.server.resourcemanager.security.NMTokenSecretManagerInRM: Sending NMToken for nodeId : ubuntu-HP-Pavilion-dv6-NoteBook-PC:35593 for container : container_1549176826207_0002_01_000002
2019-02-03 12:28:08,478 INFO org.apache.hadoop.yarn.server.resourcemanager.rmcontainer.RMContainerImpl: container_1549176826207_0002_01_000002 Container Transitioned from ALLOCATED to ACQUIRED
2019-02-03 12:28:09,006 INFO org.apache.hadoop.yarn.server.resourcemanager.rmcontainer.RMContainerImpl: container_1549176826207_0002_01_000002 Container Transitioned from ACQUIRED to RUNNING
2019-02-03 12:28:09,497 INFO org.apache.hadoop.yarn.server.resourcemanager.scheduler.AppSchedulingInfo: checking for deactivate of application :application_1549176826207_0002
2019-02-03 12:28:12,914 INFO org.apache.hadoop.yarn.server.resourcemanager.rmcontainer.RMContainerImpl: container_1549176826207_0002_01_000002 Container Transitioned from RUNNING to COMPLETED
2019-02-03 12:28:12,914 INFO org.apache.hadoop.yarn.server.resourcemanager.scheduler.common.fica.FiCaSchedulerApp: Completed container: container_1549176826207_0002_01_000002 in state: COMPLETED event:FINISHED
2019-02-03 12:28:12,914 INFO org.apache.hadoop.yarn.server.resourcemanager.RMAuditLogger: USER=root	OPERATION=AM Released Container	TARGET=SchedulerApp	RESULT=SUCCESS	APPID=application_1549176826207_0002	CONTAINERID=container_1549176826207_0002_01_000002
2019-02-03 12:28:12,914 INFO org.apache.hadoop.yarn.server.resourcemanager.scheduler.SchedulerNode: Released container container_1549176826207_0002_01_000002 of capacity <memory:1024, vCores:1> on host ubuntu-HP-Pavilion-dv6-NoteBook-PC:35593, which currently has 1 containers, <memory:2048, vCores:1> used and <memory:6144, vCores:7> available, release resources=true
2019-02-03 12:28:12,914 INFO org.apache.hadoop.yarn.server.resourcemanager.scheduler.capacity.LeafQueue: default used=<memory:2048, vCores:1> numContainers=1 user=root user-resources=<memory:2048, vCores:1>
2019-02-03 12:28:12,916 INFO org.apache.hadoop.yarn.server.resourcemanager.scheduler.capacity.LeafQueue: completedContainer container=Container: [ContainerId: container_1549176826207_0002_01_000002, NodeId: ubuntu-HP-Pavilion-dv6-NoteBook-PC:35593, NodeHttpAddress: ubuntu-HP-Pavilion-dv6-NoteBook-PC:8042, Resource: <memory:1024, vCores:1>, Priority: 20, Token: Token { kind: ContainerToken, service: 127.0.1.1:35593 }, ] queue=default: capacity=1.0, absoluteCapacity=1.0, usedResources=<memory:2048, vCores:1>, usedCapacity=0.25, absoluteUsedCapacity=0.25, numApps=1, numContainers=1 cluster=<memory:8192, vCores:8>
2019-02-03 12:28:12,917 INFO org.apache.hadoop.yarn.server.resourcemanager.scheduler.capacity.ParentQueue: completedContainer queue=root usedCapacity=0.25 absoluteUsedCapacity=0.25 used=<memory:2048, vCores:1> cluster=<memory:8192, vCores:8>
2019-02-03 12:28:12,917 INFO org.apache.hadoop.yarn.server.resourcemanager.scheduler.capacity.ParentQueue: Re-sorting completed queue: root.default stats: default: capacity=1.0, absoluteCapacity=1.0, usedResources=<memory:2048, vCores:1>, usedCapacity=0.25, absoluteUsedCapacity=0.25, numApps=1, numContainers=1
2019-02-03 12:28:12,917 INFO org.apache.hadoop.yarn.server.resourcemanager.scheduler.capacity.CapacityScheduler: Application attempt appattempt_1549176826207_0002_000001 released container container_1549176826207_0002_01_000002 on node: host: ubuntu-HP-Pavilion-dv6-NoteBook-PC:35593 #containers=1 available=<memory:6144, vCores:7> used=<memory:2048, vCores:1> with event: FINISHED
2019-02-03 12:28:14,927 INFO org.apache.hadoop.yarn.server.resourcemanager.rmcontainer.RMContainerImpl: container_1549176826207_0002_01_000003 Container Transitioned from NEW to ALLOCATED
2019-02-03 12:28:14,927 INFO org.apache.hadoop.yarn.server.resourcemanager.RMAuditLogger: USER=root	OPERATION=AM Allocated Container	TARGET=SchedulerApp	RESULT=SUCCESS	APPID=application_1549176826207_0002	CONTAINERID=container_1549176826207_0002_01_000003
2019-02-03 12:28:14,927 INFO org.apache.hadoop.yarn.server.resourcemanager.scheduler.SchedulerNode: Assigned container container_1549176826207_0002_01_000003 of capacity <memory:1024, vCores:1> on host ubuntu-HP-Pavilion-dv6-NoteBook-PC:35593, which has 2 containers, <memory:3072, vCores:2> used and <memory:5120, vCores:6> available after allocation
2019-02-03 12:28:14,927 INFO org.apache.hadoop.yarn.server.resourcemanager.scheduler.capacity.LeafQueue: assignedContainer application attempt=appattempt_1549176826207_0002_000001 container=Container: [ContainerId: container_1549176826207_0002_01_000003, NodeId: ubuntu-HP-Pavilion-dv6-NoteBook-PC:35593, NodeHttpAddress: ubuntu-HP-Pavilion-dv6-NoteBook-PC:8042, Resource: <memory:1024, vCores:1>, Priority: 10, Token: null, ] queue=default: capacity=1.0, absoluteCapacity=1.0, usedResources=<memory:2048, vCores:1>, usedCapacity=0.25, absoluteUsedCapacity=0.25, numApps=1, numContainers=1 clusterResource=<memory:8192, vCores:8> type=OFF_SWITCH
2019-02-03 12:28:14,928 INFO org.apache.hadoop.yarn.server.resourcemanager.scheduler.capacity.ParentQueue: Re-sorting assigned queue: root.default stats: default: capacity=1.0, absoluteCapacity=1.0, usedResources=<memory:3072, vCores:2>, usedCapacity=0.375, absoluteUsedCapacity=0.375, numApps=1, numContainers=2
2019-02-03 12:28:14,928 INFO org.apache.hadoop.yarn.server.resourcemanager.scheduler.capacity.ParentQueue: assignedContainer queue=root usedCapacity=0.375 absoluteUsedCapacity=0.375 used=<memory:3072, vCores:2> cluster=<memory:8192, vCores:8>
2019-02-03 12:28:15,540 INFO org.apache.hadoop.yarn.server.resourcemanager.rmcontainer.RMContainerImpl: container_1549176826207_0002_01_000003 Container Transitioned from ALLOCATED to ACQUIRED
2019-02-03 12:28:15,928 INFO org.apache.hadoop.yarn.server.resourcemanager.rmcontainer.RMContainerImpl: container_1549176826207_0002_01_000003 Container Transitioned from ACQUIRED to RUNNING
2019-02-03 12:28:16,548 INFO org.apache.hadoop.yarn.server.resourcemanager.scheduler.AppSchedulingInfo: checking for deactivate of application :application_1549176826207_0002
2019-02-03 12:28:19,431 INFO org.apache.hadoop.yarn.server.resourcemanager.rmcontainer.RMContainerImpl: container_1549176826207_0002_01_000003 Container Transitioned from RUNNING to COMPLETED
2019-02-03 12:28:19,432 INFO org.apache.hadoop.yarn.server.resourcemanager.scheduler.common.fica.FiCaSchedulerApp: Completed container: container_1549176826207_0002_01_000003 in state: COMPLETED event:FINISHED
2019-02-03 12:28:19,432 INFO org.apache.hadoop.yarn.server.resourcemanager.RMAuditLogger: USER=root	OPERATION=AM Released Container	TARGET=SchedulerApp	RESULT=SUCCESS	APPID=application_1549176826207_0002	CONTAINERID=container_1549176826207_0002_01_000003
2019-02-03 12:28:19,432 INFO org.apache.hadoop.yarn.server.resourcemanager.scheduler.SchedulerNode: Released container container_1549176826207_0002_01_000003 of capacity <memory:1024, vCores:1> on host ubuntu-HP-Pavilion-dv6-NoteBook-PC:35593, which currently has 1 containers, <memory:2048, vCores:1> used and <memory:6144, vCores:7> available, release resources=true
2019-02-03 12:28:19,432 INFO org.apache.hadoop.yarn.server.resourcemanager.scheduler.capacity.LeafQueue: default used=<memory:2048, vCores:1> numContainers=1 user=root user-resources=<memory:2048, vCores:1>
2019-02-03 12:28:19,433 INFO org.apache.hadoop.yarn.server.resourcemanager.scheduler.capacity.LeafQueue: completedContainer container=Container: [ContainerId: container_1549176826207_0002_01_000003, NodeId: ubuntu-HP-Pavilion-dv6-NoteBook-PC:35593, NodeHttpAddress: ubuntu-HP-Pavilion-dv6-NoteBook-PC:8042, Resource: <memory:1024, vCores:1>, Priority: 10, Token: Token { kind: ContainerToken, service: 127.0.1.1:35593 }, ] queue=default: capacity=1.0, absoluteCapacity=1.0, usedResources=<memory:2048, vCores:1>, usedCapacity=0.25, absoluteUsedCapacity=0.25, numApps=1, numContainers=1 cluster=<memory:8192, vCores:8>
2019-02-03 12:28:19,433 INFO org.apache.hadoop.yarn.server.resourcemanager.scheduler.capacity.ParentQueue: completedContainer queue=root usedCapacity=0.25 absoluteUsedCapacity=0.25 used=<memory:2048, vCores:1> cluster=<memory:8192, vCores:8>
2019-02-03 12:28:19,433 INFO org.apache.hadoop.yarn.server.resourcemanager.scheduler.capacity.ParentQueue: Re-sorting completed queue: root.default stats: default: capacity=1.0, absoluteCapacity=1.0, usedResources=<memory:2048, vCores:1>, usedCapacity=0.25, absoluteUsedCapacity=0.25, numApps=1, numContainers=1
2019-02-03 12:28:19,433 INFO org.apache.hadoop.yarn.server.resourcemanager.scheduler.capacity.CapacityScheduler: Application attempt appattempt_1549176826207_0002_000001 released container container_1549176826207_0002_01_000003 on node: host: ubuntu-HP-Pavilion-dv6-NoteBook-PC:35593 #containers=1 available=<memory:6144, vCores:7> used=<memory:2048, vCores:1> with event: FINISHED
2019-02-03 12:28:20,887 INFO org.apache.hadoop.yarn.server.resourcemanager.rmapp.attempt.RMAppAttemptImpl: Updating application attempt appattempt_1549176826207_0002_000001 with final state: FINISHING, and exit status: -1000
2019-02-03 12:28:20,888 INFO org.apache.hadoop.yarn.server.resourcemanager.rmapp.attempt.RMAppAttemptImpl: appattempt_1549176826207_0002_000001 State change from RUNNING to FINAL_SAVING
2019-02-03 12:28:20,888 INFO org.apache.hadoop.yarn.server.resourcemanager.rmapp.RMAppImpl: Updating application application_1549176826207_0002 with final state: FINISHING
2019-02-03 12:28:20,888 INFO org.apache.hadoop.yarn.server.resourcemanager.rmapp.RMAppImpl: application_1549176826207_0002 State change from RUNNING to FINAL_SAVING
2019-02-03 12:28:20,888 INFO org.apache.hadoop.yarn.server.resourcemanager.recovery.RMStateStore: Updating info for app: application_1549176826207_0002
2019-02-03 12:28:20,888 INFO org.apache.hadoop.yarn.server.resourcemanager.rmapp.attempt.RMAppAttemptImpl: appattempt_1549176826207_0002_000001 State change from FINAL_SAVING to FINISHING
2019-02-03 12:28:20,888 INFO org.apache.hadoop.yarn.server.resourcemanager.rmapp.RMAppImpl: application_1549176826207_0002 State change from FINAL_SAVING to FINISHING
2019-02-03 12:28:21,893 INFO org.apache.hadoop.yarn.server.resourcemanager.ApplicationMasterService: application_1549176826207_0002 unregistered successfully. 
2019-02-03 12:28:27,431 INFO org.apache.hadoop.yarn.server.resourcemanager.rmcontainer.RMContainerImpl: container_1549176826207_0002_01_000001 Container Transitioned from RUNNING to COMPLETED
2019-02-03 12:28:27,431 INFO org.apache.hadoop.yarn.server.resourcemanager.scheduler.common.fica.FiCaSchedulerApp: Completed container: container_1549176826207_0002_01_000001 in state: COMPLETED event:FINISHED
2019-02-03 12:28:27,431 INFO org.apache.hadoop.yarn.server.resourcemanager.RMAuditLogger: USER=root	OPERATION=AM Released Container	TARGET=SchedulerApp	RESULT=SUCCESS	APPID=application_1549176826207_0002	CONTAINERID=container_1549176826207_0002_01_000001
2019-02-03 12:28:27,431 INFO org.apache.hadoop.yarn.server.resourcemanager.scheduler.SchedulerNode: Released container container_1549176826207_0002_01_000001 of capacity <memory:2048, vCores:1> on host ubuntu-HP-Pavilion-dv6-NoteBook-PC:35593, which currently has 0 containers, <memory:0, vCores:0> used and <memory:8192, vCores:8> available, release resources=true
2019-02-03 12:28:27,432 INFO org.apache.hadoop.yarn.server.resourcemanager.scheduler.capacity.LeafQueue: default used=<memory:0, vCores:0> numContainers=0 user=root user-resources=<memory:0, vCores:0>
2019-02-03 12:28:27,432 INFO org.apache.hadoop.yarn.server.resourcemanager.scheduler.capacity.LeafQueue: completedContainer container=Container: [ContainerId: container_1549176826207_0002_01_000001, NodeId: ubuntu-HP-Pavilion-dv6-NoteBook-PC:35593, NodeHttpAddress: ubuntu-HP-Pavilion-dv6-NoteBook-PC:8042, Resource: <memory:2048, vCores:1>, Priority: 0, Token: Token { kind: ContainerToken, service: 127.0.1.1:35593 }, ] queue=default: capacity=1.0, absoluteCapacity=1.0, usedResources=<memory:0, vCores:0>, usedCapacity=0.0, absoluteUsedCapacity=0.0, numApps=1, numContainers=0 cluster=<memory:8192, vCores:8>
2019-02-03 12:28:27,432 INFO org.apache.hadoop.yarn.server.resourcemanager.scheduler.capacity.ParentQueue: completedContainer queue=root usedCapacity=0.0 absoluteUsedCapacity=0.0 used=<memory:0, vCores:0> cluster=<memory:8192, vCores:8>
2019-02-03 12:28:27,432 INFO org.apache.hadoop.yarn.server.resourcemanager.scheduler.capacity.ParentQueue: Re-sorting completed queue: root.default stats: default: capacity=1.0, absoluteCapacity=1.0, usedResources=<memory:0, vCores:0>, usedCapacity=0.0, absoluteUsedCapacity=0.0, numApps=1, numContainers=0
2019-02-03 12:28:27,432 INFO org.apache.hadoop.yarn.server.resourcemanager.scheduler.capacity.CapacityScheduler: Application attempt appattempt_1549176826207_0002_000001 released container container_1549176826207_0002_01_000001 on node: host: ubuntu-HP-Pavilion-dv6-NoteBook-PC:35593 #containers=0 available=<memory:8192, vCores:8> used=<memory:0, vCores:0> with event: FINISHED
2019-02-03 12:28:27,432 INFO org.apache.hadoop.yarn.server.resourcemanager.ApplicationMasterService: Unregistering app attempt : appattempt_1549176826207_0002_000001
2019-02-03 12:28:27,433 INFO org.apache.hadoop.yarn.server.resourcemanager.security.AMRMTokenSecretManager: Application finished, removing password for appattempt_1549176826207_0002_000001
2019-02-03 12:28:27,433 INFO org.apache.hadoop.yarn.server.resourcemanager.rmapp.attempt.RMAppAttemptImpl: appattempt_1549176826207_0002_000001 State change from FINISHING to FINISHED
2019-02-03 12:28:27,433 INFO org.apache.hadoop.yarn.server.resourcemanager.rmapp.RMAppImpl: application_1549176826207_0002 State change from FINISHING to FINISHED
2019-02-03 12:28:27,433 INFO org.apache.hadoop.yarn.server.resourcemanager.RMAuditLogger: USER=root	OPERATION=Application Finished - Succeeded	TARGET=RMAppManager	RESULT=SUCCESS	APPID=application_1549176826207_0002
2019-02-03 12:28:27,434 INFO org.apache.hadoop.yarn.server.resourcemanager.RMAppManager$ApplicationSummary: appId=application_1549176826207_0002,name=SELECT count(*) FROM stocks WHERE...'NASDAQ'(Stage-1),user=root,queue=default,state=FINISHED,trackingUrl=http://ubuntu-HP-Pavilion-dv6-NoteBook-PC:8088/proxy/application_1549176826207_0002/,appMasterHost=ubuntu-HP-Pavilion-dv6-NoteBook-PC,startTime=1549177080138,finishTime=1549177100888,finalStatus=SUCCEEDED,memorySeconds=63820,vcoreSeconds=34,preemptedAMContainers=0,preemptedNonAMContainers=0,preemptedResources=<memory:0\, vCores:0>,applicationType=MAPREDUCE
2019-02-03 12:28:27,434 INFO org.apache.hadoop.yarn.server.resourcemanager.scheduler.capacity.CapacityScheduler: Application Attempt appattempt_1549176826207_0002_000001 is done. finalState=FINISHED
2019-02-03 12:28:27,434 INFO org.apache.hadoop.yarn.server.resourcemanager.scheduler.AppSchedulingInfo: Application application_1549176826207_0002 requests cleared
2019-02-03 12:28:27,434 INFO org.apache.hadoop.yarn.server.resourcemanager.scheduler.capacity.LeafQueue: Application removed - appId: application_1549176826207_0002 user: root queue: default #user-pending-applications: 0 #user-active-applications: 0 #queue-pending-applications: 0 #queue-active-applications: 0
2019-02-03 12:28:27,434 INFO org.apache.hadoop.yarn.server.resourcemanager.scheduler.capacity.ParentQueue: Application removed - appId: application_1549176826207_0002 user: root leaf-queue of parent: root #applications: 0
2019-02-03 12:28:27,435 INFO org.apache.hadoop.yarn.server.resourcemanager.amlauncher.AMLauncher: Cleaning master appattempt_1549176826207_0002_000001
2019-02-03 12:29:15,549 INFO org.apache.hadoop.yarn.server.resourcemanager.ClientRMService: Allocated new applicationId: 3
2019-02-03 12:29:16,319 INFO org.apache.hadoop.yarn.server.resourcemanager.ClientRMService: Application with id 3 submitted by user root
2019-02-03 12:29:16,319 INFO org.apache.hadoop.yarn.server.resourcemanager.rmapp.RMAppImpl: Storing application with id application_1549176826207_0003
2019-02-03 12:29:16,319 INFO org.apache.hadoop.yarn.server.resourcemanager.RMAuditLogger: USER=root	IP=127.0.0.1	OPERATION=Submit Application Request	TARGET=ClientRMService	RESULT=SUCCESS	APPID=application_1549176826207_0003
2019-02-03 12:29:16,319 INFO org.apache.hadoop.yarn.server.resourcemanager.recovery.RMStateStore: Storing info for app: application_1549176826207_0003
2019-02-03 12:29:16,319 INFO org.apache.hadoop.yarn.server.resourcemanager.rmapp.RMAppImpl: application_1549176826207_0003 State change from NEW to NEW_SAVING
2019-02-03 12:29:16,323 INFO org.apache.hadoop.yarn.server.resourcemanager.rmapp.RMAppImpl: application_1549176826207_0003 State change from NEW_SAVING to SUBMITTED
2019-02-03 12:29:16,323 INFO org.apache.hadoop.yarn.server.resourcemanager.scheduler.capacity.ParentQueue: Application added - appId: application_1549176826207_0003 user: root leaf-queue of parent: root #applications: 1
2019-02-03 12:29:16,323 INFO org.apache.hadoop.yarn.server.resourcemanager.scheduler.capacity.CapacityScheduler: Accepted application application_1549176826207_0003 from user: root, in queue: default
2019-02-03 12:29:16,324 INFO org.apache.hadoop.yarn.server.resourcemanager.rmapp.RMAppImpl: application_1549176826207_0003 State change from SUBMITTED to ACCEPTED
2019-02-03 12:29:16,324 INFO org.apache.hadoop.yarn.server.resourcemanager.ApplicationMasterService: Registering app attempt : appattempt_1549176826207_0003_000001
2019-02-03 12:29:16,324 INFO org.apache.hadoop.yarn.server.resourcemanager.rmapp.attempt.RMAppAttemptImpl: appattempt_1549176826207_0003_000001 State change from NEW to SUBMITTED
2019-02-03 12:29:16,324 WARN org.apache.hadoop.yarn.server.resourcemanager.scheduler.capacity.LeafQueue: maximum-am-resource-percent is insufficient to start a single application in queue, it is likely set too low. skipping enforcement to allow at least one application to start
2019-02-03 12:29:16,324 WARN org.apache.hadoop.yarn.server.resourcemanager.scheduler.capacity.LeafQueue: maximum-am-resource-percent is insufficient to start a single application in queue for user, it is likely set too low. skipping enforcement to allow at least one application to start
2019-02-03 12:29:16,325 INFO org.apache.hadoop.yarn.server.resourcemanager.scheduler.capacity.LeafQueue: Application application_1549176826207_0003 from user: root activated in queue: default
2019-02-03 12:29:16,325 INFO org.apache.hadoop.yarn.server.resourcemanager.scheduler.capacity.LeafQueue: Application added - appId: application_1549176826207_0003 user: org.apache.hadoop.yarn.server.resourcemanager.scheduler.capacity.LeafQueue$User@5de9bbf1, leaf-queue: default #user-pending-applications: 0 #user-active-applications: 1 #queue-pending-applications: 0 #queue-active-applications: 1
2019-02-03 12:29:16,325 INFO org.apache.hadoop.yarn.server.resourcemanager.scheduler.capacity.CapacityScheduler: Added Application Attempt appattempt_1549176826207_0003_000001 to scheduler from user root in queue default
2019-02-03 12:29:16,326 INFO org.apache.hadoop.yarn.server.resourcemanager.rmapp.attempt.RMAppAttemptImpl: appattempt_1549176826207_0003_000001 State change from SUBMITTED to SCHEDULED
2019-02-03 12:29:16,573 INFO org.apache.hadoop.yarn.server.resourcemanager.rmcontainer.RMContainerImpl: container_1549176826207_0003_01_000001 Container Transitioned from NEW to ALLOCATED
2019-02-03 12:29:16,573 INFO org.apache.hadoop.yarn.server.resourcemanager.RMAuditLogger: USER=root	OPERATION=AM Allocated Container	TARGET=SchedulerApp	RESULT=SUCCESS	APPID=application_1549176826207_0003	CONTAINERID=container_1549176826207_0003_01_000001
2019-02-03 12:29:16,574 INFO org.apache.hadoop.yarn.server.resourcemanager.scheduler.SchedulerNode: Assigned container container_1549176826207_0003_01_000001 of capacity <memory:2048, vCores:1> on host ubuntu-HP-Pavilion-dv6-NoteBook-PC:35593, which has 1 containers, <memory:2048, vCores:1> used and <memory:6144, vCores:7> available after allocation
2019-02-03 12:29:16,574 INFO org.apache.hadoop.yarn.server.resourcemanager.scheduler.capacity.LeafQueue: assignedContainer application attempt=appattempt_1549176826207_0003_000001 container=Container: [ContainerId: container_1549176826207_0003_01_000001, NodeId: ubuntu-HP-Pavilion-dv6-NoteBook-PC:35593, NodeHttpAddress: ubuntu-HP-Pavilion-dv6-NoteBook-PC:8042, Resource: <memory:2048, vCores:1>, Priority: 0, Token: null, ] queue=default: capacity=1.0, absoluteCapacity=1.0, usedResources=<memory:0, vCores:0>, usedCapacity=0.0, absoluteUsedCapacity=0.0, numApps=1, numContainers=0 clusterResource=<memory:8192, vCores:8> type=OFF_SWITCH
2019-02-03 12:29:16,574 INFO org.apache.hadoop.yarn.server.resourcemanager.scheduler.capacity.ParentQueue: Re-sorting assigned queue: root.default stats: default: capacity=1.0, absoluteCapacity=1.0, usedResources=<memory:2048, vCores:1>, usedCapacity=0.25, absoluteUsedCapacity=0.25, numApps=1, numContainers=1
2019-02-03 12:29:16,575 INFO org.apache.hadoop.yarn.server.resourcemanager.scheduler.capacity.ParentQueue: assignedContainer queue=root usedCapacity=0.25 absoluteUsedCapacity=0.25 used=<memory:2048, vCores:1> cluster=<memory:8192, vCores:8>
2019-02-03 12:29:16,577 INFO org.apache.hadoop.yarn.server.resourcemanager.security.NMTokenSecretManagerInRM: Sending NMToken for nodeId : ubuntu-HP-Pavilion-dv6-NoteBook-PC:35593 for container : container_1549176826207_0003_01_000001
2019-02-03 12:29:16,582 INFO org.apache.hadoop.yarn.server.resourcemanager.rmcontainer.RMContainerImpl: container_1549176826207_0003_01_000001 Container Transitioned from ALLOCATED to ACQUIRED
2019-02-03 12:29:16,582 INFO org.apache.hadoop.yarn.server.resourcemanager.security.NMTokenSecretManagerInRM: Clear node set for appattempt_1549176826207_0003_000001
2019-02-03 12:29:16,582 INFO org.apache.hadoop.yarn.server.resourcemanager.rmapp.attempt.RMAppAttemptImpl: Storing attempt: AppId: application_1549176826207_0003 AttemptId: appattempt_1549176826207_0003_000001 MasterContainer: Container: [ContainerId: container_1549176826207_0003_01_000001, NodeId: ubuntu-HP-Pavilion-dv6-NoteBook-PC:35593, NodeHttpAddress: ubuntu-HP-Pavilion-dv6-NoteBook-PC:8042, Resource: <memory:2048, vCores:1>, Priority: 0, Token: Token { kind: ContainerToken, service: 127.0.1.1:35593 }, ]
2019-02-03 12:29:16,582 INFO org.apache.hadoop.yarn.server.resourcemanager.rmapp.attempt.RMAppAttemptImpl: appattempt_1549176826207_0003_000001 State change from SCHEDULED to ALLOCATED_SAVING
2019-02-03 12:29:16,582 INFO org.apache.hadoop.yarn.server.resourcemanager.rmapp.attempt.RMAppAttemptImpl: appattempt_1549176826207_0003_000001 State change from ALLOCATED_SAVING to ALLOCATED
2019-02-03 12:29:16,583 INFO org.apache.hadoop.yarn.server.resourcemanager.amlauncher.AMLauncher: Launching masterappattempt_1549176826207_0003_000001
2019-02-03 12:29:16,586 INFO org.apache.hadoop.yarn.server.resourcemanager.amlauncher.AMLauncher: Setting up container Container: [ContainerId: container_1549176826207_0003_01_000001, NodeId: ubuntu-HP-Pavilion-dv6-NoteBook-PC:35593, NodeHttpAddress: ubuntu-HP-Pavilion-dv6-NoteBook-PC:8042, Resource: <memory:2048, vCores:1>, Priority: 0, Token: Token { kind: ContainerToken, service: 127.0.1.1:35593 }, ] for AM appattempt_1549176826207_0003_000001
2019-02-03 12:29:16,586 INFO org.apache.hadoop.yarn.server.resourcemanager.amlauncher.AMLauncher: Command to launch container container_1549176826207_0003_01_000001 : $JAVA_HOME/bin/java -Djava.io.tmpdir=$PWD/tmp -Dlog4j.configuration=container-log4j.properties -Dyarn.app.container.log.dir=<LOG_DIR> -Dyarn.app.container.log.filesize=0 -Dhadoop.root.logger=INFO,CLA -Dhadoop.root.logfile=syslog  -Xmx1024m org.apache.hadoop.mapreduce.v2.app.MRAppMaster 1><LOG_DIR>/stdout 2><LOG_DIR>/stderr 
2019-02-03 12:29:16,587 INFO org.apache.hadoop.yarn.server.resourcemanager.security.AMRMTokenSecretManager: Create AMRMToken for ApplicationAttempt: appattempt_1549176826207_0003_000001
2019-02-03 12:29:16,587 INFO org.apache.hadoop.yarn.server.resourcemanager.security.AMRMTokenSecretManager: Creating password for appattempt_1549176826207_0003_000001
2019-02-03 12:29:16,599 INFO org.apache.hadoop.yarn.server.resourcemanager.amlauncher.AMLauncher: Done launching container Container: [ContainerId: container_1549176826207_0003_01_000001, NodeId: ubuntu-HP-Pavilion-dv6-NoteBook-PC:35593, NodeHttpAddress: ubuntu-HP-Pavilion-dv6-NoteBook-PC:8042, Resource: <memory:2048, vCores:1>, Priority: 0, Token: Token { kind: ContainerToken, service: 127.0.1.1:35593 }, ] for AM appattempt_1549176826207_0003_000001
2019-02-03 12:29:16,600 INFO org.apache.hadoop.yarn.server.resourcemanager.rmapp.attempt.RMAppAttemptImpl: appattempt_1549176826207_0003_000001 State change from ALLOCATED to LAUNCHED
2019-02-03 12:29:17,575 INFO org.apache.hadoop.yarn.server.resourcemanager.rmcontainer.RMContainerImpl: container_1549176826207_0003_01_000001 Container Transitioned from ACQUIRED to RUNNING
2019-02-03 12:29:21,828 INFO SecurityLogger.org.apache.hadoop.ipc.Server: Auth successful for appattempt_1549176826207_0003_000001 (auth:SIMPLE)
2019-02-03 12:29:21,832 INFO org.apache.hadoop.yarn.server.resourcemanager.ApplicationMasterService: AM registration appattempt_1549176826207_0003_000001
2019-02-03 12:29:21,833 INFO org.apache.hadoop.yarn.server.resourcemanager.RMAuditLogger: USER=root	IP=127.0.0.1	OPERATION=Register App Master	TARGET=ApplicationMasterService	RESULT=SUCCESS	APPID=application_1549176826207_0003	APPATTEMPTID=appattempt_1549176826207_0003_000001
2019-02-03 12:29:21,833 INFO org.apache.hadoop.yarn.server.resourcemanager.rmapp.attempt.RMAppAttemptImpl: appattempt_1549176826207_0003_000001 State change from LAUNCHED to RUNNING
2019-02-03 12:29:21,833 INFO org.apache.hadoop.yarn.server.resourcemanager.rmapp.RMAppImpl: application_1549176826207_0003 State change from ACCEPTED to RUNNING
2019-02-03 12:29:23,585 INFO org.apache.hadoop.yarn.server.resourcemanager.rmcontainer.RMContainerImpl: container_1549176826207_0003_01_000002 Container Transitioned from NEW to ALLOCATED
2019-02-03 12:29:23,585 INFO org.apache.hadoop.yarn.server.resourcemanager.RMAuditLogger: USER=root	OPERATION=AM Allocated Container	TARGET=SchedulerApp	RESULT=SUCCESS	APPID=application_1549176826207_0003	CONTAINERID=container_1549176826207_0003_01_000002
2019-02-03 12:29:23,586 INFO org.apache.hadoop.yarn.server.resourcemanager.scheduler.SchedulerNode: Assigned container container_1549176826207_0003_01_000002 of capacity <memory:1024, vCores:1> on host ubuntu-HP-Pavilion-dv6-NoteBook-PC:35593, which has 2 containers, <memory:3072, vCores:2> used and <memory:5120, vCores:6> available after allocation
2019-02-03 12:29:23,586 INFO org.apache.hadoop.yarn.server.resourcemanager.scheduler.capacity.LeafQueue: assignedContainer application attempt=appattempt_1549176826207_0003_000001 container=Container: [ContainerId: container_1549176826207_0003_01_000002, NodeId: ubuntu-HP-Pavilion-dv6-NoteBook-PC:35593, NodeHttpAddress: ubuntu-HP-Pavilion-dv6-NoteBook-PC:8042, Resource: <memory:1024, vCores:1>, Priority: 20, Token: null, ] queue=default: capacity=1.0, absoluteCapacity=1.0, usedResources=<memory:2048, vCores:1>, usedCapacity=0.25, absoluteUsedCapacity=0.25, numApps=1, numContainers=1 clusterResource=<memory:8192, vCores:8> type=NODE_LOCAL
2019-02-03 12:29:23,586 INFO org.apache.hadoop.yarn.server.resourcemanager.scheduler.capacity.ParentQueue: Re-sorting assigned queue: root.default stats: default: capacity=1.0, absoluteCapacity=1.0, usedResources=<memory:3072, vCores:2>, usedCapacity=0.375, absoluteUsedCapacity=0.375, numApps=1, numContainers=2
2019-02-03 12:29:23,586 INFO org.apache.hadoop.yarn.server.resourcemanager.scheduler.capacity.ParentQueue: assignedContainer queue=root usedCapacity=0.375 absoluteUsedCapacity=0.375 used=<memory:3072, vCores:2> cluster=<memory:8192, vCores:8>
2019-02-03 12:29:23,913 INFO org.apache.hadoop.yarn.server.resourcemanager.security.NMTokenSecretManagerInRM: Sending NMToken for nodeId : ubuntu-HP-Pavilion-dv6-NoteBook-PC:35593 for container : container_1549176826207_0003_01_000002
2019-02-03 12:29:23,915 INFO org.apache.hadoop.yarn.server.resourcemanager.rmcontainer.RMContainerImpl: container_1549176826207_0003_01_000002 Container Transitioned from ALLOCATED to ACQUIRED
2019-02-03 12:29:24,587 INFO org.apache.hadoop.yarn.server.resourcemanager.rmcontainer.RMContainerImpl: container_1549176826207_0003_01_000002 Container Transitioned from ACQUIRED to RUNNING
2019-02-03 12:29:24,934 INFO org.apache.hadoop.yarn.server.resourcemanager.scheduler.AppSchedulingInfo: checking for deactivate of application :application_1549176826207_0003
2019-02-03 12:29:27,929 INFO org.apache.hadoop.yarn.server.resourcemanager.rmcontainer.RMContainerImpl: container_1549176826207_0003_01_000002 Container Transitioned from RUNNING to COMPLETED
2019-02-03 12:29:27,929 INFO org.apache.hadoop.yarn.server.resourcemanager.scheduler.common.fica.FiCaSchedulerApp: Completed container: container_1549176826207_0003_01_000002 in state: COMPLETED event:FINISHED
2019-02-03 12:29:27,929 INFO org.apache.hadoop.yarn.server.resourcemanager.RMAuditLogger: USER=root	OPERATION=AM Released Container	TARGET=SchedulerApp	RESULT=SUCCESS	APPID=application_1549176826207_0003	CONTAINERID=container_1549176826207_0003_01_000002
2019-02-03 12:29:27,929 INFO org.apache.hadoop.yarn.server.resourcemanager.scheduler.SchedulerNode: Released container container_1549176826207_0003_01_000002 of capacity <memory:1024, vCores:1> on host ubuntu-HP-Pavilion-dv6-NoteBook-PC:35593, which currently has 1 containers, <memory:2048, vCores:1> used and <memory:6144, vCores:7> available, release resources=true
2019-02-03 12:29:27,929 INFO org.apache.hadoop.yarn.server.resourcemanager.scheduler.capacity.LeafQueue: default used=<memory:2048, vCores:1> numContainers=1 user=root user-resources=<memory:2048, vCores:1>
2019-02-03 12:29:27,930 INFO org.apache.hadoop.yarn.server.resourcemanager.scheduler.capacity.LeafQueue: completedContainer container=Container: [ContainerId: container_1549176826207_0003_01_000002, NodeId: ubuntu-HP-Pavilion-dv6-NoteBook-PC:35593, NodeHttpAddress: ubuntu-HP-Pavilion-dv6-NoteBook-PC:8042, Resource: <memory:1024, vCores:1>, Priority: 20, Token: Token { kind: ContainerToken, service: 127.0.1.1:35593 }, ] queue=default: capacity=1.0, absoluteCapacity=1.0, usedResources=<memory:2048, vCores:1>, usedCapacity=0.25, absoluteUsedCapacity=0.25, numApps=1, numContainers=1 cluster=<memory:8192, vCores:8>
2019-02-03 12:29:27,930 INFO org.apache.hadoop.yarn.server.resourcemanager.scheduler.capacity.ParentQueue: completedContainer queue=root usedCapacity=0.25 absoluteUsedCapacity=0.25 used=<memory:2048, vCores:1> cluster=<memory:8192, vCores:8>
2019-02-03 12:29:27,930 INFO org.apache.hadoop.yarn.server.resourcemanager.scheduler.capacity.ParentQueue: Re-sorting completed queue: root.default stats: default: capacity=1.0, absoluteCapacity=1.0, usedResources=<memory:2048, vCores:1>, usedCapacity=0.25, absoluteUsedCapacity=0.25, numApps=1, numContainers=1
2019-02-03 12:29:27,930 INFO org.apache.hadoop.yarn.server.resourcemanager.scheduler.capacity.CapacityScheduler: Application attempt appattempt_1549176826207_0003_000001 released container container_1549176826207_0003_01_000002 on node: host: ubuntu-HP-Pavilion-dv6-NoteBook-PC:35593 #containers=1 available=<memory:6144, vCores:7> used=<memory:2048, vCores:1> with event: FINISHED
2019-02-03 12:29:29,936 INFO org.apache.hadoop.yarn.server.resourcemanager.rmcontainer.RMContainerImpl: container_1549176826207_0003_01_000003 Container Transitioned from NEW to ALLOCATED
2019-02-03 12:29:29,937 INFO org.apache.hadoop.yarn.server.resourcemanager.RMAuditLogger: USER=root	OPERATION=AM Allocated Container	TARGET=SchedulerApp	RESULT=SUCCESS	APPID=application_1549176826207_0003	CONTAINERID=container_1549176826207_0003_01_000003
2019-02-03 12:29:29,937 INFO org.apache.hadoop.yarn.server.resourcemanager.scheduler.SchedulerNode: Assigned container container_1549176826207_0003_01_000003 of capacity <memory:1024, vCores:1> on host ubuntu-HP-Pavilion-dv6-NoteBook-PC:35593, which has 2 containers, <memory:3072, vCores:2> used and <memory:5120, vCores:6> available after allocation
2019-02-03 12:29:29,937 INFO org.apache.hadoop.yarn.server.resourcemanager.scheduler.capacity.LeafQueue: assignedContainer application attempt=appattempt_1549176826207_0003_000001 container=Container: [ContainerId: container_1549176826207_0003_01_000003, NodeId: ubuntu-HP-Pavilion-dv6-NoteBook-PC:35593, NodeHttpAddress: ubuntu-HP-Pavilion-dv6-NoteBook-PC:8042, Resource: <memory:1024, vCores:1>, Priority: 10, Token: null, ] queue=default: capacity=1.0, absoluteCapacity=1.0, usedResources=<memory:2048, vCores:1>, usedCapacity=0.25, absoluteUsedCapacity=0.25, numApps=1, numContainers=1 clusterResource=<memory:8192, vCores:8> type=OFF_SWITCH
2019-02-03 12:29:29,937 INFO org.apache.hadoop.yarn.server.resourcemanager.scheduler.capacity.ParentQueue: Re-sorting assigned queue: root.default stats: default: capacity=1.0, absoluteCapacity=1.0, usedResources=<memory:3072, vCores:2>, usedCapacity=0.375, absoluteUsedCapacity=0.375, numApps=1, numContainers=2
2019-02-03 12:29:29,937 INFO org.apache.hadoop.yarn.server.resourcemanager.scheduler.capacity.ParentQueue: assignedContainer queue=root usedCapacity=0.375 absoluteUsedCapacity=0.375 used=<memory:3072, vCores:2> cluster=<memory:8192, vCores:8>
2019-02-03 12:29:29,967 INFO org.apache.hadoop.yarn.server.resourcemanager.rmcontainer.RMContainerImpl: container_1549176826207_0003_01_000003 Container Transitioned from ALLOCATED to ACQUIRED
2019-02-03 12:29:30,937 INFO org.apache.hadoop.yarn.server.resourcemanager.rmcontainer.RMContainerImpl: container_1549176826207_0003_01_000003 Container Transitioned from ACQUIRED to RUNNING
2019-02-03 12:29:30,974 INFO org.apache.hadoop.yarn.server.resourcemanager.scheduler.AppSchedulingInfo: checking for deactivate of application :application_1549176826207_0003
2019-02-03 12:29:33,907 INFO org.apache.hadoop.yarn.server.resourcemanager.rmcontainer.RMContainerImpl: container_1549176826207_0003_01_000003 Container Transitioned from RUNNING to COMPLETED
2019-02-03 12:29:33,907 INFO org.apache.hadoop.yarn.server.resourcemanager.scheduler.common.fica.FiCaSchedulerApp: Completed container: container_1549176826207_0003_01_000003 in state: COMPLETED event:FINISHED
2019-02-03 12:29:33,907 INFO org.apache.hadoop.yarn.server.resourcemanager.RMAuditLogger: USER=root	OPERATION=AM Released Container	TARGET=SchedulerApp	RESULT=SUCCESS	APPID=application_1549176826207_0003	CONTAINERID=container_1549176826207_0003_01_000003
2019-02-03 12:29:33,907 INFO org.apache.hadoop.yarn.server.resourcemanager.scheduler.SchedulerNode: Released container container_1549176826207_0003_01_000003 of capacity <memory:1024, vCores:1> on host ubuntu-HP-Pavilion-dv6-NoteBook-PC:35593, which currently has 1 containers, <memory:2048, vCores:1> used and <memory:6144, vCores:7> available, release resources=true
2019-02-03 12:29:33,907 INFO org.apache.hadoop.yarn.server.resourcemanager.scheduler.capacity.LeafQueue: default used=<memory:2048, vCores:1> numContainers=1 user=root user-resources=<memory:2048, vCores:1>
2019-02-03 12:29:33,907 INFO org.apache.hadoop.yarn.server.resourcemanager.scheduler.capacity.LeafQueue: completedContainer container=Container: [ContainerId: container_1549176826207_0003_01_000003, NodeId: ubuntu-HP-Pavilion-dv6-NoteBook-PC:35593, NodeHttpAddress: ubuntu-HP-Pavilion-dv6-NoteBook-PC:8042, Resource: <memory:1024, vCores:1>, Priority: 10, Token: Token { kind: ContainerToken, service: 127.0.1.1:35593 }, ] queue=default: capacity=1.0, absoluteCapacity=1.0, usedResources=<memory:2048, vCores:1>, usedCapacity=0.25, absoluteUsedCapacity=0.25, numApps=1, numContainers=1 cluster=<memory:8192, vCores:8>
2019-02-03 12:29:33,908 INFO org.apache.hadoop.yarn.server.resourcemanager.scheduler.capacity.ParentQueue: completedContainer queue=root usedCapacity=0.25 absoluteUsedCapacity=0.25 used=<memory:2048, vCores:1> cluster=<memory:8192, vCores:8>
2019-02-03 12:29:33,908 INFO org.apache.hadoop.yarn.server.resourcemanager.scheduler.capacity.ParentQueue: Re-sorting completed queue: root.default stats: default: capacity=1.0, absoluteCapacity=1.0, usedResources=<memory:2048, vCores:1>, usedCapacity=0.25, absoluteUsedCapacity=0.25, numApps=1, numContainers=1
2019-02-03 12:29:33,908 INFO org.apache.hadoop.yarn.server.resourcemanager.scheduler.capacity.CapacityScheduler: Application attempt appattempt_1549176826207_0003_000001 released container container_1549176826207_0003_01_000003 on node: host: ubuntu-HP-Pavilion-dv6-NoteBook-PC:35593 #containers=1 available=<memory:6144, vCores:7> used=<memory:2048, vCores:1> with event: FINISHED
2019-02-03 12:29:34,242 INFO org.apache.hadoop.yarn.server.resourcemanager.rmapp.attempt.RMAppAttemptImpl: Updating application attempt appattempt_1549176826207_0003_000001 with final state: FINISHING, and exit status: -1000
2019-02-03 12:29:34,243 INFO org.apache.hadoop.yarn.server.resourcemanager.rmapp.attempt.RMAppAttemptImpl: appattempt_1549176826207_0003_000001 State change from RUNNING to FINAL_SAVING
2019-02-03 12:29:34,243 INFO org.apache.hadoop.yarn.server.resourcemanager.rmapp.RMAppImpl: Updating application application_1549176826207_0003 with final state: FINISHING
2019-02-03 12:29:34,243 INFO org.apache.hadoop.yarn.server.resourcemanager.rmapp.RMAppImpl: application_1549176826207_0003 State change from RUNNING to FINAL_SAVING
2019-02-03 12:29:34,243 INFO org.apache.hadoop.yarn.server.resourcemanager.recovery.RMStateStore: Updating info for app: application_1549176826207_0003
2019-02-03 12:29:34,243 INFO org.apache.hadoop.yarn.server.resourcemanager.rmapp.attempt.RMAppAttemptImpl: appattempt_1549176826207_0003_000001 State change from FINAL_SAVING to FINISHING
2019-02-03 12:29:34,243 INFO org.apache.hadoop.yarn.server.resourcemanager.rmapp.RMAppImpl: application_1549176826207_0003 State change from FINAL_SAVING to FINISHING
2019-02-03 12:29:35,249 INFO org.apache.hadoop.yarn.server.resourcemanager.ApplicationMasterService: application_1549176826207_0003 unregistered successfully. 
2019-02-03 12:29:40,773 INFO org.apache.hadoop.yarn.server.resourcemanager.rmcontainer.RMContainerImpl: container_1549176826207_0003_01_000001 Container Transitioned from RUNNING to COMPLETED
2019-02-03 12:29:40,773 INFO org.apache.hadoop.yarn.server.resourcemanager.ApplicationMasterService: Unregistering app attempt : appattempt_1549176826207_0003_000001
2019-02-03 12:29:40,774 INFO org.apache.hadoop.yarn.server.resourcemanager.scheduler.common.fica.FiCaSchedulerApp: Completed container: container_1549176826207_0003_01_000001 in state: COMPLETED event:FINISHED
2019-02-03 12:29:40,774 INFO org.apache.hadoop.yarn.server.resourcemanager.security.AMRMTokenSecretManager: Application finished, removing password for appattempt_1549176826207_0003_000001
2019-02-03 12:29:40,774 INFO org.apache.hadoop.yarn.server.resourcemanager.RMAuditLogger: USER=root	OPERATION=AM Released Container	TARGET=SchedulerApp	RESULT=SUCCESS	APPID=application_1549176826207_0003	CONTAINERID=container_1549176826207_0003_01_000001
2019-02-03 12:29:40,774 INFO org.apache.hadoop.yarn.server.resourcemanager.rmapp.attempt.RMAppAttemptImpl: appattempt_1549176826207_0003_000001 State change from FINISHING to FINISHED
2019-02-03 12:29:40,774 INFO org.apache.hadoop.yarn.server.resourcemanager.scheduler.SchedulerNode: Released container container_1549176826207_0003_01_000001 of capacity <memory:2048, vCores:1> on host ubuntu-HP-Pavilion-dv6-NoteBook-PC:35593, which currently has 0 containers, <memory:0, vCores:0> used and <memory:8192, vCores:8> available, release resources=true
2019-02-03 12:29:40,774 INFO org.apache.hadoop.yarn.server.resourcemanager.rmapp.RMAppImpl: application_1549176826207_0003 State change from FINISHING to FINISHED
2019-02-03 12:29:40,774 INFO org.apache.hadoop.yarn.server.resourcemanager.scheduler.capacity.LeafQueue: default used=<memory:0, vCores:0> numContainers=0 user=root user-resources=<memory:0, vCores:0>
2019-02-03 12:29:40,775 INFO org.apache.hadoop.yarn.server.resourcemanager.RMAuditLogger: USER=root	OPERATION=Application Finished - Succeeded	TARGET=RMAppManager	RESULT=SUCCESS	APPID=application_1549176826207_0003
2019-02-03 12:29:40,775 INFO org.apache.hadoop.yarn.server.resourcemanager.scheduler.capacity.LeafQueue: completedContainer container=Container: [ContainerId: container_1549176826207_0003_01_000001, NodeId: ubuntu-HP-Pavilion-dv6-NoteBook-PC:35593, NodeHttpAddress: ubuntu-HP-Pavilion-dv6-NoteBook-PC:8042, Resource: <memory:2048, vCores:1>, Priority: 0, Token: Token { kind: ContainerToken, service: 127.0.1.1:35593 }, ] queue=default: capacity=1.0, absoluteCapacity=1.0, usedResources=<memory:0, vCores:0>, usedCapacity=0.0, absoluteUsedCapacity=0.0, numApps=1, numContainers=0 cluster=<memory:8192, vCores:8>
2019-02-03 12:29:40,775 INFO org.apache.hadoop.yarn.server.resourcemanager.scheduler.capacity.ParentQueue: completedContainer queue=root usedCapacity=0.0 absoluteUsedCapacity=0.0 used=<memory:0, vCores:0> cluster=<memory:8192, vCores:8>
2019-02-03 12:29:40,775 INFO org.apache.hadoop.yarn.server.resourcemanager.amlauncher.AMLauncher: Cleaning master appattempt_1549176826207_0003_000001
2019-02-03 12:29:40,776 INFO org.apache.hadoop.yarn.server.resourcemanager.scheduler.capacity.ParentQueue: Re-sorting completed queue: root.default stats: default: capacity=1.0, absoluteCapacity=1.0, usedResources=<memory:0, vCores:0>, usedCapacity=0.0, absoluteUsedCapacity=0.0, numApps=1, numContainers=0
2019-02-03 12:29:40,777 INFO org.apache.hadoop.yarn.server.resourcemanager.RMAppManager$ApplicationSummary: appId=application_1549176826207_0003,name=SELECT avg(price_close) FROM stoc...'NASDAQ'(Stage-1),user=root,queue=default,state=FINISHED,trackingUrl=http://ubuntu-HP-Pavilion-dv6-NoteBook-PC:8088/proxy/application_1549176826207_0003/,appMasterHost=ubuntu-HP-Pavilion-dv6-NoteBook-PC,startTime=1549177156319,finishTime=1549177174243,finalStatus=SUCCEEDED,memorySeconds=58076,vcoreSeconds=31,preemptedAMContainers=0,preemptedNonAMContainers=0,preemptedResources=<memory:0\, vCores:0>,applicationType=MAPREDUCE
2019-02-03 12:29:40,777 INFO org.apache.hadoop.yarn.server.resourcemanager.scheduler.capacity.CapacityScheduler: Application attempt appattempt_1549176826207_0003_000001 released container container_1549176826207_0003_01_000001 on node: host: ubuntu-HP-Pavilion-dv6-NoteBook-PC:35593 #containers=0 available=<memory:8192, vCores:8> used=<memory:0, vCores:0> with event: FINISHED
2019-02-03 12:29:40,777 INFO org.apache.hadoop.yarn.server.resourcemanager.scheduler.capacity.CapacityScheduler: Application Attempt appattempt_1549176826207_0003_000001 is done. finalState=FINISHED
2019-02-03 12:29:40,777 INFO org.apache.hadoop.yarn.server.resourcemanager.scheduler.AppSchedulingInfo: Application application_1549176826207_0003 requests cleared
2019-02-03 12:29:40,777 INFO org.apache.hadoop.yarn.server.resourcemanager.scheduler.capacity.LeafQueue: Application removed - appId: application_1549176826207_0003 user: root queue: default #user-pending-applications: 0 #user-active-applications: 0 #queue-pending-applications: 0 #queue-active-applications: 0
2019-02-03 12:29:40,777 INFO org.apache.hadoop.yarn.server.resourcemanager.scheduler.capacity.ParentQueue: Application removed - appId: application_1549176826207_0003 user: root leaf-queue of parent: root #applications: 0
2019-02-03 12:32:14,764 ERROR org.apache.hadoop.yarn.server.resourcemanager.ResourceManager: RECEIVED SIGNAL 15: SIGTERM
2019-02-03 12:32:14,772 ERROR org.apache.hadoop.security.token.delegation.AbstractDelegationTokenSecretManager: ExpiredTokenRemover received java.lang.InterruptedException: sleep interrupted
2019-02-03 12:32:14,777 INFO org.mortbay.log: Stopped HttpServer2$SelectChannelConnectorWithSafeStartup@0.0.0.0:8088
2019-02-03 12:32:14,878 INFO org.apache.hadoop.ipc.Server: Stopping server on 8032
2019-02-03 12:32:14,884 INFO org.apache.hadoop.ipc.Server: Stopping IPC Server listener on 8032
2019-02-03 12:32:14,889 INFO org.apache.hadoop.ipc.Server: Stopping server on 8033
2019-02-03 12:32:14,890 INFO org.apache.hadoop.ipc.Server: Stopping IPC Server Responder
2019-02-03 12:32:14,891 INFO org.apache.hadoop.ipc.Server: Stopping IPC Server listener on 8033
2019-02-03 12:32:14,892 INFO org.apache.hadoop.ipc.Server: Stopping IPC Server Responder
2019-02-03 12:32:14,892 INFO org.apache.hadoop.yarn.server.resourcemanager.ResourceManager: Transitioning to standby state
2019-02-03 12:32:14,893 WARN org.apache.hadoop.yarn.server.resourcemanager.amlauncher.ApplicationMasterLauncher: org.apache.hadoop.yarn.server.resourcemanager.amlauncher.ApplicationMasterLauncher$LauncherThread interrupted. Returning.
2019-02-03 12:32:14,893 INFO org.apache.hadoop.ipc.Server: Stopping server on 8030
2019-02-03 12:32:14,897 INFO org.apache.hadoop.ipc.Server: Stopping server on 8031
2019-02-03 12:32:14,897 INFO org.apache.hadoop.ipc.Server: Stopping IPC Server listener on 8030
2019-02-03 12:32:14,897 INFO org.apache.hadoop.ipc.Server: Stopping IPC Server Responder
2019-02-03 12:32:14,899 INFO org.apache.hadoop.ipc.Server: Stopping IPC Server listener on 8031
2019-02-03 12:32:14,901 INFO org.apache.hadoop.ipc.Server: Stopping IPC Server Responder
2019-02-03 12:32:14,901 INFO org.apache.hadoop.yarn.util.AbstractLivelinessMonitor: NMLivelinessMonitor thread interrupted
2019-02-03 12:32:14,902 ERROR org.apache.hadoop.yarn.server.resourcemanager.ResourceManager: Returning, interrupted : java.lang.InterruptedException
2019-02-03 12:32:14,902 INFO org.apache.hadoop.yarn.event.AsyncDispatcher: AsyncDispatcher is draining to stop, igonring any new events.
2019-02-03 12:32:14,902 INFO org.apache.hadoop.yarn.util.AbstractLivelinessMonitor: AMLivelinessMonitor thread interrupted
2019-02-03 12:32:14,902 INFO org.apache.hadoop.yarn.util.AbstractLivelinessMonitor: AMLivelinessMonitor thread interrupted
2019-02-03 12:32:14,902 INFO org.apache.hadoop.yarn.util.AbstractLivelinessMonitor: org.apache.hadoop.yarn.server.resourcemanager.rmcontainer.ContainerAllocationExpirer thread interrupted
2019-02-03 12:32:14,903 ERROR org.apache.hadoop.security.token.delegation.AbstractDelegationTokenSecretManager: ExpiredTokenRemover received java.lang.InterruptedException: sleep interrupted
2019-02-03 12:32:14,903 INFO org.apache.hadoop.metrics2.impl.MetricsSystemImpl: Stopping ResourceManager metrics system...
2019-02-03 12:32:14,905 INFO org.apache.hadoop.metrics2.impl.MetricsSystemImpl: ResourceManager metrics system stopped.
2019-02-03 12:32:14,905 INFO org.apache.hadoop.metrics2.impl.MetricsSystemImpl: ResourceManager metrics system shutdown complete.
2019-02-03 12:32:14,905 INFO org.apache.hadoop.yarn.event.AsyncDispatcher: AsyncDispatcher is draining to stop, igonring any new events.
2019-02-03 12:32:14,905 INFO org.apache.hadoop.yarn.server.resourcemanager.ResourceManager: Transitioned to standby state
2019-02-03 12:32:14,905 INFO org.apache.hadoop.yarn.server.resourcemanager.ResourceManager: SHUTDOWN_MSG: 
/************************************************************
SHUTDOWN_MSG: Shutting down ResourceManager at ubuntu-HP-Pavilion-dv6-NoteBook-PC/127.0.1.1
************************************************************/
2019-02-04 16:01:48,501 INFO org.apache.hadoop.yarn.server.resourcemanager.ResourceManager: STARTUP_MSG: 
/************************************************************
STARTUP_MSG: Starting ResourceManager
STARTUP_MSG:   host = ubuntu-HP-Pavilion-dv6-NoteBook-PC/127.0.1.1
STARTUP_MSG:   args = []
STARTUP_MSG:   version = 2.7.3
STARTUP_MSG:   build = https://git-wip-us.apache.org/repos/asf/hadoop.git -r baa91f7c6bc9cb92be5982de4719c1c8af91ccff; compiled by 'root' on 2016-08-18T01:41Z
STARTUP_MSG:   java = 1.8.0_171
************************************************************/
2019-02-04 16:01:48,549 INFO org.apache.hadoop.yarn.server.resourcemanager.ResourceManager: registered UNIX signal handlers for [TERM, HUP, INT]
2019-02-04 16:01:49,580 INFO org.apache.hadoop.conf.Configuration: found resource core-site.xml at file:/opt/hadoop/hadoop-2.7.3/etc/hadoop/core-site.xml
2019-02-04 16:01:49,733 WARN org.apache.hadoop.util.NativeCodeLoader: Unable to load native-hadoop library for your platform... using builtin-java classes where applicable
2019-02-04 16:01:49,837 INFO org.apache.hadoop.security.Groups: clearing userToGroupsMap cache
2019-02-04 16:01:50,248 INFO org.apache.hadoop.conf.Configuration: found resource yarn-site.xml at file:/opt/hadoop/hadoop-2.7.3/etc/hadoop/yarn-site.xml
2019-02-04 16:01:51,026 INFO org.apache.hadoop.yarn.event.AsyncDispatcher: Registering class org.apache.hadoop.yarn.server.resourcemanager.RMFatalEventType for class org.apache.hadoop.yarn.server.resourcemanager.ResourceManager$RMFatalEventDispatcher
2019-02-04 16:01:51,303 INFO org.apache.hadoop.yarn.server.resourcemanager.security.NMTokenSecretManagerInRM: NMTokenKeyRollingInterval: 86400000ms and NMTokenKeyActivationDelay: 900000ms
2019-02-04 16:01:51,319 INFO org.apache.hadoop.yarn.server.resourcemanager.security.RMContainerTokenSecretManager: ContainerTokenKeyRollingInterval: 86400000ms and ContainerTokenKeyActivationDelay: 900000ms
2019-02-04 16:01:51,360 INFO org.apache.hadoop.yarn.server.resourcemanager.security.AMRMTokenSecretManager: AMRMTokenKeyRollingInterval: 86400000ms and AMRMTokenKeyActivationDelay: 900000 ms
2019-02-04 16:01:51,469 INFO org.apache.hadoop.yarn.event.AsyncDispatcher: Registering class org.apache.hadoop.yarn.server.resourcemanager.recovery.RMStateStoreEventType for class org.apache.hadoop.yarn.server.resourcemanager.recovery.RMStateStore$ForwardingEventHandler
2019-02-04 16:01:51,472 INFO org.apache.hadoop.yarn.event.AsyncDispatcher: Registering class org.apache.hadoop.yarn.server.resourcemanager.NodesListManagerEventType for class org.apache.hadoop.yarn.server.resourcemanager.NodesListManager
2019-02-04 16:01:51,472 INFO org.apache.hadoop.yarn.server.resourcemanager.ResourceManager: Using Scheduler: org.apache.hadoop.yarn.server.resourcemanager.scheduler.capacity.CapacityScheduler
2019-02-04 16:01:51,514 INFO org.apache.hadoop.yarn.event.AsyncDispatcher: Registering class org.apache.hadoop.yarn.server.resourcemanager.scheduler.event.SchedulerEventType for class org.apache.hadoop.yarn.server.resourcemanager.ResourceManager$SchedulerEventDispatcher
2019-02-04 16:01:51,516 INFO org.apache.hadoop.yarn.event.AsyncDispatcher: Registering class org.apache.hadoop.yarn.server.resourcemanager.rmapp.RMAppEventType for class org.apache.hadoop.yarn.server.resourcemanager.ResourceManager$ApplicationEventDispatcher
2019-02-04 16:01:51,517 INFO org.apache.hadoop.yarn.event.AsyncDispatcher: Registering class org.apache.hadoop.yarn.server.resourcemanager.rmapp.attempt.RMAppAttemptEventType for class org.apache.hadoop.yarn.server.resourcemanager.ResourceManager$ApplicationAttemptEventDispatcher
2019-02-04 16:01:51,529 INFO org.apache.hadoop.yarn.event.AsyncDispatcher: Registering class org.apache.hadoop.yarn.server.resourcemanager.rmnode.RMNodeEventType for class org.apache.hadoop.yarn.server.resourcemanager.ResourceManager$NodeEventDispatcher
2019-02-04 16:01:51,733 INFO org.apache.hadoop.metrics2.impl.MetricsConfig: loaded properties from hadoop-metrics2.properties
2019-02-04 16:01:51,909 INFO org.apache.hadoop.metrics2.impl.MetricsSystemImpl: Scheduled snapshot period at 10 second(s).
2019-02-04 16:01:51,909 INFO org.apache.hadoop.metrics2.impl.MetricsSystemImpl: ResourceManager metrics system started
2019-02-04 16:01:51,962 INFO org.apache.hadoop.yarn.event.AsyncDispatcher: Registering class org.apache.hadoop.yarn.server.resourcemanager.RMAppManagerEventType for class org.apache.hadoop.yarn.server.resourcemanager.RMAppManager
2019-02-04 16:01:52,201 INFO org.apache.hadoop.yarn.event.AsyncDispatcher: Registering class org.apache.hadoop.yarn.server.resourcemanager.amlauncher.AMLauncherEventType for class org.apache.hadoop.yarn.server.resourcemanager.amlauncher.ApplicationMasterLauncher
2019-02-04 16:01:52,205 INFO org.apache.hadoop.yarn.server.resourcemanager.RMNMInfo: Registered RMNMInfo MBean
2019-02-04 16:01:52,210 INFO org.apache.hadoop.yarn.security.YarnAuthorizationProvider: org.apache.hadoop.yarn.security.ConfiguredYarnAuthorizer is instiantiated.
2019-02-04 16:01:52,211 INFO org.apache.hadoop.util.HostsFileReader: Refreshing hosts (include/exclude) list
2019-02-04 16:01:52,214 INFO org.apache.hadoop.conf.Configuration: found resource capacity-scheduler.xml at file:/opt/hadoop/hadoop-2.7.3/etc/hadoop/capacity-scheduler.xml
2019-02-04 16:01:52,397 INFO org.apache.hadoop.yarn.server.resourcemanager.scheduler.capacity.CapacitySchedulerConfiguration: max alloc mb per queue for root is undefined
2019-02-04 16:01:52,400 INFO org.apache.hadoop.yarn.server.resourcemanager.scheduler.capacity.CapacitySchedulerConfiguration: max alloc vcore per queue for root is undefined
2019-02-04 16:01:52,408 INFO org.apache.hadoop.yarn.server.resourcemanager.scheduler.capacity.ParentQueue: root, capacity=1.0, asboluteCapacity=1.0, maxCapacity=1.0, asboluteMaxCapacity=1.0, state=RUNNING, acls=ADMINISTER_QUEUE:*SUBMIT_APP:*, labels=*,
, reservationsContinueLooking=true
2019-02-04 16:01:52,408 INFO org.apache.hadoop.yarn.server.resourcemanager.scheduler.capacity.ParentQueue: Initialized parent-queue root name=root, fullname=root
2019-02-04 16:01:52,440 INFO org.apache.hadoop.yarn.server.resourcemanager.scheduler.capacity.CapacitySchedulerConfiguration: max alloc mb per queue for root.default is undefined
2019-02-04 16:01:52,440 INFO org.apache.hadoop.yarn.server.resourcemanager.scheduler.capacity.CapacitySchedulerConfiguration: max alloc vcore per queue for root.default is undefined
2019-02-04 16:01:52,443 INFO org.apache.hadoop.yarn.server.resourcemanager.scheduler.capacity.LeafQueue: Initializing default
capacity = 1.0 [= (float) configuredCapacity / 100 ]
asboluteCapacity = 1.0 [= parentAbsoluteCapacity * capacity ]
maxCapacity = 1.0 [= configuredMaxCapacity ]
absoluteMaxCapacity = 1.0 [= 1.0 maximumCapacity undefined, (parentAbsoluteMaxCapacity * maximumCapacity) / 100 otherwise ]
userLimit = 100 [= configuredUserLimit ]
userLimitFactor = 1.0 [= configuredUserLimitFactor ]
maxApplications = 10000 [= configuredMaximumSystemApplicationsPerQueue or (int)(configuredMaximumSystemApplications * absoluteCapacity)]
maxApplicationsPerUser = 10000 [= (int)(maxApplications * (userLimit / 100.0f) * userLimitFactor) ]
usedCapacity = 0.0 [= usedResourcesMemory / (clusterResourceMemory * absoluteCapacity)]
absoluteUsedCapacity = 0.0 [= usedResourcesMemory / clusterResourceMemory]
maxAMResourcePerQueuePercent = 0.1 [= configuredMaximumAMResourcePercent ]
minimumAllocationFactor = 0.875 [= (float)(maximumAllocationMemory - minimumAllocationMemory) / maximumAllocationMemory ]
maximumAllocation = <memory:8192, vCores:32> [= configuredMaxAllocation ]
numContainers = 0 [= currentNumContainers ]
state = RUNNING [= configuredState ]
acls = ADMINISTER_QUEUE:*SUBMIT_APP:* [= configuredAcls ]
nodeLocalityDelay = 40
labels=*,
nodeLocalityDelay = 40
reservationsContinueLooking = true
preemptionDisabled = true

2019-02-04 16:01:52,443 INFO org.apache.hadoop.yarn.server.resourcemanager.scheduler.capacity.CapacityScheduler: Initialized queue: default: capacity=1.0, absoluteCapacity=1.0, usedResources=<memory:0, vCores:0>, usedCapacity=0.0, absoluteUsedCapacity=0.0, numApps=0, numContainers=0
2019-02-04 16:01:52,444 INFO org.apache.hadoop.yarn.server.resourcemanager.scheduler.capacity.CapacityScheduler: Initialized queue: root: numChildQueue= 1, capacity=1.0, absoluteCapacity=1.0, usedResources=<memory:0, vCores:0>usedCapacity=0.0, numApps=0, numContainers=0
2019-02-04 16:01:52,445 INFO org.apache.hadoop.yarn.server.resourcemanager.scheduler.capacity.CapacityScheduler: Initialized root queue root: numChildQueue= 1, capacity=1.0, absoluteCapacity=1.0, usedResources=<memory:0, vCores:0>usedCapacity=0.0, numApps=0, numContainers=0
2019-02-04 16:01:52,446 INFO org.apache.hadoop.yarn.server.resourcemanager.scheduler.capacity.CapacityScheduler: Initialized queue mappings, override: false
2019-02-04 16:01:52,447 INFO org.apache.hadoop.yarn.server.resourcemanager.scheduler.capacity.CapacityScheduler: Initialized CapacityScheduler with calculator=class org.apache.hadoop.yarn.util.resource.DefaultResourceCalculator, minimumAllocation=<<memory:1024, vCores:1>>, maximumAllocation=<<memory:8192, vCores:32>>, asynchronousScheduling=false, asyncScheduleInterval=5ms
2019-02-04 16:01:52,486 INFO org.apache.hadoop.yarn.server.resourcemanager.metrics.SystemMetricsPublisher: YARN system metrics publishing service is not enabled
2019-02-04 16:01:52,486 INFO org.apache.hadoop.yarn.server.resourcemanager.ResourceManager: Transitioning to active state
2019-02-04 16:01:52,549 INFO org.apache.hadoop.yarn.server.resourcemanager.recovery.RMStateStore: Updating AMRMToken
2019-02-04 16:01:52,549 INFO org.apache.hadoop.yarn.server.resourcemanager.security.RMContainerTokenSecretManager: Rolling master-key for container-tokens
2019-02-04 16:01:52,550 INFO org.apache.hadoop.yarn.server.resourcemanager.security.NMTokenSecretManagerInRM: Rolling master-key for nm-tokens
2019-02-04 16:01:52,550 INFO org.apache.hadoop.security.token.delegation.AbstractDelegationTokenSecretManager: Updating the current master key for generating delegation tokens
2019-02-04 16:01:52,552 INFO org.apache.hadoop.yarn.server.resourcemanager.security.RMDelegationTokenSecretManager: storing master key with keyID 1
2019-02-04 16:01:52,552 INFO org.apache.hadoop.yarn.server.resourcemanager.recovery.RMStateStore: Storing RMDTMasterKey.
2019-02-04 16:01:52,555 INFO org.apache.hadoop.security.token.delegation.AbstractDelegationTokenSecretManager: Starting expired delegation token remover thread, tokenRemoverScanInterval=60 min(s)
2019-02-04 16:01:52,558 INFO org.apache.hadoop.security.token.delegation.AbstractDelegationTokenSecretManager: Updating the current master key for generating delegation tokens
2019-02-04 16:01:52,558 INFO org.apache.hadoop.yarn.server.resourcemanager.security.RMDelegationTokenSecretManager: storing master key with keyID 2
2019-02-04 16:01:52,558 INFO org.apache.hadoop.yarn.server.resourcemanager.recovery.RMStateStore: Storing RMDTMasterKey.
2019-02-04 16:01:52,561 INFO org.apache.hadoop.yarn.event.AsyncDispatcher: Registering class org.apache.hadoop.yarn.nodelabels.event.NodeLabelsStoreEventType for class org.apache.hadoop.yarn.nodelabels.CommonNodeLabelsManager$ForwardingEventHandler
2019-02-04 16:01:52,641 INFO org.apache.hadoop.ipc.CallQueueManager: Using callQueue class java.util.concurrent.LinkedBlockingQueue
2019-02-04 16:01:52,678 INFO org.apache.hadoop.ipc.Server: Starting Socket Reader #1 for port 8031
2019-02-04 16:01:52,762 INFO org.apache.hadoop.yarn.factories.impl.pb.RpcServerFactoryPBImpl: Adding protocol org.apache.hadoop.yarn.server.api.ResourceTrackerPB to the server
2019-02-04 16:01:52,765 INFO org.apache.hadoop.ipc.Server: IPC Server Responder: starting
2019-02-04 16:01:52,872 INFO org.apache.hadoop.ipc.Server: IPC Server listener on 8031: starting
2019-02-04 16:01:53,012 INFO org.apache.hadoop.ipc.CallQueueManager: Using callQueue class java.util.concurrent.LinkedBlockingQueue
2019-02-04 16:01:53,026 INFO org.apache.hadoop.ipc.Server: Starting Socket Reader #1 for port 8030
2019-02-04 16:01:53,057 INFO org.apache.hadoop.yarn.factories.impl.pb.RpcServerFactoryPBImpl: Adding protocol org.apache.hadoop.yarn.api.ApplicationMasterProtocolPB to the server
2019-02-04 16:01:53,057 INFO org.apache.hadoop.ipc.Server: IPC Server Responder: starting
2019-02-04 16:01:53,058 INFO org.apache.hadoop.ipc.Server: IPC Server listener on 8030: starting
2019-02-04 16:01:53,491 INFO org.apache.hadoop.ipc.CallQueueManager: Using callQueue class java.util.concurrent.LinkedBlockingQueue
2019-02-04 16:01:53,492 INFO org.apache.hadoop.ipc.Server: Starting Socket Reader #1 for port 8032
2019-02-04 16:01:53,504 INFO org.apache.hadoop.yarn.factories.impl.pb.RpcServerFactoryPBImpl: Adding protocol org.apache.hadoop.yarn.api.ApplicationClientProtocolPB to the server
2019-02-04 16:01:53,506 INFO org.apache.hadoop.ipc.Server: IPC Server Responder: starting
2019-02-04 16:01:53,507 INFO org.apache.hadoop.ipc.Server: IPC Server listener on 8032: starting
2019-02-04 16:01:53,607 INFO org.apache.hadoop.yarn.server.resourcemanager.ResourceManager: Transitioned to active state
2019-02-04 16:01:53,896 INFO org.mortbay.log: Logging to org.slf4j.impl.Log4jLoggerAdapter(org.mortbay.log) via org.mortbay.log.Slf4jLog
2019-02-04 16:01:53,914 INFO org.apache.hadoop.security.authentication.server.AuthenticationFilter: Unable to initialize FileSignerSecretProvider, falling back to use random secrets.
2019-02-04 16:01:53,930 INFO org.apache.hadoop.http.HttpRequestLog: Http request log for http.requests.resourcemanager is not defined
2019-02-04 16:01:53,951 INFO org.apache.hadoop.http.HttpServer2: Added global filter 'safety' (class=org.apache.hadoop.http.HttpServer2$QuotingInputFilter)
2019-02-04 16:01:53,962 INFO org.apache.hadoop.http.HttpServer2: Added filter RMAuthenticationFilter (class=org.apache.hadoop.yarn.server.security.http.RMAuthenticationFilter) to context cluster
2019-02-04 16:01:53,962 INFO org.apache.hadoop.http.HttpServer2: Added filter RMAuthenticationFilter (class=org.apache.hadoop.yarn.server.security.http.RMAuthenticationFilter) to context logs
2019-02-04 16:01:53,962 INFO org.apache.hadoop.http.HttpServer2: Added filter RMAuthenticationFilter (class=org.apache.hadoop.yarn.server.security.http.RMAuthenticationFilter) to context static
2019-02-04 16:01:53,963 INFO org.apache.hadoop.http.HttpServer2: Added filter static_user_filter (class=org.apache.hadoop.http.lib.StaticUserWebFilter$StaticUserFilter) to context cluster
2019-02-04 16:01:53,963 INFO org.apache.hadoop.http.HttpServer2: Added filter static_user_filter (class=org.apache.hadoop.http.lib.StaticUserWebFilter$StaticUserFilter) to context logs
2019-02-04 16:01:53,964 INFO org.apache.hadoop.http.HttpServer2: Added filter static_user_filter (class=org.apache.hadoop.http.lib.StaticUserWebFilter$StaticUserFilter) to context static
2019-02-04 16:01:53,977 INFO org.apache.hadoop.http.HttpServer2: adding path spec: /cluster/*
2019-02-04 16:01:53,977 INFO org.apache.hadoop.http.HttpServer2: adding path spec: /ws/*
2019-02-04 16:01:55,220 INFO org.apache.hadoop.yarn.webapp.WebApps: Registered webapp guice modules
2019-02-04 16:01:55,226 INFO org.apache.hadoop.http.HttpServer2: Jetty bound to port 8088
2019-02-04 16:01:55,227 INFO org.mortbay.log: jetty-6.1.26
2019-02-04 16:01:55,394 INFO org.mortbay.log: Extract jar:file:/opt/hadoop/hadoop-2.7.3/share/hadoop/yarn/hadoop-yarn-common-2.7.3.jar!/webapps/cluster to /tmp/Jetty_0_0_0_0_8088_cluster____u0rgz3/webapp
2019-02-04 16:01:56,036 INFO org.apache.hadoop.security.token.delegation.AbstractDelegationTokenSecretManager: Updating the current master key for generating delegation tokens
2019-02-04 16:01:56,037 INFO org.apache.hadoop.security.token.delegation.AbstractDelegationTokenSecretManager: Starting expired delegation token remover thread, tokenRemoverScanInterval=60 min(s)
2019-02-04 16:01:56,037 INFO org.apache.hadoop.security.token.delegation.AbstractDelegationTokenSecretManager: Updating the current master key for generating delegation tokens
2019-02-04 16:02:01,538 INFO org.mortbay.log: Started HttpServer2$SelectChannelConnectorWithSafeStartup@0.0.0.0:8088
2019-02-04 16:02:01,539 INFO org.apache.hadoop.yarn.webapp.WebApps: Web app cluster started at 8088
2019-02-04 16:02:01,595 INFO org.apache.hadoop.ipc.CallQueueManager: Using callQueue class java.util.concurrent.LinkedBlockingQueue
2019-02-04 16:02:01,596 INFO org.apache.hadoop.ipc.Server: Starting Socket Reader #1 for port 8033
2019-02-04 16:02:01,600 INFO org.apache.hadoop.yarn.factories.impl.pb.RpcServerFactoryPBImpl: Adding protocol org.apache.hadoop.yarn.server.api.ResourceManagerAdministrationProtocolPB to the server
2019-02-04 16:02:01,602 INFO org.apache.hadoop.ipc.Server: IPC Server Responder: starting
2019-02-04 16:02:01,603 INFO org.apache.hadoop.ipc.Server: IPC Server listener on 8033: starting
2019-02-04 16:02:01,759 INFO org.apache.hadoop.yarn.util.RackResolver: Resolved ubuntu-HP-Pavilion-dv6-NoteBook-PC to /default-rack
2019-02-04 16:02:01,764 INFO org.apache.hadoop.yarn.server.resourcemanager.ResourceTrackerService: NodeManager from node ubuntu-HP-Pavilion-dv6-NoteBook-PC(cmPort: 39495 httpPort: 8042) registered with capability: <memory:8192, vCores:8>, assigned nodeId ubuntu-HP-Pavilion-dv6-NoteBook-PC:39495
2019-02-04 16:02:01,774 INFO org.apache.hadoop.yarn.server.resourcemanager.rmnode.RMNodeImpl: ubuntu-HP-Pavilion-dv6-NoteBook-PC:39495 Node Transitioned from NEW to RUNNING
2019-02-04 16:02:01,783 INFO org.apache.hadoop.yarn.server.resourcemanager.scheduler.capacity.CapacityScheduler: Added node ubuntu-HP-Pavilion-dv6-NoteBook-PC:39495 clusterResource: <memory:8192, vCores:8>
2019-02-04 16:11:52,214 INFO org.apache.hadoop.yarn.server.resourcemanager.scheduler.AbstractYarnScheduler: Release request cache is cleaned up
2019-02-04 16:14:27,561 INFO org.apache.hadoop.ipc.Server: Socket Reader #1 for port 8030: readAndProcess from client 127.0.0.1 threw exception [org.apache.hadoop.security.AccessControlException: SIMPLE authentication is not enabled.  Available:[TOKEN]]
org.apache.hadoop.security.AccessControlException: SIMPLE authentication is not enabled.  Available:[TOKEN]
	at org.apache.hadoop.ipc.Server$Connection.initializeAuthContext(Server.java:1564)
	at org.apache.hadoop.ipc.Server$Connection.readAndProcess(Server.java:1520)
	at org.apache.hadoop.ipc.Server$Listener.doRead(Server.java:771)
	at org.apache.hadoop.ipc.Server$Listener$Reader.doRunLoop(Server.java:637)
	at org.apache.hadoop.ipc.Server$Listener$Reader.run(Server.java:608)
2019-02-04 16:14:27,607 INFO org.apache.hadoop.ipc.Server: Socket Reader #1 for port 8030: readAndProcess from client 127.0.0.1 threw exception [org.apache.hadoop.security.AccessControlException: SIMPLE authentication is not enabled.  Available:[TOKEN]]
org.apache.hadoop.security.AccessControlException: SIMPLE authentication is not enabled.  Available:[TOKEN]
	at org.apache.hadoop.ipc.Server$Connection.initializeAuthContext(Server.java:1564)
	at org.apache.hadoop.ipc.Server$Connection.readAndProcess(Server.java:1520)
	at org.apache.hadoop.ipc.Server$Listener.doRead(Server.java:771)
	at org.apache.hadoop.ipc.Server$Listener$Reader.doRunLoop(Server.java:637)
	at org.apache.hadoop.ipc.Server$Listener$Reader.run(Server.java:608)
2019-02-08 18:13:53,878 INFO org.apache.hadoop.yarn.server.resourcemanager.ResourceManager: STARTUP_MSG: 
/************************************************************
STARTUP_MSG: Starting ResourceManager
STARTUP_MSG:   host = ubuntu-HP-Pavilion-dv6-NoteBook-PC/127.0.1.1
STARTUP_MSG:   args = []
STARTUP_MSG:   version = 2.7.3
STARTUP_MSG:   build = https://git-wip-us.apache.org/repos/asf/hadoop.git -r baa91f7c6bc9cb92be5982de4719c1c8af91ccff; compiled by 'root' on 2016-08-18T01:41Z
STARTUP_MSG:   java = 1.8.0_171
************************************************************/
2019-02-08 18:13:53,913 INFO org.apache.hadoop.yarn.server.resourcemanager.ResourceManager: registered UNIX signal handlers for [TERM, HUP, INT]
2019-02-08 18:13:54,811 INFO org.apache.hadoop.conf.Configuration: found resource core-site.xml at file:/opt/hadoop/hadoop-2.7.3/etc/hadoop/core-site.xml
2019-02-08 18:13:54,959 WARN org.apache.hadoop.util.NativeCodeLoader: Unable to load native-hadoop library for your platform... using builtin-java classes where applicable
2019-02-08 18:13:55,061 INFO org.apache.hadoop.security.Groups: clearing userToGroupsMap cache
2019-02-08 18:13:55,296 INFO org.apache.hadoop.conf.Configuration: found resource yarn-site.xml at file:/opt/hadoop/hadoop-2.7.3/etc/hadoop/yarn-site.xml
2019-02-08 18:13:55,860 INFO org.apache.hadoop.yarn.event.AsyncDispatcher: Registering class org.apache.hadoop.yarn.server.resourcemanager.RMFatalEventType for class org.apache.hadoop.yarn.server.resourcemanager.ResourceManager$RMFatalEventDispatcher
2019-02-08 18:13:56,211 INFO org.apache.hadoop.yarn.server.resourcemanager.security.NMTokenSecretManagerInRM: NMTokenKeyRollingInterval: 86400000ms and NMTokenKeyActivationDelay: 900000ms
2019-02-08 18:13:56,281 INFO org.apache.hadoop.yarn.server.resourcemanager.security.RMContainerTokenSecretManager: ContainerTokenKeyRollingInterval: 86400000ms and ContainerTokenKeyActivationDelay: 900000ms
2019-02-08 18:13:56,291 INFO org.apache.hadoop.yarn.server.resourcemanager.security.AMRMTokenSecretManager: AMRMTokenKeyRollingInterval: 86400000ms and AMRMTokenKeyActivationDelay: 900000 ms
2019-02-08 18:13:56,412 INFO org.apache.hadoop.yarn.event.AsyncDispatcher: Registering class org.apache.hadoop.yarn.server.resourcemanager.recovery.RMStateStoreEventType for class org.apache.hadoop.yarn.server.resourcemanager.recovery.RMStateStore$ForwardingEventHandler
2019-02-08 18:13:56,417 INFO org.apache.hadoop.yarn.event.AsyncDispatcher: Registering class org.apache.hadoop.yarn.server.resourcemanager.NodesListManagerEventType for class org.apache.hadoop.yarn.server.resourcemanager.NodesListManager
2019-02-08 18:13:56,417 INFO org.apache.hadoop.yarn.server.resourcemanager.ResourceManager: Using Scheduler: org.apache.hadoop.yarn.server.resourcemanager.scheduler.capacity.CapacityScheduler
2019-02-08 18:13:56,464 INFO org.apache.hadoop.yarn.event.AsyncDispatcher: Registering class org.apache.hadoop.yarn.server.resourcemanager.scheduler.event.SchedulerEventType for class org.apache.hadoop.yarn.server.resourcemanager.ResourceManager$SchedulerEventDispatcher
2019-02-08 18:13:56,466 INFO org.apache.hadoop.yarn.event.AsyncDispatcher: Registering class org.apache.hadoop.yarn.server.resourcemanager.rmapp.RMAppEventType for class org.apache.hadoop.yarn.server.resourcemanager.ResourceManager$ApplicationEventDispatcher
2019-02-08 18:13:56,468 INFO org.apache.hadoop.yarn.event.AsyncDispatcher: Registering class org.apache.hadoop.yarn.server.resourcemanager.rmapp.attempt.RMAppAttemptEventType for class org.apache.hadoop.yarn.server.resourcemanager.ResourceManager$ApplicationAttemptEventDispatcher
2019-02-08 18:13:56,470 INFO org.apache.hadoop.yarn.event.AsyncDispatcher: Registering class org.apache.hadoop.yarn.server.resourcemanager.rmnode.RMNodeEventType for class org.apache.hadoop.yarn.server.resourcemanager.ResourceManager$NodeEventDispatcher
2019-02-08 18:13:56,642 INFO org.apache.hadoop.metrics2.impl.MetricsConfig: loaded properties from hadoop-metrics2.properties
2019-02-08 18:13:56,812 INFO org.apache.hadoop.metrics2.impl.MetricsSystemImpl: Scheduled snapshot period at 10 second(s).
2019-02-08 18:13:56,812 INFO org.apache.hadoop.metrics2.impl.MetricsSystemImpl: ResourceManager metrics system started
2019-02-08 18:13:56,845 INFO org.apache.hadoop.yarn.event.AsyncDispatcher: Registering class org.apache.hadoop.yarn.server.resourcemanager.RMAppManagerEventType for class org.apache.hadoop.yarn.server.resourcemanager.RMAppManager
2019-02-08 18:13:56,865 INFO org.apache.hadoop.yarn.event.AsyncDispatcher: Registering class org.apache.hadoop.yarn.server.resourcemanager.amlauncher.AMLauncherEventType for class org.apache.hadoop.yarn.server.resourcemanager.amlauncher.ApplicationMasterLauncher
2019-02-08 18:13:56,870 INFO org.apache.hadoop.yarn.server.resourcemanager.RMNMInfo: Registered RMNMInfo MBean
2019-02-08 18:13:56,874 INFO org.apache.hadoop.yarn.security.YarnAuthorizationProvider: org.apache.hadoop.yarn.security.ConfiguredYarnAuthorizer is instiantiated.
2019-02-08 18:13:56,876 INFO org.apache.hadoop.util.HostsFileReader: Refreshing hosts (include/exclude) list
2019-02-08 18:13:56,879 INFO org.apache.hadoop.conf.Configuration: found resource capacity-scheduler.xml at file:/opt/hadoop/hadoop-2.7.3/etc/hadoop/capacity-scheduler.xml
2019-02-08 18:13:57,052 INFO org.apache.hadoop.yarn.server.resourcemanager.scheduler.capacity.CapacitySchedulerConfiguration: max alloc mb per queue for root is undefined
2019-02-08 18:13:57,052 INFO org.apache.hadoop.yarn.server.resourcemanager.scheduler.capacity.CapacitySchedulerConfiguration: max alloc vcore per queue for root is undefined
2019-02-08 18:13:57,060 INFO org.apache.hadoop.yarn.server.resourcemanager.scheduler.capacity.ParentQueue: root, capacity=1.0, asboluteCapacity=1.0, maxCapacity=1.0, asboluteMaxCapacity=1.0, state=RUNNING, acls=ADMINISTER_QUEUE:*SUBMIT_APP:*, labels=*,
, reservationsContinueLooking=true
2019-02-08 18:13:57,061 INFO org.apache.hadoop.yarn.server.resourcemanager.scheduler.capacity.ParentQueue: Initialized parent-queue root name=root, fullname=root
2019-02-08 18:13:57,082 INFO org.apache.hadoop.yarn.server.resourcemanager.scheduler.capacity.CapacitySchedulerConfiguration: max alloc mb per queue for root.default is undefined
2019-02-08 18:13:57,083 INFO org.apache.hadoop.yarn.server.resourcemanager.scheduler.capacity.CapacitySchedulerConfiguration: max alloc vcore per queue for root.default is undefined
2019-02-08 18:13:57,086 INFO org.apache.hadoop.yarn.server.resourcemanager.scheduler.capacity.LeafQueue: Initializing default
capacity = 1.0 [= (float) configuredCapacity / 100 ]
asboluteCapacity = 1.0 [= parentAbsoluteCapacity * capacity ]
maxCapacity = 1.0 [= configuredMaxCapacity ]
absoluteMaxCapacity = 1.0 [= 1.0 maximumCapacity undefined, (parentAbsoluteMaxCapacity * maximumCapacity) / 100 otherwise ]
userLimit = 100 [= configuredUserLimit ]
userLimitFactor = 1.0 [= configuredUserLimitFactor ]
maxApplications = 10000 [= configuredMaximumSystemApplicationsPerQueue or (int)(configuredMaximumSystemApplications * absoluteCapacity)]
maxApplicationsPerUser = 10000 [= (int)(maxApplications * (userLimit / 100.0f) * userLimitFactor) ]
usedCapacity = 0.0 [= usedResourcesMemory / (clusterResourceMemory * absoluteCapacity)]
absoluteUsedCapacity = 0.0 [= usedResourcesMemory / clusterResourceMemory]
maxAMResourcePerQueuePercent = 0.1 [= configuredMaximumAMResourcePercent ]
minimumAllocationFactor = 0.875 [= (float)(maximumAllocationMemory - minimumAllocationMemory) / maximumAllocationMemory ]
maximumAllocation = <memory:8192, vCores:32> [= configuredMaxAllocation ]
numContainers = 0 [= currentNumContainers ]
state = RUNNING [= configuredState ]
acls = ADMINISTER_QUEUE:*SUBMIT_APP:* [= configuredAcls ]
nodeLocalityDelay = 40
labels=*,
nodeLocalityDelay = 40
reservationsContinueLooking = true
preemptionDisabled = true

2019-02-08 18:13:57,086 INFO org.apache.hadoop.yarn.server.resourcemanager.scheduler.capacity.CapacityScheduler: Initialized queue: default: capacity=1.0, absoluteCapacity=1.0, usedResources=<memory:0, vCores:0>, usedCapacity=0.0, absoluteUsedCapacity=0.0, numApps=0, numContainers=0
2019-02-08 18:13:57,087 INFO org.apache.hadoop.yarn.server.resourcemanager.scheduler.capacity.CapacityScheduler: Initialized queue: root: numChildQueue= 1, capacity=1.0, absoluteCapacity=1.0, usedResources=<memory:0, vCores:0>usedCapacity=0.0, numApps=0, numContainers=0
2019-02-08 18:13:57,088 INFO org.apache.hadoop.yarn.server.resourcemanager.scheduler.capacity.CapacityScheduler: Initialized root queue root: numChildQueue= 1, capacity=1.0, absoluteCapacity=1.0, usedResources=<memory:0, vCores:0>usedCapacity=0.0, numApps=0, numContainers=0
2019-02-08 18:13:57,089 INFO org.apache.hadoop.yarn.server.resourcemanager.scheduler.capacity.CapacityScheduler: Initialized queue mappings, override: false
2019-02-08 18:13:57,090 INFO org.apache.hadoop.yarn.server.resourcemanager.scheduler.capacity.CapacityScheduler: Initialized CapacityScheduler with calculator=class org.apache.hadoop.yarn.util.resource.DefaultResourceCalculator, minimumAllocation=<<memory:1024, vCores:1>>, maximumAllocation=<<memory:8192, vCores:32>>, asynchronousScheduling=false, asyncScheduleInterval=5ms
2019-02-08 18:13:57,141 INFO org.apache.hadoop.yarn.server.resourcemanager.metrics.SystemMetricsPublisher: YARN system metrics publishing service is not enabled
2019-02-08 18:13:57,141 INFO org.apache.hadoop.yarn.server.resourcemanager.ResourceManager: Transitioning to active state
2019-02-08 18:13:57,176 INFO org.apache.hadoop.yarn.server.resourcemanager.recovery.RMStateStore: Updating AMRMToken
2019-02-08 18:13:57,176 INFO org.apache.hadoop.yarn.server.resourcemanager.security.RMContainerTokenSecretManager: Rolling master-key for container-tokens
2019-02-08 18:13:57,177 INFO org.apache.hadoop.yarn.server.resourcemanager.security.NMTokenSecretManagerInRM: Rolling master-key for nm-tokens
2019-02-08 18:13:57,177 INFO org.apache.hadoop.security.token.delegation.AbstractDelegationTokenSecretManager: Updating the current master key for generating delegation tokens
2019-02-08 18:13:57,178 INFO org.apache.hadoop.yarn.server.resourcemanager.security.RMDelegationTokenSecretManager: storing master key with keyID 1
2019-02-08 18:13:57,179 INFO org.apache.hadoop.yarn.server.resourcemanager.recovery.RMStateStore: Storing RMDTMasterKey.
2019-02-08 18:13:57,181 INFO org.apache.hadoop.security.token.delegation.AbstractDelegationTokenSecretManager: Starting expired delegation token remover thread, tokenRemoverScanInterval=60 min(s)
2019-02-08 18:13:57,182 INFO org.apache.hadoop.security.token.delegation.AbstractDelegationTokenSecretManager: Updating the current master key for generating delegation tokens
2019-02-08 18:13:57,182 INFO org.apache.hadoop.yarn.server.resourcemanager.security.RMDelegationTokenSecretManager: storing master key with keyID 2
2019-02-08 18:13:57,182 INFO org.apache.hadoop.yarn.server.resourcemanager.recovery.RMStateStore: Storing RMDTMasterKey.
2019-02-08 18:13:57,185 INFO org.apache.hadoop.yarn.event.AsyncDispatcher: Registering class org.apache.hadoop.yarn.nodelabels.event.NodeLabelsStoreEventType for class org.apache.hadoop.yarn.nodelabels.CommonNodeLabelsManager$ForwardingEventHandler
2019-02-08 18:13:57,255 INFO org.apache.hadoop.ipc.CallQueueManager: Using callQueue class java.util.concurrent.LinkedBlockingQueue
2019-02-08 18:13:57,275 INFO org.apache.hadoop.ipc.Server: Starting Socket Reader #1 for port 8031
2019-02-08 18:13:57,314 INFO org.apache.hadoop.yarn.factories.impl.pb.RpcServerFactoryPBImpl: Adding protocol org.apache.hadoop.yarn.server.api.ResourceTrackerPB to the server
2019-02-08 18:13:57,314 INFO org.apache.hadoop.ipc.Server: IPC Server Responder: starting
2019-02-08 18:13:57,331 INFO org.apache.hadoop.ipc.Server: IPC Server listener on 8031: starting
2019-02-08 18:13:57,574 INFO org.apache.hadoop.ipc.CallQueueManager: Using callQueue class java.util.concurrent.LinkedBlockingQueue
2019-02-08 18:13:57,586 INFO org.apache.hadoop.ipc.Server: Starting Socket Reader #1 for port 8030
2019-02-08 18:13:57,619 INFO org.apache.hadoop.yarn.factories.impl.pb.RpcServerFactoryPBImpl: Adding protocol org.apache.hadoop.yarn.api.ApplicationMasterProtocolPB to the server
2019-02-08 18:13:57,623 INFO org.apache.hadoop.ipc.Server: IPC Server Responder: starting
2019-02-08 18:13:57,624 INFO org.apache.hadoop.ipc.Server: IPC Server listener on 8030: starting
2019-02-08 18:13:57,831 INFO org.apache.hadoop.ipc.CallQueueManager: Using callQueue class java.util.concurrent.LinkedBlockingQueue
2019-02-08 18:13:57,832 INFO org.apache.hadoop.ipc.Server: Starting Socket Reader #1 for port 8032
2019-02-08 18:13:57,839 INFO org.apache.hadoop.yarn.factories.impl.pb.RpcServerFactoryPBImpl: Adding protocol org.apache.hadoop.yarn.api.ApplicationClientProtocolPB to the server
2019-02-08 18:13:57,857 INFO org.apache.hadoop.ipc.Server: IPC Server Responder: starting
2019-02-08 18:13:57,858 INFO org.apache.hadoop.ipc.Server: IPC Server listener on 8032: starting
2019-02-08 18:13:57,925 INFO org.apache.hadoop.yarn.server.resourcemanager.ResourceManager: Transitioned to active state
2019-02-08 18:13:58,277 INFO org.mortbay.log: Logging to org.slf4j.impl.Log4jLoggerAdapter(org.mortbay.log) via org.mortbay.log.Slf4jLog
2019-02-08 18:13:58,297 INFO org.apache.hadoop.security.authentication.server.AuthenticationFilter: Unable to initialize FileSignerSecretProvider, falling back to use random secrets.
2019-02-08 18:13:58,308 INFO org.apache.hadoop.http.HttpRequestLog: Http request log for http.requests.resourcemanager is not defined
2019-02-08 18:13:58,330 INFO org.apache.hadoop.http.HttpServer2: Added global filter 'safety' (class=org.apache.hadoop.http.HttpServer2$QuotingInputFilter)
2019-02-08 18:13:58,368 INFO org.apache.hadoop.http.HttpServer2: Added filter RMAuthenticationFilter (class=org.apache.hadoop.yarn.server.security.http.RMAuthenticationFilter) to context cluster
2019-02-08 18:13:58,368 INFO org.apache.hadoop.http.HttpServer2: Added filter RMAuthenticationFilter (class=org.apache.hadoop.yarn.server.security.http.RMAuthenticationFilter) to context logs
2019-02-08 18:13:58,368 INFO org.apache.hadoop.http.HttpServer2: Added filter RMAuthenticationFilter (class=org.apache.hadoop.yarn.server.security.http.RMAuthenticationFilter) to context static
2019-02-08 18:13:58,369 INFO org.apache.hadoop.http.HttpServer2: Added filter static_user_filter (class=org.apache.hadoop.http.lib.StaticUserWebFilter$StaticUserFilter) to context cluster
2019-02-08 18:13:58,370 INFO org.apache.hadoop.http.HttpServer2: Added filter static_user_filter (class=org.apache.hadoop.http.lib.StaticUserWebFilter$StaticUserFilter) to context logs
2019-02-08 18:13:58,371 INFO org.apache.hadoop.http.HttpServer2: Added filter static_user_filter (class=org.apache.hadoop.http.lib.StaticUserWebFilter$StaticUserFilter) to context static
2019-02-08 18:13:58,376 INFO org.apache.hadoop.http.HttpServer2: adding path spec: /cluster/*
2019-02-08 18:13:58,377 INFO org.apache.hadoop.http.HttpServer2: adding path spec: /ws/*
2019-02-08 18:13:59,675 INFO org.apache.hadoop.yarn.webapp.WebApps: Registered webapp guice modules
2019-02-08 18:13:59,680 INFO org.apache.hadoop.http.HttpServer2: Jetty bound to port 8088
2019-02-08 18:13:59,680 INFO org.mortbay.log: jetty-6.1.26
2019-02-08 18:13:59,982 INFO org.mortbay.log: Extract jar:file:/opt/hadoop/hadoop-2.7.3/share/hadoop/yarn/hadoop-yarn-common-2.7.3.jar!/webapps/cluster to /tmp/Jetty_0_0_0_0_8088_cluster____u0rgz3/webapp
2019-02-08 18:14:01,093 INFO org.apache.hadoop.security.token.delegation.AbstractDelegationTokenSecretManager: Updating the current master key for generating delegation tokens
2019-02-08 18:14:01,099 INFO org.apache.hadoop.security.token.delegation.AbstractDelegationTokenSecretManager: Starting expired delegation token remover thread, tokenRemoverScanInterval=60 min(s)
2019-02-08 18:14:01,100 INFO org.apache.hadoop.security.token.delegation.AbstractDelegationTokenSecretManager: Updating the current master key for generating delegation tokens
2019-02-08 18:14:05,737 INFO org.mortbay.log: Started HttpServer2$SelectChannelConnectorWithSafeStartup@0.0.0.0:8088
2019-02-08 18:14:05,738 INFO org.apache.hadoop.yarn.webapp.WebApps: Web app cluster started at 8088
2019-02-08 18:14:05,962 INFO org.apache.hadoop.ipc.CallQueueManager: Using callQueue class java.util.concurrent.LinkedBlockingQueue
2019-02-08 18:14:05,975 INFO org.apache.hadoop.ipc.Server: Starting Socket Reader #1 for port 8033
2019-02-08 18:14:05,989 INFO org.apache.hadoop.yarn.factories.impl.pb.RpcServerFactoryPBImpl: Adding protocol org.apache.hadoop.yarn.server.api.ResourceManagerAdministrationProtocolPB to the server
2019-02-08 18:14:05,990 INFO org.apache.hadoop.ipc.Server: IPC Server Responder: starting
2019-02-08 18:14:05,991 INFO org.apache.hadoop.ipc.Server: IPC Server listener on 8033: starting
2019-02-08 18:14:07,751 INFO org.apache.hadoop.yarn.util.RackResolver: Resolved ubuntu-HP-Pavilion-dv6-NoteBook-PC to /default-rack
2019-02-08 18:14:07,761 INFO org.apache.hadoop.yarn.server.resourcemanager.rmnode.RMNodeImpl: ubuntu-HP-Pavilion-dv6-NoteBook-PC:34935 Node Transitioned from NEW to RUNNING
2019-02-08 18:14:07,767 INFO org.apache.hadoop.yarn.server.resourcemanager.scheduler.capacity.CapacityScheduler: Added node ubuntu-HP-Pavilion-dv6-NoteBook-PC:34935 clusterResource: <memory:8192, vCores:8>
2019-02-08 18:14:07,770 INFO org.apache.hadoop.yarn.server.resourcemanager.ResourceTrackerService: NodeManager from node ubuntu-HP-Pavilion-dv6-NoteBook-PC(cmPort: 34935 httpPort: 8042) registered with capability: <memory:8192, vCores:8>, assigned nodeId ubuntu-HP-Pavilion-dv6-NoteBook-PC:34935
2019-02-08 18:23:56,878 INFO org.apache.hadoop.yarn.server.resourcemanager.scheduler.AbstractYarnScheduler: Release request cache is cleaned up
2019-02-08 18:36:28,468 INFO org.apache.hadoop.yarn.server.resourcemanager.ClientRMService: Allocated new applicationId: 1
2019-02-08 18:36:30,941 INFO org.apache.hadoop.yarn.server.resourcemanager.rmapp.RMAppImpl: Storing application with id application_1549629837143_0001
2019-02-08 18:36:30,949 INFO org.apache.hadoop.yarn.server.resourcemanager.ClientRMService: Application with id 1 submitted by user root
2019-02-08 18:36:30,954 INFO org.apache.hadoop.yarn.server.resourcemanager.RMAuditLogger: USER=root	IP=127.0.0.1	OPERATION=Submit Application Request	TARGET=ClientRMService	RESULT=SUCCESS	APPID=application_1549629837143_0001
2019-02-08 18:36:30,985 INFO org.apache.hadoop.yarn.server.resourcemanager.rmapp.RMAppImpl: application_1549629837143_0001 State change from NEW to NEW_SAVING
2019-02-08 18:36:30,987 INFO org.apache.hadoop.yarn.server.resourcemanager.recovery.RMStateStore: Storing info for app: application_1549629837143_0001
2019-02-08 18:36:31,005 INFO org.apache.hadoop.yarn.server.resourcemanager.rmapp.RMAppImpl: application_1549629837143_0001 State change from NEW_SAVING to SUBMITTED
2019-02-08 18:36:31,018 INFO org.apache.hadoop.yarn.server.resourcemanager.scheduler.capacity.ParentQueue: Application added - appId: application_1549629837143_0001 user: root leaf-queue of parent: root #applications: 1
2019-02-08 18:36:31,021 INFO org.apache.hadoop.yarn.server.resourcemanager.scheduler.capacity.CapacityScheduler: Accepted application application_1549629837143_0001 from user: root, in queue: default
2019-02-08 18:36:31,114 INFO org.apache.hadoop.yarn.server.resourcemanager.rmapp.RMAppImpl: application_1549629837143_0001 State change from SUBMITTED to ACCEPTED
2019-02-08 18:36:31,473 INFO org.apache.hadoop.yarn.server.resourcemanager.ApplicationMasterService: Registering app attempt : appattempt_1549629837143_0001_000001
2019-02-08 18:36:31,479 INFO org.apache.hadoop.yarn.server.resourcemanager.rmapp.attempt.RMAppAttemptImpl: appattempt_1549629837143_0001_000001 State change from NEW to SUBMITTED
2019-02-08 18:36:31,523 WARN org.apache.hadoop.yarn.server.resourcemanager.scheduler.capacity.LeafQueue: maximum-am-resource-percent is insufficient to start a single application in queue, it is likely set too low. skipping enforcement to allow at least one application to start
2019-02-08 18:36:31,523 WARN org.apache.hadoop.yarn.server.resourcemanager.scheduler.capacity.LeafQueue: maximum-am-resource-percent is insufficient to start a single application in queue for user, it is likely set too low. skipping enforcement to allow at least one application to start
2019-02-08 18:36:31,523 INFO org.apache.hadoop.yarn.server.resourcemanager.scheduler.capacity.LeafQueue: Application application_1549629837143_0001 from user: root activated in queue: default
2019-02-08 18:36:31,524 INFO org.apache.hadoop.yarn.server.resourcemanager.scheduler.capacity.LeafQueue: Application added - appId: application_1549629837143_0001 user: org.apache.hadoop.yarn.server.resourcemanager.scheduler.capacity.LeafQueue$User@1c20cd4e, leaf-queue: default #user-pending-applications: 0 #user-active-applications: 1 #queue-pending-applications: 0 #queue-active-applications: 1
2019-02-08 18:36:31,524 INFO org.apache.hadoop.yarn.server.resourcemanager.scheduler.capacity.CapacityScheduler: Added Application Attempt appattempt_1549629837143_0001_000001 to scheduler from user root in queue default
2019-02-08 18:36:31,567 INFO org.apache.hadoop.yarn.server.resourcemanager.rmapp.attempt.RMAppAttemptImpl: appattempt_1549629837143_0001_000001 State change from SUBMITTED to SCHEDULED
2019-02-08 18:36:31,783 INFO org.apache.hadoop.yarn.server.resourcemanager.rmcontainer.RMContainerImpl: container_1549629837143_0001_01_000001 Container Transitioned from NEW to ALLOCATED
2019-02-08 18:36:31,784 INFO org.apache.hadoop.yarn.server.resourcemanager.RMAuditLogger: USER=root	OPERATION=AM Allocated Container	TARGET=SchedulerApp	RESULT=SUCCESS	APPID=application_1549629837143_0001	CONTAINERID=container_1549629837143_0001_01_000001
2019-02-08 18:36:31,786 INFO org.apache.hadoop.yarn.server.resourcemanager.scheduler.SchedulerNode: Assigned container container_1549629837143_0001_01_000001 of capacity <memory:2048, vCores:1> on host ubuntu-HP-Pavilion-dv6-NoteBook-PC:34935, which has 1 containers, <memory:2048, vCores:1> used and <memory:6144, vCores:7> available after allocation
2019-02-08 18:36:31,786 INFO org.apache.hadoop.yarn.server.resourcemanager.scheduler.capacity.LeafQueue: assignedContainer application attempt=appattempt_1549629837143_0001_000001 container=Container: [ContainerId: container_1549629837143_0001_01_000001, NodeId: ubuntu-HP-Pavilion-dv6-NoteBook-PC:34935, NodeHttpAddress: ubuntu-HP-Pavilion-dv6-NoteBook-PC:8042, Resource: <memory:2048, vCores:1>, Priority: 0, Token: null, ] queue=default: capacity=1.0, absoluteCapacity=1.0, usedResources=<memory:0, vCores:0>, usedCapacity=0.0, absoluteUsedCapacity=0.0, numApps=1, numContainers=0 clusterResource=<memory:8192, vCores:8> type=OFF_SWITCH
2019-02-08 18:36:31,805 INFO org.apache.hadoop.yarn.server.resourcemanager.scheduler.capacity.ParentQueue: Re-sorting assigned queue: root.default stats: default: capacity=1.0, absoluteCapacity=1.0, usedResources=<memory:2048, vCores:1>, usedCapacity=0.25, absoluteUsedCapacity=0.25, numApps=1, numContainers=1
2019-02-08 18:36:31,809 INFO org.apache.hadoop.yarn.server.resourcemanager.scheduler.capacity.ParentQueue: assignedContainer queue=root usedCapacity=0.25 absoluteUsedCapacity=0.25 used=<memory:2048, vCores:1> cluster=<memory:8192, vCores:8>
2019-02-08 18:36:31,936 INFO org.apache.hadoop.yarn.server.resourcemanager.security.NMTokenSecretManagerInRM: Sending NMToken for nodeId : ubuntu-HP-Pavilion-dv6-NoteBook-PC:34935 for container : container_1549629837143_0001_01_000001
2019-02-08 18:36:31,970 INFO org.apache.hadoop.yarn.server.resourcemanager.rmcontainer.RMContainerImpl: container_1549629837143_0001_01_000001 Container Transitioned from ALLOCATED to ACQUIRED
2019-02-08 18:36:31,971 INFO org.apache.hadoop.yarn.server.resourcemanager.security.NMTokenSecretManagerInRM: Clear node set for appattempt_1549629837143_0001_000001
2019-02-08 18:36:31,980 INFO org.apache.hadoop.yarn.server.resourcemanager.rmapp.attempt.RMAppAttemptImpl: Storing attempt: AppId: application_1549629837143_0001 AttemptId: appattempt_1549629837143_0001_000001 MasterContainer: Container: [ContainerId: container_1549629837143_0001_01_000001, NodeId: ubuntu-HP-Pavilion-dv6-NoteBook-PC:34935, NodeHttpAddress: ubuntu-HP-Pavilion-dv6-NoteBook-PC:8042, Resource: <memory:2048, vCores:1>, Priority: 0, Token: Token { kind: ContainerToken, service: 127.0.1.1:34935 }, ]
2019-02-08 18:36:32,011 INFO org.apache.hadoop.yarn.server.resourcemanager.rmapp.attempt.RMAppAttemptImpl: appattempt_1549629837143_0001_000001 State change from SCHEDULED to ALLOCATED_SAVING
2019-02-08 18:36:32,014 INFO org.apache.hadoop.yarn.server.resourcemanager.rmapp.attempt.RMAppAttemptImpl: appattempt_1549629837143_0001_000001 State change from ALLOCATED_SAVING to ALLOCATED
2019-02-08 18:36:32,027 INFO org.apache.hadoop.yarn.server.resourcemanager.amlauncher.AMLauncher: Launching masterappattempt_1549629837143_0001_000001
2019-02-08 18:36:32,111 INFO org.apache.hadoop.yarn.server.resourcemanager.amlauncher.AMLauncher: Setting up container Container: [ContainerId: container_1549629837143_0001_01_000001, NodeId: ubuntu-HP-Pavilion-dv6-NoteBook-PC:34935, NodeHttpAddress: ubuntu-HP-Pavilion-dv6-NoteBook-PC:8042, Resource: <memory:2048, vCores:1>, Priority: 0, Token: Token { kind: ContainerToken, service: 127.0.1.1:34935 }, ] for AM appattempt_1549629837143_0001_000001
2019-02-08 18:36:32,111 INFO org.apache.hadoop.yarn.server.resourcemanager.amlauncher.AMLauncher: Command to launch container container_1549629837143_0001_01_000001 : $JAVA_HOME/bin/java -Djava.io.tmpdir=$PWD/tmp -Dlog4j.configuration=container-log4j.properties -Dyarn.app.container.log.dir=<LOG_DIR> -Dyarn.app.container.log.filesize=0 -Dhadoop.root.logger=INFO,CLA -Dhadoop.root.logfile=syslog  -Xmx1024m org.apache.hadoop.mapreduce.v2.app.MRAppMaster 1><LOG_DIR>/stdout 2><LOG_DIR>/stderr 
2019-02-08 18:36:32,115 INFO org.apache.hadoop.yarn.server.resourcemanager.security.AMRMTokenSecretManager: Create AMRMToken for ApplicationAttempt: appattempt_1549629837143_0001_000001
2019-02-08 18:36:32,121 INFO org.apache.hadoop.yarn.server.resourcemanager.security.AMRMTokenSecretManager: Creating password for appattempt_1549629837143_0001_000001
2019-02-08 18:36:33,574 INFO org.apache.hadoop.yarn.server.resourcemanager.amlauncher.AMLauncher: Done launching container Container: [ContainerId: container_1549629837143_0001_01_000001, NodeId: ubuntu-HP-Pavilion-dv6-NoteBook-PC:34935, NodeHttpAddress: ubuntu-HP-Pavilion-dv6-NoteBook-PC:8042, Resource: <memory:2048, vCores:1>, Priority: 0, Token: Token { kind: ContainerToken, service: 127.0.1.1:34935 }, ] for AM appattempt_1549629837143_0001_000001
2019-02-08 18:36:33,574 INFO org.apache.hadoop.yarn.server.resourcemanager.rmapp.attempt.RMAppAttemptImpl: appattempt_1549629837143_0001_000001 State change from ALLOCATED to LAUNCHED
2019-02-08 18:36:33,784 INFO org.apache.hadoop.yarn.server.resourcemanager.rmcontainer.RMContainerImpl: container_1549629837143_0001_01_000001 Container Transitioned from ACQUIRED to RUNNING
2019-02-08 18:36:51,139 INFO SecurityLogger.org.apache.hadoop.ipc.Server: Auth successful for appattempt_1549629837143_0001_000001 (auth:SIMPLE)
2019-02-08 18:36:51,172 INFO org.apache.hadoop.yarn.server.resourcemanager.ApplicationMasterService: AM registration appattempt_1549629837143_0001_000001
2019-02-08 18:36:51,174 INFO org.apache.hadoop.yarn.server.resourcemanager.rmapp.attempt.RMAppAttemptImpl: appattempt_1549629837143_0001_000001 State change from LAUNCHED to RUNNING
2019-02-08 18:36:51,175 INFO org.apache.hadoop.yarn.server.resourcemanager.rmapp.RMAppImpl: application_1549629837143_0001 State change from ACCEPTED to RUNNING
2019-02-08 18:36:51,195 INFO org.apache.hadoop.yarn.server.resourcemanager.RMAuditLogger: USER=root	IP=127.0.0.1	OPERATION=Register App Master	TARGET=ApplicationMasterService	RESULT=SUCCESS	APPID=application_1549629837143_0001	APPATTEMPTID=appattempt_1549629837143_0001_000001
2019-02-08 18:36:52,990 INFO org.apache.hadoop.yarn.server.resourcemanager.rmcontainer.RMContainerImpl: container_1549629837143_0001_01_000002 Container Transitioned from NEW to ALLOCATED
2019-02-08 18:36:52,990 INFO org.apache.hadoop.yarn.server.resourcemanager.RMAuditLogger: USER=root	OPERATION=AM Allocated Container	TARGET=SchedulerApp	RESULT=SUCCESS	APPID=application_1549629837143_0001	CONTAINERID=container_1549629837143_0001_01_000002
2019-02-08 18:36:52,991 INFO org.apache.hadoop.yarn.server.resourcemanager.scheduler.SchedulerNode: Assigned container container_1549629837143_0001_01_000002 of capacity <memory:1024, vCores:1> on host ubuntu-HP-Pavilion-dv6-NoteBook-PC:34935, which has 2 containers, <memory:3072, vCores:2> used and <memory:5120, vCores:6> available after allocation
2019-02-08 18:36:52,991 INFO org.apache.hadoop.yarn.server.resourcemanager.scheduler.capacity.LeafQueue: assignedContainer application attempt=appattempt_1549629837143_0001_000001 container=Container: [ContainerId: container_1549629837143_0001_01_000002, NodeId: ubuntu-HP-Pavilion-dv6-NoteBook-PC:34935, NodeHttpAddress: ubuntu-HP-Pavilion-dv6-NoteBook-PC:8042, Resource: <memory:1024, vCores:1>, Priority: 20, Token: null, ] queue=default: capacity=1.0, absoluteCapacity=1.0, usedResources=<memory:2048, vCores:1>, usedCapacity=0.25, absoluteUsedCapacity=0.25, numApps=1, numContainers=1 clusterResource=<memory:8192, vCores:8> type=NODE_LOCAL
2019-02-08 18:36:52,992 INFO org.apache.hadoop.yarn.server.resourcemanager.scheduler.capacity.ParentQueue: Re-sorting assigned queue: root.default stats: default: capacity=1.0, absoluteCapacity=1.0, usedResources=<memory:3072, vCores:2>, usedCapacity=0.375, absoluteUsedCapacity=0.375, numApps=1, numContainers=2
2019-02-08 18:36:52,992 INFO org.apache.hadoop.yarn.server.resourcemanager.scheduler.capacity.ParentQueue: assignedContainer queue=root usedCapacity=0.375 absoluteUsedCapacity=0.375 used=<memory:3072, vCores:2> cluster=<memory:8192, vCores:8>
2019-02-08 18:36:53,766 INFO org.apache.hadoop.yarn.server.resourcemanager.security.NMTokenSecretManagerInRM: Sending NMToken for nodeId : ubuntu-HP-Pavilion-dv6-NoteBook-PC:34935 for container : container_1549629837143_0001_01_000002
2019-02-08 18:36:53,770 INFO org.apache.hadoop.yarn.server.resourcemanager.rmcontainer.RMContainerImpl: container_1549629837143_0001_01_000002 Container Transitioned from ALLOCATED to ACQUIRED
2019-02-08 18:36:54,840 INFO org.apache.hadoop.yarn.server.resourcemanager.scheduler.AppSchedulingInfo: checking for deactivate of application :application_1549629837143_0001
2019-02-08 18:36:55,002 INFO org.apache.hadoop.yarn.server.resourcemanager.rmcontainer.RMContainerImpl: container_1549629837143_0001_01_000002 Container Transitioned from ACQUIRED to RUNNING
2019-02-08 18:37:10,176 INFO org.apache.hadoop.yarn.server.resourcemanager.rmcontainer.RMContainerImpl: container_1549629837143_0001_01_000002 Container Transitioned from RUNNING to COMPLETED
2019-02-08 18:37:10,176 INFO org.apache.hadoop.yarn.server.resourcemanager.scheduler.common.fica.FiCaSchedulerApp: Completed container: container_1549629837143_0001_01_000002 in state: COMPLETED event:FINISHED
2019-02-08 18:37:10,176 INFO org.apache.hadoop.yarn.server.resourcemanager.RMAuditLogger: USER=root	OPERATION=AM Released Container	TARGET=SchedulerApp	RESULT=SUCCESS	APPID=application_1549629837143_0001	CONTAINERID=container_1549629837143_0001_01_000002
2019-02-08 18:37:10,177 INFO org.apache.hadoop.yarn.server.resourcemanager.scheduler.SchedulerNode: Released container container_1549629837143_0001_01_000002 of capacity <memory:1024, vCores:1> on host ubuntu-HP-Pavilion-dv6-NoteBook-PC:34935, which currently has 1 containers, <memory:2048, vCores:1> used and <memory:6144, vCores:7> available, release resources=true
2019-02-08 18:37:10,177 INFO org.apache.hadoop.yarn.server.resourcemanager.scheduler.capacity.LeafQueue: default used=<memory:2048, vCores:1> numContainers=1 user=root user-resources=<memory:2048, vCores:1>
2019-02-08 18:37:10,179 INFO org.apache.hadoop.yarn.server.resourcemanager.scheduler.capacity.LeafQueue: completedContainer container=Container: [ContainerId: container_1549629837143_0001_01_000002, NodeId: ubuntu-HP-Pavilion-dv6-NoteBook-PC:34935, NodeHttpAddress: ubuntu-HP-Pavilion-dv6-NoteBook-PC:8042, Resource: <memory:1024, vCores:1>, Priority: 20, Token: Token { kind: ContainerToken, service: 127.0.1.1:34935 }, ] queue=default: capacity=1.0, absoluteCapacity=1.0, usedResources=<memory:2048, vCores:1>, usedCapacity=0.25, absoluteUsedCapacity=0.25, numApps=1, numContainers=1 cluster=<memory:8192, vCores:8>
2019-02-08 18:37:10,179 INFO org.apache.hadoop.yarn.server.resourcemanager.scheduler.capacity.ParentQueue: completedContainer queue=root usedCapacity=0.25 absoluteUsedCapacity=0.25 used=<memory:2048, vCores:1> cluster=<memory:8192, vCores:8>
2019-02-08 18:37:10,179 INFO org.apache.hadoop.yarn.server.resourcemanager.scheduler.capacity.ParentQueue: Re-sorting completed queue: root.default stats: default: capacity=1.0, absoluteCapacity=1.0, usedResources=<memory:2048, vCores:1>, usedCapacity=0.25, absoluteUsedCapacity=0.25, numApps=1, numContainers=1
2019-02-08 18:37:10,179 INFO org.apache.hadoop.yarn.server.resourcemanager.scheduler.capacity.CapacityScheduler: Application attempt appattempt_1549629837143_0001_000001 released container container_1549629837143_0001_01_000002 on node: host: ubuntu-HP-Pavilion-dv6-NoteBook-PC:34935 #containers=1 available=<memory:6144, vCores:7> used=<memory:2048, vCores:1> with event: FINISHED
2019-02-08 18:37:10,996 INFO org.apache.hadoop.yarn.server.resourcemanager.rmapp.attempt.RMAppAttemptImpl: Updating application attempt appattempt_1549629837143_0001_000001 with final state: FINISHING, and exit status: -1000
2019-02-08 18:37:10,999 INFO org.apache.hadoop.yarn.server.resourcemanager.rmapp.attempt.RMAppAttemptImpl: appattempt_1549629837143_0001_000001 State change from RUNNING to FINAL_SAVING
2019-02-08 18:37:10,999 INFO org.apache.hadoop.yarn.server.resourcemanager.rmapp.attempt.RMAppAttemptImpl: appattempt_1549629837143_0001_000001 State change from FINAL_SAVING to FINISHING
2019-02-08 18:37:10,999 INFO org.apache.hadoop.yarn.server.resourcemanager.rmapp.RMAppImpl: Updating application application_1549629837143_0001 with final state: FINISHING
2019-02-08 18:37:11,003 INFO org.apache.hadoop.yarn.server.resourcemanager.rmapp.RMAppImpl: application_1549629837143_0001 State change from RUNNING to FINAL_SAVING
2019-02-08 18:37:11,003 INFO org.apache.hadoop.yarn.server.resourcemanager.recovery.RMStateStore: Updating info for app: application_1549629837143_0001
2019-02-08 18:37:11,004 INFO org.apache.hadoop.yarn.server.resourcemanager.rmapp.RMAppImpl: application_1549629837143_0001 State change from FINAL_SAVING to FINISHING
2019-02-08 18:37:12,019 INFO org.apache.hadoop.yarn.server.resourcemanager.ApplicationMasterService: application_1549629837143_0001 unregistered successfully. 
2019-02-08 18:37:17,580 INFO org.apache.hadoop.yarn.server.resourcemanager.rmcontainer.RMContainerImpl: container_1549629837143_0001_01_000001 Container Transitioned from RUNNING to COMPLETED
2019-02-08 18:37:17,580 INFO org.apache.hadoop.yarn.server.resourcemanager.scheduler.common.fica.FiCaSchedulerApp: Completed container: container_1549629837143_0001_01_000001 in state: COMPLETED event:FINISHED
2019-02-08 18:37:17,580 INFO org.apache.hadoop.yarn.server.resourcemanager.ApplicationMasterService: Unregistering app attempt : appattempt_1549629837143_0001_000001
2019-02-08 18:37:17,580 INFO org.apache.hadoop.yarn.server.resourcemanager.RMAuditLogger: USER=root	OPERATION=AM Released Container	TARGET=SchedulerApp	RESULT=SUCCESS	APPID=application_1549629837143_0001	CONTAINERID=container_1549629837143_0001_01_000001
2019-02-08 18:37:17,581 INFO org.apache.hadoop.yarn.server.resourcemanager.scheduler.SchedulerNode: Released container container_1549629837143_0001_01_000001 of capacity <memory:2048, vCores:1> on host ubuntu-HP-Pavilion-dv6-NoteBook-PC:34935, which currently has 0 containers, <memory:0, vCores:0> used and <memory:8192, vCores:8> available, release resources=true
2019-02-08 18:37:17,581 INFO org.apache.hadoop.yarn.server.resourcemanager.scheduler.capacity.LeafQueue: default used=<memory:0, vCores:0> numContainers=0 user=root user-resources=<memory:0, vCores:0>
2019-02-08 18:37:17,581 INFO org.apache.hadoop.yarn.server.resourcemanager.scheduler.capacity.LeafQueue: completedContainer container=Container: [ContainerId: container_1549629837143_0001_01_000001, NodeId: ubuntu-HP-Pavilion-dv6-NoteBook-PC:34935, NodeHttpAddress: ubuntu-HP-Pavilion-dv6-NoteBook-PC:8042, Resource: <memory:2048, vCores:1>, Priority: 0, Token: Token { kind: ContainerToken, service: 127.0.1.1:34935 }, ] queue=default: capacity=1.0, absoluteCapacity=1.0, usedResources=<memory:0, vCores:0>, usedCapacity=0.0, absoluteUsedCapacity=0.0, numApps=1, numContainers=0 cluster=<memory:8192, vCores:8>
2019-02-08 18:37:17,581 INFO org.apache.hadoop.yarn.server.resourcemanager.scheduler.capacity.ParentQueue: completedContainer queue=root usedCapacity=0.0 absoluteUsedCapacity=0.0 used=<memory:0, vCores:0> cluster=<memory:8192, vCores:8>
2019-02-08 18:37:17,582 INFO org.apache.hadoop.yarn.server.resourcemanager.scheduler.capacity.ParentQueue: Re-sorting completed queue: root.default stats: default: capacity=1.0, absoluteCapacity=1.0, usedResources=<memory:0, vCores:0>, usedCapacity=0.0, absoluteUsedCapacity=0.0, numApps=1, numContainers=0
2019-02-08 18:37:17,582 INFO org.apache.hadoop.yarn.server.resourcemanager.scheduler.capacity.CapacityScheduler: Application attempt appattempt_1549629837143_0001_000001 released container container_1549629837143_0001_01_000001 on node: host: ubuntu-HP-Pavilion-dv6-NoteBook-PC:34935 #containers=0 available=<memory:8192, vCores:8> used=<memory:0, vCores:0> with event: FINISHED
2019-02-08 18:37:17,582 INFO org.apache.hadoop.yarn.server.resourcemanager.security.AMRMTokenSecretManager: Application finished, removing password for appattempt_1549629837143_0001_000001
2019-02-08 18:37:17,585 INFO org.apache.hadoop.yarn.server.resourcemanager.rmapp.attempt.RMAppAttemptImpl: appattempt_1549629837143_0001_000001 State change from FINISHING to FINISHED
2019-02-08 18:37:17,593 INFO org.apache.hadoop.yarn.server.resourcemanager.rmapp.RMAppImpl: application_1549629837143_0001 State change from FINISHING to FINISHED
2019-02-08 18:37:17,594 INFO org.apache.hadoop.yarn.server.resourcemanager.scheduler.capacity.CapacityScheduler: Application Attempt appattempt_1549629837143_0001_000001 is done. finalState=FINISHED
2019-02-08 18:37:17,596 INFO org.apache.hadoop.yarn.server.resourcemanager.RMAuditLogger: USER=root	OPERATION=Application Finished - Succeeded	TARGET=RMAppManager	RESULT=SUCCESS	APPID=application_1549629837143_0001
2019-02-08 18:37:17,594 INFO org.apache.hadoop.yarn.server.resourcemanager.scheduler.AppSchedulingInfo: Application application_1549629837143_0001 requests cleared
2019-02-08 18:37:17,607 INFO org.apache.hadoop.yarn.server.resourcemanager.scheduler.capacity.LeafQueue: Application removed - appId: application_1549629837143_0001 user: root queue: default #user-pending-applications: 0 #user-active-applications: 0 #queue-pending-applications: 0 #queue-active-applications: 0
2019-02-08 18:37:17,608 INFO org.apache.hadoop.yarn.server.resourcemanager.scheduler.capacity.ParentQueue: Application removed - appId: application_1549629837143_0001 user: root leaf-queue of parent: root #applications: 0
2019-02-08 18:37:17,604 INFO org.apache.hadoop.yarn.server.resourcemanager.amlauncher.AMLauncher: Cleaning master appattempt_1549629837143_0001_000001
2019-02-08 18:37:17,620 INFO org.apache.hadoop.yarn.server.resourcemanager.RMAppManager$ApplicationSummary: appId=application_1549629837143_0001,name=insert into vip_clients values\n    ...Inc.')(Stage-1),user=root,queue=default,state=FINISHED,trackingUrl=http://ubuntu-HP-Pavilion-dv6-NoteBook-PC:8088/proxy/application_1549629837143_0001/,appMasterHost=ubuntu-HP-Pavilion-dv6-NoteBook-PC,startTime=1549631190923,finishTime=1549631230999,finalStatus=SUCCEEDED,memorySeconds=111394,vcoreSeconds=62,preemptedAMContainers=0,preemptedNonAMContainers=0,preemptedResources=<memory:0\, vCores:0>,applicationType=MAPREDUCE
2019-02-08 18:40:40,847 INFO org.apache.hadoop.yarn.server.resourcemanager.ClientRMService: Allocated new applicationId: 2
2019-02-08 18:40:42,739 INFO org.apache.hadoop.yarn.server.resourcemanager.ClientRMService: Application with id 2 submitted by user root
2019-02-08 18:40:42,740 INFO org.apache.hadoop.yarn.server.resourcemanager.RMAuditLogger: USER=root	IP=127.0.0.1	OPERATION=Submit Application Request	TARGET=ClientRMService	RESULT=SUCCESS	APPID=application_1549629837143_0002
2019-02-08 18:40:42,739 INFO org.apache.hadoop.yarn.server.resourcemanager.rmapp.RMAppImpl: Storing application with id application_1549629837143_0002
2019-02-08 18:40:42,741 INFO org.apache.hadoop.yarn.server.resourcemanager.rmapp.RMAppImpl: application_1549629837143_0002 State change from NEW to NEW_SAVING
2019-02-08 18:40:42,741 INFO org.apache.hadoop.yarn.server.resourcemanager.recovery.RMStateStore: Storing info for app: application_1549629837143_0002
2019-02-08 18:40:42,741 INFO org.apache.hadoop.yarn.server.resourcemanager.rmapp.RMAppImpl: application_1549629837143_0002 State change from NEW_SAVING to SUBMITTED
2019-02-08 18:40:42,741 INFO org.apache.hadoop.yarn.server.resourcemanager.scheduler.capacity.ParentQueue: Application added - appId: application_1549629837143_0002 user: root leaf-queue of parent: root #applications: 1
2019-02-08 18:40:42,742 INFO org.apache.hadoop.yarn.server.resourcemanager.scheduler.capacity.CapacityScheduler: Accepted application application_1549629837143_0002 from user: root, in queue: default
2019-02-08 18:40:42,743 INFO org.apache.hadoop.yarn.server.resourcemanager.rmapp.RMAppImpl: application_1549629837143_0002 State change from SUBMITTED to ACCEPTED
2019-02-08 18:40:42,743 INFO org.apache.hadoop.yarn.server.resourcemanager.ApplicationMasterService: Registering app attempt : appattempt_1549629837143_0002_000001
2019-02-08 18:40:42,743 INFO org.apache.hadoop.yarn.server.resourcemanager.rmapp.attempt.RMAppAttemptImpl: appattempt_1549629837143_0002_000001 State change from NEW to SUBMITTED
2019-02-08 18:40:42,744 WARN org.apache.hadoop.yarn.server.resourcemanager.scheduler.capacity.LeafQueue: maximum-am-resource-percent is insufficient to start a single application in queue, it is likely set too low. skipping enforcement to allow at least one application to start
2019-02-08 18:40:42,744 WARN org.apache.hadoop.yarn.server.resourcemanager.scheduler.capacity.LeafQueue: maximum-am-resource-percent is insufficient to start a single application in queue for user, it is likely set too low. skipping enforcement to allow at least one application to start
2019-02-08 18:40:42,744 INFO org.apache.hadoop.yarn.server.resourcemanager.scheduler.capacity.LeafQueue: Application application_1549629837143_0002 from user: root activated in queue: default
2019-02-08 18:40:42,744 INFO org.apache.hadoop.yarn.server.resourcemanager.scheduler.capacity.LeafQueue: Application added - appId: application_1549629837143_0002 user: org.apache.hadoop.yarn.server.resourcemanager.scheduler.capacity.LeafQueue$User@7134a410, leaf-queue: default #user-pending-applications: 0 #user-active-applications: 1 #queue-pending-applications: 0 #queue-active-applications: 1
2019-02-08 18:40:42,745 INFO org.apache.hadoop.yarn.server.resourcemanager.scheduler.capacity.CapacityScheduler: Added Application Attempt appattempt_1549629837143_0002_000001 to scheduler from user root in queue default
2019-02-08 18:40:42,747 INFO org.apache.hadoop.yarn.server.resourcemanager.rmapp.attempt.RMAppAttemptImpl: appattempt_1549629837143_0002_000001 State change from SUBMITTED to SCHEDULED
2019-02-08 18:40:42,919 INFO org.apache.hadoop.yarn.server.resourcemanager.rmcontainer.RMContainerImpl: container_1549629837143_0002_01_000001 Container Transitioned from NEW to ALLOCATED
2019-02-08 18:40:42,919 INFO org.apache.hadoop.yarn.server.resourcemanager.RMAuditLogger: USER=root	OPERATION=AM Allocated Container	TARGET=SchedulerApp	RESULT=SUCCESS	APPID=application_1549629837143_0002	CONTAINERID=container_1549629837143_0002_01_000001
2019-02-08 18:40:42,919 INFO org.apache.hadoop.yarn.server.resourcemanager.scheduler.SchedulerNode: Assigned container container_1549629837143_0002_01_000001 of capacity <memory:2048, vCores:1> on host ubuntu-HP-Pavilion-dv6-NoteBook-PC:34935, which has 1 containers, <memory:2048, vCores:1> used and <memory:6144, vCores:7> available after allocation
2019-02-08 18:40:42,919 INFO org.apache.hadoop.yarn.server.resourcemanager.scheduler.capacity.LeafQueue: assignedContainer application attempt=appattempt_1549629837143_0002_000001 container=Container: [ContainerId: container_1549629837143_0002_01_000001, NodeId: ubuntu-HP-Pavilion-dv6-NoteBook-PC:34935, NodeHttpAddress: ubuntu-HP-Pavilion-dv6-NoteBook-PC:8042, Resource: <memory:2048, vCores:1>, Priority: 0, Token: null, ] queue=default: capacity=1.0, absoluteCapacity=1.0, usedResources=<memory:0, vCores:0>, usedCapacity=0.0, absoluteUsedCapacity=0.0, numApps=1, numContainers=0 clusterResource=<memory:8192, vCores:8> type=OFF_SWITCH
2019-02-08 18:40:42,920 INFO org.apache.hadoop.yarn.server.resourcemanager.scheduler.capacity.ParentQueue: Re-sorting assigned queue: root.default stats: default: capacity=1.0, absoluteCapacity=1.0, usedResources=<memory:2048, vCores:1>, usedCapacity=0.25, absoluteUsedCapacity=0.25, numApps=1, numContainers=1
2019-02-08 18:40:42,921 INFO org.apache.hadoop.yarn.server.resourcemanager.scheduler.capacity.ParentQueue: assignedContainer queue=root usedCapacity=0.25 absoluteUsedCapacity=0.25 used=<memory:2048, vCores:1> cluster=<memory:8192, vCores:8>
2019-02-08 18:40:42,922 INFO org.apache.hadoop.yarn.server.resourcemanager.security.NMTokenSecretManagerInRM: Sending NMToken for nodeId : ubuntu-HP-Pavilion-dv6-NoteBook-PC:34935 for container : container_1549629837143_0002_01_000001
2019-02-08 18:40:42,932 INFO org.apache.hadoop.yarn.server.resourcemanager.rmcontainer.RMContainerImpl: container_1549629837143_0002_01_000001 Container Transitioned from ALLOCATED to ACQUIRED
2019-02-08 18:40:42,933 INFO org.apache.hadoop.yarn.server.resourcemanager.security.NMTokenSecretManagerInRM: Clear node set for appattempt_1549629837143_0002_000001
2019-02-08 18:40:42,933 INFO org.apache.hadoop.yarn.server.resourcemanager.rmapp.attempt.RMAppAttemptImpl: Storing attempt: AppId: application_1549629837143_0002 AttemptId: appattempt_1549629837143_0002_000001 MasterContainer: Container: [ContainerId: container_1549629837143_0002_01_000001, NodeId: ubuntu-HP-Pavilion-dv6-NoteBook-PC:34935, NodeHttpAddress: ubuntu-HP-Pavilion-dv6-NoteBook-PC:8042, Resource: <memory:2048, vCores:1>, Priority: 0, Token: Token { kind: ContainerToken, service: 127.0.1.1:34935 }, ]
2019-02-08 18:40:42,933 INFO org.apache.hadoop.yarn.server.resourcemanager.rmapp.attempt.RMAppAttemptImpl: appattempt_1549629837143_0002_000001 State change from SCHEDULED to ALLOCATED_SAVING
2019-02-08 18:40:42,934 INFO org.apache.hadoop.yarn.server.resourcemanager.rmapp.attempt.RMAppAttemptImpl: appattempt_1549629837143_0002_000001 State change from ALLOCATED_SAVING to ALLOCATED
2019-02-08 18:40:42,935 INFO org.apache.hadoop.yarn.server.resourcemanager.amlauncher.AMLauncher: Launching masterappattempt_1549629837143_0002_000001
2019-02-08 18:40:42,955 INFO org.apache.hadoop.yarn.server.resourcemanager.amlauncher.AMLauncher: Setting up container Container: [ContainerId: container_1549629837143_0002_01_000001, NodeId: ubuntu-HP-Pavilion-dv6-NoteBook-PC:34935, NodeHttpAddress: ubuntu-HP-Pavilion-dv6-NoteBook-PC:8042, Resource: <memory:2048, vCores:1>, Priority: 0, Token: Token { kind: ContainerToken, service: 127.0.1.1:34935 }, ] for AM appattempt_1549629837143_0002_000001
2019-02-08 18:40:42,955 INFO org.apache.hadoop.yarn.server.resourcemanager.amlauncher.AMLauncher: Command to launch container container_1549629837143_0002_01_000001 : $JAVA_HOME/bin/java -Djava.io.tmpdir=$PWD/tmp -Dlog4j.configuration=container-log4j.properties -Dyarn.app.container.log.dir=<LOG_DIR> -Dyarn.app.container.log.filesize=0 -Dhadoop.root.logger=INFO,CLA -Dhadoop.root.logfile=syslog  -Xmx1024m org.apache.hadoop.mapreduce.v2.app.MRAppMaster 1><LOG_DIR>/stdout 2><LOG_DIR>/stderr 
2019-02-08 18:40:42,956 INFO org.apache.hadoop.yarn.server.resourcemanager.security.AMRMTokenSecretManager: Create AMRMToken for ApplicationAttempt: appattempt_1549629837143_0002_000001
2019-02-08 18:40:42,956 INFO org.apache.hadoop.yarn.server.resourcemanager.security.AMRMTokenSecretManager: Creating password for appattempt_1549629837143_0002_000001
2019-02-08 18:40:42,997 INFO org.apache.hadoop.yarn.server.resourcemanager.amlauncher.AMLauncher: Done launching container Container: [ContainerId: container_1549629837143_0002_01_000001, NodeId: ubuntu-HP-Pavilion-dv6-NoteBook-PC:34935, NodeHttpAddress: ubuntu-HP-Pavilion-dv6-NoteBook-PC:8042, Resource: <memory:2048, vCores:1>, Priority: 0, Token: Token { kind: ContainerToken, service: 127.0.1.1:34935 }, ] for AM appattempt_1549629837143_0002_000001
2019-02-08 18:40:42,998 INFO org.apache.hadoop.yarn.server.resourcemanager.rmapp.attempt.RMAppAttemptImpl: appattempt_1549629837143_0002_000001 State change from ALLOCATED to LAUNCHED
2019-02-08 18:40:43,924 INFO org.apache.hadoop.yarn.server.resourcemanager.rmcontainer.RMContainerImpl: container_1549629837143_0002_01_000001 Container Transitioned from ACQUIRED to RUNNING
2019-02-08 18:40:57,550 INFO SecurityLogger.org.apache.hadoop.ipc.Server: Auth successful for appattempt_1549629837143_0002_000001 (auth:SIMPLE)
2019-02-08 18:40:57,577 INFO org.apache.hadoop.yarn.server.resourcemanager.ApplicationMasterService: AM registration appattempt_1549629837143_0002_000001
2019-02-08 18:40:57,577 INFO org.apache.hadoop.yarn.server.resourcemanager.RMAuditLogger: USER=root	IP=127.0.0.1	OPERATION=Register App Master	TARGET=ApplicationMasterService	RESULT=SUCCESS	APPID=application_1549629837143_0002	APPATTEMPTID=appattempt_1549629837143_0002_000001
2019-02-08 18:40:57,578 INFO org.apache.hadoop.yarn.server.resourcemanager.rmapp.attempt.RMAppAttemptImpl: appattempt_1549629837143_0002_000001 State change from LAUNCHED to RUNNING
2019-02-08 18:40:57,578 INFO org.apache.hadoop.yarn.server.resourcemanager.rmapp.RMAppImpl: application_1549629837143_0002 State change from ACCEPTED to RUNNING
2019-02-08 18:40:59,014 INFO org.apache.hadoop.yarn.server.resourcemanager.rmcontainer.RMContainerImpl: container_1549629837143_0002_01_000002 Container Transitioned from NEW to ALLOCATED
2019-02-08 18:40:59,015 INFO org.apache.hadoop.yarn.server.resourcemanager.RMAuditLogger: USER=root	OPERATION=AM Allocated Container	TARGET=SchedulerApp	RESULT=SUCCESS	APPID=application_1549629837143_0002	CONTAINERID=container_1549629837143_0002_01_000002
2019-02-08 18:40:59,015 INFO org.apache.hadoop.yarn.server.resourcemanager.scheduler.SchedulerNode: Assigned container container_1549629837143_0002_01_000002 of capacity <memory:1024, vCores:1> on host ubuntu-HP-Pavilion-dv6-NoteBook-PC:34935, which has 2 containers, <memory:3072, vCores:2> used and <memory:5120, vCores:6> available after allocation
2019-02-08 18:40:59,015 INFO org.apache.hadoop.yarn.server.resourcemanager.scheduler.capacity.LeafQueue: assignedContainer application attempt=appattempt_1549629837143_0002_000001 container=Container: [ContainerId: container_1549629837143_0002_01_000002, NodeId: ubuntu-HP-Pavilion-dv6-NoteBook-PC:34935, NodeHttpAddress: ubuntu-HP-Pavilion-dv6-NoteBook-PC:8042, Resource: <memory:1024, vCores:1>, Priority: 20, Token: null, ] queue=default: capacity=1.0, absoluteCapacity=1.0, usedResources=<memory:2048, vCores:1>, usedCapacity=0.25, absoluteUsedCapacity=0.25, numApps=1, numContainers=1 clusterResource=<memory:8192, vCores:8> type=NODE_LOCAL
2019-02-08 18:40:59,016 INFO org.apache.hadoop.yarn.server.resourcemanager.scheduler.capacity.ParentQueue: Re-sorting assigned queue: root.default stats: default: capacity=1.0, absoluteCapacity=1.0, usedResources=<memory:3072, vCores:2>, usedCapacity=0.375, absoluteUsedCapacity=0.375, numApps=1, numContainers=2
2019-02-08 18:40:59,016 INFO org.apache.hadoop.yarn.server.resourcemanager.scheduler.capacity.ParentQueue: assignedContainer queue=root usedCapacity=0.375 absoluteUsedCapacity=0.375 used=<memory:3072, vCores:2> cluster=<memory:8192, vCores:8>
2019-02-08 18:40:59,909 INFO org.apache.hadoop.yarn.server.resourcemanager.security.NMTokenSecretManagerInRM: Sending NMToken for nodeId : ubuntu-HP-Pavilion-dv6-NoteBook-PC:34935 for container : container_1549629837143_0002_01_000002
2019-02-08 18:40:59,914 INFO org.apache.hadoop.yarn.server.resourcemanager.rmcontainer.RMContainerImpl: container_1549629837143_0002_01_000002 Container Transitioned from ALLOCATED to ACQUIRED
2019-02-08 18:41:00,992 INFO org.apache.hadoop.yarn.server.resourcemanager.scheduler.AppSchedulingInfo: checking for deactivate of application :application_1549629837143_0002
2019-02-08 18:41:01,023 INFO org.apache.hadoop.yarn.server.resourcemanager.rmcontainer.RMContainerImpl: container_1549629837143_0002_01_000002 Container Transitioned from ACQUIRED to RUNNING
2019-02-08 18:41:16,129 INFO org.apache.hadoop.yarn.server.resourcemanager.rmcontainer.RMContainerImpl: container_1549629837143_0002_01_000002 Container Transitioned from RUNNING to COMPLETED
2019-02-08 18:41:16,129 INFO org.apache.hadoop.yarn.server.resourcemanager.scheduler.common.fica.FiCaSchedulerApp: Completed container: container_1549629837143_0002_01_000002 in state: COMPLETED event:FINISHED
2019-02-08 18:41:16,129 INFO org.apache.hadoop.yarn.server.resourcemanager.RMAuditLogger: USER=root	OPERATION=AM Released Container	TARGET=SchedulerApp	RESULT=SUCCESS	APPID=application_1549629837143_0002	CONTAINERID=container_1549629837143_0002_01_000002
2019-02-08 18:41:16,129 INFO org.apache.hadoop.yarn.server.resourcemanager.scheduler.SchedulerNode: Released container container_1549629837143_0002_01_000002 of capacity <memory:1024, vCores:1> on host ubuntu-HP-Pavilion-dv6-NoteBook-PC:34935, which currently has 1 containers, <memory:2048, vCores:1> used and <memory:6144, vCores:7> available, release resources=true
2019-02-08 18:41:16,129 INFO org.apache.hadoop.yarn.server.resourcemanager.scheduler.capacity.LeafQueue: default used=<memory:2048, vCores:1> numContainers=1 user=root user-resources=<memory:2048, vCores:1>
2019-02-08 18:41:16,130 INFO org.apache.hadoop.yarn.server.resourcemanager.scheduler.capacity.LeafQueue: completedContainer container=Container: [ContainerId: container_1549629837143_0002_01_000002, NodeId: ubuntu-HP-Pavilion-dv6-NoteBook-PC:34935, NodeHttpAddress: ubuntu-HP-Pavilion-dv6-NoteBook-PC:8042, Resource: <memory:1024, vCores:1>, Priority: 20, Token: Token { kind: ContainerToken, service: 127.0.1.1:34935 }, ] queue=default: capacity=1.0, absoluteCapacity=1.0, usedResources=<memory:2048, vCores:1>, usedCapacity=0.25, absoluteUsedCapacity=0.25, numApps=1, numContainers=1 cluster=<memory:8192, vCores:8>
2019-02-08 18:41:16,131 INFO org.apache.hadoop.yarn.server.resourcemanager.scheduler.capacity.ParentQueue: completedContainer queue=root usedCapacity=0.25 absoluteUsedCapacity=0.25 used=<memory:2048, vCores:1> cluster=<memory:8192, vCores:8>
2019-02-08 18:41:16,131 INFO org.apache.hadoop.yarn.server.resourcemanager.scheduler.capacity.ParentQueue: Re-sorting completed queue: root.default stats: default: capacity=1.0, absoluteCapacity=1.0, usedResources=<memory:2048, vCores:1>, usedCapacity=0.25, absoluteUsedCapacity=0.25, numApps=1, numContainers=1
2019-02-08 18:41:16,132 INFO org.apache.hadoop.yarn.server.resourcemanager.scheduler.capacity.CapacityScheduler: Application attempt appattempt_1549629837143_0002_000001 released container container_1549629837143_0002_01_000002 on node: host: ubuntu-HP-Pavilion-dv6-NoteBook-PC:34935 #containers=1 available=<memory:6144, vCores:7> used=<memory:2048, vCores:1> with event: FINISHED
2019-02-08 18:41:18,133 INFO org.apache.hadoop.yarn.server.resourcemanager.rmcontainer.RMContainerImpl: container_1549629837143_0002_01_000003 Container Transitioned from NEW to ALLOCATED
2019-02-08 18:41:18,133 INFO org.apache.hadoop.yarn.server.resourcemanager.RMAuditLogger: USER=root	OPERATION=AM Allocated Container	TARGET=SchedulerApp	RESULT=SUCCESS	APPID=application_1549629837143_0002	CONTAINERID=container_1549629837143_0002_01_000003
2019-02-08 18:41:18,133 INFO org.apache.hadoop.yarn.server.resourcemanager.scheduler.SchedulerNode: Assigned container container_1549629837143_0002_01_000003 of capacity <memory:1024, vCores:1> on host ubuntu-HP-Pavilion-dv6-NoteBook-PC:34935, which has 2 containers, <memory:3072, vCores:2> used and <memory:5120, vCores:6> available after allocation
2019-02-08 18:41:18,133 INFO org.apache.hadoop.yarn.server.resourcemanager.scheduler.capacity.LeafQueue: assignedContainer application attempt=appattempt_1549629837143_0002_000001 container=Container: [ContainerId: container_1549629837143_0002_01_000003, NodeId: ubuntu-HP-Pavilion-dv6-NoteBook-PC:34935, NodeHttpAddress: ubuntu-HP-Pavilion-dv6-NoteBook-PC:8042, Resource: <memory:1024, vCores:1>, Priority: 10, Token: null, ] queue=default: capacity=1.0, absoluteCapacity=1.0, usedResources=<memory:2048, vCores:1>, usedCapacity=0.25, absoluteUsedCapacity=0.25, numApps=1, numContainers=1 clusterResource=<memory:8192, vCores:8> type=OFF_SWITCH
2019-02-08 18:41:18,134 INFO org.apache.hadoop.yarn.server.resourcemanager.scheduler.capacity.ParentQueue: Re-sorting assigned queue: root.default stats: default: capacity=1.0, absoluteCapacity=1.0, usedResources=<memory:3072, vCores:2>, usedCapacity=0.375, absoluteUsedCapacity=0.375, numApps=1, numContainers=2
2019-02-08 18:41:18,134 INFO org.apache.hadoop.yarn.server.resourcemanager.scheduler.capacity.ParentQueue: assignedContainer queue=root usedCapacity=0.375 absoluteUsedCapacity=0.375 used=<memory:3072, vCores:2> cluster=<memory:8192, vCores:8>
2019-02-08 18:41:18,192 INFO org.apache.hadoop.yarn.server.resourcemanager.rmcontainer.RMContainerImpl: container_1549629837143_0002_01_000003 Container Transitioned from ALLOCATED to ACQUIRED
2019-02-08 18:41:19,136 INFO org.apache.hadoop.yarn.server.resourcemanager.rmcontainer.RMContainerImpl: container_1549629837143_0002_01_000003 Container Transitioned from ACQUIRED to RUNNING
2019-02-08 18:41:19,198 INFO org.apache.hadoop.yarn.server.resourcemanager.scheduler.AppSchedulingInfo: checking for deactivate of application :application_1549629837143_0002
2019-02-08 18:41:34,801 INFO org.apache.hadoop.yarn.server.resourcemanager.rmcontainer.RMContainerImpl: container_1549629837143_0002_01_000003 Container Transitioned from RUNNING to COMPLETED
2019-02-08 18:41:34,801 INFO org.apache.hadoop.yarn.server.resourcemanager.scheduler.common.fica.FiCaSchedulerApp: Completed container: container_1549629837143_0002_01_000003 in state: COMPLETED event:FINISHED
2019-02-08 18:41:34,802 INFO org.apache.hadoop.yarn.server.resourcemanager.RMAuditLogger: USER=root	OPERATION=AM Released Container	TARGET=SchedulerApp	RESULT=SUCCESS	APPID=application_1549629837143_0002	CONTAINERID=container_1549629837143_0002_01_000003
2019-02-08 18:41:34,802 INFO org.apache.hadoop.yarn.server.resourcemanager.scheduler.SchedulerNode: Released container container_1549629837143_0002_01_000003 of capacity <memory:1024, vCores:1> on host ubuntu-HP-Pavilion-dv6-NoteBook-PC:34935, which currently has 1 containers, <memory:2048, vCores:1> used and <memory:6144, vCores:7> available, release resources=true
2019-02-08 18:41:34,802 INFO org.apache.hadoop.yarn.server.resourcemanager.scheduler.capacity.LeafQueue: default used=<memory:2048, vCores:1> numContainers=1 user=root user-resources=<memory:2048, vCores:1>
2019-02-08 18:41:34,803 INFO org.apache.hadoop.yarn.server.resourcemanager.scheduler.capacity.LeafQueue: completedContainer container=Container: [ContainerId: container_1549629837143_0002_01_000003, NodeId: ubuntu-HP-Pavilion-dv6-NoteBook-PC:34935, NodeHttpAddress: ubuntu-HP-Pavilion-dv6-NoteBook-PC:8042, Resource: <memory:1024, vCores:1>, Priority: 10, Token: Token { kind: ContainerToken, service: 127.0.1.1:34935 }, ] queue=default: capacity=1.0, absoluteCapacity=1.0, usedResources=<memory:2048, vCores:1>, usedCapacity=0.25, absoluteUsedCapacity=0.25, numApps=1, numContainers=1 cluster=<memory:8192, vCores:8>
2019-02-08 18:41:34,804 INFO org.apache.hadoop.yarn.server.resourcemanager.scheduler.capacity.ParentQueue: completedContainer queue=root usedCapacity=0.25 absoluteUsedCapacity=0.25 used=<memory:2048, vCores:1> cluster=<memory:8192, vCores:8>
2019-02-08 18:41:34,804 INFO org.apache.hadoop.yarn.server.resourcemanager.scheduler.capacity.ParentQueue: Re-sorting completed queue: root.default stats: default: capacity=1.0, absoluteCapacity=1.0, usedResources=<memory:2048, vCores:1>, usedCapacity=0.25, absoluteUsedCapacity=0.25, numApps=1, numContainers=1
2019-02-08 18:41:34,804 INFO org.apache.hadoop.yarn.server.resourcemanager.scheduler.capacity.CapacityScheduler: Application attempt appattempt_1549629837143_0002_000001 released container container_1549629837143_0002_01_000003 on node: host: ubuntu-HP-Pavilion-dv6-NoteBook-PC:34935 #containers=1 available=<memory:6144, vCores:7> used=<memory:2048, vCores:1> with event: FINISHED
2019-02-08 18:41:35,247 INFO org.apache.hadoop.yarn.server.resourcemanager.rmapp.attempt.RMAppAttemptImpl: Updating application attempt appattempt_1549629837143_0002_000001 with final state: FINISHING, and exit status: -1000
2019-02-08 18:41:35,248 INFO org.apache.hadoop.yarn.server.resourcemanager.rmapp.attempt.RMAppAttemptImpl: appattempt_1549629837143_0002_000001 State change from RUNNING to FINAL_SAVING
2019-02-08 18:41:35,249 INFO org.apache.hadoop.yarn.server.resourcemanager.rmapp.RMAppImpl: Updating application application_1549629837143_0002 with final state: FINISHING
2019-02-08 18:41:35,249 INFO org.apache.hadoop.yarn.server.resourcemanager.rmapp.RMAppImpl: application_1549629837143_0002 State change from RUNNING to FINAL_SAVING
2019-02-08 18:41:35,249 INFO org.apache.hadoop.yarn.server.resourcemanager.recovery.RMStateStore: Updating info for app: application_1549629837143_0002
2019-02-08 18:41:35,249 INFO org.apache.hadoop.yarn.server.resourcemanager.rmapp.attempt.RMAppAttemptImpl: appattempt_1549629837143_0002_000001 State change from FINAL_SAVING to FINISHING
2019-02-08 18:41:35,249 INFO org.apache.hadoop.yarn.server.resourcemanager.rmapp.RMAppImpl: application_1549629837143_0002 State change from FINAL_SAVING to FINISHING
2019-02-08 18:41:36,254 INFO org.apache.hadoop.yarn.server.resourcemanager.ApplicationMasterService: application_1549629837143_0002 unregistered successfully. 
2019-02-08 18:41:37,718 INFO org.apache.hadoop.yarn.server.resourcemanager.ClientRMService: Allocated new applicationId: 3
2019-02-08 18:41:38,628 INFO org.apache.hadoop.yarn.server.resourcemanager.ClientRMService: Application with id 3 submitted by user root
2019-02-08 18:41:38,629 INFO org.apache.hadoop.yarn.server.resourcemanager.RMAuditLogger: USER=root	IP=127.0.0.1	OPERATION=Submit Application Request	TARGET=ClientRMService	RESULT=SUCCESS	APPID=application_1549629837143_0003
2019-02-08 18:41:38,630 INFO org.apache.hadoop.yarn.server.resourcemanager.rmapp.RMAppImpl: Storing application with id application_1549629837143_0003
2019-02-08 18:41:38,631 INFO org.apache.hadoop.yarn.server.resourcemanager.recovery.RMStateStore: Storing info for app: application_1549629837143_0003
2019-02-08 18:41:38,631 INFO org.apache.hadoop.yarn.server.resourcemanager.rmapp.RMAppImpl: application_1549629837143_0003 State change from NEW to NEW_SAVING
2019-02-08 18:41:38,631 INFO org.apache.hadoop.yarn.server.resourcemanager.rmapp.RMAppImpl: application_1549629837143_0003 State change from NEW_SAVING to SUBMITTED
2019-02-08 18:41:38,631 INFO org.apache.hadoop.yarn.server.resourcemanager.scheduler.capacity.ParentQueue: Application added - appId: application_1549629837143_0003 user: root leaf-queue of parent: root #applications: 2
2019-02-08 18:41:38,631 INFO org.apache.hadoop.yarn.server.resourcemanager.scheduler.capacity.CapacityScheduler: Accepted application application_1549629837143_0003 from user: root, in queue: default
2019-02-08 18:41:38,634 INFO org.apache.hadoop.yarn.server.resourcemanager.rmapp.RMAppImpl: application_1549629837143_0003 State change from SUBMITTED to ACCEPTED
2019-02-08 18:41:38,634 INFO org.apache.hadoop.yarn.server.resourcemanager.ApplicationMasterService: Registering app attempt : appattempt_1549629837143_0003_000001
2019-02-08 18:41:38,635 INFO org.apache.hadoop.yarn.server.resourcemanager.rmapp.attempt.RMAppAttemptImpl: appattempt_1549629837143_0003_000001 State change from NEW to SUBMITTED
2019-02-08 18:41:38,635 INFO org.apache.hadoop.yarn.server.resourcemanager.scheduler.capacity.LeafQueue: not starting application as amIfStarted exceeds amLimit
2019-02-08 18:41:38,635 INFO org.apache.hadoop.yarn.server.resourcemanager.scheduler.capacity.LeafQueue: Application added - appId: application_1549629837143_0003 user: org.apache.hadoop.yarn.server.resourcemanager.scheduler.capacity.LeafQueue$User@7134a410, leaf-queue: default #user-pending-applications: 1 #user-active-applications: 1 #queue-pending-applications: 1 #queue-active-applications: 1
2019-02-08 18:41:38,635 INFO org.apache.hadoop.yarn.server.resourcemanager.scheduler.capacity.CapacityScheduler: Added Application Attempt appattempt_1549629837143_0003_000001 to scheduler from user root in queue default
2019-02-08 18:41:38,661 INFO org.apache.hadoop.yarn.server.resourcemanager.rmapp.attempt.RMAppAttemptImpl: appattempt_1549629837143_0003_000001 State change from SUBMITTED to SCHEDULED
2019-02-08 18:41:41,752 INFO org.apache.hadoop.yarn.server.resourcemanager.rmcontainer.RMContainerImpl: container_1549629837143_0002_01_000001 Container Transitioned from RUNNING to COMPLETED
2019-02-08 18:41:41,752 INFO org.apache.hadoop.yarn.server.resourcemanager.scheduler.common.fica.FiCaSchedulerApp: Completed container: container_1549629837143_0002_01_000001 in state: COMPLETED event:FINISHED
2019-02-08 18:41:41,752 INFO org.apache.hadoop.yarn.server.resourcemanager.RMAuditLogger: USER=root	OPERATION=AM Released Container	TARGET=SchedulerApp	RESULT=SUCCESS	APPID=application_1549629837143_0002	CONTAINERID=container_1549629837143_0002_01_000001
2019-02-08 18:41:41,752 INFO org.apache.hadoop.yarn.server.resourcemanager.scheduler.SchedulerNode: Released container container_1549629837143_0002_01_000001 of capacity <memory:2048, vCores:1> on host ubuntu-HP-Pavilion-dv6-NoteBook-PC:34935, which currently has 0 containers, <memory:0, vCores:0> used and <memory:8192, vCores:8> available, release resources=true
2019-02-08 18:41:41,753 INFO org.apache.hadoop.yarn.server.resourcemanager.scheduler.capacity.LeafQueue: default used=<memory:0, vCores:0> numContainers=0 user=root user-resources=<memory:0, vCores:0>
2019-02-08 18:41:41,753 INFO org.apache.hadoop.yarn.server.resourcemanager.scheduler.capacity.LeafQueue: completedContainer container=Container: [ContainerId: container_1549629837143_0002_01_000001, NodeId: ubuntu-HP-Pavilion-dv6-NoteBook-PC:34935, NodeHttpAddress: ubuntu-HP-Pavilion-dv6-NoteBook-PC:8042, Resource: <memory:2048, vCores:1>, Priority: 0, Token: Token { kind: ContainerToken, service: 127.0.1.1:34935 }, ] queue=default: capacity=1.0, absoluteCapacity=1.0, usedResources=<memory:0, vCores:0>, usedCapacity=0.0, absoluteUsedCapacity=0.0, numApps=2, numContainers=0 cluster=<memory:8192, vCores:8>
2019-02-08 18:41:41,753 INFO org.apache.hadoop.yarn.server.resourcemanager.scheduler.capacity.ParentQueue: completedContainer queue=root usedCapacity=0.0 absoluteUsedCapacity=0.0 used=<memory:0, vCores:0> cluster=<memory:8192, vCores:8>
2019-02-08 18:41:41,753 INFO org.apache.hadoop.yarn.server.resourcemanager.scheduler.capacity.ParentQueue: Re-sorting completed queue: root.default stats: default: capacity=1.0, absoluteCapacity=1.0, usedResources=<memory:0, vCores:0>, usedCapacity=0.0, absoluteUsedCapacity=0.0, numApps=2, numContainers=0
2019-02-08 18:41:41,754 INFO org.apache.hadoop.yarn.server.resourcemanager.scheduler.capacity.CapacityScheduler: Application attempt appattempt_1549629837143_0002_000001 released container container_1549629837143_0002_01_000001 on node: host: ubuntu-HP-Pavilion-dv6-NoteBook-PC:34935 #containers=0 available=<memory:8192, vCores:8> used=<memory:0, vCores:0> with event: FINISHED
2019-02-08 18:41:41,754 INFO org.apache.hadoop.yarn.server.resourcemanager.ApplicationMasterService: Unregistering app attempt : appattempt_1549629837143_0002_000001
2019-02-08 18:41:41,755 INFO org.apache.hadoop.yarn.server.resourcemanager.security.AMRMTokenSecretManager: Application finished, removing password for appattempt_1549629837143_0002_000001
2019-02-08 18:41:41,755 INFO org.apache.hadoop.yarn.server.resourcemanager.rmapp.attempt.RMAppAttemptImpl: appattempt_1549629837143_0002_000001 State change from FINISHING to FINISHED
2019-02-08 18:41:41,755 INFO org.apache.hadoop.yarn.server.resourcemanager.rmapp.RMAppImpl: application_1549629837143_0002 State change from FINISHING to FINISHED
2019-02-08 18:41:41,756 INFO org.apache.hadoop.yarn.server.resourcemanager.RMAuditLogger: USER=root	OPERATION=Application Finished - Succeeded	TARGET=RMAppManager	RESULT=SUCCESS	APPID=application_1549629837143_0002
2019-02-08 18:41:41,757 INFO org.apache.hadoop.yarn.server.resourcemanager.amlauncher.AMLauncher: Cleaning master appattempt_1549629837143_0002_000001
2019-02-08 18:41:41,757 INFO org.apache.hadoop.yarn.server.resourcemanager.RMAppManager$ApplicationSummary: appId=application_1549629837143_0002,name=select\n    ordermonthyear as OrderMon...desc(Stage-1),user=root,queue=default,state=FINISHED,trackingUrl=http://ubuntu-HP-Pavilion-dv6-NoteBook-PC:8088/proxy/application_1549629837143_0002/,appMasterHost=ubuntu-HP-Pavilion-dv6-NoteBook-PC,startTime=1549631442738,finishTime=1549631495249,finalStatus=SUCCEEDED,memorySeconds=155085,vcoreSeconds=91,preemptedAMContainers=0,preemptedNonAMContainers=0,preemptedResources=<memory:0\, vCores:0>,applicationType=MAPREDUCE
2019-02-08 18:41:41,757 INFO org.apache.hadoop.yarn.server.resourcemanager.scheduler.capacity.CapacityScheduler: Application Attempt appattempt_1549629837143_0002_000001 is done. finalState=FINISHED
2019-02-08 18:41:41,757 INFO org.apache.hadoop.yarn.server.resourcemanager.scheduler.AppSchedulingInfo: Application application_1549629837143_0002 requests cleared
2019-02-08 18:41:41,758 WARN org.apache.hadoop.yarn.server.resourcemanager.scheduler.capacity.LeafQueue: maximum-am-resource-percent is insufficient to start a single application in queue, it is likely set too low. skipping enforcement to allow at least one application to start
2019-02-08 18:41:41,758 WARN org.apache.hadoop.yarn.server.resourcemanager.scheduler.capacity.LeafQueue: maximum-am-resource-percent is insufficient to start a single application in queue for user, it is likely set too low. skipping enforcement to allow at least one application to start
2019-02-08 18:41:41,758 INFO org.apache.hadoop.yarn.server.resourcemanager.scheduler.capacity.LeafQueue: Application application_1549629837143_0003 from user: root activated in queue: default
2019-02-08 18:41:41,758 INFO org.apache.hadoop.yarn.server.resourcemanager.scheduler.capacity.LeafQueue: Application removed - appId: application_1549629837143_0002 user: root queue: default #user-pending-applications: 0 #user-active-applications: 1 #queue-pending-applications: 0 #queue-active-applications: 1
2019-02-08 18:41:41,758 INFO org.apache.hadoop.yarn.server.resourcemanager.scheduler.capacity.ParentQueue: Application removed - appId: application_1549629837143_0002 user: root leaf-queue of parent: root #applications: 1
2019-02-08 18:41:42,753 INFO org.apache.hadoop.yarn.server.resourcemanager.rmcontainer.RMContainerImpl: container_1549629837143_0003_01_000001 Container Transitioned from NEW to ALLOCATED
2019-02-08 18:41:42,753 INFO org.apache.hadoop.yarn.server.resourcemanager.RMAuditLogger: USER=root	OPERATION=AM Allocated Container	TARGET=SchedulerApp	RESULT=SUCCESS	APPID=application_1549629837143_0003	CONTAINERID=container_1549629837143_0003_01_000001
2019-02-08 18:41:42,753 INFO org.apache.hadoop.yarn.server.resourcemanager.scheduler.SchedulerNode: Assigned container container_1549629837143_0003_01_000001 of capacity <memory:2048, vCores:1> on host ubuntu-HP-Pavilion-dv6-NoteBook-PC:34935, which has 1 containers, <memory:2048, vCores:1> used and <memory:6144, vCores:7> available after allocation
2019-02-08 18:41:42,754 INFO org.apache.hadoop.yarn.server.resourcemanager.scheduler.capacity.LeafQueue: assignedContainer application attempt=appattempt_1549629837143_0003_000001 container=Container: [ContainerId: container_1549629837143_0003_01_000001, NodeId: ubuntu-HP-Pavilion-dv6-NoteBook-PC:34935, NodeHttpAddress: ubuntu-HP-Pavilion-dv6-NoteBook-PC:8042, Resource: <memory:2048, vCores:1>, Priority: 0, Token: null, ] queue=default: capacity=1.0, absoluteCapacity=1.0, usedResources=<memory:0, vCores:0>, usedCapacity=0.0, absoluteUsedCapacity=0.0, numApps=1, numContainers=0 clusterResource=<memory:8192, vCores:8> type=OFF_SWITCH
2019-02-08 18:41:42,754 INFO org.apache.hadoop.yarn.server.resourcemanager.scheduler.capacity.ParentQueue: Re-sorting assigned queue: root.default stats: default: capacity=1.0, absoluteCapacity=1.0, usedResources=<memory:2048, vCores:1>, usedCapacity=0.25, absoluteUsedCapacity=0.25, numApps=1, numContainers=1
2019-02-08 18:41:42,754 INFO org.apache.hadoop.yarn.server.resourcemanager.scheduler.capacity.ParentQueue: assignedContainer queue=root usedCapacity=0.25 absoluteUsedCapacity=0.25 used=<memory:2048, vCores:1> cluster=<memory:8192, vCores:8>
2019-02-08 18:41:42,757 INFO org.apache.hadoop.yarn.server.resourcemanager.security.NMTokenSecretManagerInRM: Sending NMToken for nodeId : ubuntu-HP-Pavilion-dv6-NoteBook-PC:34935 for container : container_1549629837143_0003_01_000001
2019-02-08 18:41:42,762 INFO org.apache.hadoop.yarn.server.resourcemanager.rmcontainer.RMContainerImpl: container_1549629837143_0003_01_000001 Container Transitioned from ALLOCATED to ACQUIRED
2019-02-08 18:41:42,762 INFO org.apache.hadoop.yarn.server.resourcemanager.security.NMTokenSecretManagerInRM: Clear node set for appattempt_1549629837143_0003_000001
2019-02-08 18:41:42,762 INFO org.apache.hadoop.yarn.server.resourcemanager.rmapp.attempt.RMAppAttemptImpl: Storing attempt: AppId: application_1549629837143_0003 AttemptId: appattempt_1549629837143_0003_000001 MasterContainer: Container: [ContainerId: container_1549629837143_0003_01_000001, NodeId: ubuntu-HP-Pavilion-dv6-NoteBook-PC:34935, NodeHttpAddress: ubuntu-HP-Pavilion-dv6-NoteBook-PC:8042, Resource: <memory:2048, vCores:1>, Priority: 0, Token: Token { kind: ContainerToken, service: 127.0.1.1:34935 }, ]
2019-02-08 18:41:42,763 INFO org.apache.hadoop.yarn.server.resourcemanager.rmapp.attempt.RMAppAttemptImpl: appattempt_1549629837143_0003_000001 State change from SCHEDULED to ALLOCATED_SAVING
2019-02-08 18:41:42,763 INFO org.apache.hadoop.yarn.server.resourcemanager.rmapp.attempt.RMAppAttemptImpl: appattempt_1549629837143_0003_000001 State change from ALLOCATED_SAVING to ALLOCATED
2019-02-08 18:41:42,766 INFO org.apache.hadoop.yarn.server.resourcemanager.amlauncher.AMLauncher: Launching masterappattempt_1549629837143_0003_000001
2019-02-08 18:41:42,771 INFO org.apache.hadoop.yarn.server.resourcemanager.amlauncher.AMLauncher: Setting up container Container: [ContainerId: container_1549629837143_0003_01_000001, NodeId: ubuntu-HP-Pavilion-dv6-NoteBook-PC:34935, NodeHttpAddress: ubuntu-HP-Pavilion-dv6-NoteBook-PC:8042, Resource: <memory:2048, vCores:1>, Priority: 0, Token: Token { kind: ContainerToken, service: 127.0.1.1:34935 }, ] for AM appattempt_1549629837143_0003_000001
2019-02-08 18:41:42,771 INFO org.apache.hadoop.yarn.server.resourcemanager.amlauncher.AMLauncher: Command to launch container container_1549629837143_0003_01_000001 : $JAVA_HOME/bin/java -Djava.io.tmpdir=$PWD/tmp -Dlog4j.configuration=container-log4j.properties -Dyarn.app.container.log.dir=<LOG_DIR> -Dyarn.app.container.log.filesize=0 -Dhadoop.root.logger=INFO,CLA -Dhadoop.root.logfile=syslog  -Xmx1024m org.apache.hadoop.mapreduce.v2.app.MRAppMaster 1><LOG_DIR>/stdout 2><LOG_DIR>/stderr 
2019-02-08 18:41:42,772 INFO org.apache.hadoop.yarn.server.resourcemanager.security.AMRMTokenSecretManager: Create AMRMToken for ApplicationAttempt: appattempt_1549629837143_0003_000001
2019-02-08 18:41:42,772 INFO org.apache.hadoop.yarn.server.resourcemanager.security.AMRMTokenSecretManager: Creating password for appattempt_1549629837143_0003_000001
2019-02-08 18:41:42,824 INFO org.apache.hadoop.yarn.server.resourcemanager.amlauncher.AMLauncher: Done launching container Container: [ContainerId: container_1549629837143_0003_01_000001, NodeId: ubuntu-HP-Pavilion-dv6-NoteBook-PC:34935, NodeHttpAddress: ubuntu-HP-Pavilion-dv6-NoteBook-PC:8042, Resource: <memory:2048, vCores:1>, Priority: 0, Token: Token { kind: ContainerToken, service: 127.0.1.1:34935 }, ] for AM appattempt_1549629837143_0003_000001
2019-02-08 18:41:42,827 INFO org.apache.hadoop.yarn.server.resourcemanager.rmapp.attempt.RMAppAttemptImpl: appattempt_1549629837143_0003_000001 State change from ALLOCATED to LAUNCHED
2019-02-08 18:41:43,757 INFO org.apache.hadoop.yarn.server.resourcemanager.rmcontainer.RMContainerImpl: container_1549629837143_0003_01_000001 Container Transitioned from ACQUIRED to RUNNING
2019-02-08 18:41:43,758 INFO org.apache.hadoop.yarn.server.resourcemanager.scheduler.capacity.CapacityScheduler: Null container completed...
2019-02-08 18:42:01,423 INFO SecurityLogger.org.apache.hadoop.ipc.Server: Auth successful for appattempt_1549629837143_0003_000001 (auth:SIMPLE)
2019-02-08 18:42:01,446 INFO org.apache.hadoop.yarn.server.resourcemanager.ApplicationMasterService: AM registration appattempt_1549629837143_0003_000001
2019-02-08 18:42:01,446 INFO org.apache.hadoop.yarn.server.resourcemanager.RMAuditLogger: USER=root	IP=127.0.0.1	OPERATION=Register App Master	TARGET=ApplicationMasterService	RESULT=SUCCESS	APPID=application_1549629837143_0003	APPATTEMPTID=appattempt_1549629837143_0003_000001
2019-02-08 18:42:01,447 INFO org.apache.hadoop.yarn.server.resourcemanager.rmapp.attempt.RMAppAttemptImpl: appattempt_1549629837143_0003_000001 State change from LAUNCHED to RUNNING
2019-02-08 18:42:01,447 INFO org.apache.hadoop.yarn.server.resourcemanager.rmapp.RMAppImpl: application_1549629837143_0003 State change from ACCEPTED to RUNNING
2019-02-08 18:42:02,884 INFO org.apache.hadoop.yarn.server.resourcemanager.rmcontainer.RMContainerImpl: container_1549629837143_0003_01_000002 Container Transitioned from NEW to ALLOCATED
2019-02-08 18:42:02,885 INFO org.apache.hadoop.yarn.server.resourcemanager.RMAuditLogger: USER=root	OPERATION=AM Allocated Container	TARGET=SchedulerApp	RESULT=SUCCESS	APPID=application_1549629837143_0003	CONTAINERID=container_1549629837143_0003_01_000002
2019-02-08 18:42:02,885 INFO org.apache.hadoop.yarn.server.resourcemanager.scheduler.SchedulerNode: Assigned container container_1549629837143_0003_01_000002 of capacity <memory:1024, vCores:1> on host ubuntu-HP-Pavilion-dv6-NoteBook-PC:34935, which has 2 containers, <memory:3072, vCores:2> used and <memory:5120, vCores:6> available after allocation
2019-02-08 18:42:02,885 INFO org.apache.hadoop.yarn.server.resourcemanager.scheduler.capacity.LeafQueue: assignedContainer application attempt=appattempt_1549629837143_0003_000001 container=Container: [ContainerId: container_1549629837143_0003_01_000002, NodeId: ubuntu-HP-Pavilion-dv6-NoteBook-PC:34935, NodeHttpAddress: ubuntu-HP-Pavilion-dv6-NoteBook-PC:8042, Resource: <memory:1024, vCores:1>, Priority: 20, Token: null, ] queue=default: capacity=1.0, absoluteCapacity=1.0, usedResources=<memory:2048, vCores:1>, usedCapacity=0.25, absoluteUsedCapacity=0.25, numApps=1, numContainers=1 clusterResource=<memory:8192, vCores:8> type=NODE_LOCAL
2019-02-08 18:42:02,885 INFO org.apache.hadoop.yarn.server.resourcemanager.scheduler.capacity.ParentQueue: Re-sorting assigned queue: root.default stats: default: capacity=1.0, absoluteCapacity=1.0, usedResources=<memory:3072, vCores:2>, usedCapacity=0.375, absoluteUsedCapacity=0.375, numApps=1, numContainers=2
2019-02-08 18:42:02,886 INFO org.apache.hadoop.yarn.server.resourcemanager.scheduler.capacity.ParentQueue: assignedContainer queue=root usedCapacity=0.375 absoluteUsedCapacity=0.375 used=<memory:3072, vCores:2> cluster=<memory:8192, vCores:8>
2019-02-08 18:42:03,714 INFO org.apache.hadoop.yarn.server.resourcemanager.security.NMTokenSecretManagerInRM: Sending NMToken for nodeId : ubuntu-HP-Pavilion-dv6-NoteBook-PC:34935 for container : container_1549629837143_0003_01_000002
2019-02-08 18:42:03,716 INFO org.apache.hadoop.yarn.server.resourcemanager.rmcontainer.RMContainerImpl: container_1549629837143_0003_01_000002 Container Transitioned from ALLOCATED to ACQUIRED
2019-02-08 18:42:04,748 INFO org.apache.hadoop.yarn.server.resourcemanager.scheduler.AppSchedulingInfo: checking for deactivate of application :application_1549629837143_0003
2019-02-08 18:42:04,899 INFO org.apache.hadoop.yarn.server.resourcemanager.rmcontainer.RMContainerImpl: container_1549629837143_0003_01_000002 Container Transitioned from ACQUIRED to RUNNING
2019-02-08 18:42:14,718 INFO org.apache.hadoop.yarn.server.resourcemanager.rmcontainer.RMContainerImpl: container_1549629837143_0003_01_000002 Container Transitioned from RUNNING to COMPLETED
2019-02-08 18:42:14,719 INFO org.apache.hadoop.yarn.server.resourcemanager.scheduler.common.fica.FiCaSchedulerApp: Completed container: container_1549629837143_0003_01_000002 in state: COMPLETED event:FINISHED
2019-02-08 18:42:14,719 INFO org.apache.hadoop.yarn.server.resourcemanager.RMAuditLogger: USER=root	OPERATION=AM Released Container	TARGET=SchedulerApp	RESULT=SUCCESS	APPID=application_1549629837143_0003	CONTAINERID=container_1549629837143_0003_01_000002
2019-02-08 18:42:14,719 INFO org.apache.hadoop.yarn.server.resourcemanager.scheduler.SchedulerNode: Released container container_1549629837143_0003_01_000002 of capacity <memory:1024, vCores:1> on host ubuntu-HP-Pavilion-dv6-NoteBook-PC:34935, which currently has 1 containers, <memory:2048, vCores:1> used and <memory:6144, vCores:7> available, release resources=true
2019-02-08 18:42:14,720 INFO org.apache.hadoop.yarn.server.resourcemanager.scheduler.capacity.LeafQueue: default used=<memory:2048, vCores:1> numContainers=1 user=root user-resources=<memory:2048, vCores:1>
2019-02-08 18:42:14,721 INFO org.apache.hadoop.yarn.server.resourcemanager.scheduler.capacity.LeafQueue: completedContainer container=Container: [ContainerId: container_1549629837143_0003_01_000002, NodeId: ubuntu-HP-Pavilion-dv6-NoteBook-PC:34935, NodeHttpAddress: ubuntu-HP-Pavilion-dv6-NoteBook-PC:8042, Resource: <memory:1024, vCores:1>, Priority: 20, Token: Token { kind: ContainerToken, service: 127.0.1.1:34935 }, ] queue=default: capacity=1.0, absoluteCapacity=1.0, usedResources=<memory:2048, vCores:1>, usedCapacity=0.25, absoluteUsedCapacity=0.25, numApps=1, numContainers=1 cluster=<memory:8192, vCores:8>
2019-02-08 18:42:14,721 INFO org.apache.hadoop.yarn.server.resourcemanager.scheduler.capacity.ParentQueue: completedContainer queue=root usedCapacity=0.25 absoluteUsedCapacity=0.25 used=<memory:2048, vCores:1> cluster=<memory:8192, vCores:8>
2019-02-08 18:42:14,721 INFO org.apache.hadoop.yarn.server.resourcemanager.scheduler.capacity.ParentQueue: Re-sorting completed queue: root.default stats: default: capacity=1.0, absoluteCapacity=1.0, usedResources=<memory:2048, vCores:1>, usedCapacity=0.25, absoluteUsedCapacity=0.25, numApps=1, numContainers=1
2019-02-08 18:42:14,721 INFO org.apache.hadoop.yarn.server.resourcemanager.scheduler.capacity.CapacityScheduler: Application attempt appattempt_1549629837143_0003_000001 released container container_1549629837143_0003_01_000002 on node: host: ubuntu-HP-Pavilion-dv6-NoteBook-PC:34935 #containers=1 available=<memory:6144, vCores:7> used=<memory:2048, vCores:1> with event: FINISHED
2019-02-08 18:42:16,733 INFO org.apache.hadoop.yarn.server.resourcemanager.rmcontainer.RMContainerImpl: container_1549629837143_0003_01_000003 Container Transitioned from NEW to ALLOCATED
2019-02-08 18:42:16,733 INFO org.apache.hadoop.yarn.server.resourcemanager.RMAuditLogger: USER=root	OPERATION=AM Allocated Container	TARGET=SchedulerApp	RESULT=SUCCESS	APPID=application_1549629837143_0003	CONTAINERID=container_1549629837143_0003_01_000003
2019-02-08 18:42:16,733 INFO org.apache.hadoop.yarn.server.resourcemanager.scheduler.SchedulerNode: Assigned container container_1549629837143_0003_01_000003 of capacity <memory:1024, vCores:1> on host ubuntu-HP-Pavilion-dv6-NoteBook-PC:34935, which has 2 containers, <memory:3072, vCores:2> used and <memory:5120, vCores:6> available after allocation
2019-02-08 18:42:16,734 INFO org.apache.hadoop.yarn.server.resourcemanager.scheduler.capacity.LeafQueue: assignedContainer application attempt=appattempt_1549629837143_0003_000001 container=Container: [ContainerId: container_1549629837143_0003_01_000003, NodeId: ubuntu-HP-Pavilion-dv6-NoteBook-PC:34935, NodeHttpAddress: ubuntu-HP-Pavilion-dv6-NoteBook-PC:8042, Resource: <memory:1024, vCores:1>, Priority: 10, Token: null, ] queue=default: capacity=1.0, absoluteCapacity=1.0, usedResources=<memory:2048, vCores:1>, usedCapacity=0.25, absoluteUsedCapacity=0.25, numApps=1, numContainers=1 clusterResource=<memory:8192, vCores:8> type=OFF_SWITCH
2019-02-08 18:42:16,734 INFO org.apache.hadoop.yarn.server.resourcemanager.scheduler.capacity.ParentQueue: Re-sorting assigned queue: root.default stats: default: capacity=1.0, absoluteCapacity=1.0, usedResources=<memory:3072, vCores:2>, usedCapacity=0.375, absoluteUsedCapacity=0.375, numApps=1, numContainers=2
2019-02-08 18:42:16,734 INFO org.apache.hadoop.yarn.server.resourcemanager.scheduler.capacity.ParentQueue: assignedContainer queue=root usedCapacity=0.375 absoluteUsedCapacity=0.375 used=<memory:3072, vCores:2> cluster=<memory:8192, vCores:8>
2019-02-08 18:42:16,925 INFO org.apache.hadoop.yarn.server.resourcemanager.rmcontainer.RMContainerImpl: container_1549629837143_0003_01_000003 Container Transitioned from ALLOCATED to ACQUIRED
2019-02-08 18:42:17,734 INFO org.apache.hadoop.yarn.server.resourcemanager.rmcontainer.RMContainerImpl: container_1549629837143_0003_01_000003 Container Transitioned from ACQUIRED to RUNNING
2019-02-08 18:42:17,940 INFO org.apache.hadoop.yarn.server.resourcemanager.scheduler.AppSchedulingInfo: checking for deactivate of application :application_1549629837143_0003
2019-02-08 18:42:29,530 INFO org.apache.hadoop.yarn.server.resourcemanager.rmcontainer.RMContainerImpl: container_1549629837143_0003_01_000003 Container Transitioned from RUNNING to COMPLETED
2019-02-08 18:42:29,530 INFO org.apache.hadoop.yarn.server.resourcemanager.scheduler.common.fica.FiCaSchedulerApp: Completed container: container_1549629837143_0003_01_000003 in state: COMPLETED event:FINISHED
2019-02-08 18:42:29,530 INFO org.apache.hadoop.yarn.server.resourcemanager.RMAuditLogger: USER=root	OPERATION=AM Released Container	TARGET=SchedulerApp	RESULT=SUCCESS	APPID=application_1549629837143_0003	CONTAINERID=container_1549629837143_0003_01_000003
2019-02-08 18:42:29,531 INFO org.apache.hadoop.yarn.server.resourcemanager.scheduler.SchedulerNode: Released container container_1549629837143_0003_01_000003 of capacity <memory:1024, vCores:1> on host ubuntu-HP-Pavilion-dv6-NoteBook-PC:34935, which currently has 1 containers, <memory:2048, vCores:1> used and <memory:6144, vCores:7> available, release resources=true
2019-02-08 18:42:29,531 INFO org.apache.hadoop.yarn.server.resourcemanager.scheduler.capacity.LeafQueue: default used=<memory:2048, vCores:1> numContainers=1 user=root user-resources=<memory:2048, vCores:1>
2019-02-08 18:42:29,534 INFO org.apache.hadoop.yarn.server.resourcemanager.scheduler.capacity.LeafQueue: completedContainer container=Container: [ContainerId: container_1549629837143_0003_01_000003, NodeId: ubuntu-HP-Pavilion-dv6-NoteBook-PC:34935, NodeHttpAddress: ubuntu-HP-Pavilion-dv6-NoteBook-PC:8042, Resource: <memory:1024, vCores:1>, Priority: 10, Token: Token { kind: ContainerToken, service: 127.0.1.1:34935 }, ] queue=default: capacity=1.0, absoluteCapacity=1.0, usedResources=<memory:2048, vCores:1>, usedCapacity=0.25, absoluteUsedCapacity=0.25, numApps=1, numContainers=1 cluster=<memory:8192, vCores:8>
2019-02-08 18:42:29,534 INFO org.apache.hadoop.yarn.server.resourcemanager.scheduler.capacity.ParentQueue: completedContainer queue=root usedCapacity=0.25 absoluteUsedCapacity=0.25 used=<memory:2048, vCores:1> cluster=<memory:8192, vCores:8>
2019-02-08 18:42:29,534 INFO org.apache.hadoop.yarn.server.resourcemanager.scheduler.capacity.ParentQueue: Re-sorting completed queue: root.default stats: default: capacity=1.0, absoluteCapacity=1.0, usedResources=<memory:2048, vCores:1>, usedCapacity=0.25, absoluteUsedCapacity=0.25, numApps=1, numContainers=1
2019-02-08 18:42:29,534 INFO org.apache.hadoop.yarn.server.resourcemanager.scheduler.capacity.CapacityScheduler: Application attempt appattempt_1549629837143_0003_000001 released container container_1549629837143_0003_01_000003 on node: host: ubuntu-HP-Pavilion-dv6-NoteBook-PC:34935 #containers=1 available=<memory:6144, vCores:7> used=<memory:2048, vCores:1> with event: FINISHED
2019-02-08 18:42:29,973 INFO org.apache.hadoop.yarn.server.resourcemanager.rmapp.attempt.RMAppAttemptImpl: Updating application attempt appattempt_1549629837143_0003_000001 with final state: FINISHING, and exit status: -1000
2019-02-08 18:42:29,973 INFO org.apache.hadoop.yarn.server.resourcemanager.rmapp.attempt.RMAppAttemptImpl: appattempt_1549629837143_0003_000001 State change from RUNNING to FINAL_SAVING
2019-02-08 18:42:29,974 INFO org.apache.hadoop.yarn.server.resourcemanager.rmapp.RMAppImpl: Updating application application_1549629837143_0003 with final state: FINISHING
2019-02-08 18:42:29,974 INFO org.apache.hadoop.yarn.server.resourcemanager.rmapp.RMAppImpl: application_1549629837143_0003 State change from RUNNING to FINAL_SAVING
2019-02-08 18:42:29,974 INFO org.apache.hadoop.yarn.server.resourcemanager.recovery.RMStateStore: Updating info for app: application_1549629837143_0003
2019-02-08 18:42:29,974 INFO org.apache.hadoop.yarn.server.resourcemanager.rmapp.attempt.RMAppAttemptImpl: appattempt_1549629837143_0003_000001 State change from FINAL_SAVING to FINISHING
2019-02-08 18:42:29,974 INFO org.apache.hadoop.yarn.server.resourcemanager.rmapp.RMAppImpl: application_1549629837143_0003 State change from FINAL_SAVING to FINISHING
2019-02-08 18:42:30,979 INFO org.apache.hadoop.yarn.server.resourcemanager.ApplicationMasterService: application_1549629837143_0003 unregistered successfully. 
2019-02-08 18:42:36,574 INFO org.apache.hadoop.yarn.server.resourcemanager.rmcontainer.RMContainerImpl: container_1549629837143_0003_01_000001 Container Transitioned from RUNNING to COMPLETED
2019-02-08 18:42:36,574 INFO org.apache.hadoop.yarn.server.resourcemanager.ApplicationMasterService: Unregistering app attempt : appattempt_1549629837143_0003_000001
2019-02-08 18:42:36,574 INFO org.apache.hadoop.yarn.server.resourcemanager.scheduler.common.fica.FiCaSchedulerApp: Completed container: container_1549629837143_0003_01_000001 in state: COMPLETED event:FINISHED
2019-02-08 18:42:36,574 INFO org.apache.hadoop.yarn.server.resourcemanager.security.AMRMTokenSecretManager: Application finished, removing password for appattempt_1549629837143_0003_000001
2019-02-08 18:42:36,574 INFO org.apache.hadoop.yarn.server.resourcemanager.RMAuditLogger: USER=root	OPERATION=AM Released Container	TARGET=SchedulerApp	RESULT=SUCCESS	APPID=application_1549629837143_0003	CONTAINERID=container_1549629837143_0003_01_000001
2019-02-08 18:42:36,574 INFO org.apache.hadoop.yarn.server.resourcemanager.rmapp.attempt.RMAppAttemptImpl: appattempt_1549629837143_0003_000001 State change from FINISHING to FINISHED
2019-02-08 18:42:36,574 INFO org.apache.hadoop.yarn.server.resourcemanager.scheduler.SchedulerNode: Released container container_1549629837143_0003_01_000001 of capacity <memory:2048, vCores:1> on host ubuntu-HP-Pavilion-dv6-NoteBook-PC:34935, which currently has 0 containers, <memory:0, vCores:0> used and <memory:8192, vCores:8> available, release resources=true
2019-02-08 18:42:36,574 INFO org.apache.hadoop.yarn.server.resourcemanager.rmapp.RMAppImpl: application_1549629837143_0003 State change from FINISHING to FINISHED
2019-02-08 18:42:36,574 INFO org.apache.hadoop.yarn.server.resourcemanager.scheduler.capacity.LeafQueue: default used=<memory:0, vCores:0> numContainers=0 user=root user-resources=<memory:0, vCores:0>
2019-02-08 18:42:36,575 INFO org.apache.hadoop.yarn.server.resourcemanager.RMAuditLogger: USER=root	OPERATION=Application Finished - Succeeded	TARGET=RMAppManager	RESULT=SUCCESS	APPID=application_1549629837143_0003
2019-02-08 18:42:36,575 INFO org.apache.hadoop.yarn.server.resourcemanager.scheduler.capacity.LeafQueue: completedContainer container=Container: [ContainerId: container_1549629837143_0003_01_000001, NodeId: ubuntu-HP-Pavilion-dv6-NoteBook-PC:34935, NodeHttpAddress: ubuntu-HP-Pavilion-dv6-NoteBook-PC:8042, Resource: <memory:2048, vCores:1>, Priority: 0, Token: Token { kind: ContainerToken, service: 127.0.1.1:34935 }, ] queue=default: capacity=1.0, absoluteCapacity=1.0, usedResources=<memory:0, vCores:0>, usedCapacity=0.0, absoluteUsedCapacity=0.0, numApps=1, numContainers=0 cluster=<memory:8192, vCores:8>
2019-02-08 18:42:36,575 INFO org.apache.hadoop.yarn.server.resourcemanager.scheduler.capacity.ParentQueue: completedContainer queue=root usedCapacity=0.0 absoluteUsedCapacity=0.0 used=<memory:0, vCores:0> cluster=<memory:8192, vCores:8>
2019-02-08 18:42:36,575 INFO org.apache.hadoop.yarn.server.resourcemanager.scheduler.capacity.ParentQueue: Re-sorting completed queue: root.default stats: default: capacity=1.0, absoluteCapacity=1.0, usedResources=<memory:0, vCores:0>, usedCapacity=0.0, absoluteUsedCapacity=0.0, numApps=1, numContainers=0
2019-02-08 18:42:36,575 INFO org.apache.hadoop.yarn.server.resourcemanager.scheduler.capacity.CapacityScheduler: Application attempt appattempt_1549629837143_0003_000001 released container container_1549629837143_0003_01_000001 on node: host: ubuntu-HP-Pavilion-dv6-NoteBook-PC:34935 #containers=0 available=<memory:8192, vCores:8> used=<memory:0, vCores:0> with event: FINISHED
2019-02-08 18:42:36,575 INFO org.apache.hadoop.yarn.server.resourcemanager.scheduler.capacity.CapacityScheduler: Application Attempt appattempt_1549629837143_0003_000001 is done. finalState=FINISHED
2019-02-08 18:42:36,575 INFO org.apache.hadoop.yarn.server.resourcemanager.RMAppManager$ApplicationSummary: appId=application_1549629837143_0003,name=select\n    ordermonthyear as OrderMon...desc(Stage-2),user=root,queue=default,state=FINISHED,trackingUrl=http://ubuntu-HP-Pavilion-dv6-NoteBook-PC:8088/proxy/application_1549629837143_0003/,appMasterHost=ubuntu-HP-Pavilion-dv6-NoteBook-PC,startTime=1549631498628,finishTime=1549631549974,finalStatus=SUCCEEDED,memorySeconds=135449,vcoreSeconds=76,preemptedAMContainers=0,preemptedNonAMContainers=0,preemptedResources=<memory:0\, vCores:0>,applicationType=MAPREDUCE
2019-02-08 18:42:36,575 INFO org.apache.hadoop.yarn.server.resourcemanager.scheduler.AppSchedulingInfo: Application application_1549629837143_0003 requests cleared
2019-02-08 18:42:36,577 INFO org.apache.hadoop.yarn.server.resourcemanager.amlauncher.AMLauncher: Cleaning master appattempt_1549629837143_0003_000001
2019-02-08 18:42:36,578 INFO org.apache.hadoop.yarn.server.resourcemanager.scheduler.capacity.LeafQueue: Application removed - appId: application_1549629837143_0003 user: root queue: default #user-pending-applications: 0 #user-active-applications: 0 #queue-pending-applications: 0 #queue-active-applications: 0
2019-02-08 18:42:36,578 INFO org.apache.hadoop.yarn.server.resourcemanager.scheduler.capacity.ParentQueue: Application removed - appId: application_1549629837143_0003 user: root leaf-queue of parent: root #applications: 0
2019-02-08 18:42:38,577 INFO org.apache.hadoop.yarn.server.resourcemanager.scheduler.capacity.CapacityScheduler: Null container completed...
2019-02-08 18:44:07,550 INFO org.apache.hadoop.yarn.server.resourcemanager.ClientRMService: Allocated new applicationId: 4
2019-02-08 18:44:08,691 INFO org.apache.hadoop.yarn.server.resourcemanager.ClientRMService: Application with id 4 submitted by user root
2019-02-08 18:44:08,691 INFO org.apache.hadoop.yarn.server.resourcemanager.rmapp.RMAppImpl: Storing application with id application_1549629837143_0004
2019-02-08 18:44:08,692 INFO org.apache.hadoop.yarn.server.resourcemanager.RMAuditLogger: USER=root	IP=127.0.0.1	OPERATION=Submit Application Request	TARGET=ClientRMService	RESULT=SUCCESS	APPID=application_1549629837143_0004
2019-02-08 18:44:08,692 INFO org.apache.hadoop.yarn.server.resourcemanager.rmapp.RMAppImpl: application_1549629837143_0004 State change from NEW to NEW_SAVING
2019-02-08 18:44:08,692 INFO org.apache.hadoop.yarn.server.resourcemanager.recovery.RMStateStore: Storing info for app: application_1549629837143_0004
2019-02-08 18:44:08,692 INFO org.apache.hadoop.yarn.server.resourcemanager.rmapp.RMAppImpl: application_1549629837143_0004 State change from NEW_SAVING to SUBMITTED
2019-02-08 18:44:08,692 INFO org.apache.hadoop.yarn.server.resourcemanager.scheduler.capacity.ParentQueue: Application added - appId: application_1549629837143_0004 user: root leaf-queue of parent: root #applications: 1
2019-02-08 18:44:08,692 INFO org.apache.hadoop.yarn.server.resourcemanager.scheduler.capacity.CapacityScheduler: Accepted application application_1549629837143_0004 from user: root, in queue: default
2019-02-08 18:44:08,693 INFO org.apache.hadoop.yarn.server.resourcemanager.rmapp.RMAppImpl: application_1549629837143_0004 State change from SUBMITTED to ACCEPTED
2019-02-08 18:44:08,693 INFO org.apache.hadoop.yarn.server.resourcemanager.ApplicationMasterService: Registering app attempt : appattempt_1549629837143_0004_000001
2019-02-08 18:44:08,693 INFO org.apache.hadoop.yarn.server.resourcemanager.rmapp.attempt.RMAppAttemptImpl: appattempt_1549629837143_0004_000001 State change from NEW to SUBMITTED
2019-02-08 18:44:08,694 WARN org.apache.hadoop.yarn.server.resourcemanager.scheduler.capacity.LeafQueue: maximum-am-resource-percent is insufficient to start a single application in queue, it is likely set too low. skipping enforcement to allow at least one application to start
2019-02-08 18:44:08,694 WARN org.apache.hadoop.yarn.server.resourcemanager.scheduler.capacity.LeafQueue: maximum-am-resource-percent is insufficient to start a single application in queue for user, it is likely set too low. skipping enforcement to allow at least one application to start
2019-02-08 18:44:08,694 INFO org.apache.hadoop.yarn.server.resourcemanager.scheduler.capacity.LeafQueue: Application application_1549629837143_0004 from user: root activated in queue: default
2019-02-08 18:44:08,694 INFO org.apache.hadoop.yarn.server.resourcemanager.scheduler.capacity.LeafQueue: Application added - appId: application_1549629837143_0004 user: org.apache.hadoop.yarn.server.resourcemanager.scheduler.capacity.LeafQueue$User@6e872d12, leaf-queue: default #user-pending-applications: 0 #user-active-applications: 1 #queue-pending-applications: 0 #queue-active-applications: 1
2019-02-08 18:44:08,694 INFO org.apache.hadoop.yarn.server.resourcemanager.scheduler.capacity.CapacityScheduler: Added Application Attempt appattempt_1549629837143_0004_000001 to scheduler from user root in queue default
2019-02-08 18:44:08,697 INFO org.apache.hadoop.yarn.server.resourcemanager.rmapp.attempt.RMAppAttemptImpl: appattempt_1549629837143_0004_000001 State change from SUBMITTED to SCHEDULED
2019-02-08 18:44:08,717 INFO org.apache.hadoop.yarn.server.resourcemanager.rmcontainer.RMContainerImpl: container_1549629837143_0004_01_000001 Container Transitioned from NEW to ALLOCATED
2019-02-08 18:44:08,717 INFO org.apache.hadoop.yarn.server.resourcemanager.RMAuditLogger: USER=root	OPERATION=AM Allocated Container	TARGET=SchedulerApp	RESULT=SUCCESS	APPID=application_1549629837143_0004	CONTAINERID=container_1549629837143_0004_01_000001
2019-02-08 18:44:08,717 INFO org.apache.hadoop.yarn.server.resourcemanager.scheduler.SchedulerNode: Assigned container container_1549629837143_0004_01_000001 of capacity <memory:2048, vCores:1> on host ubuntu-HP-Pavilion-dv6-NoteBook-PC:34935, which has 1 containers, <memory:2048, vCores:1> used and <memory:6144, vCores:7> available after allocation
2019-02-08 18:44:08,717 INFO org.apache.hadoop.yarn.server.resourcemanager.scheduler.capacity.LeafQueue: assignedContainer application attempt=appattempt_1549629837143_0004_000001 container=Container: [ContainerId: container_1549629837143_0004_01_000001, NodeId: ubuntu-HP-Pavilion-dv6-NoteBook-PC:34935, NodeHttpAddress: ubuntu-HP-Pavilion-dv6-NoteBook-PC:8042, Resource: <memory:2048, vCores:1>, Priority: 0, Token: null, ] queue=default: capacity=1.0, absoluteCapacity=1.0, usedResources=<memory:0, vCores:0>, usedCapacity=0.0, absoluteUsedCapacity=0.0, numApps=1, numContainers=0 clusterResource=<memory:8192, vCores:8> type=OFF_SWITCH
2019-02-08 18:44:08,717 INFO org.apache.hadoop.yarn.server.resourcemanager.scheduler.capacity.ParentQueue: Re-sorting assigned queue: root.default stats: default: capacity=1.0, absoluteCapacity=1.0, usedResources=<memory:2048, vCores:1>, usedCapacity=0.25, absoluteUsedCapacity=0.25, numApps=1, numContainers=1
2019-02-08 18:44:08,717 INFO org.apache.hadoop.yarn.server.resourcemanager.scheduler.capacity.ParentQueue: assignedContainer queue=root usedCapacity=0.25 absoluteUsedCapacity=0.25 used=<memory:2048, vCores:1> cluster=<memory:8192, vCores:8>
2019-02-08 18:44:08,720 INFO org.apache.hadoop.yarn.server.resourcemanager.security.NMTokenSecretManagerInRM: Sending NMToken for nodeId : ubuntu-HP-Pavilion-dv6-NoteBook-PC:34935 for container : container_1549629837143_0004_01_000001
2019-02-08 18:44:08,725 INFO org.apache.hadoop.yarn.server.resourcemanager.rmcontainer.RMContainerImpl: container_1549629837143_0004_01_000001 Container Transitioned from ALLOCATED to ACQUIRED
2019-02-08 18:44:08,725 INFO org.apache.hadoop.yarn.server.resourcemanager.security.NMTokenSecretManagerInRM: Clear node set for appattempt_1549629837143_0004_000001
2019-02-08 18:44:08,725 INFO org.apache.hadoop.yarn.server.resourcemanager.rmapp.attempt.RMAppAttemptImpl: Storing attempt: AppId: application_1549629837143_0004 AttemptId: appattempt_1549629837143_0004_000001 MasterContainer: Container: [ContainerId: container_1549629837143_0004_01_000001, NodeId: ubuntu-HP-Pavilion-dv6-NoteBook-PC:34935, NodeHttpAddress: ubuntu-HP-Pavilion-dv6-NoteBook-PC:8042, Resource: <memory:2048, vCores:1>, Priority: 0, Token: Token { kind: ContainerToken, service: 127.0.1.1:34935 }, ]
2019-02-08 18:44:08,726 INFO org.apache.hadoop.yarn.server.resourcemanager.rmapp.attempt.RMAppAttemptImpl: appattempt_1549629837143_0004_000001 State change from SCHEDULED to ALLOCATED_SAVING
2019-02-08 18:44:08,726 INFO org.apache.hadoop.yarn.server.resourcemanager.rmapp.attempt.RMAppAttemptImpl: appattempt_1549629837143_0004_000001 State change from ALLOCATED_SAVING to ALLOCATED
2019-02-08 18:44:08,727 INFO org.apache.hadoop.yarn.server.resourcemanager.amlauncher.AMLauncher: Launching masterappattempt_1549629837143_0004_000001
2019-02-08 18:44:08,732 INFO org.apache.hadoop.yarn.server.resourcemanager.amlauncher.AMLauncher: Setting up container Container: [ContainerId: container_1549629837143_0004_01_000001, NodeId: ubuntu-HP-Pavilion-dv6-NoteBook-PC:34935, NodeHttpAddress: ubuntu-HP-Pavilion-dv6-NoteBook-PC:8042, Resource: <memory:2048, vCores:1>, Priority: 0, Token: Token { kind: ContainerToken, service: 127.0.1.1:34935 }, ] for AM appattempt_1549629837143_0004_000001
2019-02-08 18:44:08,732 INFO org.apache.hadoop.yarn.server.resourcemanager.amlauncher.AMLauncher: Command to launch container container_1549629837143_0004_01_000001 : $JAVA_HOME/bin/java -Djava.io.tmpdir=$PWD/tmp -Dlog4j.configuration=container-log4j.properties -Dyarn.app.container.log.dir=<LOG_DIR> -Dyarn.app.container.log.filesize=0 -Dhadoop.root.logger=INFO,CLA -Dhadoop.root.logfile=syslog  -Xmx1024m org.apache.hadoop.mapreduce.v2.app.MRAppMaster 1><LOG_DIR>/stdout 2><LOG_DIR>/stderr 
2019-02-08 18:44:08,732 INFO org.apache.hadoop.yarn.server.resourcemanager.security.AMRMTokenSecretManager: Create AMRMToken for ApplicationAttempt: appattempt_1549629837143_0004_000001
2019-02-08 18:44:08,733 INFO org.apache.hadoop.yarn.server.resourcemanager.security.AMRMTokenSecretManager: Creating password for appattempt_1549629837143_0004_000001
2019-02-08 18:44:08,759 INFO org.apache.hadoop.yarn.server.resourcemanager.amlauncher.AMLauncher: Done launching container Container: [ContainerId: container_1549629837143_0004_01_000001, NodeId: ubuntu-HP-Pavilion-dv6-NoteBook-PC:34935, NodeHttpAddress: ubuntu-HP-Pavilion-dv6-NoteBook-PC:8042, Resource: <memory:2048, vCores:1>, Priority: 0, Token: Token { kind: ContainerToken, service: 127.0.1.1:34935 }, ] for AM appattempt_1549629837143_0004_000001
2019-02-08 18:44:08,760 INFO org.apache.hadoop.yarn.server.resourcemanager.rmapp.attempt.RMAppAttemptImpl: appattempt_1549629837143_0004_000001 State change from ALLOCATED to LAUNCHED
2019-02-08 18:44:09,719 INFO org.apache.hadoop.yarn.server.resourcemanager.rmcontainer.RMContainerImpl: container_1549629837143_0004_01_000001 Container Transitioned from ACQUIRED to RUNNING
2019-02-08 18:44:22,283 INFO SecurityLogger.org.apache.hadoop.ipc.Server: Auth successful for appattempt_1549629837143_0004_000001 (auth:SIMPLE)
2019-02-08 18:44:22,298 INFO org.apache.hadoop.yarn.server.resourcemanager.ApplicationMasterService: AM registration appattempt_1549629837143_0004_000001
2019-02-08 18:44:22,298 INFO org.apache.hadoop.yarn.server.resourcemanager.RMAuditLogger: USER=root	IP=127.0.0.1	OPERATION=Register App Master	TARGET=ApplicationMasterService	RESULT=SUCCESS	APPID=application_1549629837143_0004	APPATTEMPTID=appattempt_1549629837143_0004_000001
2019-02-08 18:44:22,299 INFO org.apache.hadoop.yarn.server.resourcemanager.rmapp.attempt.RMAppAttemptImpl: appattempt_1549629837143_0004_000001 State change from LAUNCHED to RUNNING
2019-02-08 18:44:22,299 INFO org.apache.hadoop.yarn.server.resourcemanager.rmapp.RMAppImpl: application_1549629837143_0004 State change from ACCEPTED to RUNNING
2019-02-08 18:44:23,833 INFO org.apache.hadoop.yarn.server.resourcemanager.rmcontainer.RMContainerImpl: container_1549629837143_0004_01_000002 Container Transitioned from NEW to ALLOCATED
2019-02-08 18:44:23,833 INFO org.apache.hadoop.yarn.server.resourcemanager.RMAuditLogger: USER=root	OPERATION=AM Allocated Container	TARGET=SchedulerApp	RESULT=SUCCESS	APPID=application_1549629837143_0004	CONTAINERID=container_1549629837143_0004_01_000002
2019-02-08 18:44:23,833 INFO org.apache.hadoop.yarn.server.resourcemanager.scheduler.SchedulerNode: Assigned container container_1549629837143_0004_01_000002 of capacity <memory:1024, vCores:1> on host ubuntu-HP-Pavilion-dv6-NoteBook-PC:34935, which has 2 containers, <memory:3072, vCores:2> used and <memory:5120, vCores:6> available after allocation
2019-02-08 18:44:23,834 INFO org.apache.hadoop.yarn.server.resourcemanager.scheduler.capacity.LeafQueue: assignedContainer application attempt=appattempt_1549629837143_0004_000001 container=Container: [ContainerId: container_1549629837143_0004_01_000002, NodeId: ubuntu-HP-Pavilion-dv6-NoteBook-PC:34935, NodeHttpAddress: ubuntu-HP-Pavilion-dv6-NoteBook-PC:8042, Resource: <memory:1024, vCores:1>, Priority: 20, Token: null, ] queue=default: capacity=1.0, absoluteCapacity=1.0, usedResources=<memory:2048, vCores:1>, usedCapacity=0.25, absoluteUsedCapacity=0.25, numApps=1, numContainers=1 clusterResource=<memory:8192, vCores:8> type=NODE_LOCAL
2019-02-08 18:44:23,834 INFO org.apache.hadoop.yarn.server.resourcemanager.scheduler.capacity.ParentQueue: Re-sorting assigned queue: root.default stats: default: capacity=1.0, absoluteCapacity=1.0, usedResources=<memory:3072, vCores:2>, usedCapacity=0.375, absoluteUsedCapacity=0.375, numApps=1, numContainers=2
2019-02-08 18:44:23,834 INFO org.apache.hadoop.yarn.server.resourcemanager.scheduler.capacity.ParentQueue: assignedContainer queue=root usedCapacity=0.375 absoluteUsedCapacity=0.375 used=<memory:3072, vCores:2> cluster=<memory:8192, vCores:8>
2019-02-08 18:44:24,513 INFO org.apache.hadoop.yarn.server.resourcemanager.security.NMTokenSecretManagerInRM: Sending NMToken for nodeId : ubuntu-HP-Pavilion-dv6-NoteBook-PC:34935 for container : container_1549629837143_0004_01_000002
2019-02-08 18:44:24,532 INFO org.apache.hadoop.yarn.server.resourcemanager.rmcontainer.RMContainerImpl: container_1549629837143_0004_01_000002 Container Transitioned from ALLOCATED to ACQUIRED
2019-02-08 18:44:25,607 INFO org.apache.hadoop.yarn.server.resourcemanager.scheduler.AppSchedulingInfo: checking for deactivate of application :application_1549629837143_0004
2019-02-08 18:44:25,844 INFO org.apache.hadoop.yarn.server.resourcemanager.rmcontainer.RMContainerImpl: container_1549629837143_0004_01_000002 Container Transitioned from ACQUIRED to RUNNING
2019-02-08 18:44:38,102 INFO org.apache.hadoop.yarn.server.resourcemanager.rmcontainer.RMContainerImpl: container_1549629837143_0004_01_000002 Container Transitioned from RUNNING to COMPLETED
2019-02-08 18:44:38,102 INFO org.apache.hadoop.yarn.server.resourcemanager.scheduler.common.fica.FiCaSchedulerApp: Completed container: container_1549629837143_0004_01_000002 in state: COMPLETED event:FINISHED
2019-02-08 18:44:38,102 INFO org.apache.hadoop.yarn.server.resourcemanager.RMAuditLogger: USER=root	OPERATION=AM Released Container	TARGET=SchedulerApp	RESULT=SUCCESS	APPID=application_1549629837143_0004	CONTAINERID=container_1549629837143_0004_01_000002
2019-02-08 18:44:38,102 INFO org.apache.hadoop.yarn.server.resourcemanager.scheduler.SchedulerNode: Released container container_1549629837143_0004_01_000002 of capacity <memory:1024, vCores:1> on host ubuntu-HP-Pavilion-dv6-NoteBook-PC:34935, which currently has 1 containers, <memory:2048, vCores:1> used and <memory:6144, vCores:7> available, release resources=true
2019-02-08 18:44:38,102 INFO org.apache.hadoop.yarn.server.resourcemanager.scheduler.capacity.LeafQueue: default used=<memory:2048, vCores:1> numContainers=1 user=root user-resources=<memory:2048, vCores:1>
2019-02-08 18:44:38,104 INFO org.apache.hadoop.yarn.server.resourcemanager.scheduler.capacity.LeafQueue: completedContainer container=Container: [ContainerId: container_1549629837143_0004_01_000002, NodeId: ubuntu-HP-Pavilion-dv6-NoteBook-PC:34935, NodeHttpAddress: ubuntu-HP-Pavilion-dv6-NoteBook-PC:8042, Resource: <memory:1024, vCores:1>, Priority: 20, Token: Token { kind: ContainerToken, service: 127.0.1.1:34935 }, ] queue=default: capacity=1.0, absoluteCapacity=1.0, usedResources=<memory:2048, vCores:1>, usedCapacity=0.25, absoluteUsedCapacity=0.25, numApps=1, numContainers=1 cluster=<memory:8192, vCores:8>
2019-02-08 18:44:38,104 INFO org.apache.hadoop.yarn.server.resourcemanager.scheduler.capacity.ParentQueue: completedContainer queue=root usedCapacity=0.25 absoluteUsedCapacity=0.25 used=<memory:2048, vCores:1> cluster=<memory:8192, vCores:8>
2019-02-08 18:44:38,104 INFO org.apache.hadoop.yarn.server.resourcemanager.scheduler.capacity.ParentQueue: Re-sorting completed queue: root.default stats: default: capacity=1.0, absoluteCapacity=1.0, usedResources=<memory:2048, vCores:1>, usedCapacity=0.25, absoluteUsedCapacity=0.25, numApps=1, numContainers=1
2019-02-08 18:44:38,104 INFO org.apache.hadoop.yarn.server.resourcemanager.scheduler.capacity.CapacityScheduler: Application attempt appattempt_1549629837143_0004_000001 released container container_1549629837143_0004_01_000002 on node: host: ubuntu-HP-Pavilion-dv6-NoteBook-PC:34935 #containers=1 available=<memory:6144, vCores:7> used=<memory:2048, vCores:1> with event: FINISHED
2019-02-08 18:44:40,109 INFO org.apache.hadoop.yarn.server.resourcemanager.rmcontainer.RMContainerImpl: container_1549629837143_0004_01_000003 Container Transitioned from NEW to ALLOCATED
2019-02-08 18:44:40,109 INFO org.apache.hadoop.yarn.server.resourcemanager.RMAuditLogger: USER=root	OPERATION=AM Allocated Container	TARGET=SchedulerApp	RESULT=SUCCESS	APPID=application_1549629837143_0004	CONTAINERID=container_1549629837143_0004_01_000003
2019-02-08 18:44:40,109 INFO org.apache.hadoop.yarn.server.resourcemanager.scheduler.SchedulerNode: Assigned container container_1549629837143_0004_01_000003 of capacity <memory:1024, vCores:1> on host ubuntu-HP-Pavilion-dv6-NoteBook-PC:34935, which has 2 containers, <memory:3072, vCores:2> used and <memory:5120, vCores:6> available after allocation
2019-02-08 18:44:40,110 INFO org.apache.hadoop.yarn.server.resourcemanager.scheduler.capacity.LeafQueue: assignedContainer application attempt=appattempt_1549629837143_0004_000001 container=Container: [ContainerId: container_1549629837143_0004_01_000003, NodeId: ubuntu-HP-Pavilion-dv6-NoteBook-PC:34935, NodeHttpAddress: ubuntu-HP-Pavilion-dv6-NoteBook-PC:8042, Resource: <memory:1024, vCores:1>, Priority: 10, Token: null, ] queue=default: capacity=1.0, absoluteCapacity=1.0, usedResources=<memory:2048, vCores:1>, usedCapacity=0.25, absoluteUsedCapacity=0.25, numApps=1, numContainers=1 clusterResource=<memory:8192, vCores:8> type=OFF_SWITCH
2019-02-08 18:44:40,110 INFO org.apache.hadoop.yarn.server.resourcemanager.scheduler.capacity.ParentQueue: Re-sorting assigned queue: root.default stats: default: capacity=1.0, absoluteCapacity=1.0, usedResources=<memory:3072, vCores:2>, usedCapacity=0.375, absoluteUsedCapacity=0.375, numApps=1, numContainers=2
2019-02-08 18:44:40,140 INFO org.apache.hadoop.yarn.server.resourcemanager.scheduler.capacity.ParentQueue: assignedContainer queue=root usedCapacity=0.375 absoluteUsedCapacity=0.375 used=<memory:3072, vCores:2> cluster=<memory:8192, vCores:8>
2019-02-08 18:44:40,696 INFO org.apache.hadoop.yarn.server.resourcemanager.rmcontainer.RMContainerImpl: container_1549629837143_0004_01_000003 Container Transitioned from ALLOCATED to ACQUIRED
2019-02-08 18:44:41,110 INFO org.apache.hadoop.yarn.server.resourcemanager.rmcontainer.RMContainerImpl: container_1549629837143_0004_01_000003 Container Transitioned from ACQUIRED to RUNNING
2019-02-08 18:44:41,701 INFO org.apache.hadoop.yarn.server.resourcemanager.scheduler.AppSchedulingInfo: checking for deactivate of application :application_1549629837143_0004
2019-02-08 18:44:51,646 INFO org.apache.hadoop.yarn.server.resourcemanager.rmcontainer.RMContainerImpl: container_1549629837143_0004_01_000003 Container Transitioned from RUNNING to COMPLETED
2019-02-08 18:44:51,646 INFO org.apache.hadoop.yarn.server.resourcemanager.scheduler.common.fica.FiCaSchedulerApp: Completed container: container_1549629837143_0004_01_000003 in state: COMPLETED event:FINISHED
2019-02-08 18:44:51,646 INFO org.apache.hadoop.yarn.server.resourcemanager.RMAuditLogger: USER=root	OPERATION=AM Released Container	TARGET=SchedulerApp	RESULT=SUCCESS	APPID=application_1549629837143_0004	CONTAINERID=container_1549629837143_0004_01_000003
2019-02-08 18:44:51,647 INFO org.apache.hadoop.yarn.server.resourcemanager.scheduler.SchedulerNode: Released container container_1549629837143_0004_01_000003 of capacity <memory:1024, vCores:1> on host ubuntu-HP-Pavilion-dv6-NoteBook-PC:34935, which currently has 1 containers, <memory:2048, vCores:1> used and <memory:6144, vCores:7> available, release resources=true
2019-02-08 18:44:51,647 INFO org.apache.hadoop.yarn.server.resourcemanager.scheduler.capacity.LeafQueue: default used=<memory:2048, vCores:1> numContainers=1 user=root user-resources=<memory:2048, vCores:1>
2019-02-08 18:44:51,649 INFO org.apache.hadoop.yarn.server.resourcemanager.scheduler.capacity.LeafQueue: completedContainer container=Container: [ContainerId: container_1549629837143_0004_01_000003, NodeId: ubuntu-HP-Pavilion-dv6-NoteBook-PC:34935, NodeHttpAddress: ubuntu-HP-Pavilion-dv6-NoteBook-PC:8042, Resource: <memory:1024, vCores:1>, Priority: 10, Token: Token { kind: ContainerToken, service: 127.0.1.1:34935 }, ] queue=default: capacity=1.0, absoluteCapacity=1.0, usedResources=<memory:2048, vCores:1>, usedCapacity=0.25, absoluteUsedCapacity=0.25, numApps=1, numContainers=1 cluster=<memory:8192, vCores:8>
2019-02-08 18:44:51,649 INFO org.apache.hadoop.yarn.server.resourcemanager.scheduler.capacity.ParentQueue: completedContainer queue=root usedCapacity=0.25 absoluteUsedCapacity=0.25 used=<memory:2048, vCores:1> cluster=<memory:8192, vCores:8>
2019-02-08 18:44:51,649 INFO org.apache.hadoop.yarn.server.resourcemanager.scheduler.capacity.ParentQueue: Re-sorting completed queue: root.default stats: default: capacity=1.0, absoluteCapacity=1.0, usedResources=<memory:2048, vCores:1>, usedCapacity=0.25, absoluteUsedCapacity=0.25, numApps=1, numContainers=1
2019-02-08 18:44:51,649 INFO org.apache.hadoop.yarn.server.resourcemanager.scheduler.capacity.CapacityScheduler: Application attempt appattempt_1549629837143_0004_000001 released container container_1549629837143_0004_01_000003 on node: host: ubuntu-HP-Pavilion-dv6-NoteBook-PC:34935 #containers=1 available=<memory:6144, vCores:7> used=<memory:2048, vCores:1> with event: FINISHED
2019-02-08 18:44:52,123 INFO org.apache.hadoop.yarn.server.resourcemanager.rmapp.attempt.RMAppAttemptImpl: Updating application attempt appattempt_1549629837143_0004_000001 with final state: FINISHING, and exit status: -1000
2019-02-08 18:44:52,125 INFO org.apache.hadoop.yarn.server.resourcemanager.rmapp.attempt.RMAppAttemptImpl: appattempt_1549629837143_0004_000001 State change from RUNNING to FINAL_SAVING
2019-02-08 18:44:52,126 INFO org.apache.hadoop.yarn.server.resourcemanager.rmapp.RMAppImpl: Updating application application_1549629837143_0004 with final state: FINISHING
2019-02-08 18:44:52,126 INFO org.apache.hadoop.yarn.server.resourcemanager.recovery.RMStateStore: Updating info for app: application_1549629837143_0004
2019-02-08 18:44:52,126 INFO org.apache.hadoop.yarn.server.resourcemanager.rmapp.RMAppImpl: application_1549629837143_0004 State change from RUNNING to FINAL_SAVING
2019-02-08 18:44:52,127 INFO org.apache.hadoop.yarn.server.resourcemanager.rmapp.attempt.RMAppAttemptImpl: appattempt_1549629837143_0004_000001 State change from FINAL_SAVING to FINISHING
2019-02-08 18:44:52,127 INFO org.apache.hadoop.yarn.server.resourcemanager.rmapp.RMAppImpl: application_1549629837143_0004 State change from FINAL_SAVING to FINISHING
2019-02-08 18:44:53,132 INFO org.apache.hadoop.yarn.server.resourcemanager.ApplicationMasterService: application_1549629837143_0004 unregistered successfully. 
2019-02-08 18:44:58,714 INFO org.apache.hadoop.yarn.server.resourcemanager.rmcontainer.RMContainerImpl: container_1549629837143_0004_01_000001 Container Transitioned from RUNNING to COMPLETED
2019-02-08 18:44:58,715 INFO org.apache.hadoop.yarn.server.resourcemanager.scheduler.common.fica.FiCaSchedulerApp: Completed container: container_1549629837143_0004_01_000001 in state: COMPLETED event:FINISHED
2019-02-08 18:44:58,715 INFO org.apache.hadoop.yarn.server.resourcemanager.RMAuditLogger: USER=root	OPERATION=AM Released Container	TARGET=SchedulerApp	RESULT=SUCCESS	APPID=application_1549629837143_0004	CONTAINERID=container_1549629837143_0004_01_000001
2019-02-08 18:44:58,715 INFO org.apache.hadoop.yarn.server.resourcemanager.scheduler.SchedulerNode: Released container container_1549629837143_0004_01_000001 of capacity <memory:2048, vCores:1> on host ubuntu-HP-Pavilion-dv6-NoteBook-PC:34935, which currently has 0 containers, <memory:0, vCores:0> used and <memory:8192, vCores:8> available, release resources=true
2019-02-08 18:44:58,715 INFO org.apache.hadoop.yarn.server.resourcemanager.scheduler.capacity.LeafQueue: default used=<memory:0, vCores:0> numContainers=0 user=root user-resources=<memory:0, vCores:0>
2019-02-08 18:44:58,716 INFO org.apache.hadoop.yarn.server.resourcemanager.scheduler.capacity.LeafQueue: completedContainer container=Container: [ContainerId: container_1549629837143_0004_01_000001, NodeId: ubuntu-HP-Pavilion-dv6-NoteBook-PC:34935, NodeHttpAddress: ubuntu-HP-Pavilion-dv6-NoteBook-PC:8042, Resource: <memory:2048, vCores:1>, Priority: 0, Token: Token { kind: ContainerToken, service: 127.0.1.1:34935 }, ] queue=default: capacity=1.0, absoluteCapacity=1.0, usedResources=<memory:0, vCores:0>, usedCapacity=0.0, absoluteUsedCapacity=0.0, numApps=1, numContainers=0 cluster=<memory:8192, vCores:8>
2019-02-08 18:44:58,716 INFO org.apache.hadoop.yarn.server.resourcemanager.scheduler.capacity.ParentQueue: completedContainer queue=root usedCapacity=0.0 absoluteUsedCapacity=0.0 used=<memory:0, vCores:0> cluster=<memory:8192, vCores:8>
2019-02-08 18:44:58,716 INFO org.apache.hadoop.yarn.server.resourcemanager.scheduler.capacity.ParentQueue: Re-sorting completed queue: root.default stats: default: capacity=1.0, absoluteCapacity=1.0, usedResources=<memory:0, vCores:0>, usedCapacity=0.0, absoluteUsedCapacity=0.0, numApps=1, numContainers=0
2019-02-08 18:44:58,716 INFO org.apache.hadoop.yarn.server.resourcemanager.scheduler.capacity.CapacityScheduler: Application attempt appattempt_1549629837143_0004_000001 released container container_1549629837143_0004_01_000001 on node: host: ubuntu-HP-Pavilion-dv6-NoteBook-PC:34935 #containers=0 available=<memory:8192, vCores:8> used=<memory:0, vCores:0> with event: FINISHED
2019-02-08 18:44:58,716 INFO org.apache.hadoop.yarn.server.resourcemanager.ApplicationMasterService: Unregistering app attempt : appattempt_1549629837143_0004_000001
2019-02-08 18:44:58,717 INFO org.apache.hadoop.yarn.server.resourcemanager.security.AMRMTokenSecretManager: Application finished, removing password for appattempt_1549629837143_0004_000001
2019-02-08 18:44:58,717 INFO org.apache.hadoop.yarn.server.resourcemanager.rmapp.attempt.RMAppAttemptImpl: appattempt_1549629837143_0004_000001 State change from FINISHING to FINISHED
2019-02-08 18:44:58,717 INFO org.apache.hadoop.yarn.server.resourcemanager.rmapp.RMAppImpl: application_1549629837143_0004 State change from FINISHING to FINISHED
2019-02-08 18:44:58,718 INFO org.apache.hadoop.yarn.server.resourcemanager.RMAuditLogger: USER=root	OPERATION=Application Finished - Succeeded	TARGET=RMAppManager	RESULT=SUCCESS	APPID=application_1549629837143_0004
2019-02-08 18:44:58,718 INFO org.apache.hadoop.yarn.server.resourcemanager.RMAppManager$ApplicationSummary: appId=application_1549629837143_0004,name=select count(1)\nfrom sales_all_year...c.name(Stage-2),user=root,queue=default,state=FINISHED,trackingUrl=http://ubuntu-HP-Pavilion-dv6-NoteBook-PC:8088/proxy/application_1549629837143_0004/,appMasterHost=ubuntu-HP-Pavilion-dv6-NoteBook-PC,startTime=1549631648691,finishTime=1549631692126,finalStatus=SUCCEEDED,memorySeconds=128819,vcoreSeconds=74,preemptedAMContainers=0,preemptedNonAMContainers=0,preemptedResources=<memory:0\, vCores:0>,applicationType=MAPREDUCE
2019-02-08 18:44:58,719 INFO org.apache.hadoop.yarn.server.resourcemanager.scheduler.capacity.CapacityScheduler: Application Attempt appattempt_1549629837143_0004_000001 is done. finalState=FINISHED
2019-02-08 18:44:58,719 INFO org.apache.hadoop.yarn.server.resourcemanager.scheduler.AppSchedulingInfo: Application application_1549629837143_0004 requests cleared
2019-02-08 18:44:58,719 INFO org.apache.hadoop.yarn.server.resourcemanager.scheduler.capacity.LeafQueue: Application removed - appId: application_1549629837143_0004 user: root queue: default #user-pending-applications: 0 #user-active-applications: 0 #queue-pending-applications: 0 #queue-active-applications: 0
2019-02-08 18:44:58,719 INFO org.apache.hadoop.yarn.server.resourcemanager.scheduler.capacity.ParentQueue: Application removed - appId: application_1549629837143_0004 user: root leaf-queue of parent: root #applications: 0
2019-02-08 18:44:58,720 INFO org.apache.hadoop.yarn.server.resourcemanager.amlauncher.AMLauncher: Cleaning master appattempt_1549629837143_0004_000001
2019-02-08 18:45:14,058 INFO org.apache.hadoop.yarn.server.resourcemanager.ClientRMService: Allocated new applicationId: 5
2019-02-08 18:45:16,340 INFO org.apache.hadoop.yarn.server.resourcemanager.ClientRMService: Application with id 5 submitted by user root
2019-02-08 18:45:16,340 INFO org.apache.hadoop.yarn.server.resourcemanager.RMAuditLogger: USER=root	IP=127.0.0.1	OPERATION=Submit Application Request	TARGET=ClientRMService	RESULT=SUCCESS	APPID=application_1549629837143_0005
2019-02-08 18:45:16,340 INFO org.apache.hadoop.yarn.server.resourcemanager.rmapp.RMAppImpl: Storing application with id application_1549629837143_0005
2019-02-08 18:45:16,341 INFO org.apache.hadoop.yarn.server.resourcemanager.rmapp.RMAppImpl: application_1549629837143_0005 State change from NEW to NEW_SAVING
2019-02-08 18:45:16,341 INFO org.apache.hadoop.yarn.server.resourcemanager.recovery.RMStateStore: Storing info for app: application_1549629837143_0005
2019-02-08 18:45:16,341 INFO org.apache.hadoop.yarn.server.resourcemanager.rmapp.RMAppImpl: application_1549629837143_0005 State change from NEW_SAVING to SUBMITTED
2019-02-08 18:45:16,341 INFO org.apache.hadoop.yarn.server.resourcemanager.scheduler.capacity.ParentQueue: Application added - appId: application_1549629837143_0005 user: root leaf-queue of parent: root #applications: 1
2019-02-08 18:45:16,341 INFO org.apache.hadoop.yarn.server.resourcemanager.scheduler.capacity.CapacityScheduler: Accepted application application_1549629837143_0005 from user: root, in queue: default
2019-02-08 18:45:16,343 INFO org.apache.hadoop.yarn.server.resourcemanager.rmapp.RMAppImpl: application_1549629837143_0005 State change from SUBMITTED to ACCEPTED
2019-02-08 18:45:16,343 INFO org.apache.hadoop.yarn.server.resourcemanager.ApplicationMasterService: Registering app attempt : appattempt_1549629837143_0005_000001
2019-02-08 18:45:16,343 INFO org.apache.hadoop.yarn.server.resourcemanager.rmapp.attempt.RMAppAttemptImpl: appattempt_1549629837143_0005_000001 State change from NEW to SUBMITTED
2019-02-08 18:45:16,343 WARN org.apache.hadoop.yarn.server.resourcemanager.scheduler.capacity.LeafQueue: maximum-am-resource-percent is insufficient to start a single application in queue, it is likely set too low. skipping enforcement to allow at least one application to start
2019-02-08 18:45:16,343 WARN org.apache.hadoop.yarn.server.resourcemanager.scheduler.capacity.LeafQueue: maximum-am-resource-percent is insufficient to start a single application in queue for user, it is likely set too low. skipping enforcement to allow at least one application to start
2019-02-08 18:45:16,343 INFO org.apache.hadoop.yarn.server.resourcemanager.scheduler.capacity.LeafQueue: Application application_1549629837143_0005 from user: root activated in queue: default
2019-02-08 18:45:16,343 INFO org.apache.hadoop.yarn.server.resourcemanager.scheduler.capacity.LeafQueue: Application added - appId: application_1549629837143_0005 user: org.apache.hadoop.yarn.server.resourcemanager.scheduler.capacity.LeafQueue$User@19080b59, leaf-queue: default #user-pending-applications: 0 #user-active-applications: 1 #queue-pending-applications: 0 #queue-active-applications: 1
2019-02-08 18:45:16,343 INFO org.apache.hadoop.yarn.server.resourcemanager.scheduler.capacity.CapacityScheduler: Added Application Attempt appattempt_1549629837143_0005_000001 to scheduler from user root in queue default
2019-02-08 18:45:16,346 INFO org.apache.hadoop.yarn.server.resourcemanager.rmapp.attempt.RMAppAttemptImpl: appattempt_1549629837143_0005_000001 State change from SUBMITTED to SCHEDULED
